Workbook
Name \0: #REF!
Name \A: #REF!
Name \A: #REF!
Name \B: #REF!
Name \B: #REF!
Name \C: #N/A
Name \D: #REF!
Name \E: #REF!
Name \f: #REF!
Name \I: #N/A
Name \J: #REF!
Name \K: #N/A
Name \L: #N/A
Name \M: #N/A
Name \N: #N/A
Name \o: #REF!
Name \P: #REF!
Name \R: #N/A
Name \S: #REF!
Name \T: #REF!
Name \W: #N/A
Name \X: #N/A
Name \Y: #N/A
Name \Z: #N/A
Name ___________________CAP2: #REF!
Name ___________________clp2: #REF!
Name ___________________coc2: #REF!
Name ___________________hpe1: #REF!
Name ___________________hpe2: #REF!
Name ___________________hwp1: #REF!
Name ___________________hwp2: #REF!
Name __________________CAP2: #REF!
Name __________________clp2: #REF!
Name __________________coc2: #REF!
Name __________________hpe1: #REF!
Name __________________hpe2: #REF!
Name __________________hwp1: #REF!
Name __________________hwp2: #REF!
Name _________________CAP2: #REF!
Name _________________clp2: #REF!
Name _________________coc2: #REF!
Name _________________hpe1: #REF!
Name _________________hpe2: #REF!
Name _________________hwp1: #REF!
Name _________________hwp2: #REF!
Name ________________CAP2: #REF!
Name ________________clp2: #REF!
Name ________________coc2: #REF!
Name ________________hpe1: #REF!
Name ________________hpe2: #REF!
Name ________________hwp1: #REF!
Name ________________hwp2: #REF!
Name _______________CAP2: #REF!
Name _______________clp2: #REF!
Name _______________coc2: #REF!
Name _______________hpe1: #REF!
Name _______________hpe2: #REF!
Name _______________hwp1: #REF!
Name _______________hwp2: #REF!
Name ______________apr06: #REF!

Sheet Att 1 Summary
A1: Central Maine Power Company
A2: Proposed Price Change for Rate A-Seasonal Rate
A3: Effective October 1, 2026
A5: A-Seasonal/Heat-Pump Rate
A7: Rates in Effect October 1, 2025 1/
C9: Distribution | D9: ELP | E9: EMT | F9: Stranded | G9: Transmission | H9: Total Rates | I9: % Change
C10: Rates | D10: Assessment | E10: Assessment | F10: Cost Rates | G10: Rates | H10: Effective | I10: in
C11: 45839 | D11: 44927 | E11: 45839 | F11: 45931 | G11: 45839 | H11: 45931 | I11: Component
A12: Service Charge | C12: 31.6 | D12: 0 | E12: 0 | F12: 9.64 | G12: 0 | H12: =SUM(C12:G12) -> 41.24
A13: kWh-May to October | C13: 0.156129 | D13: 0.001468 | E13: 0.007767 | F13: -0.000991 | G13: 0.111237 | H13: =SUM(C13:G13) -> 0.27561
A14: kWh-November to April | C14: 0 | D14: 0.001468 | E14: 0.007767 | F14: -0.000991 | G14: 0 | H14: =SUM(C14:G14) -> 0.008244
A16: Rates proposed to be effective October 1, 2026
C18: Distribution | D18: ELP | E18: EMT | F18: Stranded | G18: Transmission | H18: Total Rates | I18: % Change
C19: Rates | D19: Assessment | E19: Assessment | F19: Cost Rates | G19: Rates | H19: Effective | I19: in
C20: 46204 | D20: 44927 | E20: 46204 | F20: 45931 | G20: 46023 | H20: 46296 | I20: Component
A21: Service Charge | C21: =ROUND(+'Att 1 Rate Design p2'!K11,2) -> 31.6 | F21: =ROUND(+'Att 1 Rate Design p2'!N11,2) -> 9.64 | H21: =+C21+F21 -> 41.24 | I21: =+(+H21-H12)/H12 -> 0
A22: kWh-May to October | C22: =ROUND(+'Att 1 Rate Design p2'!K12,6) -> 0.123468 | D22: =ROUND(+'Att 1 Rate Design p2'!L12,6) -> 0.001468 | E22: =ROUND(+'Att 1 Rate Design p2'!M12,6) -> 0.002722 | F22: =ROUND(+'Att 1 Rate Design p2'!N12,6) -> -0.000991 | G22: =ROUND(+'Att 1 Rate Design p2'!O12,6) -> 0.122643 | H22: =SUM(C22:G22) -> 0.24931 | I22: =+(+H22-H13)/H13 -> -0.095424694
A23: kWh-November to April | C23: 0 | D23: =ROUND(+'Att 1 Rate Design p2'!L13,6) -> 0.001468 | E23: =ROUND(+'Att 1 Rate Design p2'!M13,6) -> 0.002722 | F23: =ROUND(+'Att 1 Rate Design p2'!N13,6) -> -0.000991 | G23: =ROUND(+'Att 1 Rate Design p2'!O13,6) -> 0 | H23: =SUM(C23:G23) -> 0.003199 | I23: =+(+H23-H14)/H14 -> -0.61196021
A26: 1/ On January 29, 2026, CMP filed a cancellation of the A-Seasonal Rate in compliance with the Termination Date
A27: lanuage from the A-Seasonal Tariff, effective February 1, 2026.

Sheet Att 1 Rate Design p2
A1: Heat Pump Rate
A2: Rate Design - October 1 2026
D4: Rates in Effect October 1, 2025 | K4: Rates Proposed October 1, 2026
D7: Distribution | E7: ELP | F7: EMT | G7: Stranded | H7: Transmission | I7: Total Rates | K7: Distribution | L7: ELP | M7: EMT | N7: Stranded | O7: Transmission | P7: Total Rates
D8: Rates | E8: Assessment | F8: Assessment | G8: Cost Rates | H8: Rates | I8: Effective | K8: Rates | L8: Assessment | M8: Assessment | N8: Cost Rates | O8: Rates | P8: Effective
D9: 45839 | E9: 44927 | F9: 45839 | G9: 45931 | H9: 45839 | I9: 45931 | K9: 46204 | L9: 44927 | M9: 46204 | N9: 45931 | O9: 46023 | P9: 46296
A10: Heat Pump Rate
A11: Service Charge | D11: 31.6 | E11: 0 | F11: 0 | G11: 9.64 | H11: 0 | I11: =SUM(D11:H11) -> 41.24 | K11: =+C29 -> 31.6 | N11: =+G11 -> 9.64 | P11: =SUM(K11:O11) -> 41.24
A12: kWh-May to October | D12: 0.156129 | E12: 0.001468 | F12: 0.007767 | G12: -0.000991 | H12: 0.111237 | I12: =SUM(D12:H12) -> 0.27561 | K12: =+C30 -> 0.123468 | L12: =+D30 -> 0.001468 | M12: =+E30 -> 0.002722 | N12: =+G12 -> -0.000991 | O12: =+G30 -> 0.122643 | P12: =SUM(K12:O12) -> 0.24931
A13: kWh-November to April | D13: 0 | E13: 0.001468 | F13: 0.007767 | G13: -0.000991 | H13: 0 | I13: =SUM(D13:H13) -> 0.008244 | L13: =+D31 -> 0.001468 | M13: =+E31 -> 0.002722 | N13: =+G13 -> -0.000991 | O13: =+G31 -> 0 | P13: =SUM(K13:O13) -> 0.003199
A25: Rate Design by Component - Proposed
C27: Distribution (1) | D27: ELP (2) | E27: EMT (2) | F27: Stranded (2) | G27: Transmission (3) | H27: Total
A29: Customer Charge - October 1, 2026 | C29: 31.6 | F29: 9.64 | H29: =SUM(C29:G29) -> 41.24 | I29: <= Set equal to the Service Charge under Rate ET Rate
A30: Per KWH - May to October | C30: =0.123468 -> 0.123468 | D30: 0.001468 | E30: 0.002722 | F30: -0.000991 | G30: =+'Att 1 Rate Design p3'!I21 -> 0.122643 | H30: =SUM(C30:G30) -> 0.24931 | I30: <= Set to generate the same level of revenue as under the Rate ETS for January 1 Rates
A31: Per KWH - All Other | D31: 0.001468 | E31: 0.002722 | F31: -0.000991 | G31: =+'Att 1 Rate Design p3'!I22 -> 0 | H31: =SUM(C31:G31) -> 0.003199
A35: (1) Distribution rate component is adjusted such that the level of revenue generated from a heat pump customer using 9,335 kWh for heating and 1000 kWh for cooling is the same as under the ET rate but collected from May through October only. See Bill Calculations for ETS vs Heat Pump on page 3
A37: (2) ELP, EMT and Stranded Costs Rates are set to equal the rate under the ET rate and are collected evenly over the 12 months
A39: (3) Transmission rate updated 1/1/2026 to collect from May to October only.

Sheet Att 1 Rate Design p3
C1: Central Maine Power Company
C2: Residential Heat Pump Rate
C3: Collect T & D kwh charge in May to October Only. Monthly Service Charge = Marginal Cost 2018-00194 (Table 5 from 10-15-2018 Marginal cost Study Testimony and Exhibits)
I6: Transmission Rate for Residential Heat Pump Customers
C9: Transmission Revenue Requirement - Residential - January 1, 2026 | I9: 2.2996759e+08
C13: Billing Units kWh: | R13: 2026 RDM Target Units
C14: KWH - May & October 50 or less | I14: 1.7835757e+08 | R14: 171158958 | S14: =+R14+R16 -> 340147870 | T14: =+R14/S14 -> 0.50318986
C15: KWH - May to October | I15: 1.8750992e+09 | R15: 1879078526 | S15: =+R15+R17 -> 3980451551 | T15: =+R15/S15 -> 0.47207672
C16: KWH - All Other 50 or less | I16: 1.7609626e+08 | R16: 168988912 | T16: =+R16/S14 -> 0.49681014
C17: KWH - All Other | I17: 2.096923e+09 | R17: 2101373025 | T17: =+R17/S15 -> 0.52792328
C18: Total | I18: =SUM(I14:I17) -> 4.3264761e+09 | M18: Total kWh Transmission Rate Calculation - January 1, 2026 | N18: 4.3264761e+09
M19: Variance | N19: =+N18-I18 -> 0
C20: Rate per kWh
C21: Per KWH - May to October | I21: =ROUND((I9)/(+I15),6) -> 0.122643
C22: Per KWH - All Other | I22: =ROUND((+I9-I26)/(I17+I16),6) -> 0
C25: Revenue per kWh | E25: =+#REF!*E20 -> #REF! | F25: #REF! | G25: #REF! | H25: #REF!
C26: Per KWH - May to October | E26: =+E15*E21 -> 0 | F26: =+F15*F21 -> 0 | G26: =+G15*G21 -> 0 | H26: =+H15*H21 -> 0 | I26: =(+I15)*I21 -> 2.299678e+08
C27: Per KWH - All Other | E27: =+E17*E22 -> 0 | F27: =+F17*F22 -> 0 | G27: =+G17*G22 -> 0 | H27: =+H17*H22 -> 0 | I27: =+I17*I22 -> 0
C28: Total | E28: =SUM(E25:E27) -> #REF! | F28: =SUM(F25:F27) -> #REF! | G28: =SUM(G25:G27) -> #REF! | H28: =SUM(H25:H27) -> #REF! | I28: =SUM(I25:I27) -> 2.299678e+08

Sheet Att 1 Rate Design p4
A1: Heat Pump Customer
A2: Bill Calculations - Heat Pump Rate
C3: January | D3: February | E3: March | F3: April | G3: May | H3: June | I3: July | J3: August | K3: September | L3: October | M3: November | N3: December
A4: ASHP Monthly Load Profile - Heat | C4: 0.18147567 | D4: 0.17198345 | E4: 0.15236963 | F4: 0.079857486 | G4: 0.038785245 | H4: 0.021243667 | I4: 0.014596531 | J4: 0.014400789 | K4: 0.016202452 | L4: 0.03785267 | M4: 0.088059081 | N4: 0.18317333 | O4: => Total Load | P4: 9335
A5: ASHP Monthly Load Profile - AC | C5: 0 | D5: 0 | E5: 0 | F5: 0.024177785 | G5: 0.048924905 | H5: 0.18810848 | I5: 0.28973488 | J5: 0.26436149 | K5: 0.15960374 | L5: 0.024329607 | M5: 0.00075911411 | N5: 0 | O5: => Total Load | P5: 1000
A8: HEAT PUMP
C9: January | D9: February | E9: March | F9: April | G9: May | H9: June | I9: July | J9: August | K9: September | L9: October | M9: November | N9: December | O9: Total
B10: Base kWh | C10: 500 | D10: 500 | E10: 500 | F10: 500 | G10: 500 | H10: 500 | I10: 500 | J10: 500 | K10: 500 | L10: 500 | M10: 500 | N10: 500 | O10: =SUM(C10:N10) -> 6000
B11: ASHP kWh - Heat | C11: =C4*$O$11 -> 1694.0754 | D11: =D4*$O$11 -> 1605.4655 | E11: =E4*$O$11 -> 1422.3705 | F11: =F4*$O$11 -> 745.46964 | G11: =G4*$O$11 -> 362.06026 | H11: =H4*$O$11 -> 198.30963 | I11: =I4*$O$11 -> 136.25862 | J11: =J4*$O$11 -> 134.43137 | ... N11: =N4*$O$11 -> 1709.9231 | O11: =P4 -> 9335
B12: ASHP kWh - AC | C12: =C5*$O$12 -> 0 | D12: =D5*$O$12 -> 0 | E12: =E5*$O$12 -> 0 | F12: =F5*$O$12 -> 24.177785 | G12: =G5*$O$12 -> 48.924905 | H12: =H5*$O$12 -> 188.10848 | I12: =I5*$O$12 -> 289.73488 | J12: =J5*$O$12 -> 264.36149 | ... N12: =N5*$O$12 -> 0 | O12: =P5 -> 1000 | P12: => Heating Load monthly profile
B14: Service Charge | C14: =+'Att 1 Rate Design p2'!$H$29 -> 41.24 | D14: =+'Att 1 Rate Design p2'!$H$29 -> 41.24 | E14: =+'Att 1 Rate Design p2'!$H$29 -> 41.24 | F14: =+'Att 1 Rate Design p2'!$H$29 -> 41.24 | G14: =+'Att 1 Rate Design p2'!$H$29 -> 41.24 | H14: =+'Att 1 Rate Design p2'!$H$29 -> 41.24 | I14: =+'Att 1 Rate Design p2'!$H$29 -> 41.24 | J14: =+'Att 1 Rate Design p2'!$H$29 -> 41.24 | ... N14: =+'Att 1 Rate Design p2'!$H$29 -> 41.24 | O14: =SUM(C14:N14) -> 494.88
B15: Base kWh | C15: =ROUND((C10)*'Att 1 Rate Design p2'!$H$31,2) -> 1.6 | D15: =ROUND((D10)*'Att 1 Rate Design p2'!$H$31,2) -> 1.6 | E15: =ROUND((E10)*'Att 1 Rate Design p2'!$H$31,2) -> 1.6 | F15: =ROUND((F10)*'Att 1 Rate Design p2'!$H$31,2) -> 1.6 | G15: =ROUND((G10)*'Att 1 Rate Design p2'!$H$30,2) -> 124.66 | H15: =ROUND((H10)*'Att 1 Rate Design p2'!$H$30,2) -> 124.66 | I15: =ROUND((I10)*'Att 1 Rate Design p2'!$H$30,2) -> 124.66 | J15: =ROUND((J10)*'Att 1 Rate Design p2'!$H$30,2) -> 124.66 | K15: =ROUND((K10)*'Att 1 Rate Design p2'!$H$30,2) -> 124.66 | L15: =ROUND((L10)*'Att 1 Rate Design p2'!$H$30,2) -> 124.66 | M15: =ROUND((M10)*'Att 1 Rate Design p2'!$H$31,2) -> 1.6 | N15: =ROUND((N10)*'Att 1 Rate Design p2'!$H$31,2) -> 1.6 | O15: =SUM(C15:N15) -> 757.56
B16: ASHP - Heat | C16: =ROUND((C11)*'Att 1 Rate Design p2'!$H$31,2) -> 5.42 | D16: =ROUND((D11)*'Att 1 Rate Design p2'!$H$31,2) -> 5.14 | E16: =ROUND((E11)*'Att 1 Rate Design p2'!$H$31,2) -> 4.55 | F16: =ROUND((F11)*'Att 1 Rate Design p2'!$H$31,2) -> 2.38 | G16: =ROUND((G11)*'Att 1 Rate Design p2'!$H$30,2) -> 90.27 | H16: =ROUND((H11)*'Att 1 Rate Design p2'!$H$30,2) -> 49.44 | I16: =ROUND((I11)*'Att 1 Rate Design p2'!$H$30,2) -> 33.97 | J16: =ROUND((J11)*'Att 1 Rate Design p2'!$H$30,2) -> 33.52 | K16: =ROUND((K11)*'Att 1 Rate Design p2'!$H$30,2) -> 37.71 | L16: =ROUND((L11)*'Att 1 Rate Design p2'!$H$30,2) -> 88.09 | M16: =ROUND((M11)*'Att 1 Rate Design p2'!$H$31,2) -> 2.63 | N16: =ROUND((N11)*'Att 1 Rate Design p2'!$H$31,2) -> 5.47 | O16: =SUM(C16:N16) -> 358.59
B17: ASHP - AC | C17: =ROUND((C12)*'Att 1 Rate Design p2'!$H$31,2) -> 0 | D17: =ROUND((D12)*'Att 1 Rate Design p2'!$H$31,2) -> 0 | E17: =ROUND((E12)*'Att 1 Rate Design p2'!$H$31,2) -> 0 | F17: =ROUND((F12)*'Att 1 Rate Design p2'!$H$31,2) -> 0.08 | G17: =ROUND((G12)*'Att 1 Rate Design p2'!$H$30,2) -> 12.2 | H17: =ROUND((H12)*'Att 1 Rate Design p2'!$H$30,2) -> 46.9 | I17: =ROUND((I12)*'Att 1 Rate Design p2'!$H$30,2) -> 72.23 | J17: =ROUND((J12)*'Att 1 Rate Design p2'!$H$30,2) -> 65.91 | K17: =ROUND((K12)*'Att 1 Rate Design p2'!$H$30,2) -> 39.79 | L17: =ROUND((L12)*'Att 1 Rate Design p2'!$H$30,2) -> 6.07 | M17: =ROUND((M12)*'Att 1 Rate Design p2'!$H$31,2) -> 0 | N17: =ROUND((N12)*'Att 1 Rate Design p2'!$H$31,2) -> 0 | O17: =SUM(C17:N17) -> 243.18
B18: Total | C18: =+C14+C15+C16+C17 -> 48.26 | D18: =+D14+D15+D16+D17 -> 47.98 | E18: =+E14+E15+E16+E17 -> 47.39 | F18: =+F14+F15+F16+F17 -> 45.3 | G18: =+G14+G15+G16+G17 -> 268.37 | H18: =+H14+H15+H16+H17 -> 262.24 | I18: =+I14+I15+I16+I17 -> 272.1 | J18: =+J14+J15+J16+J17 -> 265.33 | ... O18: =+O14+O15+O16+O17 -> 1854.21 | P18: A
A21: Heat Pump Customer
A22: Bill Calculations - ET Rate
D24: Customer Charge | F24: 41.24
D25: kwh Rate | F25: 0.088638
A27: ET Rate July 1, 2026
B28: =B10 -> Base kWh | C28: =C10 -> 500 | D28: =D10 -> 500 | E28: =E10 -> 500 | F28: =F10 -> 500 | G28: =G10 -> 500 | H28: =H10 -> 500 | I28: =I10 -> 500 | ... N28: =N10 -> 500
B29: =B11 -> ASHP kWh - Heat | C29: =C11 -> 1694.0754 | D29: =D11 -> 1605.4655 | E29: =E11 -> 1422.3705 | F29: =F11 -> 745.46964 | G29: =G11 -> 362.06026 | H29: =H11 -> 198.30963 | I29: =I11 -> 136.25862 | ... N29: =N11 -> 1709.9231 | O29: =SUM(C29:N29) -> 9335
B30: =B12 -> ASHP kWh - AC | C30: =C12 -> 0 | D30: =D12 -> 0 | E30: =E12 -> 0 | F30: =F12 -> 24.177785 | G30: =G12 -> 48.924905 | H30: =H12 -> 188.10848 | I30: =I12 -> 289.73488 | ... O30: =O12 -> 1000
B32: =B14 -> Service Charge | C32: =+$F$24 -> 41.24 | D32: =+$F$24 -> 41.24 | E32: =+$F$24 -> 41.24 | F32: =+$F$24 -> 41.24 | G32: =+$F$24 -> 41.24 | H32: =+$F$24 -> 41.24 | I32: =+$F$24 -> 41.24 | J32: =+$F$24 -> 41.24 | ... N32: =+$F$24 -> 41.24 | O32: =SUM(C32:N32) -> 494.88
B33: =B15 -> Base kWh | C33: =ROUND((C28)*$F$25,2) -> 44.32 | D33: =ROUND((D28)*$F$25,2) -> 44.32 | E33: =ROUND((E28)*$F$25,2) -> 44.32 | F33: =ROUND((F28)*$F$25,2) -> 44.32 | G33: =ROUND((G28)*$F$25,2) -> 44.32 | H33: =ROUND((H28)*$F$25,2) -> 44.32 | I33: =ROUND((I28)*$F$25,2) -> 44.32 | J33: =ROUND((J28)*$F$25,2) -> 44.32 | ... N33: =ROUND((N28)*$F$25,2) -> 44.32 | O33: =SUM(C33:N33) -> 531.84
B34: =B16 -> ASHP - Heat | C34: =ROUND((C29)*$F$25,2) -> 150.16 | D34: =ROUND((D29)*$F$25,2) -> 142.31 | E34: =ROUND((E29)*$F$25,2) -> 126.08 | F34: =ROUND((F29)*$F$25,2) -> 66.08 | G34: =ROUND((G29)*$F$25,2) -> 32.09 | H34: =ROUND((H29)*$F$25,2) -> 17.58 | I34: =ROUND((I29)*$F$25,2) -> 12.08 | J34: =ROUND((J29)*$F$25,2) -> 11.92 | ... N34: =ROUND((N29)*$F$25,2) -> 151.56 | O34: =SUM(C34:N34) -> 827.45
B35: =B17 -> ASHP - AC | C35: =ROUND((C30)*$F$25,2) -> 0 | D35: =ROUND((D30)*$F$25,2) -> 0 | E35: =ROUND((E30)*$F$25,2) -> 0 | F35: =ROUND((F30)*$F$25,2) -> 2.14 | G35: =ROUND((G30)*$F$25,2) -> 4.34 | H35: =ROUND((H30)*$F$25,2) -> 16.67 | I35: =ROUND((I30)*$F$25,2) -> 25.68 | J35: =ROUND((J30)*$F$25,2) -> 23.43 | ... N35: =ROUND((N30)*$F$25,2) -> 0 | O35: =SUM(C35:N35) -> 88.64
B36: Total | C36: =+C32+C33+C34+C35 -> 235.72 | D36: =+D32+D33+D34+D35 -> 227.87 | E36: =+E32+E33+E34+E35 -> 211.64 | F36: =+F32+F33+F34+F35 -> 153.78 | G36: =+G32+G33+G34+G35 -> 121.99 | H36: =+H32+H33+H34+H35 -> 119.81 | I36: =+I32+I33+I34+I35 -> 123.32 | J36: =+J32+J33+J34+J35 -> 120.91 | ... N36: =+N32+N33+N34+N35 -> 237.12 | O36: =+O32+O33+O34 -> 1854.17 | P36: B
D40: Customer Charge | F40: 13.73
D41: kwh Rate | F41: 0.087751
A42: Existing Rate A
B44: =B10 -> Base kWh | C44: =C10 -> 500 | D44: =D10 -> 500 | E44: =E10 -> 500 | F44: =F10 -> 500 | G44: =G10 -> 500 | H44: =H10 -> 500 | I44: =I10 -> 500 | ... N44: =N10 -> 500 | O44: =SUM(C44:N44) -> 6000
B45: =B11 -> ASHP kWh - Heat | C45: =C11 -> 1694.0754 | D45: =D11 -> 1605.4655 | E45: =E11 -> 1422.3705 | F45: =F11 -> 745.46964 | G45: =G11 -> 362.06026 | H45: =H11 -> 198.30963 | I45: =I11 -> 136.25862 | ... N45: =N11 -> 1709.9231 | O45: =SUM(C45:N45) -> 9335
B46: =B12 -> ASHP kWh - AC | C46: =C12 -> 0 | D46: =D12 -> 0 | E46: =E12 -> 0 | F46: =F12 -> 24.177785 | G46: =G12 -> 48.924905 | H46: =H12 -> 188.10848 | I46: =I12 -> 289.73488 | ... O46: =O12 -> 1000
B47: =B13 -> 0
B48: =B14 -> Service Charge | C48: =+$F$40 -> 13.73 | D48: =+$F$40 -> 13.73 | E48: =+$F$40 -> 13.73 | F48: =+$F$40 -> 13.73 | G48: =+$F$40 -> 13.73 | H48: =+$F$40 -> 13.73 | I48: =+$F$40 -> 13.73 | J48: =+$F$40 -> 13.73 | ... N48: =+$F$40 -> 13.73 | O48: =SUM(C48:N48) -> 164.76
B49: =B15 -> Base kWh | C49: =ROUND((C44-50)*$F$41,2) -> 39.49 | D49: =ROUND((D44-50)*$F$41,2) -> 39.49 | E49: =ROUND((E44-50)*$F$41,2) -> 39.49 | F49: =ROUND((F44-50)*$F$41,2) -> 39.49 | G49: =ROUND((G44-50)*$F$41,2) -> 39.49 | H49: =ROUND((H44-50)*$F$41,2) -> 39.49 | I49: =ROUND((I44-50)*$F$41,2) -> 39.49 | J49: =ROUND((J44-50)*$F$41,2) -> 39.49 | ... N49: =ROUND((N44-50)*$F$41,2) -> 39.49 | O49: =SUM(C49:N49) -> 473.88 | P49: =O48+O49 -> 638.64
B50: =B16 -> ASHP - Heat | C50: =ROUND(C45*$F$41,2) -> 148.66 | D50: =ROUND(D45*$F$41,2) -> 140.88 | E50: =ROUND(E45*$F$41,2) -> 124.81 | F50: =ROUND(F45*$F$41,2) -> 65.42 | G50: =ROUND(G45*$F$41,2) -> 31.77 | H50: =ROUND(H45*$F$41,2) -> 17.4 | I50: =ROUND(I45*$F$41,2) -> 11.96 | J50: =ROUND(J45*$F$41,2) -> 11.8 | ... N50: =ROUND(N45*$F$41,2) -> 150.05 | O50: =SUM(C50:N50) -> 819.16
B51: =B17 -> ASHP - AC | C51: =ROUND(C46*$F$41,2) -> 0 | D51: =ROUND(D46*$F$41,2) -> 0 | E51: =ROUND(E46*$F$41,2) -> 0 | F51: =ROUND(F46*$F$41,2) -> 2.12 | G51: =ROUND(G46*$F$41,2) -> 4.29 | H51: =ROUND(H46*$F$41,2) -> 16.51 | I51: =ROUND(I46*$F$41,2) -> 25.42 | J51: =ROUND(J46*$F$41,2) -> 23.2 | ... N51: =ROUND(N46*$F$41,2) -> 0 | O51: =SUM(C51:N51) -> 87.75
B52: Total | C52: =+C48+C49+C50+C51 -> 201.88 | D52: =+D48+D49+D50+D51 -> 194.1 | E52: =+E48+E49+E50+E51 -> 178.03 | F52: =+F48+F49+F50+F51 -> 120.76 | G52: =+G48+G49+G50+G51 -> 89.28 | H52: =+H48+H49+H50+H51 -> 87.13 | I52: =+I48+I49+I50+I51 -> 90.6 | J52: =+J48+J49+J50+J51 -> 88.22 | ... O52: =+O48+O49+O50+O51 -> 1545.55
...
