Workbook
Name _NH12: [4]Market!#REF!
Name _NH2: [4]Market!#REF!
Name _NH3: [4]Market!#REF!
Name _NH5: [4]Market!#REF!
Name _NH6: [4]Market!#REF!
Name _NH7: [4]Market!#REF!
Name _NH8: [4]Market!#REF!
Name _NH9: [4]Market!#REF!
Name _RI1: [4]Market!#REF!
Name _RI10: [4]Market!#REF!
Name _RI11: [4]Market!#REF!
Name _RI12: [4]Market!#REF!
Name _RI3: [4]Market!#REF!
Name _RI4: [4]Market!#REF!
Name _RI5: [4]Market!#REF!
Name _RI7: [4]Market!#REF!
Name _RI8: [4]Market!#REF!
Name _RI9: [4]Market!#REF!
Name Alloc0: [5]AllocFctr!$F$7
Name arClassOff: [5]Total!$7:$7
Name August_January_Basic_Service_Rate: '[6]Summary Bill Impacts'!$D$5
Name Current_Year_1: #REF!
Name Current_Year_1: #REF!
Name DEF_RECLASS: #REF!
Name DEF_RECLASS: #REF!
Name DEF_RECLASS_MA: #REF!
Name DEF_RECLASS_MA: #REF!
Name DEF_RECLASS_SURCHARGE: #REF!
Name DEF_RECLASS_SURCHARGE: #REF!
Name DEF_RECLASS_SURCHARGE_MA: #REF!
Name Delivery_Peak_Period_End: '[6]Summary Bill Impacts'!$D$7
Name Delivery_Peak_Period_Start: '[6]Summary Bill Impacts'!$D$6
Name February_July_Basic_Service_Rate: '[6]Summary Bill Impacts'!$D$4
Name ForecastError: '[7]NH Summary Ind'!#REF!
Name FUEL_ADJ_VALUE: #REF!
Name GAS: #REF!
Name GranAvgLF: [7]NHLoads!$U$2
Name GranLrgLF: [7]NHLoads!$S$2
Name GranSmlLF: [7]NHLoads!$T$2
Name HVM: #REF!
Name HVM: #REF!
Name Index: #REF!
Name Index: #REF!
Name LR: #REF!
Name LR: #REF!
Name MassCLF: [7]MALoads!$AD$1
Name MidMonth2: [7]Data!$L$10
Name MKT_GAS_PRICE: #REF!
Name MKT_OIL_PRICE: #REF!
Name OIL: #REF!
Name OnPeak: [8]Data!#REF!
Name page1: #REF!
Name page2: #REF!
Name page3: #REF!
Name page4: #REF!
Name Proj_Exp: #REF!
Name Proj_Exp: #REF!
Name Rev_Est: #REF!
Name Rev_Est: #REF!
Name SO_Rev: #REF!

Sheet Transmission Rate Design
C1: Massachusetts Electric Company
C2: and Nantucket Electric Company
C3: each d/b/a National Grid
C4: D.P.U. 25-08
C5: Attachment DPU-Common 1-5-NG
C6: Page 1 of 3
A10: =C1 -> Massachusetts Electric Company
A11: =C2 -> and Nantucket Electric Company
A12: Calculation of Illustrative Transmission Heat Pump Rates
A15: -1 | B15: Allocated 2025 Residential Transmission Expense to be Recovered | C15: 486659129
A17: =A15-1 -> -2 | B17: Forecasted Residential kWh Sales - March 2025 through February 2026 | C17: ='Adjusted Forecast'!E31 -> 8392795599
A19: =A17-1 -> -3 | B19: 2025 Net Transmission Charge per kWh eff. March 2025 through February 2026 | C19: =TRUNC(C15/C17,5) -> 0.05798
A21: =A19-1 -> -4 | B21: Forecasted Residential kWh Sales - Summer | C21: =SUM('Adjusted Forecast'!E20:E25) -> 3980617498
A23: =A21-1 -> -5 | B23: Energy Revenue - Summer | C23: =C21*C19 -> 2.307962e+08
A25: =A23-1 -> -6 | B25: Energy Revenue - Winter | C25: =C15-C23 -> 2.5586293e+08
A27: =A25-1 -> -7 | B27: Forecasted Residential kWh Sales - Winter - HP Adjusted | C27: ='Adjusted Forecast'!G31 -> 1.2067903e+10
A29: =A27-1 -> -8 | B29: 2025 Net Transmission Charge per kWh eff. November through April | C29: =TRUNC(C25/C27,5) -> 0.0212
A34: (1) | B34: Per D.P.U. 25-02, Exhibit DEG-10, Page 1, Line (4), Column (b) + Exhibit DEG-9, Page 1, Line (4), Column (b)
A35: =A34-1 -> -2 | B35: Per Company Forecast
A36: =A35-1 -> -3 | B36: Line (1) ÷ Line (2), truncated after 5 decimal places
A37: =A36-1 -> -4 | B37: Page 2, Lines (3) through (8), Column (c)
A38: =A37-1 -> -5 | B38: Line (3) x Line (4)
A39: =A38-1 -> -6 | B39: Line (1) - Line (5)
A40: =A39-1 -> -7 | B40: Page 2, Line (14), Column (e)
A41: =A40-1 -> -8 | B41: Line (6) ÷ Line (7), truncated after 5 decimal places

Sheet Adjusted Forecast
G1: ='Transmission Rate Design'!C1 -> Massachusetts Electric Company
G2: ='Transmission Rate Design'!C2 -> and Nantucket Electric Company
G3: ='Transmission Rate Design'!C3 -> each d/b/a National Grid
G4: ='Transmission Rate Design'!C4 -> D.P.U. 25-08
G5: ='Transmission Rate Design'!C5 -> Attachment DPU-Common 1-5-NG
G6: Page 2 of 3
G7: ='Transmission Rate Design'!C7 -> 0
A10: =G1 -> Massachusetts Electric Company
A11: =G2 -> and Nantucket Electric Company
A12: Company Forecast kWh Deliveries and Heat Pump Adjustment
F15: Winter Heat Pump | G15: Heat Pump
C16: R1 | D16: R2 | E16: Total | F16: Adjustment Factor | G16: Adj. Forecast
C17: (a) | D17: (b) | E17: (c) | F17: (d) | G17: (e)
A18: -1 | B18: 45717 | C18: 633907208 | D18: 96347101 | E18: =C18+D18 -> 730254309 | F18: =SUM('Heat Pump Rate Design'!G24:G27,'Heat Pump Rate Design'!G34:G35)/SUM('Heat Pump Rate Design'!C24:C27,'Heat Pump Rate Design'!C34:C35) -> 2.735135 | G18: =E18*F18 -> 1.9973441e+09
A19: =A18-1 -> -2 | B19: 45748 | C19: 539686038 | D19: 81839426 | E19: =C19+D19 -> 621525464 | F19: =F18 -> 2.735135 | G19: =E19*F19 -> 1.6999561e+09
A20: =A19-1 -> -3 | B20: 45778 | C20: 443644573 | D20: 67153753 | E20: =C20+D20 -> 510798326
A21: =A20-1 -> -4 | B21: 45809 | C21: 516638051 | D21: 78265302 | E21: =C21+D21 -> 594903353
A22: =A21-1 -> -5 | B22: 45839 | C22: 658966357 | D22: 99664627 | E22: =C22+D22 -> 758630984
A23: =A22-1 -> -6 | B23: 45870 | C23: 709936543 | D23: 107151015 | E23: =C23+D23 -> 817087558
A24: =A23-1 -> -7 | B24: 45901 | C24: 633888471 | D24: 95631768 | E24: =C24+D24 -> 729520239
A25: =A24-1 -> -8 | B25: 45931 | C25: 494901857 | D25: 74775181 | E25: =C25+D25 -> 569677038
A26: =A25-1 -> -9 | B26: 45962 | C26: 518541609 | D26: 78736627 | E26: =C26+D26 -> 597278236 | F26: =F19 -> 2.735135 | G26: =E26*F26 -> 1.6336366e+09
A27: =A26-1 -> -10 | B27: 45992 | C27: 667370081 | D27: 101534418 | E27: =C27+D27 -> 768904499 | F27: =F26 -> 2.735135 | G27: =E27*F27 -> 2.1030576e+09
A28: =A27-1 -> -11 | B28: 46023 | C28: 758861290 | D28: 115471502 | E28: =C28+D28 -> 874332792 | F28: =F27 -> 2.735135 | G28: =E28*F28 -> 2.3914183e+09
A29: =A28-1 -> -12 | B29: 46054 | C29: 711689667 | D29: 108193134 | E29: =C29+D29 -> 819882801 | F29: =F28 -> 2.735135 | G29: =E29*F29 -> 2.2424902e+09
A30: =A29-1 -> -13
A31: =A30-1 -> -14 | B31: Total kWh | C31: =SUM(C18:C29) -> 7288031745 | D31: =SUM(D18:D29) -> 1104763854 | E31: =SUM(E18:E29) -> 8392795599 | G31: =SUM(G18:G29) -> 1.2067903e+10
A36: (a) | B36: Per Company Forecast
A37: (b) | B37: Per Company Forecast
A38: (c) | B38: Column (a) + Column (b)
A39: (d) | B39: Page 3, Winter months Column (e) ÷ Winter months Column (a)
A40: (e) | B40: Column (c) x Column (d)

Sheet Heat Pump Rate Design
O1: ='Adjusted Forecast'!G1 -> Massachusetts Electric Company
O2: ='Adjusted Forecast'!G2 -> and Nantucket Electric Company
O3: ='Adjusted Forecast'!G3 -> each d/b/a National Grid
O4: ='Adjusted Forecast'!G4 -> D.P.U. 25-08
O5: ='Adjusted Forecast'!G5 -> Attachment DPU-Common 1-5-NG
O6: Page 3 of 3
O7: ='Adjusted Forecast'!G7 -> 0
O9: Massachusetts Electric Company
O10: Nantucket Electric Company
O11: d/b/a National Grid
O12: D.P.U 23-150
O13: Exhibit NG-4
O14: Page 1 of 2
A16: Line | D16: Residential Heat Pump Rate Design (using Unitil's approach)
A17: 1 | B17: Assumptions:
A18: =IF(ISBLANK(B18),"",MAX($A$16:A17)+1)
A19: =IF(ISBLANK(B19),"",MAX($A$16:A18)+1) -> 2 | B19: R-1: Residential | C19: Proposed Rate
A20: =IF(ISBLANK(B20),"",MAX($A$16:A19)+1) -> 3 | B20: Customer Charge | C20: 10
A21: =IF(ISBLANK(B21),"",MAX($A$16:A20)+1) -> 4 | B21: Distribution Charge | C21: 0.06546
A22: =IF(ISBLANK(B22),"",MAX($A$16:A21)+1)
A23: =IF(ISBLANK(B23),"",MAX($A$16:A22)+1) -> 5 | B23: Average Monthly UPC | C23: R-1 Average Monthly Use (kWh) (a) | D23: Cost Recovery per Month (b) | E23: Fixed Cost Recovery in Volumetric Rate (c) | F23: Fixed Cost Recovery in Fixed Charge (d) | G23: Avg. Monthly Use with Heat Pump (kWh) (e) | J23: Normal Therm UPC (f) | K23: Therms (Heating Load) (g) | L23: Avg. Temp. (h) | M23: Avg. Temp COP (i) | N23: kWh Conversion (j) | O23: kWh Usage (k)
A24: =IF(ISBLANK(B24),"",MAX($A$16:A23)+1) -> 6 | B24: January | C24: 610.63541 | D24: =SUM(E24:F24) -> 49.972194 | E24: =($C$21-$C$53)*C24 -> 39.972194 | F24: =$C$20 -> 10 | G24: =C24+O24 -> 1891.8051 | J24: 132 | K24: =J24-$K$37 -> 114 | L24: 28.704892 | M24: 2.6071487 | N24: =K24*$K$38 -> 3340.2 | O24: =N24/M24 -> 1281.1697
A25: =IF(ISBLANK(B25),"",MAX($A$16:A24)+1) -> 7 | B25: February | C25: 530.69348 | D25: =SUM(E25:F25) -> 44.739195 | E25: =($C$21-$C$53)*C25 -> 34.739195 | F25: =$C$20 -> 10 | G25: =C25+O25 -> 1972.9964 | J25: 149 | K25: =J25-$K$37 -> 131 | L25: 30.572961 | M25: 2.6612302 | N25: =K25*$K$38 -> 3838.3 | O25: =N25/M25 -> 1442.3029
A26: =IF(ISBLANK(B26),"",MAX($A$16:A25)+1) -> 8 | B26: March | C26: 530.1181 | D26: =SUM(E26:F26) -> 44.701531 | E26: =($C$21-$C$53)*C26 -> 34.701531 | F26: =$C$20 -> 10 | G26: =C26+O26 -> 1712.1461 | J26: 133 | K26: =J26-$K$37 -> 115 | L26: 37.643763 | M26: 2.8506093 | N26: =K26*$K$38 -> 3369.5 | O26: =N26/M26 -> 1182.028
A27: =IF(ISBLANK(B27),"",MAX($A$16:A26)+1) -> 9 | B27: April | C27: 454.90082 | D27: =SUM(E27:F27) -> 39.777808 | E27: =($C$21-$C$53)*C27 -> 29.777808 | F27: =$C$20 -> 10 | G27: =C27+O27 -> 1131.2313 | J27: 90 | K27: =J27-$K$37 -> 72 | L27: 48.023181 | M27: 3.1191852 | N27: =K27*$K$38 -> 2109.6 | O27: =N27/M27 -> 676.33048
A28: =IF(ISBLANK(B28),"",MAX($A$16:A27)+1) -> 10 | B28: May | C28: 484.5277 | D28: =SUM(E28:F28) -> 41.717183 | E28: =($C$21-$C$53)*C28 -> 31.717183 | F28: =$C$20 -> 10 | G28: =C28+O28 -> 484.5277 | J28: 46
A29: =IF(ISBLANK(B29),"",MAX($A$16:A28)+1) -> 11 | B29: June | C29: 586.91619 | D29: =SUM(E29:F29) -> 48.419534 | E29: =($C$21-$C$53)*C29 -> 38.419534 | F29: =$C$20 -> 10 | G29: =C29+O29 -> 586.91619 | J29: 23
A30: =IF(ISBLANK(B30),"",MAX($A$16:A29)+1) -> 12 | B30: July | C30: 770.46363 | D30: =SUM(E30:F30) -> 60.434549 | E30: =($C$21-$C$53)*C30 -> 50.434549 | F30: =$C$20 -> 10 | G30: =C30+O30 -> 770.46363 | J30: 18
A31: =IF(ISBLANK(B31),"",MAX($A$16:A30)+1) -> 13 | B31: August | C31: 762.80177 | D31: =SUM(E31:F31) -> 59.933004 | E31: =($C$21-$C$53)*C31 -> 49.933004 | F31: =$C$20 -> 10 | G31: =C31+O31 -> 762.80177 | J31: 15
A32: =IF(ISBLANK(B32),"",MAX($A$16:A31)+1) -> 14 | B32: September | C32: 536.15882 | D32: =SUM(E32:F32) -> 45.096957 | E32: =($C$21-$C$53)*C32 -> 35.096957 | F32: =$C$20 -> 10 | G32: =C32+O32 -> 536.15882 | J32: 16
A33: =IF(ISBLANK(B33),"",MAX($A$16:A32)+1) -> 15 | B33: October | C33: 457.55933 | D33: =SUM(E33:F33) -> 39.951834 | E33: =($C$21-$C$53)*C33 -> 29.951834 | F33: =$C$20 -> 10 | G33: =C33+O33 -> 457.55933 | J33: 20
A34: =IF(ISBLANK(B34),"",MAX($A$16:A33)+1) -> 16 | B34: November | C34: 494.2623 | D34: =SUM(E34:F34) -> 42.35441 | E34: =($C$21-$C$53)*C34 -> 32.35441 | F34: =$C$20 -> 10 | G34: =C34+O34 -> 777.59007 | J34: 47 | K34: =J34-$K$37 -> 29 | L34: 43.20475 | M34: 2.999 | N34: =K34*$K$38 -> 849.7 | O34: =N34/M34 -> 283.32778
A35: =IF(ISBLANK(B35),"",MAX($A$16:A34)+1) -> 17 | B35: December | C35: 641.47874 | D35: =SUM(E35:F35) -> 51.991198 | E35: =($C$21-$C$53)*C35 -> 41.991198 | F35: =$C$20 -> 10 | G35: =C35+O35 -> 1436.4845 | J35: 93 | K35: =J35-$K$37 -> 75 | L35: 34.429086 | M35: 2.7641308 | N35: =K35*$K$38 -> 2197.5 | O35: =N35/M35 -> 795.00579
A36: =IF(ISBLANK(C36),"",MAX($A$16:A35)+1) -> 18 | C36: =SUM(C24:C35) -> 6860.5163 | D36: =SUM(D24:D35) -> 569.0894 | E36: =SUM(E24:E35) -> 449.0894 | F36: =SUM(F24:F35) -> 120 | G36: =SUM(G24:G35) -> 12520.681 | O36: =SUM(O24:O35) -> 5660.1646
A37: =IF(ISBLANK(K37),"",MAX($A$16:A36)+1) -> 19 | J37: Summer Base Load | K37: =AVERAGE(J29:J32) -> 18
A38: =IF(ISBLANK(B38),"",MAX($A$16:A37)+1) -> 20 | B38: Derrivation of Heat Pump Rate | J38: Therm to kWH Factor | K38: 29.3
A39: =IF(ISBLANK(B39),"",MAX($A$16:A38)+1) -> 21 | B39: Customer Charge | C39: =C20 -> 10
A40: =IF(ISBLANK(B40),"",MAX($A$16:A39)+1) -> 22 | B40: Customer Charge Revenue | C40: =C39*12 -> 120
A41: =IF(ISBLANK(B41),"",MAX($A$16:A40)+1)
A42: =IF(ISBLANK(B42),"",MAX($A$16:A41)+1) -> 23 | B42: Winter Volumetric Charge Revenue | C42: =SUM(E24:E27,E34:E35) -> 213.53634 | D42: per customer, November through April
...
