Workbook

Sheet P1. RD-1 to HP-RES
S1: DPU 23-80
S2: DOER 2-03 Attachment 1
S3: Page 1 of 4
B5: Fitchburg Gas and Electric Light Company d/b/a Unitil
B6: Basic Service Customer Typical Bill Impacts - Distribution Rate Proposal
B7: Impact on RD-1 Rate Customers converting to Heat Pump Rate HP-RES
E9: Res | J9: Res with Heat
E10: Average | G10: Rate RD-1 | I10: Average kWh | J10: Pump Average | K10: Rate HP-RES | O10: %
E11: Monthly | G11: Total | I11: Increase from | J11: Monthly | K11: Total | M11: Total | O11: Total
C12: Decile | E12: kWh | G12: Revenue | I12: Heat Pump | J12: kWh | K12: Revenue | M12: Difference | O12: Difference
C14: 0.1 | E14: 70.122989 | G14: =$I$34+E14*$I$72 -> 39.216009 | I14: =E14/$E$25*$I$25 -> 61.279948 | J14: =E14+I14 -> 131.40294 | K14: =$P$34+J14*($P$71*$O$40)+J14*($P$72*$O$41) -> 59.318075 | M14: =K14-G14 -> 20.102066 | O14: =K14/G14-1 -> 0.51259845
C15: 0.2 | E15: 182.93414 | G15: =$I$34+E15*$I$72 -> 88.630739 | I15: =E15/$E$25*$I$25 -> 159.86476 | J15: =E15+I15 -> 342.7989 | K15: =$P$34+J15*($P$71*$O$40)+J15*($P$72*$O$41) -> 141.07223 | M15: =K15-G15 -> 52.441492 | O15: =K15/G15-1 -> 0.59168515
C16: 0.3 | E16: 262.31339 | G16: =$I$34+E16*$I$72 -> 123.40127 | I16: =E16/$E$25*$I$25 -> 229.23368 | J16: =E16+I16 -> 491.54707 | K16: =$P$34+J16*($P$71*$O$40)+J16*($P$72*$O$41) -> 198.59831 | M16: =K16-G16 -> 75.197037 | O16: =K16/G16-1 -> 0.60937003
C17: 0.4 | E17: 335.31655 | G17: =$I$34+E17*$I$72 -> 155.37888 | I17: =E17/$E$25*$I$25 -> 293.03059 | J17: =E17+I17 -> 628.34714 | K17: =$P$34+J17*($P$71*$O$40)+J17*($P$72*$O$41) -> 251.50364 | M17: =K17-G17 -> 96.124757 | O17: =K17/G17-1 -> 0.61864749
C18: 0.5 | E18: 410.31906 | G18: =$I$34+E18*$I$72 -> 188.23228 | I18: =E18/$E$25*$I$25 -> 358.57472 | J18: =E18+I18 -> 768.89378 | K18: =$P$34+J18*($P$71*$O$40)+J18*($P$72*$O$41) -> 305.85791 | M18: =K18-G18 -> 117.62563 | O18: =K18/G18-1 -> 0.62489618
C19: 0.6 | E19: 493.45217 | G19: =$I$34+E19*$I$72 -> 224.64711 | I19: =E19/$E$25*$I$25 -> 431.22411 | J19: =E19+I19 -> 924.67629 | K19: =$P$34+J19*($P$71*$O$40)+J19*($P$72*$O$41) -> 366.1044 | M19: =K19-G19 -> 141.45729 | O19: =K19/G19-1 -> 0.62968665
C20: 0.7 | E20: 593.31135 | G20: =$I$34+E20*$I$72 -> 268.38848 | I20: =E20/$E$25*$I$25 -> 518.49029 | J20: =E20+I20 -> 1111.8016 | K20: =$P$34+J20*($P$71*$O$40)+J20*($P$72*$O$41) -> 438.47227 | M20: =K20-G20 -> 170.08379 | O20: =K20/G20-1 -> 0.63372239
C21: 0.8 | E21: 724.63237 | G21: =$I$34+E21*$I$72 -> 325.9111 | I21: =E21/$E$25*$I$25 -> 633.25073 | J21: =E21+I21 -> 1357.8831 | K21: =$P$34+J21*($P$71*$O$40)+J21*($P$72*$O$41) -> 533.64051 | M21: =K21-G21 -> 207.72942 | O21: =K21/G21-1 -> 0.63738061
C22: 0.9 | E22: 928.94127 | G22: =$I$34+E22*$I$72 -> 415.40463 | I22: =E22/$E$25*$I$25 -> 811.79473 | J22: =E22+I22 -> 1740.736 | K22: =$P$34+J22*($P$71*$O$40)+J22*($P$72*$O$41) -> 681.70302 | M22: =K22-G22 -> 266.29838 | O22: =K22/G22-1 -> 0.6410578
C23: 1 | E23: 1650.9479 | G23: =$I$34+E23*$I$72 -> 731.66557 | I23: =E23/$E$25*$I$25 -> 1442.7508 | J23: =E23+I23 -> 3093.6987 | K23: =$P$34+J23*($P$71*$O$40)+J23*($P$72*$O$41) -> 1204.9406 | M23: =K23-G23 -> 473.27507 | O23: =K23/G23-1 -> 0.64684617
C25: Average | E25: =AVERAGE(E14:E23) -> 565.22912 | G25: =$I$34+E25*$I$72 -> 256.08761 | I25: 493.94944 | J25: =AVERAGE(J14:J23) -> 1059.1786 | K25: =$P$34+J25*($P$71*$O$40)+J25*($P$72*$O$41) -> 418.1211 | M25: =K25-G25 -> 162.03349 | O25: =K25/G25-1 -> 0.6327268
C26: Annual
B31: RD-1 Proposed Rates:* | K31: HP-Res Proposed Rates:*
I32: RD-1 | P32: HP-RES | R32: Difference
B33: Delivery Charges: | K33: Delivery Charges:
B34: Customer Charge | I34: 8.5 | K34: Customer Charge | P34: =I34 -> 8.5 | R34: =+P34-I34 -> 0
I35: kWh | P35: kWh | R35: kWh
B36: Internal Transmission | I36: 0.0060546025 | K36: Internal Transmission | P36: =I36 -> 0.0060546025 | R36: =+P36-I36 -> 0
B37: External Transmission | I37: 0.030282807 | K37: External Transmission | P37: =I37 -> 0.030282807 | R37: =+P37-I37 -> 0
H38: Transmission Subtotal | I38: =+I37+I36 -> 0.036337409 | O38: Transmission Subtotal | P38: =+P37+P36 -> 0.036337409 | R38: =+P38-I38 -> 0
B40: Distribution - July 1, 2024 | I40: 0.10716 | K40: Distribution - Summer | N40: Percent kWh | O40: 0.25550324 | P40: =I40 -> 0.10716 | R40: =+P40-I40 -> 0
K41: Distribution - Winter | N41: Percent kWh | O41: 0.74449676 | P41: 0.03826 | R41: =+P41-I40 -> -0.0689
B43: Pension/PBOP Adjustment Factor | I43: 0.0036367193 | K43: Pension/PBOP Adjustment Factor | P43: =I43 -> 0.0036367193 | R43: =+P43-I43 -> 0
B44: Residential Assistance Adjustment Factor | I44: 0.030653998 | K44: Residential Assistance Adjustment Factor | P44: =I44 -> 0.030653998 | R44: =+P44-I44 -> 0
B45: Net Metering Recovery Surcharge | I45: 0.016445998 | K45: Net Metering Recovery Surcharge | P45: =I45 -> 0.016445998 | R45: =+P45-I45 -> 0
B46: Revenue Decoupling Adjustment Factor | I46: 0 | K46: Revenue Decoupling Adjustment Factor | P46: =I46 -> 0 | R46: =+P46-I46 -> 0
B47: Attorney General Consultant Expense Factor | I47: 0.00056729449 | K47: Attorney General Consultant Expense Factor | P47: =I47 -> 0.00056729449 | R47: =+P47-I47 -> 0
B48: L-T Renewable Contract Adjustment Factor | I48: -0.00275 | K48: L-T Renewable Contract Adjustment Factor | P48: =I48 -> -0.00275 | R48: =+P48-I48 -> 0
B49: Capital Cost Adjustment Factor | I49: 0 | K49: Capital Cost Adjustment Factor | P49: =I49 -> 0 | R49: =+P49-I49 -> 0
B50: Solar Cost Adjustment | I50: 0 | K50: Solar Cost Adjustment | P50: =I50 -> 0 | R50: =+P50-I50 -> 0
...

Sheet P2. RD-2 to HP-RES
S1: ='P1. RD-1 to HP-RES'!S1 -> DPU 23-80
S2: ='P1. RD-1 to HP-RES'!S2 -> DOER 2-03 Attachment 1
S3: Page 2 of 4
B5: Fitchburg Gas and Electric Light Company d/b/a Unitil
B6: ='P1. RD-1 to HP-RES'!B6 -> Basic Service Customer Typical Bill Impacts - Distribution Rate Proposal
B7: Impact on RD-2 Rate Customers converting to Heat Pump Rate HP RES
E9: Res | J9: Res with Heat
E10: Average | G10: Rate RD-2 | I10: Average kWh | J10: Pump Average | K10: Rate HP-RES | O10: %
E11: Monthly | G11: Total | I11: Increase from | J11: Monthly | K11: Total | M11: Total | O11: Total
C12: Decile | E12: kWh | G12: Revenue | I12: Heat Pump | J12: kWh | K12: Revenue | M12: Difference | O12: Difference | U12: Discount Check to RD-1
U13: Current
C14: 0.1 | E14: 70.122989 | G14: =$I$33+$I$74+E14*$I$79 -> 23.529606 | I14: =E14/$E$25*$I$25 -> 61.279948 | J14: =E14+I14 -> 131.40294 | K14: =$P$33+$P$74+J14*($P$78*$O$39)+J14*($P$79*$O$40) -> 35.590845 | M14: =K14-G14 -> 12.061239 | O14: =K14/G14-1 -> 0.51259845 | U14: =-('P1. RD-1 to HP-RES'!G14-'P2. RD-2 to HP-RES'!G14)/'P1. RD-1 to HP-RES'!G14 -> -0.4 | V14: ='P1. RD-1 to HP-RES'!G14*0.6-'P2. RD-2 to HP-RES'!G14 -> 0 | W14: =-('P1. RD-1 to HP-RES'!K14-'P2. RD-2 to HP-RES'!K14)/'P1. RD-1 to HP-RES'!K14 -> -0.4 | X14: =-('P1. RD-1 to HP-RES'!J14-'P2. RD-2 to HP-RES'!J14)/'P1. RD-1 to HP-RES'!J14 -> 0
C15: 0.2 | E15: 182.93414 | G15: =$I$33+$I$74+E15*$I$79 -> 53.178443 | I15: =E15/$E$25*$I$25 -> 159.86476 | J15: =E15+I15 -> 342.7989 | K15: =$P$33+$P$74+J15*($P$78*$O$39)+J15*($P$79*$O$40) -> 84.643338 | M15: =K15-G15 -> 31.464895 | O15: =K15/G15-1 -> 0.59168515 | U15: =-('P1. RD-1 to HP-RES'!G15-'P2. RD-2 to HP-RES'!G15)/'P1. RD-1 to HP-RES'!G15 -> -0.4 | V15: ='P1. RD-1 to HP-RES'!G15*0.6-'P2. RD-2 to HP-RES'!G15 -> 0 | W15: =-('P1. RD-1 to HP-RES'!K15-'P2. RD-2 to HP-RES'!K15)/'P1. RD-1 to HP-RES'!K15 -> -0.4 | X15: =-('P1. RD-1 to HP-RES'!J15-'P2. RD-2 to HP-RES'!J15)/'P1. RD-1 to HP-RES'!J15 -> 0
C16: 0.3 | E16: 262.31339 | G16: =$I$33+$I$74+E16*$I$79 -> 74.040763 | I16: =E16/$E$25*$I$25 -> 229.23368 | J16: =E16+I16 -> 491.54707 | K16: =$P$33+$P$74+J16*($P$78*$O$39)+J16*($P$79*$O$40) -> 119.15898 | M16: =K16-G16 -> 45.118222 | O16: =K16/G16-1 -> 0.60937003 | U16: =-('P1. RD-1 to HP-RES'!G16-'P2. RD-2 to HP-RES'!G16)/'P1. RD-1 to HP-RES'!G16 -> -0.4 | V16: ='P1. RD-1 to HP-RES'!G16*0.6-'P2. RD-2 to HP-RES'!G16 -> 0 | W16: =-('P1. RD-1 to HP-RES'!K16-'P2. RD-2 to HP-RES'!K16)/'P1. RD-1 to HP-RES'!K16 -> -0.4 | X16: =-('P1. RD-1 to HP-RES'!J16-'P2. RD-2 to HP-RES'!J16)/'P1. RD-1 to HP-RES'!J16 -> 0
C17: 0.4 | E17: 335.31655 | G17: =$I$33+$I$74+E17*$I$79 -> 93.22733 | I17: =E17/$E$25*$I$25 -> 293.03059 | J17: =E17+I17 -> 628.34714 | K17: =$P$33+$P$74+J17*($P$78*$O$39)+J17*($P$79*$O$40) -> 150.90218 | M17: =K17-G17 -> 57.674854 | O17: =K17/G17-1 -> 0.61864749 | U17: =-('P1. RD-1 to HP-RES'!G17-'P2. RD-2 to HP-RES'!G17)/'P1. RD-1 to HP-RES'!G17 -> -0.4 | V17: ='P1. RD-1 to HP-RES'!G17*0.6-'P2. RD-2 to HP-RES'!G17 -> 0 | W17: =-('P1. RD-1 to HP-RES'!K17-'P2. RD-2 to HP-RES'!K17)/'P1. RD-1 to HP-RES'!K17 -> -0.4 | X17: =-('P1. RD-1 to HP-RES'!J17-'P2. RD-2 to HP-RES'!J17)/'P1. RD-1 to HP-RES'!J17 -> 0
C18: 0.5 | E18: 410.31906 | G18: =$I$33+$I$74+E18*$I$79 -> 112.93937 | I18: =E18/$E$25*$I$25 -> 358.57472 | J18: =E18+I18 -> 768.89378 | K18: =$P$33+$P$74+J18*($P$78*$O$39)+J18*($P$79*$O$40) -> 183.51474 | M18: =K18-G18 -> 70.575378 | O18: =K18/G18-1 -> 0.62489618 | U18: =-('P1. RD-1 to HP-RES'!G18-'P2. RD-2 to HP-RES'!G18)/'P1. RD-1 to HP-RES'!G18 -> -0.4 | V18: ='P1. RD-1 to HP-RES'!G18*0.6-'P2. RD-2 to HP-RES'!G18 -> 0 | W18: =-('P1. RD-1 to HP-RES'!K18-'P2. RD-2 to HP-RES'!K18)/'P1. RD-1 to HP-RES'!K18 -> -0.4 | X18: =-('P1. RD-1 to HP-RES'!J18-'P2. RD-2 to HP-RES'!J18)/'P1. RD-1 to HP-RES'!J18 -> 0
C19: 0.6 | E19: 493.45217 | G19: =$I$33+$I$74+E19*$I$79 -> 134.78827 | I19: =E19/$E$25*$I$25 -> 431.22411 | J19: =E19+I19 -> 924.67629 | K19: =$P$33+$P$74+J19*($P$78*$O$39)+J19*($P$79*$O$40) -> 219.66264 | M19: =K19-G19 -> 84.874374 | O19: =K19/G19-1 -> 0.62968665 | U19: =-('P1. RD-1 to HP-RES'!G19-'P2. RD-2 to HP-RES'!G19)/'P1. RD-1 to HP-RES'!G19 -> -0.4 | V19: ='P1. RD-1 to HP-RES'!G19*0.6-'P2. RD-2 to HP-RES'!G19 -> 0 | W19: =-('P1. RD-1 to HP-RES'!K19-'P2. RD-2 to HP-RES'!K19)/'P1. RD-1 to HP-RES'!K19 -> -0.4 | X19: =-('P1. RD-1 to HP-RES'!J19-'P2. RD-2 to HP-RES'!J19)/'P1. RD-1 to HP-RES'!J19 -> 0
C20: 0.7 | E20: 593.31135 | G20: =$I$33+$I$74+E20*$I$79 -> 161.03309 | I20: =E20/$E$25*$I$25 -> 518.49029 | J20: =E20+I20 -> 1111.8016 | K20: =$P$33+$P$74+J20*($P$78*$O$39)+J20*($P$79*$O$40) -> 263.08336 | M20: =K20-G20 -> 102.05027 | O20: =K20/G20-1 -> 0.63372239 | U20: =-('P1. RD-1 to HP-RES'!G20-'P2. RD-2 to HP-RES'!G20)/'P1. RD-1 to HP-RES'!G20 -> -0.4 | V20: ='P1. RD-1 to HP-RES'!G20*0.6-'P2. RD-2 to HP-RES'!G20 -> 0 | W20: =-('P1. RD-1 to HP-RES'!K20-'P2. RD-2 to HP-RES'!K20)/'P1. RD-1 to HP-RES'!K20 -> -0.4 | X20: =-('P1. RD-1 to HP-RES'!J20-'P2. RD-2 to HP-RES'!J20)/'P1. RD-1 to HP-RES'!J20 -> 0
C21: 0.8 | E21: 724.63237 | G21: =$I$33+$I$74+E21*$I$79 -> 195.54666 | I21: =E21/$E$25*$I$25 -> 633.25073 | J21: =E21+I21 -> 1357.8831 | K21: =$P$33+$P$74+J21*($P$78*$O$39)+J21*($P$79*$O$40) -> 320.18431 | M21: =K21-G21 -> 124.63765 | O21: =K21/G21-1 -> 0.63738061 | U21: =-('P1. RD-1 to HP-RES'!G21-'P2. RD-2 to HP-RES'!G21)/'P1. RD-1 to HP-RES'!G21 -> -0.4 | V21: ='P1. RD-1 to HP-RES'!G21*0.6-'P2. RD-2 to HP-RES'!G21 -> 0 | W21: =-('P1. RD-1 to HP-RES'!K21-'P2. RD-2 to HP-RES'!K21)/'P1. RD-1 to HP-RES'!K21 -> -0.4 | X21: =-('P1. RD-1 to HP-RES'!J21-'P2. RD-2 to HP-RES'!J21)/'P1. RD-1 to HP-RES'!J21 -> 0
C22: 0.9 | E22: 928.94127 | G22: =$I$33+$I$74+E22*$I$79 -> 249.24278 | I22: =E22/$E$25*$I$25 -> 811.79473 | J22: =E22+I22 -> 1740.736 | K22: =$P$33+$P$74+J22*($P$78*$O$39)+J22*($P$79*$O$40) -> 409.02181 | M22: =K22-G22 -> 159.77903 | O22: =K22/G22-1 -> 0.6410578 | U22: =-('P1. RD-1 to HP-RES'!G22-'P2. RD-2 to HP-RES'!G22)/'P1. RD-1 to HP-RES'!G22 -> -0.4 | V22: ='P1. RD-1 to HP-RES'!G22*0.6-'P2. RD-2 to HP-RES'!G22 -> 0 | W22: =-('P1. RD-1 to HP-RES'!K22-'P2. RD-2 to HP-RES'!K22)/'P1. RD-1 to HP-RES'!K22 -> -0.4 | X22: =-('P1. RD-1 to HP-RES'!J22-'P2. RD-2 to HP-RES'!J22)/'P1. RD-1 to HP-RES'!J22 -> 0
C23: 1 | E23: 1650.9479 | G23: =$I$33+$I$74+E23*$I$79 -> 438.99934 | I23: =E23/$E$25*$I$25 -> 1442.7508 | J23: =E23+I23 -> 3093.6987 | K23: =$P$33+$P$74+J23*($P$78*$O$39)+J23*($P$79*$O$40) -> 722.96438 | M23: =K23-G23 -> 283.96504 | O23: =K23/G23-1 -> 0.64684617 | U23: =-('P1. RD-1 to HP-RES'!G23-'P2. RD-2 to HP-RES'!G23)/'P1. RD-1 to HP-RES'!G23 -> -0.4 | V23: ='P1. RD-1 to HP-RES'!G23*0.6-'P2. RD-2 to HP-RES'!G23 -> 0 | W23: =-('P1. RD-1 to HP-RES'!K23-'P2. RD-2 to HP-RES'!K23)/'P1. RD-1 to HP-RES'!K23 -> -0.4 | X23: =-('P1. RD-1 to HP-RES'!J23-'P2. RD-2 to HP-RES'!J23)/'P1. RD-1 to HP-RES'!J23 -> 0
C25: Average | E25: =AVERAGE(E14:E23) -> 565.22912 | G25: =$I$33+$I$74+E25*$I$79 -> 153.65256 | I25: 493.94944 | J25: =AVERAGE(J14:J23) -> 1059.1786 | K25: =$P$33+$P$74+J25*($P$78*$O$39)+J25*($P$79*$O$40) -> 250.87266 | M25: =K25-G25 -> 97.220096 | O25: =K25/G25-1 -> 0.6327268 | U25: =-('P1. RD-1 to HP-RES'!G25-'P2. RD-2 to HP-RES'!G25)/'P1. RD-1 to HP-RES'!G25 -> -0.4 | V25: ='P1. RD-1 to HP-RES'!G25*0.6-'P2. RD-2 to HP-RES'!G25 -> 0 | W25: =-('P1. RD-1 to HP-RES'!K25-'P2. RD-2 to HP-RES'!K25)/'P1. RD-1 to HP-RES'!K25 -> -0.4 | X25: =-('P1. RD-1 to HP-RES'!J25-'P2. RD-2 to HP-RES'!J25)/'P1. RD-1 to HP-RES'!J25 -> 0
B30: ='P1. RD-1 to HP-RES'!B31 -> RD-1 Proposed Rates:* | K30: ='P1. RD-1 to HP-RES'!K31 -> HP-Res Proposed Rates:*
I31: RD-2 | P31: RD-2 | R31: Difference
B32: Delivery Charges: | K32: Delivery Charges:
B33: Customer Charge | I33: 8.5 | K33: Customer Charge | P33: =I33 -> 8.5 | R33: =+P33-I33 -> 0
I34: kWh | P34: kWh | R34: kWh
B35: Internal Transmission | I35: ='P1. RD-1 to HP-RES'!I36 -> 0.0060546025 | K35: Internal Transmission | P35: =I35 -> 0.0060546025 | R35: =+P35-I35 -> 0
B36: External Transmission | I36: ='P1. RD-1 to HP-RES'!I37 -> 0.030282807 | K36: External Transmission | P36: =I36 -> 0.030282807 | R36: =+P36-I36 -> 0
H37: Transmission Subtotal | I37: =+I36+I35 -> 0.036337409 | O37: Transmission Subtotal | P37: =+P36+P35 -> 0.036337409 | R37: =+P37-I37 -> 0
B39: ='P1. RD-1 to HP-RES'!B40 -> Distribution - July 1, 2024 | I39: ='P1. RD-1 to HP-RES'!I40 -> 0.10716 | K39: Distribution - Summer | N39: Percent kWh | O39: ='P1. RD-1 to HP-RES'!O40 -> 0.25550324 | P39: =I39 -> 0.10716 | Q39: =I39 -> 0.10716 | R39: =+P39-I39 -> 0
K40: Distribution - Winter | N40: Percent kWh | O40: ='P1. RD-1 to HP-RES'!O41 -> 0.74449676 | P40: ='P1. RD-1 to HP-RES'!P41 -> 0.03826 | R40: =+P40-I39 -> -0.0689
B42: Pension/PBOP Adjustment Factor | I42: ='P1. RD-1 to HP-RES'!I43 -> 0.0036367193 | K42: Pension/PBOP Adjustment Factor | P42: =I42 -> 0.0036367193 | R42: =+P42-I42 -> 0
B43: Residential Assistance Adjustment Factor | I43: ='P1. RD-1 to HP-RES'!I44 -> 0.030653998 | K43: Residential Assistance Adjustment Factor | P43: =I43 -> 0.030653998 | R43: =+P43-I43 -> 0
B44: Net Metering Recovery Surcharge | I44: ='P1. RD-1 to HP-RES'!I45 -> 0.016445998 | K44: Net Metering Recovery Surcharge | P44: =I44 -> 0.016445998 | R44: =+P44-I44 -> 0
B45: Revenue Decoupling Adjustment Factor | I45: ='P1. RD-1 to HP-RES'!I46 -> 0 | K45: Revenue Decoupling Adjustment Factor | P45: =I45 -> 0 | R45: =+P45-I45 -> 0
B46: Attorney General Consultant Expense Factor | I46: ='P1. RD-1 to HP-RES'!I47 -> 0.00056729449 | K46: Attorney General Consultant Expense Factor | P46: =I46 -> 0.00056729449 | R46: =+P46-I46 -> 0
B47: L-T Renewable Contract Adjustment Factor | I47: ='P1. RD-1 to HP-RES'!I48 -> -0.00275 | K47: L-T Renewable Contract Adjustment Factor | P47: =I47 -> -0.00275 | R47: =+P47-I47 -> 0
B48: Capital Cost Adjustment Factor | I48: ='P1. RD-1 to HP-RES'!I49 -> 0 | K48: Capital Cost Adjustment Factor | P48: =I48 -> 0 | R48: =+P48-I48 -> 0
B49: Solar Cost Adjustment | I49: ='P1. RD-1 to HP-RES'!I50 -> 0 | K49: Solar Cost Adjustment | P49: =I49 -> 0 | R49: =+P49-I49 -> 0
...

Sheet P3. R3 with HP-RES
I1: ='P1. RD-1 to HP-RES'!S1 -> DPU 23-80
I2: ='P1. RD-1 to HP-RES'!S2 -> DOER 2-03 Attachment 1
I3: Page 3 of 4
A4: Fitchburg Gas and Electric Light Company - Gas Division
A5: Gas Bill Impact of Customer Transitioned to Heat Pump Rate
L8: 2022 Data
A9: Line No. | B9: Decile | C9: Average Monthly Usage (Therms) | D9: Monthly Bills @ Proposed Rates | E9: Average Therm Reduction - Heat Pump | F9: Average Monthly Usage with Heat Pump | G9: Monthly Bills @ Proposed Rates | H9: $ Difference | I9: % Difference | L9: Bills | M9: Therms
A10: 1 | B10: 0.1 | C10: =M10/L10 -> 2.3244677 | D10: =+$E$24+C10*SUM($E$25:$E$28) -> 22.348572 | E10: =C10/$C$20*$E$20 -> -1.8088988 | F10: =C10+E10 -> 0.51556895 | G10: =+$E$24+F10*SUM($E$25:$E$28) -> 16.62992 | H10: =+G10-D10 -> -5.7186525 | I10: =+H10/D10 -> -0.25588447 | L10: 11443.9 | M10: 26600.976
A11: =A10+1 -> 2 | B11: =+B10+0.1 -> 0.2 | C11: =M11/L11 -> 8.9825109 | D11: =+$E$24+C11*SUM($E$25:$E$28) -> 43.39731 | E11: =C11/$C$20*$E$20 -> -6.9901822 | F11: =C11+E11 -> 1.9923287 | G11: =+$E$24+F11*SUM($E$25:$E$28) -> 21.298548 | H11: =+G11-D11 -> -22.098762 | I11: =+H11/D11 -> -0.50921963 | L11: 11443.9 | M11: 102794.96
A12: =A11+1 -> 3 | B12: =+B11+0.1 -> 0.3 | C12: =M12/L12 -> 14.250271 | D12: =+$E$24+C12*SUM($E$25:$E$28) -> 60.050808 | E12: =C12/$C$20*$E$20 -> -11.089549 | F12: =C12+E12 -> 3.1607225 | G12: =+$E$24+F12*SUM($E$25:$E$28) -> 24.992308 | H12: =+G12-D12 -> -35.0585 | I12: =+H12/D12 -> -0.58381395 | L12: 11443.9 | M12: 163078.68
A13: =A12+1 -> 4 | B13: =+B12+0.1 -> 0.4 | C13: =M13/L13 -> 20.000597 | D13: =+$E$24+C13*SUM($E$25:$E$28) -> 78.229887 | E13: =C13/$C$20*$E$20 -> -15.564447 | F13: =C13+E13 -> 4.4361498 | G13: =+$E$24+F13*SUM($E$25:$E$28) -> 29.024444 | H13: =+G13-D13 -> -49.205444 | I13: =+H13/D13 -> -0.62898523 | L13: 11443.9 | M13: 228884.83
A14: =A13+1 -> 5 | B14: =+B13+0.1 -> 0.5 | C14: =M14/L14 -> 28.176646 | D14: =+$E$24+C14*SUM($E$25:$E$28) -> 104.07765 | E14: =C14/$C$20*$E$20 -> -21.927041 | F14: =C14+E14 -> 6.2496044 | G14: =+$E$24+F14*SUM($E$25:$E$28) -> 34.757499 | H14: =+G14-D14 -> -69.320148 | I14: =+H14/D14 -> -0.66604261 | L14: 11443.9 | M14: 322450.72
A15: =A14+1 -> 6 | B15: =+B14+0.1 -> 0.6 | C15: =M15/L15 -> 41.942269 | D15: =+$E$24+C15*SUM($E$25:$E$28) -> 147.59629 | E15: =C15/$C$20*$E$20 -> -32.639437 | F15: =C15+E15 -> 9.3028317 | G15: =+$E$24+F15*SUM($E$25:$E$28) -> 44.409972 | H15: =+G15-D15 -> -103.18632 | I15: =+H15/D15 -> -0.69911187 | L15: 11443.9 | M15: 479983.13
A16: =A15+1 -> 7 | B16: =+B15+0.1 -> 0.7 | C16: =M16/L16 -> 63.253013 | D16: =+$E$24+C16*SUM($E$25:$E$28) -> 214.96808 | E16: =C16/$C$20*$E$20 -> -49.22344 | F16: =C16+E16 -> 14.029573 | G16: =+$E$24+F16*SUM($E$25:$E$28) -> 59.353092 | H16: =+G16-D16 -> -155.61498 | I16: =+H16/D16 -> -0.72389811 | L16: 11443.9 | M16: 723861.16
A17: =A16+1 -> 8 | B17: =+B16+0.1 -> 0.8 | C17: =M17/L17 -> 91.064514 | D17: =+$E$24+C17*SUM($E$25:$E$28) -> 302.89135 | E17: =C17/$C$20*$E$20 -> -70.866326 | F17: =C17+E17 -> 20.198188 | G17: =+$E$24+F17*SUM($E$25:$E$28) -> 78.854552 | H17: =+G17-D17 -> -224.0368 | I17: =+H17/D17 -> -0.7396606 | L17: 11443.9 | M17: 1042133.2
A18: =A17+1 -> 9 | B18: =+B17+0.1 -> 0.9 | C18: =M18/L18 -> 129.62478 | D18: =+$E$24+C18*SUM($E$25:$E$28) -> 424.79579 | E18: =C18/$C$20*$E$20 -> -100.87389 | F18: =C18+E18 -> 28.750889 | G18: =+$E$24+F18*SUM($E$25:$E$28) -> 105.89306 | H18: =+G18-D18 -> -318.90273 | I18: =+H18/D18 -> -0.75072008 | L18: 11443.9 | M18: 1483413.1
A19: =A18+1 -> 10 | B19: =+B18+0.1 -> 1 | C19: =M19/L19 -> 227.64623 | D19: =+$E$24+C19*SUM($E$25:$E$28) -> 734.6808 | E19: =C19/$C$20*$E$20 -> -177.1541 | F19: =C19+E19 -> 50.492132 | G19: =+$E$24+F19*SUM($E$25:$E$28) -> 174.62582 | H19: =+G19-D19 -> -560.05497 | I19: =+H19/D19 -> -0.76231062 | L19: 11443.9 | M19: 2605160.7
A20: =A19+1 -> 11 | B20: Average | C20: =AVERAGE(C10:C19) -> 62.72653 | D20: =+$E$24+C20*SUM($E$25:$E$28) -> 213.30365 | E20: -48.813731 | F20: =AVERAGE(F10:F19) -> 13.912799 | G20: =+$E$24+F20*SUM($E$25:$E$28) -> 58.983922 | H20: =AVERAGE(H10:H19) -> -154.31973 | I20: =+H20/D20 -> -0.72347439
A21: =A20+1 -> 12
A22: =A21+1 -> 13 | B22: R-3 Proposed Rates:
A23: =A22+1 -> 14
A24: =A23+1 -> 15 | B24: Customer Charge ($/customer) | E24: 15 | F24: (1)
A25: =A24+1 -> 16 | B25: Distribution Charge - All therms ($/thm) | E25: 1.7097 | F25: (1)
A26: =A25+1 -> 17 | B26: Revenue Decoupling Adjustment Factor ($/thm) | E26: 0.0297 | F26: (2)
A27: =A26+1 -> 18 | B27: LDAC ($/thm) | E27: 0.4881 | F27: (3)
A28: =A27+1 -> 19 | B28: CGA ($/thm) | E28: 0.9339 | F28: (4)
A29: =A28+1 -> 20
A30: =A29+1 -> 21 | B30: (1) Rate Design worksheets (Adjusted for 12/15/23 Filing) - July 1, 2024
A31: =A30+1 -> 22 | B31: (2) May 1, 2023 rates (present rates at time of initial filing)
A32: =A31+1 -> 23 | B32: (3) May 1, 2023 rates (present rates at time of initial filing) adjusted for rate case increments
A33: =A32+1 -> 24 | B33: (4) Test Year 12 month average CGA adjusted for rate case increments

Sheet P4. R4 with HP-RES
I1: ='P3. R3 with HP-RES'!I1 -> DPU 23-80
I2: ='P3. R3 with HP-RES'!I2 -> DOER 2-03 Attachment 1
I3: Page 4 of 4
A4: Fitchburg Gas and Electric Light Company - Gas Division
A5: Low Income Gas Bill Impact of Customer Transitioned to Heat Pump Rate
L8: 2022 Data
A9: Line No. | B9: Decile | C9: Average Monthly Usage (Therms) | D9: Monthly Bills @ Proposed Rates | E9: Average Therm Reduction - Heat Pump | F9: Average Monthly Usage with Heat Pump | G9: Monthly Bills with Heat Pump @ Proposed Rates | H9: $ Difference | I9: % Difference | L9: Bills | M9: Therms
A10: 1 | B10: 0.1 | C10: =M10/L10 -> 2.4484562 | D10: =+E$24+E$31+C10*SUM($E$25:$E$28,$E$32) -> 17.05529 | E10: =C10/$C$20*$E$20 -> -1.8402631 | F10: =C10+E10 -> 0.60819308 | G10: =+E$24+E$31+F10*SUM($E$25:$E$28,$E$32) -> 12.692026 | H10: =+G10-D10 -> -4.3632639 | I10: =+H10/D10 -> -0.25583054 | L10: 3518 | M10: 8613.669 | O10: 12.695208
A11: =A10+1 -> 2 | B11: =+B10+0.1 -> 0.2 | C11: =M11/L11 -> 9.6899247 | D11: =+E$24+E$31+C11*SUM($E$25:$E$28,$E$32) -> 34.224811 | E11: =C11/$C$20*$E$20 -> -7.282961 | F11: =C11+E11 -> 2.4069637 | G11: =+E$24+E$31+F11*SUM($E$25:$E$28,$E$32) -> 16.956911 | H11: =+G11-D11 -> -17.267901 | I11: =+H11/D11 -> -0.50454334 | L11: 3518 | M11: 34089.155 | O11: 16.969503
A12: =A11+1 -> 3 | B12: =+B11+0.1 -> 0.3 | C12: =M12/L12 -> 15.692477 | D12: =+E$24+E$31+C12*SUM($E$25:$E$28,$E$32) -> 48.456862 | E12: =C12/$C$20*$E$20 -> -11.794488 | F12: =C12+E12 -> 3.8979891 | G12: =+E$24+E$31+F12*SUM($E$25:$E$28,$E$32) -> 20.492132 | H12: =+G12-D12 -> -27.96473 | I12: =+H12/D12 -> -0.57710567 | L12: 3518 | M12: 55206.133 | O12: 20.512525
A13: =A12+1 -> 4 | B13: =+B12+0.1 -> 0.4 | C13: =M13/L13 -> 22.100431 | D13: =+E$24+E$31+C13*SUM($E$25:$E$28,$E$32) -> 63.650122 | E13: =C13/$C$20*$E$20 -> -16.610715 | F13: =C13+E13 -> 5.4897159 | G13: =+E$24+E$31+F13*SUM($E$25:$E$28,$E$32) -> 24.266117 | H13: =+G13-D13 -> -39.384005 | I13: =+H13/D13 -> -0.61875774 | L13: 3518 | M13: 77749.316 | O13: 24.294837
A14: =A13+1 -> 5 | B14: =+B13+0.1 -> 0.5 | C14: =M14/L14 -> 30.716353 | D14: =+E$24+E$31+C14*SUM($E$25:$E$28,$E$32) -> 84.078472 | E14: =C14/$C$20*$E$20 -> -23.086454 | F14: =C14+E14 -> 7.6298988 | G14: =+E$24+E$31+F14*SUM($E$25:$E$28,$E$32) -> 29.34049 | H14: =+G14-D14 -> -54.737982 | I14: =+H14/D14 -> -0.65103445 | L14: 3518 | M14: 108060.13 | O14: 29.380407
A15: =A14+1 -> 6 | B15: =+B14+0.1 -> 0.6 | C15: =M15/L15 -> 44.876445 | D15: =+E$24+E$31+C15*SUM($E$25:$E$28,$E$32) -> 117.65205 | E15: =C15/$C$20*$E$20 -> -33.729199 | F15: =C15+E15 -> 11.147246 | G15: =+E$24+E$31+F15*SUM($E$25:$E$28,$E$32) -> 37.68012 | H15: =+G15-D15 -> -79.971931 | I15: =+H15/D15 -> -0.67973257 | L15: 3518 | M15: 157875.33 | O15: 37.738438
A16: =A15+1 -> 7 | B16: =+B15+0.1 -> 0.7 | C16: =M16/L16 -> 65.762103 | D16: =+E$24+E$31+C16*SUM($E$25:$E$28,$E$32) -> 167.17195 | E16: =C16/$C$20*$E$20 -> -49.426889 | F16: =C16+E16 -> 16.335214 | G16: =+E$24+E$31+F16*SUM($E$25:$E$28,$E$32) -> 49.980792 | H16: =+G16-D16 -> -117.19115 | I16: =+H16/D16 -> -0.70102165 | L16: 3518 | M16: 231351.08 | O16: 50.066253
A17: =A16+1 -> 8 | B17: =+B16+0.1 -> 0.8 | C17: =M17/L17 -> 94.348401 | D17: =+E$24+E$31+C17*SUM($E$25:$E$28,$E$32) -> 234.95006 | E17: =C17/$C$20*$E$20 -> -70.912391 | F17: =C17+E17 -> 23.43601 | G17: =+E$24+E$31+F17*SUM($E$25:$E$28,$E$32) -> 66.81678 | H17: =+G17-D17 -> -168.13328 | I17: =+H17/D17 -> -0.71561284 | L17: 3518 | M17: 331917.67 | O17: 66.939389
A18: =A17+1 -> 9 | B18: =+B17+0.1 -> 0.9 | C18: =M18/L18 -> 134.99908 | D18: =+E$24+E$31+C18*SUM($E$25:$E$28,$E$32) -> 331.33282 | E18: =C18/$C$20*$E$20 -> -101.4655 | F18: =C18+E18 -> 33.533582 | G18: =+E$24+E$31+F18*SUM($E$25:$E$28,$E$32) -> 90.758123 | H18: =+G18-D18 -> -240.5747 | I18: =+H18/D18 -> -0.7260817 | L18: 3518 | M18: 474926.77 | O18: 90.933559
A19: =A18+1 -> 10 | B19: =+B18+0.1 -> 1 | C19: =M19/L19 -> 228.82934 | D19: =+E$24+E$31+C19*SUM($E$25:$E$28,$E$32) -> 553.80437 | E19: =C19/$C$20*$E$20 -> -171.98845 | F19: =C19+E19 -> 56.840886 | G19: =+E$24+E$31+F19*SUM($E$25:$E$28,$E$32) -> 146.01974 | H19: =+G19-D19 -> -407.78463 | I19: =+H19/D19 -> -0.73633335 | L19: 3518 | M19: 805021.62 | O19: 146.31711
A20: =A19+1 -> 11 | B20: Average | C20: =AVERAGE(C10:C19) -> 64.946301 | D20: =+E$24+E$31+C20*SUM($E$25:$E$28,$E$32) -> 165.23768 | E20: -48.813731 | F20: =AVERAGE(F10:F19) -> 16.13257 | G20: =+E$24+E$31+F20*SUM($E$25:$E$28,$E$32) -> 49.500323 | H20: =AVERAGE(H10:H19) -> -115.73736 | I20: =+H20/D20 -> -0.70042957 | L20: =SUM(L10:L19) -> 35180 | M20: =SUM(M10:M19) -> 2284810.9 | O20: 49.584723
A21: =A20+1 -> 12
A22: =A21+1 -> 13 | B22: R-4 Proposed Rates:
A23: =A22+1 -> 14
A24: =A23+1 -> 15 | B24: Customer Charge ($/customer) | E24: 15 | F24: (1)
A25: =A24+1 -> 16 | B25: Distribution Charge - All therms ($/thm) | E25: 1.7097 | F25: (1)
A26: =A25+1 -> 17 | B26: Revenue Decoupling Adjustment Factor ($/thm) | E26: 0.0297 | F26: (2)
A27: =A26+1 -> 18 | B27: LDAC ($/thm) | E27: 0.4881 | F27: (3)
A28: =A27+1 -> 19 | B28: CGA ($/thm) | E28: 0.9339 | F28: (4)
A29: =A28+1 -> 20
A30: =A29+1 -> 21 | B30: 25% Low Income Discount
A31: =A30+1 -> 22 | B31: Customer Charge ($/customer) | E31: =-ROUND((E24*0.25),2) -> -3.75
A32: =A31+1 -> 23 | B32: Volumetric Charges - All therms ($/thm) | E32: =ROUND(SUM(E25,E26:E27)*(1-0.25),4)-SUM(E25,E26:E27)+ROUND((E28*(1-0.25)-E28),4) -> -0.7904
A33: =A32+1 -> 24
A34: =A33+1 -> 25 | B34: (1) Rate Design worksheets (Adjusted for 12/15/23 Filing) - July 1, 2024
A35: =A34+1 -> 26 | B35: (2) May 1, 2023 rates (present rates at time of initial filing)
A36: =A35+1 -> 27 | B36: (3) May 1, 2023 rates (present rates at time of initial filing) adjusted for rate case increments
A37: =A36+1 -> 28 | B37: (4) Test Year 12 month average CGA adjusted for rate case increments
