Workbook

Sheet Index
A1: Fitchburg Gas and Electric Light Company
A2: Electric Revenue Apportionment and Rate Design
A3: Table of Contents
A5: Line No. | B5: Worksheet | C5: Exhibit No. | D5: Schedule No. | E5: Schedule Description | F5: Schedule Full Description
B6: Index
B7: Revenue Apportionment | C7: Exhibit Unitil-JDT-4 | D7: Schedule 1 | E7: Revenue Apportionment | F7: =CONCATENATE(D7," - ",E7) -> Schedule 1 - Revenue Apportionment
B8: Rate Design | C8: Exhibit Unitil-JDT-4 | D8: Schedule 2 | E8: Revenue Proof and Rate Design | F8: =CONCATENATE(D8," - ",E8) -> Schedule 2 - Revenue Proof and Rate Design
B9: Heat Pump Rate Design | C9: Exhibit Unitil-JDT-6 | E9: Residential Heat Pump Rate Design | F9: =E9 -> Residential Heat Pump Rate Design
B10: Rate Design Lighting | C10: Exhibit Unitil-JDT-4 | D10: Schedule 2 | E10: Revenue Proof and Rate Design | F10: =CONCATENATE(D10," - ",E10) -> Schedule 2 - Revenue Proof and Rate Design
B11: Rates | C11: Workpaper to Exhibit Unitil-JDT-4, Schedule 2 | D11: WP | E11: Current and Proposed Rates | F11: =CONCATENATE(D11," - ",E11) -> WP - Current and Proposed Rates
B12: EV-RES Rate | C12: Exhibit Unitil-JDT-7 | E12: Residential Electric Vehicle Annualized Rate | F12: Residential Electric Vehicle Annualized Rate
B13: Annual EV-RES | C13: Exhibit Unitil-JDT-7
B14: Demand Charge Alternative | C14: Exhibit Unitil-JDT-8 | E14: General Service EV Demand Charge Alternative Rates | F14: =E14 -> General Service EV Demand Charge Alternative Rates
B15: Decoupling Target | C15: Exhibit Unitil-JDT-9 | E15: Revenue Decoupling Annual Target Revenue | F15: =E15 -> Revenue Decoupling Annual Target Revenue
B16: CONFIDENTIAL | D16: CONFIDENTIAL Workpaper to Exhibit Unitil-JDT-4 | E16: Special Contract Data and Rate Change | F16: =CONCATENATE(D16," - ",E16) -> CONFIDENTIAL Workpaper to Exhibit Unitil-JDT-4 - Special Contract Data and Rate Change | G16: REDACTED
B17: FGE Bill Impact Tabs ---> | F17: =CONCATENATE(D17," - ",E17) -> -
B18: RD-1 | C18: Exhibit Unitil-JDT-5 | E18: Bill Impact | F18: =E18 -> Bill Impact
B19: RD-2 | C19: Exhibit Unitil-JDT-5 | E19: Bill Impact | F19: =E19 -> Bill Impact
B20: GD-1 | C20: Exhibit Unitil-JDT-5 | E20: Bill Impact | F20: =E20 -> Bill Impact
B21: GD-2 | C21: Exhibit Unitil-JDT-5 | E21: Bill Impact | F21: =E21 -> Bill Impact
B22: GD-3 | C22: Exhibit Unitil-JDT-5 | E22: Bill Impact | F22: =E22 -> Bill Impact
B23: GD-4 | C23: Exhibit Unitil-JDT-5 | E23: Bill Impact | F23: =E23 -> Bill Impact
B24: GD-5 | C24: Exhibit Unitil-JDT-5 | E24: Bill Impact | F24: =E24 -> Bill Impact
B25: SD | C25: Exhibit Unitil-JDT-5 | E25: Bill Impact | F25: =E25 -> Bill Impact
B26: SDC | C26: Exhibit Unitil-JDT-5 | E26: Bill Impact | F26: =E26 -> Bill Impact
B27: Support Files ---> | F27: =CONCATENATE(D27," - ",E27) -> -
B28: ProForma Revenue | C28: INCLUDED IN WORKPAPERS TO EXHIBIT UNITIL-JDT-3 | F28: =CONCATENATE(D28," - ",E28) -> - | G28: REDACTED
B29: Unitil LED Light Summary | C29: Workpaper to Exhibit Unitil-JDT-4, Schedule 2 | D29: WP | E29: Cost Based Analysis of LED Lighting Fixtures | F29: =CONCATENATE(D29," - ",E29) -> WP - Cost Based Analysis of LED Lighting Fixtures
B30: Rev_Billing_Det | C30: Workpaper to Exhibit Unitil-JDT-4, Schedule 2 | D30: WP | E30: Per Books Accuracy Report | F30: =CONCATENATE(D30," - ",E30) -> WP - Per Books Accuracy Report | G30: REDACTED
B31: Outdoor Lighting Update | C31: Workpaper to Exhibit Unitil-JDT-4, Schedule 2 | D31: WP | E31: 2022 Annual Outdoor Lighting Summary | F31: =CONCATENATE(D31," - ",E31) -> WP - 2022 Annual Outdoor Lighting Summary
B32: Atrium + Updated Rates | C32: Workpaper to Exhibit Unitil-JDT-4, Schedule 2 | D32: WP | E32: June 2023 Annualized Outdoor Lighting Fixtures | F32: =CONCATENATE(D32," - ",E32) -> WP - June 2023 Annualized Outdoor Lighting Fixtures
B33: Customer Owned Lights | C33: Workpaper to Exhibit Unitil-JDT-4, Schedule 2 | D33: WP | E33: Fitchburg/Lunenburg Customer Owned Lights | F33: =CONCATENATE(D33," - ",E33) -> WP - Fitchburg/Lunenburg Customer Owned Lights
B34: Rates and Eff Dates | C34: Workpaper to Exhibit Unitil-JDT-4, Schedule 2 | D34: WP | E34: Tariff Rates and Effective Dates | F34: =CONCATENATE(D34," - ",E34) -> WP - Tariff Rates and Effective Dates
B35: Total Revenues by Class | C35: Workpaper to Exhibit Unitil-JDT-4, Schedule 1 | D35: WP | E35: Computation of Total Current Revenues by Rate Class using test year average Basic Service | F35: =CONCATENATE(D35," - ",E35) -> WP - Computation of Total Current Revenues by Rate Class using test year average Basic Service
B36: Rider_Revenue | C36: Workpaper to Exhibit Unitil-JDT-4, Schedule 1 | D36: WP | E36: Rider Revenue Rolled into Base Rates | F36: =CONCATENATE(D36," - ",E36) -> WP - Rider Revenue Rolled into Base Rates
B37: For Bill Impacts | C37: Workpaper to Exhibit Unitil-JDT-5 | D37: WP | E37: Change to Reconciliation Mechanisms for Bill Impacts | F37: =CONCATENATE(D37," - ",E37) -> WP - Change to Reconciliation Mechanisms for Bill Impacts

Sheet Revenue Apportionment
A1: Fitchburg Gas and Electric Light Company
A2: Exhibit Unitil-JDT-4
A3: Schedule 1 - Revenue Apportionment
A7: (A) | B7: (B) | C7: (C) | D7: (D) | E7: (E) | F7: (F) | G7: (G) | H7: (H) | I7: (I) | J7: (J) | K7: (K) | L7: (L) | M7: (M) | N7: (N) | O7: (O) | P7: (P)
A9: Line | B9: Class | D9: Pro Forma Distribution Revenue | E9: Cost to Serve at Equal Rates of Return | F9: Increase (Decrease) @ 8.03% ROR | G9: 150% Overall System Increase | H9: Above 150% Overall Increase | I9: 10% Cap on Total Revenue | J9: Above 10% Cap on Total Revenue | K9: Increase Limited by Caps / No Decrease | L9: Reallocation of Excess | M9: Proposed Increase (Decrease) | N9: Proposed Margin | O9: Percentage Change | P9: Still within 150% Cap
A10: 1 | B10: Residential, Low Income | C10: RD-1/RD-2 | D10: ='Rate Design'!$E$21 -> 17394497 | E10: 22701838 | F10: =E10-D10 -> 5307340.7 | G10: =D10*$H$21 -> 3538423.9 | H10: =IF(F10>G10,"Yes","No") -> Yes | I10: =F29 -> 5903915.3 | J10: =IF(H10="yes",IF(G10>I10,"Yes","No"),IF(F10>I10,"Yes","No")) -> No | K10: =IF(AND(H10="No",J10="No",F10>0),F10,IF(J10="yes",I10,IF(H10="Yes",G10,0))) -> 3538423.9 | L10: =IF(H10="No", $L$22*(E10/SUMIF($H$10:$H$17, "No", $E$10:$E$17)),0) -> 0 | M10: =K10+L10 -> 3538423.9 | N10: =M10+D10 -> 20932921 | O10: =M10/D10 -> 0.20342203 | P10: =IF(M10>G10, "No", "Yes") -> Yes
A11: 2 | B11: Small General | C11: GD-1 | D11: ='Rate Design'!$E$29 -> 823493.82 | E11: 1445084.2 | F11: =E11-D11 -> 621590.37 | G11: =D11*$H$21 -> 167516.78 | H11: =IF(F11>G11,"Yes","No") -> Yes | I11: =F30 -> 211736.36 | J11: =IF(H11="yes",IF(G11>I11,"Yes","No"),IF(F11>I11,"Yes","No")) -> No | K11: =IF(AND(H11="No",J11="No",F11>0),F11,IF(J11="yes",I11,IF(H11="Yes",G11,0))) -> 167516.78 | L11: =IF(H11="No", $L$22*(E11/SUMIF($H$10:$H$17, "No", $E$10:$E$17)),0) -> 0 | M11: =K11+L11 -> 167516.78 | N11: =M11+D11 -> 991010.6 | O11: =M11/D11 -> 0.20342203 | P11: =IF(M11>G11, "No", "Yes") -> Yes
A12: 3 | B12: Regular General | C12: GD-2 | D12: ='Rate Design'!$E$39 -> 6129339.3 | E12: =D12*$D$22/$D$21 -> 4400753.8 | F12: =E12-D12 -> -1728585.5 | G12: =D12*$H$21 -> 1246842.7 | H12: =IF(F12>G12,"Yes","No") -> No | I12: =F31 -> 2639546.9 | J12: =IF(H12="yes",IF(G12>I12,"Yes","No"),IF(F12>I12,"Yes","No")) -> No | K12: =IF(AND(H12="No",J12="No",F12>0),F12,IF(J12="yes",I12,IF(H12="Yes",G12,0))) -> 0 | L12: =IF(H12="No", $L$22*(E12/SUMIF($H$10:$H$17, "No", $E$10:$E$17)),0) -> 128933.05 | M12: =K12+L12 -> 128933.05 | N12: =M12+D12 -> 6258272.4 | O12: =M12/D12 -> 0.021035391 | P12: =IF(M12>G12, "No", "Yes") -> Yes
A13: 4 | B13: Large General | C13: GD-3 | D13: ='Rate Design'!$E$48 -> 4134127.2 | E13: 3832874.6 | F13: =E13-D13 -> -301252.59 | G13: =D13*$H$21 -> 840972.55 | H13: =IF(F13>G13,"Yes","No") -> No | I13: =F32 -> 2739293.3 | J13: =IF(H13="yes",IF(G13>I13,"Yes","No"),IF(F13>I13,"Yes","No")) -> No | K13: =IF(AND(H13="No",J13="No",F13>0),F13,IF(J13="yes",I13,IF(H13="Yes",G13,0))) -> 0 | L13: =IF(H13="No", $L$22*(E13/SUMIF($H$10:$H$17, "No", $E$10:$E$17)),0) -> 112295.35 | M13: =K13+L13 -> 112295.35 | N13: =M13+D13 -> 4246422.6 | O13: =M13/D13 -> 0.027163014 | P13: =IF(M13>G13, "No", "Yes") -> Yes
A14: 5 | B14: Regular General Optional TOU | C14: GD-4 | D14: ='Rate Design'!$E$62 -> 8851.1352 | E14: =D14*$D$22/$D$21 -> 6354.9536 | F14: =E14-D14 -> -2496.1816 | G14: =D14*$H$21 -> 1800.5159 | H14: =IF(F14>G14,"Yes","No") -> No | I14: =F33 -> 7782.3829 | J14: =IF(H14="yes",IF(G14>I14,"Yes","No"),IF(F14>I14,"Yes","No")) -> No | K14: =IF(AND(H14="No",J14="No",F14>0),F14,IF(J14="yes",I14,IF(H14="Yes",G14,0))) -> 0 | L14: =IF(H14="No", $L$22*(E14/SUMIF($H$10:$H$17, "No", $E$10:$E$17)),0) -> 186.18709 | M14: =K14+L14 -> 186.18709 | N14: =M14+D14 -> 9037.3223 | O14: =M14/D14 -> 0.021035391 | P14: =IF(M14>G14, "No", "Yes") -> Yes
A15: 6 | B15: Water and/or Space Heating Rider | C15: GD-5 | D15: ='Rate Design'!$E$74 -> 23656.225 | E15: =D15*$D$22/$D$21 -> 16984.738 | F15: =E15-D15 -> -6671.4868 | G15: =D15*$H$21 -> 4812.1972 | H15: =IF(F15>G15,"Yes","No") -> No | I15: =F34 -> 10376.253 | J15: =IF(H15="yes",IF(G15>I15,"Yes","No"),IF(F15>I15,"Yes","No")) -> No | K15: =IF(AND(H15="No",J15="No",F15>0),F15,IF(J15="yes",I15,IF(H15="Yes",G15,0))) -> 0 | L15: =IF(H15="No", $L$22*(E15/SUMIF($H$10:$H$17, "No", $E$10:$E$17)),0) -> 497.61794 | M15: =K15+L15 -> 497.61794 | N15: =M15+D15 -> 24153.842 | O15: =M15/D15 -> 0.021035391 | P15: =IF(M15>G15, "No", "Yes") -> Yes
A16: 7 | B16: Lighting Company Owned | C16: SD | D16: ='Rate Design'!$E$91 -> 266880.39 | E16: 413273.59 | F16: =E16-D16 -> 146393.2 | G16: =D16*$H$21 -> 54289.35 | H16: =IF(F16>G16,"Yes","No") -> Yes | I16: =F35 -> 52187.196 | J16: =IF(H16="yes",IF(G16>I16,"Yes","No"),IF(F16>I16,"Yes","No")) -> Yes | K16: =IF(AND(H16="No",J16="No",F16>0),F16,IF(J16="yes",I16,IF(H16="Yes",G16,0))) -> 52187.196 | L16: =IF(H16="No", $L$22*(E16/SUMIF($H$10:$H$17, "No", $E$10:$E$17)),0) -> 0 | M16: =K16+L16 -> 52187.196 | N16: =M16+D16 -> 319067.58 | O16: =M16/D16 -> 0.19554526 | P16: =IF(M16>G16, "No", "Yes") -> Yes
A17: 8 | B17: Lighting Customer Owned | C17: SDC | D17: ='Rate Design'!$E$92 -> 46202.774 | E17: 111660.93 | F17: =E17-D17 -> 65458.156 | G17: =D17*$H$21 -> 9398.6621 | H17: =IF(F17>G17,"Yes","No") -> Yes | I17: =F36 -> 19097.933 | J17: =IF(H17="yes",IF(G17>I17,"Yes","No"),IF(F17>I17,"Yes","No")) -> No | K17: =IF(AND(H17="No",J17="No",F17>0),F17,IF(J17="yes",I17,IF(H17="Yes",G17,0))) -> 9398.6621 | L17: =IF(H17="No", $L$22*(E17/SUMIF($H$10:$H$17, "No", $E$10:$E$17)),0) -> 0 | M17: =K17+L17 -> 9398.6621 | N17: =M17+D17 -> 55601.436 | O17: =M17/D17 -> 0.20342203 | P17: =IF(M17>G17, "No", "Yes") -> Yes
A18: 9 | B18: Miscellaneous Revenues | D18: 1418766.1 | E18: =D18 -> 1418766.1 | F18: 0 | M18: =L21 -> 92337.829 | N18: =E18+L21 -> 1511103.9 | O18: =M18/D18 -> 0.065083194
A19: 10 | B19: System Total | D19: =SUM(D10:D18) -> 30245814 | E19: =SUM(E10:E18) -> 34347591 | F19: =SUM(F10:F18) -> 4101776.6 | K19: =SUM(K10:K18) -> 3767526.6 | L19: =SUM(L10:L18) -> 241912.21 | M19: =SUM(M10:M18) -> 4101776.6 | N19: =SUM(N10:N18) -> 34347591
A20: 11 | B20: GD-2, GD-4, GD-5: Regular General | G20: Overall System Increase | H20: =F19/D19 -> 0.13561469 | L20: =F19-K19 -> 334250.04 | M20: Required Additional Increase
A21: 12 | B21: Pro Forma Distribution Revenue | D21: =D12+D14+D15 -> 6161846.7 | G21: 150% Overall System System | H21: =H20*150% -> 0.20342203 | L21: 92337.829 | M21: Change in Misc. Revenues
A22: 13 | B22: Revenue @ Equal ROR | D22: 4424093.5 | L22: =L20-L21 -> 241912.21 | M22: Required Additional Increase
A23: 14
A24: 15 | M24: GD-2, GD-4, GD-5: Regular General | N24: =SUM(N12,N14,N15) -> 6291463.6
A25: 16 | M25: OL Combined | N25: =SUM(N16:N17) -> 374669.02
A26: (A) | B26: (B) | C26: (C) | D26: (D) | E26: (E) | F26: (F) | G26: (G) | H26: (H)
A28: Line | B28: Class | D28: 10% Cap on Total Revenue | E28: Changes to Reconciliation Mechanisms | F28: Revised Cap w/ Changes to Reconciliation Mechanism | G28: Proposed Increase (Decrease) | H28: Under 10% Cap on Total Revenue
A29: =+A25+1 -> 17 | B29: Residential, Low Income | C29: RD-1/RD-2 | D29: ='Total Revenues by Class'!L11 -> 6370957 | E29: =SUM(E41:E42) -> 467041.67 | F29: =D29-E29 -> 5903915.3 | G29: =M10 -> 3538423.9 | H29: =IF(G29>F29, "No", "Yes") -> Yes
A30: =+A29+1 -> 18 | B30: Small General | C30: GD-1 | D30: ='Total Revenues by Class'!L15 -> 223856.67 | E30: =+Rider_Revenue!O11 -> 12120.311 | F30: =D30-E30 -> 211736.36 | G30: =M11 -> 167516.78 | H30: =IF(G30>F30, "No", "Yes") -> Yes
A31: =+A30+1 -> 19 | B31: Regular General | C31: GD-2 | D31: ='Total Revenues by Class'!L19 -> 2817542.2 | E31: =+Rider_Revenue!O12 -> 177995.33 | F31: =D31-E31 -> 2639546.9 | G31: =M12 -> 128933.05 | H31: =IF(G31>F31, "No", "Yes") -> Yes
A32: =+A31+1 -> 20 | B32: Large General | C32: GD-3 | D32: ='Total Revenues by Class'!L25 -> 2793064.7 | E32: =+Rider_Revenue!O13 -> 53771.363 | F32: =D32-E32 -> 2739293.3 | G32: =M13 -> 112295.35 | H32: =IF(G32>F32, "No", "Yes") -> Yes
A33: =+A32+1 -> 21 | B33: Regular General Optional TOU | C33: GD-4 | D33: ='Total Revenues by Class'!L31 -> 8389.0701 | E33: =+Rider_Revenue!O14 -> 606.68725 | F33: =D33-E33 -> 7782.3829 | G33: =M14 -> 186.18709 | H33: =IF(G33>F33, "No", "Yes") -> Yes
A34: =+A33+1 -> 22 | B34: Water and/or Space Heating Rider | C34: GD-5 | D34: ='Total Revenues by Class'!L38 -> 11079.796 | E34: =+Rider_Revenue!O15 -> 703.5436 | F34: =D34-E34 -> 10376.253 | G34: =M15 -> 497.61794 | H34: =IF(G34>F34, "No", "Yes") -> Yes
A35: =+A34+1 -> 23 | B35: Lighting Company Owned | C35: SD | D35: ='Total Revenues by Class'!L44 -> 54186.743 | E35: =+Rider_Revenue!O16 -> 1999.5475 | F35: =D35-E35 -> 52187.196 | G35: =M16 -> 52187.196 | H35: =IF(G35>F35, "No", "Yes") -> Yes
A36: =+A35+1 -> 24 | B36: Lighting Customer Owned | C36: SDC | D36: ='Total Revenues by Class'!L45 -> 20238.301 | E36: =+Rider_Revenue!O17 -> 1140.3686 | F36: =D36-E36 -> 19097.933 | G36: =M17 -> 9398.6621 | H36: =IF(G36>F36, "No", "Yes") -> Yes
A37: =+A36+1 -> 25 | B37: Miscellaneous Revenues | G37: =M18 -> 92337.829
A38: =+A37+1 -> 26 | D38: =SUM(D29:D37) -> 12299314 | E38: =SUM(E29:E37) -> 715378.82 | F38: =SUM(F29:F37) -> 11583936 | G38: =M19 -> 4101776.6
E40: Changes to Reconciliation Mechanisms
D41: RD-1 | E41: =+Rider_Revenue!O9 -> 372016.85
D42: RD-2 | E42: =+Rider_Revenue!O10 -> 95024.817

Sheet Rate Design
A1: Fitchburg Gas and Electric Light Company
A2: Exhibit Unitil-JDT-4
A3: Schedule 2 - Revenue Proof and Rate Design
A6: Line No. | B6: Description | C6: TY Billing Determinants | D6: Current Rate | E6: Current Total Distribution Revenue | G6: Proposed Rate | H6: Proposed Total Distribution Revenue | J6: Difference ($) | K6: Difference (%)
A7: =IF(AND(B7="",E7=""),"",MAX(A$1:A6)+1) -> 1 | B7: RD-1: Residential
A8: =IF(AND(B8="",E8=""),"",MAX(A$1:A7)+1) -> 2 | B8: Customer Charge | C8: =SUMIFS(Rev_Billing_Det!$C$180:$C$186,Rev_Billing_Det!$A$180:$A$186,LEFT($B7,4)) -> 254959.9 | D8: =Rates!C8 -> 7 | E8: =D8*C8 -> 1784719.3 | G8: =G18 -> 8.5 | H8: =C8*G8 -> 2167159.1 | J8: =H8-E8 -> 382439.85 | K8: =J8/E8 -> 0.21428571 | M8: RD-1: Residential
A9: =IF(AND(B9="",E9=""),"",MAX(A$1:A8)+1) -> 3 | B9: Distribution Charge | C9: =SUMIFS(Rev_Billing_Det!$E$180:$E$186,Rev_Billing_Det!$A$180:$A$186,LEFT($B7,4)) -> 137275588 | D9: =Rates!C9 -> 0.07903 | E9: =D9*C9 -> 10848890 | G9: =G19 -> 0.10585 | H9: =C9*G9 -> 14530621 | J9: =H9-E9 -> 3681731.3 | K9: =J9/E9 -> 0.3393648 | M9: RD-1: Residential
A10: =IF(AND(B10="",E10=""),"",MAX(A$1:A9)+1) -> 4 | B10: Riders | E10: =-Rider_Revenue!N9 -> 1242344.1 | H10: 0 | J10: =H10-E10 -> -1242344.1
A11: =IF(AND(B11="",E11=""),"",MAX(A$1:A10)+1) -> 5 | E11: =SUM(E8:E10) -> 13875953 | H11: =SUM(H8:H10) -> 16697780 | J11: =H11-E11 -> 2821827 | K11: =J11/E11 -> 0.20336095
A12: =IF(AND(B12="",E12=""),"",MAX(A$1:A11)+1) -> 6 | B12: RD-2: Residential, Low Income
A13: =IF(AND(B13="",E13=""),"",MAX(A$1:A12)+1) -> 7 | B13: Customer Charge | C13: =SUMIFS(Rev_Billing_Det!$C$180:$C$186,Rev_Billing_Det!$A$180:$A$186,LEFT($B12,4)) -> 61437.474 | D13: =Rates!C12 -> 7 | E13: =D13*C13 -> 430062.32 | G13: =G18 -> 8.5 | H13: =C13*G13 -> 522218.53 | J13: =H13-E13 -> 92156.211 | K13: =J13/E13 -> 0.21428571 | M13: RD-2: Residential, Low Income
A14: =IF(AND(B14="",E14=""),"",MAX(A$1:A13)+1) -> 8 | B14: Distribution Charge | C14: =SUMIFS(Rev_Billing_Det!$E$180:$E$186,Rev_Billing_Det!$A$180:$A$186,LEFT($B12,4)) -> 35064508 | D14: =Rates!C13 -> 0.07903 | E14: =D14*C14 -> 2771148.1 | G14: =G19 -> 0.10585 | H14: =C14*G14 -> 3711578.2 | J14: =H14-E14 -> 940430.1 | K14: =J14/E14 -> 0.3393648 | M14: RD-2: Residential, Low Income
A15: =IF(AND(B15="",E15=""),"",MAX(A$1:A14)+1) -> 9 | B15: Riders | E15: =-Rider_Revenue!N10 -> 317333.8 | H15: 0 | J15: =H15-E15 -> -317333.8
A16: =IF(AND(B16="",E16=""),"",MAX(A$1:A15)+1) -> 10 | E16: =SUM(E13:E15) -> 3518544.2 | H16: =SUM(H13:H15) -> 4233796.7 | J16: =H16-E16 -> 715252.52 | K16: =J16/E16 -> 0.20328081
A17: =IF(AND(B17="",E17=""),"",MAX(A$1:A16)+1) -> 11 | B17: Total_R-1, R-2: Residential
A18: =IF(AND(B18="",E18=""),"",MAX(A$1:A17)+1) -> 12 | B18: Total Customer Charge | C18: =C8+C13 -> 316397.37 | E18: =E8+E13 -> 2214781.6 | G18: =Rates!M8 -> 8.5 | H18: =H8+H13 -> 2689377.7 | J18: =H18-E18 -> 474596.06 | K18: =J18/E18 -> 0.21428571
A19: =IF(AND(B19="",E19=""),"",MAX(A$1:A18)+1) -> 13 | B19: Total Distribution Charge | C19: =C9+C14 -> 172340096 | E19: =E9+E14 -> 13620038 | G19: =TRUNC((H23-H18)/C19,5) -> 0.10585 | H19: =G19*C19 -> 18242199 | J19: =H19-E19 -> 4622161.4 | K19: =J19/E19 -> 0.3393648
A20: =IF(AND(B20="",E20=""),"",MAX(A$1:A19)+1) -> 14 | B20: Riders | E20: =E10+E15 -> 1559677.9 | H20: =G20*C20 -> 0 | J20: =H20-E20 -> -1559677.9
A21: =IF(AND(B21="",E21=""),"",MAX(A$1:A20)+1) -> 15 | E21: =SUM(E18:E20) -> 17394497 | H21: =SUM(H18:H20) -> 20931577 | J21: =H21-E21 -> 3537079.6 | K21: =J21/E21 -> 0.20334474
A22: =IF(AND(B22="",E22=""),"",MAX(A$1:A21)+1)
A23: =IF(AND(B23="",E23=""),"",MAX(A$1:A22)+1) -> 16 | B23: Revenue Target_R-1, R-2: Residential | H23: ='Revenue Apportionment'!N10 -> 20932921
A24: =IF(AND(B24="",E24=""),"",MAX(A$1:A23)+1) -> 17 | B24: Difference | H24: =H23-H21 -> 1344.3775
A25: =IF(AND(B25="",E25=""),"",MAX(A$1:A24)+1) -> 18 | B25: GD-1: Small General
A26: =IF(AND(B26="",E26=""),"",MAX(A$1:A25)+1) -> 19 | B26: Customer Charge | C26: =SUMIFS(Rev_Billing_Det!$C$180:$C$186,Rev_Billing_Det!$A$180:$A$186,LEFT($B25,4)) -> 30492.186 | D26: =Rates!C16 -> 10 | E26: =D26*C26 -> 304921.86 | G26: =Rates!M9 -> 12 | H26: =C26*G26 -> 365906.23 | J26: =H26-E26 -> 60984.372 | K26: =J26/E26 -> 0.2 | M26: GD-1: Small General
A27: =IF(AND(B27="",E27=""),"",MAX(A$1:A26)+1) -> 20 | B27: Distribution Charge | C27: =SUMIFS(Rev_Billing_Det!$E$180:$E$186,Rev_Billing_Det!$A$180:$A$186,LEFT($B25,4)) -> 5912347 | D27: =Rates!C17 -> 0.0785 | E27: =D27*C27 -> 464119.24 | G27: =TRUNC((H31-H26)/C27,5) -> 0.10572 | H27: =G27*C27 -> 625053.32 | J27: =H27-E27 -> 160934.09 | K27: =J27/E27 -> 0.34675159 | M27: GD-1: Small General
A28: =IF(AND(B28="",E28=""),"",MAX(A$1:A27)+1) -> 21 | B28: Riders | E28: =-Rider_Revenue!N11 -> 54452.716 | H28: 0
A29: =IF(AND(B29="",E29=""),"",MAX(A$1:A28)+1) -> 22 | E29: =SUM(E26:E28) -> 823493.82 | H29: =SUM(H26:H28) -> 990959.56 | J29: =SUM(J26:J27) -> 221918.46 | K29: =J29/E29 -> 0.26948406
A30: =IF(AND(B30="",E30=""),"",MAX(A$1:A29)+1)
A31: =IF(AND(B31="",E31=""),"",MAX(A$1:A30)+1) -> 23 | B31: =CONCATENATE("Revenue Target_",B25) -> Revenue Target_GD-1: Small General | H31: ='Revenue Apportionment'!N11 -> 991010.6
A32: =IF(AND(B32="",E32=""),"",MAX(A$1:A31)+1) -> 24 | B32: Difference | H32: =H31-H29 -> 51.04213
A33: =IF(AND(B33="",E33=""),"",MAX(A$1:A32)+1) -> 25 | B33: GD-2: Regular General
A34: =IF(AND(B34="",E34=""),"",MAX(A$1:A33)+1) -> 26 | B34: Customer Charge | C34: =SUMIFS(Rev_Billing_Det!$C$180:$C$186,Rev_Billing_Det!$A$180:$A$186,LEFT($B33,4)) -> 18164.621 | D34: =Rates!C20 -> 10 | E34: =C34*D34 -> 181646.21 | G34: =Rates!M10 -> 12 | H34: =C34*G34 -> 217975.45 | J34: =H34-E34 -> 36329.242 | K34: =J34/E34 -> 0.2 | M34: GD-2: Regular General
A35: =IF(AND(B35="",E35=""),"",MAX(A$1:A34)+1) -> 27 | B35: Demand Charge | C35: =SUMIFS(Rev_Billing_Det!$M$180:$M$186,Rev_Billing_Det!$A$180:$A$186,LEFT($B33,4)) -> 323618.5 | D35: =Rates!C21 -> 9.81 | E35: =C35*D35 -> 3174697.5 | G35: =Rates!M11 -> 10 | H35: =C35*G35 -> 3236185 | J35: =H35-E35 -> 61487.515 | K35: =J35/E35 -> 0.019367992 | M35: GD-2: Regular General
A36: =IF(AND(B36="",E36=""),"",MAX(A$1:A35)+1) -> 28 | B36: Distribution Charge | C36: =SUMIFS(Rev_Billing_Det!$E$180:$E$186,Rev_Billing_Det!$A$180:$A$186,LEFT($B33,4)) -> 86826989 | D36: =Rates!C22 -> 0.02377 | E36: =C36*D36 -> 2063877.5 | G36: =TRUNC((H41-H34-H35-H37)/C36,5) -> 0.03234 | H36: =C36*G36 -> 2807984.8 | J36: =H36-E36 -> 744107.3 | K36: =J36/E36 -> 0.36053849 | M36: GD-2: Regular General
A37: =IF(AND(B37="",E37=""),"",MAX(A$1:A36)+1) -> 29 | B37: Transformer Credit | C37: =E37/D37 -> 24209.105 | D37: =$D$82 -> -0.19 | E37: ='ProForma Revenue'!E28 -> -4599.73 | G37: =D37 -> -0.19 | H37: =C37*G37 -> -4599.73 | J37: =H37-E37 -> 0 | K37: =J37/E37 -> 0 | M37: GD-2: Regular General
A38: =IF(AND(B38="",E38=""),"",MAX(A$1:A37)+1) -> 30 | B38: Riders | E38: =-Rider_Revenue!N12 -> 713717.85 | H38: 0
A39: =IF(AND(B39="",E39=""),"",MAX(A$1:A38)+1) -> 31 | E39: =SUM(E34:E38) -> 6129339.3 | H39: =SUM(H34:H38) -> 6257545.5 | J39: =H39-E39 -> 128206.2 | K39: =J39/E39 -> 0.020916806
A40: =IF(AND(B40="",E40=""),"",MAX(A$1:A39)+1)
A41: =IF(AND(B41="",E41=""),"",MAX(A$1:A40)+1) -> 32 | B41: =CONCATENATE("Revenue Target_",B33) -> Revenue Target_GD-2: Regular General | H41: ='Revenue Apportionment'!N12 -> 6258272.4
A42: =IF(AND(B42="",E42=""),"",MAX(A$1:A41)+1) -> 33 | B42: Difference | H42: =H41-H39 -> 726.84706
...

Sheet Rate Design Lighting
A1: Fitchburg Gas and Electric Light Company
A2: Exhibit Unitil-JDT-4
A3: Schedule 2 - Revenue Proof and Rate Design
A5: Line No. | D5: TY Billing | E5: Current | F5: Current | H5: Proposed | I5: Proposed
B6: Outdoor Lighting | D6: Determinants | E6: Rates | F6: Revenue | H6: Rates | I6: Revenue
A7: =IF(B7="","",MAX(A$6:A6)+1) -> 1 | B7: SD: Outdoor Lighting - Company Owned
A8: =IF(B8="","",MAX(A$6:A7)+1)
A9: =IF(B9="","",MAX(A$6:A8)+1) -> 2 | B9: Energy | C9: Company Owned - All kWh | D9: ='ProForma Revenue'!G105 -> 1041430.9 | E9: ='Rates and Eff Dates'!D46 -> 0 | F9: =D9*E9 -> 0 | H9: =TRUNC(E9*($I$76),5) -> 0 | I9: =H9*D9 -> 0
A10: =IF(B10="","",MAX(A$6:A9)+1)
A11: =IF(B11="","",MAX(A$6:A10)+1) -> 3 | B11: Lumens | C11: Luminaire
A12: =IF(B12="","",MAX(A$6:A11)+1) -> 4 | B12: Mercury Vapor:
A13: =IF(B13="","",MAX(A$6:A12)+1) -> 5 | B13: 3500 | C13: Street and Highway Type | D13: ='ProForma Revenue'!G53 -> 48 | E13: ='Rates and Eff Dates'!E53 -> 13.54 | F13: =D13*E13 -> 649.92 | H13: =TRUNC(E13*($I$76),2) -> 17.3 | I13: =H13*D13 -> 830.4
A14: =IF(B14="","",MAX(A$6:A13)+1) -> 6 | B14: 7000 | C14: Street and Highway Type | D14: ='ProForma Revenue'!G54 -> 84 | E14: ='Rates and Eff Dates'!E54 -> 15.02 | F14: =D14*E14 -> 1261.68 | H14: =TRUNC(E14*($I$76),2) -> 19.19 | I14: =H14*D14 -> 1611.96
A15: =IF(B15="","",MAX(A$6:A14)+1) -> 7 | B15: 20000 | C15: Street and Highway Type | D15: ='ProForma Revenue'!G55 -> 0 | E15: ='Rates and Eff Dates'!E55 -> 27.29 | F15: =D15*E15 -> 0 | H15: =TRUNC(E15*($I$76),2) -> 34.88 | I15: =H15*D15 -> 0
A16: =IF(B16="","",MAX(A$6:A15)+1) -> 8 | B16: 60000 | C16: Street and Highway Type | D16: ='ProForma Revenue'!G56 -> 84 | E16: ='Rates and Eff Dates'!E56 -> 52.18 | F16: =D16*E16 -> 4383.12 | H16: =TRUNC(E16*($I$76),2) -> 66.69 | I16: =H16*D16 -> 5601.96
A17: =IF(B17="","",MAX(A$6:A16)+1) -> 9 | B17: 20000 | C17: Flood Light Type | D17: ='ProForma Revenue'!G57 -> 300 | E17: ='Rates and Eff Dates'!E57 -> 30.18 | F17: =D17*E17 -> 9054 | H17: =TRUNC(E17*($I$76),2) -> 38.57 | I17: =H17*D17 -> 11571
A18: =IF(B18="","",MAX(A$6:A17)+1) -> 10 | B18: 3500 | C18: Power Bracket Included | D18: ='ProForma Revenue'!G58 -> 348 | E18: ='Rates and Eff Dates'!E58 -> 14.18 | F18: =D18*E18 -> 4934.64 | H18: =TRUNC(E18*($I$76),2) -> 18.12 | I18: =H18*D18 -> 6305.76
A19: =IF(B19="","",MAX(A$6:A18)+1) -> 11 | B19: 7000 | C19: Power Bracket Included | D19: ='ProForma Revenue'!G59 -> 300 | E19: ='Rates and Eff Dates'!E59 -> 15.97 | F19: =D19*E19 -> 4791 | H19: =TRUNC(E19*($I$76),2) -> 20.41 | I19: =H19*D19 -> 6123
A20: =IF(B20="","",MAX(A$6:A19)+1)
A21: =IF(B21="","",MAX(A$6:A20)+1) -> 12 | B21: High Pressure Sodium:
A22: =IF(B22="","",MAX(A$6:A21)+1) -> 13 | B22: 3300 | C22: Street and Highway Type | D22: ='ProForma Revenue'!G61 -> 1580 | E22: ='Rates and Eff Dates'!E62 -> 11.75 | F22: =D22*E22 -> 18565 | H22: =TRUNC(E22*($I$76),2) -> 15.01 | I22: =H22*D22 -> 23715.8
A23: =IF(B23="","",MAX(A$6:A22)+1) -> 14 | B23: 9500 | C23: Street and Highway Type | D23: ='ProForma Revenue'!G62 -> 996 | E23: ='Rates and Eff Dates'!E63 -> 13.97 | F23: =D23*E23 -> 13914.12 | H23: =TRUNC(E23*($I$76),2) -> 17.85 | I23: =H23*D23 -> 17778.6
A24: =IF(B24="","",MAX(A$6:A23)+1) -> 15 | B24: 20000 | C24: Street and Highway Type | D24: ='ProForma Revenue'!G63 -> 96 | E24: ='Rates and Eff Dates'!E64 -> 20.83 | F24: =D24*E24 -> 1999.68 | H24: =TRUNC(E24*($I$76),2) -> 26.62 | I24: =H24*D24 -> 2555.52
A25: =IF(B25="","",MAX(A$6:A24)+1) -> 16 | B25: 50000 | C25: Street and Highway Type | D25: ='ProForma Revenue'!G64 -> 72 | E25: ='Rates and Eff Dates'!E65 -> 29.62 | F25: =D25*E25 -> 2132.64 | H25: =TRUNC(E25*($I$76),2) -> 37.86 | I25: =H25*D25 -> 2725.92
A26: =IF(B26="","",MAX(A$6:A25)+1) -> 17 | B26: 140000 | C26: Street and Highway Type | D26: ='ProForma Revenue'!G65 -> 516 | E26: ='Rates and Eff Dates'!E66 -> 60.77 | F26: =D26*E26 -> 31357.32 | H26: =TRUNC(E26*($I$76),2) -> 77.67 | I26: =H26*D26 -> 40077.72
A27: =IF(B27="","",MAX(A$6:A26)+1) -> 18 | B27: 50000 | C27: Flood Light Type | D27: ='ProForma Revenue'!G66 -> 3480 | E27: ='Rates and Eff Dates'!E67 -> 34.38 | F27: =D27*E27 -> 119642.4 | H27: =TRUNC(E27*($I$76),2) -> 43.94 | I27: =H27*D27 -> 152911.2
A28: =IF(B28="","",MAX(A$6:A27)+1)
A29: =IF(B29="","",MAX(A$6:A28)+1) -> 19 | B29: Light Emitting Diode (LED):
A30: =IF(B30="","",MAX(A$6:A29)+1) -> 20 | B30: 10680 | C30: Cobra Head Type | D30: ='ProForma Revenue'!G81 -> 84 | E30: ='ProForma Revenue'!M81 -> 15.1 | F30: =D30*E30 -> 1268.4
A31: =IF(B31="","",MAX(A$6:A30)+1) -> 21 | C31: 28 Watt LED Street | D31: ='ProForma Revenue'!G95 -> 1296 | E31: ='ProForma Revenue'!M95 -> 7.58 | F31: =D31*E31 -> 9823.68
A32: =IF(B32="","",MAX(A$6:A31)+1) -> 22 | C32: 47 Watt LED Street | D32: ='ProForma Revenue'!G96 -> 138 | E32: ='ProForma Revenue'!M96 -> 8.36 | F32: =D32*E32 -> 1153.68
A33: =IF(B33="","",MAX(A$6:A32)+1) -> 23 | C33: 54 Watt LED Street | D33: ='ProForma Revenue'!G97 -> 180 | E33: ='ProForma Revenue'!M97 -> 8.65 | F33: =D33*E33 -> 1557
A34: =IF(B34="","",MAX(A$6:A33)+1) -> 24 | C34: 70 Watt LED Street | D34: ='ProForma Revenue'!G98 -> 12 | E34: ='ProForma Revenue'!M98 -> 12.83 | F34: =D34*E34 -> 153.96
A35: =IF(B35="","",MAX(A$6:A34)+1) -> 25 | C35: 110 Watt LED Flood | D35: ='ProForma Revenue'!G99 -> 1448 | E35: ='ProForma Revenue'!M99 -> 15.08 | F35: =D35*E35 -> 21835.84
A36: =IF(B36="","",MAX(A$6:A35)+1) -> 26 | C36: 110 Watt LED Flood - CREE | D36: ='ProForma Revenue'!G100 -> 12 | E36: ='ProForma Revenue'!M100 -> 25.79 | F36: =D36*E36 -> 309.48
A37: =IF(B37="","",MAX(A$6:A36)+1)
A38: =IF(B38="","",MAX(A$6:A37)+1) -> 27 | B38: New LED Offering
A39: =IF(B39="","",MAX(A$6:A38)+1) -> 28 | B39: Cobra | C39: 20-30 Cobra Head | D39: =D31 -> 1296 | E39: =E31 -> 7.58 | F39: =D39*E39 -> 9823.68 | H39: 9.5 | I39: =H39*D39 -> 12312
A40: =IF(B40="","",MAX(A$6:A39)+1) -> 29 | C40: 31-40 Cobra Head | H40: 10.25 | I40: =H40*D40 -> 0
A41: =IF(B41="","",MAX(A$6:A40)+1) -> 30 | C41: 41-50 Cobra Head | D41: =D32 -> 138 | E41: =E32 -> 8.36 | F41: =D41*E41 -> 1153.68 | H41: 11 | I41: =H41*D41 -> 1518
...

Sheet Heat Pump Rate Design
A1: Fitchburg Gas and Electric Light Company
A2: Exhibit Unitil-JDT-6
A3: Residential Heat Pump Rate Design
A6: Line
A7: 1 | B7: Assumptions:
A8: =IF(ISBLANK(B8),"",MAX($A$6:A7)+1)
A9: =IF(ISBLANK(B9),"",MAX($A$6:A8)+1) -> 2 | B9: RD-1: Residential | C9: Proposed Rate
A10: =IF(ISBLANK(B10),"",MAX($A$6:A9)+1) -> 3 | B10: Customer Charge | C10: ='Rate Design'!G8 -> 8.5
A11: =IF(ISBLANK(B11),"",MAX($A$6:A10)+1) -> 4 | B11: Distribution Charge | C11: ='Rate Design'!G9 -> 0.10585
A12: =IF(ISBLANK(B12),"",MAX($A$6:A11)+1)
A13: =IF(ISBLANK(B13),"",MAX($A$6:A12)+1) -> 5 | B13: Average Monthly UPC | C13: RD-1 Average Monthly Use | D13: Cost Recovery per Month | E13: Fixed Cost Recovery in Volumetric Rate | F13: Fixed Cost Recovery in Fixed Charge | G13: Avg. Monthly Use with Heat Pump (kWh) | J13: Normal Therm UPC | K13: Therms (Heating Load) | L13: Avg. Temp. | M13: Avg. Temp COP | N13: kWh Conversion | O13: kWh Usage
A14: =IF(ISBLANK(B14),"",MAX($A$6:A13)+1) -> 6 | B14: January | C14: =SUMIFS(Rev_Billing_Det!E:E,Rev_Billing_Det!$A:$A,"RD-1",Rev_Billing_Det!$S:$S,$B14)/SUMIFS(Rev_Billing_Det!C:C,Rev_Billing_Det!$A:$A,"RD-1",Rev_Billing_Det!$S:$S,$B14) -> 684.49087 | D14: =$C$10+$C$11*C14 -> 80.953359 | E14: =($C$11-$C$43)*C14 -> 72.453359 | F14: =$C$10 -> 8.5 | G14: =C14+O14 -> 2137.0376 | J14: 139.19505 | K14: =J14-$K$27 -> 123.93744 | L14: 26.802554 | M14: 2.5 | N14: =K14*$K$28 -> 3631.3669 | O14: =N14/M14 -> 1452.5468
A15: =IF(ISBLANK(B15),"",MAX($A$6:A14)+1) -> 7 | B15: February | C15: =SUMIFS(Rev_Billing_Det!E:E,Rev_Billing_Det!$A:$A,"RD-1",Rev_Billing_Det!$S:$S,$B15)/SUMIFS(Rev_Billing_Det!C:C,Rev_Billing_Det!$A:$A,"RD-1",Rev_Billing_Det!$S:$S,$B15) -> 634.50006 | D15: =$C$10+$C$11*C15 -> 75.661831 | E15: =($C$11-$C$43)*C15 -> 67.161831 | F15: =$C$10 -> 8.5 | G15: =C15+O15 -> 2019.855 | J15: 145.2824 | K15: =J15-$K$27 -> 130.02478 | L15: 28.677307 | M15: 2.75 | N15: =K15*$K$28 -> 3809.726 | O15: =N15/M15 -> 1385.3549
A16: =IF(ISBLANK(B16),"",MAX($A$6:A15)+1) -> 8 | B16: March | C16: =SUMIFS(Rev_Billing_Det!E:E,Rev_Billing_Det!$A:$A,"RD-1",Rev_Billing_Det!$S:$S,$B16)/SUMIFS(Rev_Billing_Det!C:C,Rev_Billing_Det!$A:$A,"RD-1",Rev_Billing_Det!$S:$S,$B16) -> 552.57366 | D16: =$C$10+$C$11*C16 -> 66.989922 | E16: =($C$11-$C$43)*C16 -> 58.489922 | F16: =$C$10 -> 8.5 | G16: =C16+O16 -> 1632.7635 | J16: 125.85726 | K16: =J16-$K$27 -> 110.59964 | L16: 35.628226 | M16: 3 | N16: =K16*$K$28 -> 3240.5694 | O16: =N16/M16 -> 1080.1898
A17: =IF(ISBLANK(B17),"",MAX($A$6:A16)+1) -> 9 | B17: April | C17: =SUMIFS(Rev_Billing_Det!E:E,Rev_Billing_Det!$A:$A,"RD-1",Rev_Billing_Det!$S:$S,$B17)/SUMIFS(Rev_Billing_Det!C:C,Rev_Billing_Det!$A:$A,"RD-1",Rev_Billing_Det!$S:$S,$B17) -> 441.96789 | D17: =$C$10+$C$11*C17 -> 55.282301 | E17: =($C$11-$C$43)*C17 -> 46.782301 | F17: =$C$10 -> 8.5 | G17: =C17+O17 -> 1130.1593 | J17: 97.464783 | K17: =J17-$K$27 -> 82.207166 | L17: 46.415833 | M17: 3.5 | N17: =K17*$K$28 -> 2408.67 | O17: =N17/M17 -> 688.19142
A18: =IF(ISBLANK(B18),"",MAX($A$6:A17)+1) -> 10 | B18: May | C18: =SUMIFS(Rev_Billing_Det!E:E,Rev_Billing_Det!$A:$A,"RD-1",Rev_Billing_Det!$S:$S,$B18)/SUMIFS(Rev_Billing_Det!C:C,Rev_Billing_Det!$A:$A,"RD-1",Rev_Billing_Det!$S:$S,$B18) -> 434.81857 | D18: =$C$10+$C$11*C18 -> 54.525546 | E18: =($C$11-$C$43)*C18 -> 46.025546 | F18: =$C$10 -> 8.5 | G18: =C18+O18 -> 434.81857 | J18: 51.10096
A19: =IF(ISBLANK(B19),"",MAX($A$6:A18)+1) -> 11 | B19: June | C19: =SUMIFS(Rev_Billing_Det!E:E,Rev_Billing_Det!$A:$A,"RD-1",Rev_Billing_Det!$S:$S,$B19)/SUMIFS(Rev_Billing_Det!C:C,Rev_Billing_Det!$A:$A,"RD-1",Rev_Billing_Det!$S:$S,$B19) -> 472.29002 | D19: =$C$10+$C$11*C19 -> 58.491899 | E19: =($C$11-$C$43)*C19 -> 49.991899 | F19: =$C$10 -> 8.5 | G19: =C19+O19 -> 472.29002 | J19: 15.105046
A20: =IF(ISBLANK(B20),"",MAX($A$6:A19)+1) -> 12 | B20: July | C20: =SUMIFS(Rev_Billing_Det!E:E,Rev_Billing_Det!$A:$A,"RD-1",Rev_Billing_Det!$S:$S,$B20)/SUMIFS(Rev_Billing_Det!C:C,Rev_Billing_Det!$A:$A,"RD-1",Rev_Billing_Det!$S:$S,$B20) -> 596.22826 | D20: =$C$10+$C$11*C20 -> 71.610761 | E20: =($C$11-$C$43)*C20 -> 63.110761 | F20: =$C$10 -> 8.5 | G20: =C20+O20 -> 596.22826 | J20: 16.015968
A21: =IF(ISBLANK(B21),"",MAX($A$6:A20)+1) -> 13 | B21: August | C21: =SUMIFS(Rev_Billing_Det!E:E,Rev_Billing_Det!$A:$A,"RD-1",Rev_Billing_Det!$S:$S,$B21)/SUMIFS(Rev_Billing_Det!C:C,Rev_Billing_Det!$A:$A,"RD-1",Rev_Billing_Det!$S:$S,$B21) -> 717.36074 | D21: =$C$10+$C$11*C21 -> 84.432634 | E21: =($C$11-$C$43)*C21 -> 75.932634 | F21: =$C$10 -> 8.5 | G21: =C21+O21 -> 717.36074 | J21: 11.958408
A22: =IF(ISBLANK(B22),"",MAX($A$6:A21)+1) -> 14 | B22: September | C22: =SUMIFS(Rev_Billing_Det!E:E,Rev_Billing_Det!$A:$A,"RD-1",Rev_Billing_Det!$S:$S,$B22)/SUMIFS(Rev_Billing_Det!C:C,Rev_Billing_Det!$A:$A,"RD-1",Rev_Billing_Det!$S:$S,$B22) -> 537.72136 | D22: =$C$10+$C$11*C22 -> 65.417806 | E22: =($C$11-$C$43)*C22 -> 56.917806 | F22: =$C$10 -> 8.5 | G22: =C22+O22 -> 537.72136 | J22: 17.951044
A23: =IF(ISBLANK(B23),"",MAX($A$6:A22)+1) -> 15 | B23: October | C23: =SUMIFS(Rev_Billing_Det!E:E,Rev_Billing_Det!$A:$A,"RD-1",Rev_Billing_Det!$S:$S,$B23)/SUMIFS(Rev_Billing_Det!C:C,Rev_Billing_Det!$A:$A,"RD-1",Rev_Billing_Det!$S:$S,$B23) -> 405.51164 | D23: =$C$10+$C$11*C23 -> 51.423407 | E23: =($C$11-$C$43)*C23 -> 42.923407 | F23: =$C$10 -> 8.5 | G23: =C23+O23 -> 405.51164 | J23: 22.802519
A24: =IF(ISBLANK(B24),"",MAX($A$6:A23)+1) -> 16 | B24: November | C24: =SUMIFS(Rev_Billing_Det!E:E,Rev_Billing_Det!$A:$A,"RD-1",Rev_Billing_Det!$S:$S,$B24)/SUMIFS(Rev_Billing_Det!C:C,Rev_Billing_Det!$A:$A,"RD-1",Rev_Billing_Det!$S:$S,$B24) -> 427.77897 | D24: =$C$10+$C$11*C24 -> 53.780404 | E24: =($C$11-$C$43)*C24 -> 45.280404 | F24: =$C$10 -> 8.5 | G24: =C24+O24 -> 864.75714 | J24: 63.727892 | K24: =J24-$K$27 -> 48.470275 | L24: 40.179306 | M24: 3.25 | N24: =K24*$K$28 -> 1420.1791 | O24: =N24/M24 -> 436.97817
A25: =IF(ISBLANK(B25),"",MAX($A$6:A24)+1) -> 17 | B25: December | C25: =SUMIFS(Rev_Billing_Det!E:E,Rev_Billing_Det!$A:$A,"RD-1",Rev_Billing_Det!$S:$S,$B25)/SUMIFS(Rev_Billing_Det!C:C,Rev_Billing_Det!$A:$A,"RD-1",Rev_Billing_Det!$S:$S,$B25) -> 550.49742 | D25: =$C$10+$C$11*C25 -> 66.770152 | E25: =($C$11-$C$43)*C25 -> 58.270152 | F25: =$C$10 -> 8.5 | G25: =C25+O25 -> 1434.6296 | J25: 105.7831 | K25: =J25-$K$27 -> 90.525482 | L25: 32.670027 | M25: 3 | N25: =K25*$K$28 -> 2652.3966 | O25: =N25/M25 -> 884.13221
A26: =IF(ISBLANK(B26),"",MAX($A$6:A25)+1) | C26: =SUM(C14:C25) -> 6455.7395 | D26: =SUM(D14:D25) -> 785.34002 | E26: =SUM(E14:E25) -> 683.34002 | F26: =SUM(F14:F25) -> 102 | G26: =SUM(G14:G25) -> 12383.133 | O26: =SUM(O14:O25) -> 5927.3933
A27: =IF(ISBLANK(B27),"",MAX($A$6:A26)+1) | J27: Summer Base Load | K27: =AVERAGE(J19:J22) -> 15.257617
A28: =IF(ISBLANK(B28),"",MAX($A$6:A27)+1) -> 18 | B28: Derrivation of Heat Pump Rate | J28: Therm to kWH Factor | K28: 29.3
A29: =IF(ISBLANK(B29),"",MAX($A$6:A28)+1) -> 19 | B29: Customer Charge | C29: =C10 -> 8.5
A30: =IF(ISBLANK(B30),"",MAX($A$6:A29)+1) -> 20 | B30: Customer Charge Revenue | C30: =C29*12 -> 102
A31: =IF(ISBLANK(B31),"",MAX($A$6:A30)+1)
A32: =IF(ISBLANK(B32),"",MAX($A$6:A31)+1) -> 21 | B32: Winter Volumetric Charge Revenue | C32: =SUM(E14:E17,E24:E25) -> 348.43797 | D32: per customer, November through April
A33: =IF(ISBLANK(B33),"",MAX($A$6:A32)+1) -> 22 | B33: Volumetric Fixed Cost Recovery Charge | C33: =TRUNC(C32/SUM(G14:G17,G24:G25),5) -> 0.03779 | D33: Line 21 divided by Heat Pump kWh for Nov. through Apr.
A34: =IF(ISBLANK(B34),"",MAX($A$6:A33)+1)
A35: =IF(ISBLANK(B35),"",MAX($A$6:A34)+1) -> 23 | B35: Results
A36: =IF(ISBLANK(B36),"",MAX($A$6:A35)+1) -> 24 | B36: HP-RES: Residential Heat Pump Service | C36: Proposed Rate
A37: =IF(ISBLANK(B37),"",MAX($A$6:A36)+1) -> 25 | B37: Customer Charge | C37: =C29 -> 8.5
A38: =IF(ISBLANK(B38),"",MAX($A$6:A37)+1) -> 26 | B38: Distribution Charge - Winter | C38: =C33 -> 0.03779
A39: =IF(ISBLANK(B39),"",MAX($A$6:A38)+1) -> 27 | B39: Distribution Charge - Summer | C39: =C11 -> 0.10585
A40: =IF(ISBLANK(B40),"",MAX($A$6:A39)+1)
A41: =IF(ISBLANK(B41),"",MAX($A$6:A40)+1)
B43: Unit Cost of Service | E43: RD-1 | F43: Heat Pump | G43: Difference
...

Sheet EV-RES Rate
B1: Fitchburg Gas and Electric Light Company
B2: d/b/a Unitil
B3: Residential Electric Vehicle Time of Use - Proposed Rate Annualization
B5: As Approved in D.P.U. 21-92, Exhibit JDT-4 Page 2 of 2 - Option 2:
B7: Basic Service | G7: Transmission | K7: Distribution
A8: 1 | B8: Period | C8: Residential TOU Basic Service Rates (w/o REC & BSCA) (after losses) ($/kWh) | D8: Projected Residential Basic Service Purchases (kWh) | E8: Projected Basic Service Revenue ($) | G8: Residential TOU Transmission Rate ($/kWh) | H8: Est Residential Transmission Deliveries (kWh) | I8: Residential Transmission Cost ($) | K8: Residential TOU Base Distribution Rates ($/kWh) | L8: Total Residential Customers Energy (kWh) | M8: Residential TOU Base Distribution Revenues ($)
A9: =+A8+1 -> 2 | B9: Summer Peak | C9: 0.080639053 | D9: 10189579 | E9: =+C9*D9 -> 821678.02 | G9: 0.1143489 | H9: 16149797 | I9: =+G9*H9 -> 1846711.5 | K9: 0.1553335 | L9: 16824679 | M9: =+K9*L9 -> 2613436.2
A10: =+A9+1 -> 3 | B10: Summer Off-Peak | C10: 0.056697193 | D10: 31409076 | E10: =+C10*D10 -> 1780806.4 | G10: 0 | H10: 49781271 | I10: =+G10*H10 -> 0 | K10: 0.03876 | L10: 51861572 | M10: =+K10*L10 -> 2010154.5
A11: =+A10+1 -> 4 | B11: Summer Mid-Peak | C11: 0.063347222 | D11: 12802255 | E11: =+C11*D11 -> 810987.3 | G11: 0.035004864 | H11: 20290713 | I11: =+G11*H11 -> 710273.65 | K11: 0.11068048 | L11: 21138638 | M11: =+K11*L11 -> 2339634.6
A12: =+A11+1 -> 5 | C12: 0.062746593 | D12: =SUM(D9:D11) -> 54400910 | E12: =+C12*D12 -> 3413471.7 | G12: 0.029655907 | H12: =SUM(H9:H11) -> 86221781 | I12: =+G12*H12 -> 2556985.1 | K12: 0.07752 | L12: =SUM(L9:L11) -> 89824888 | M12: =+K12*L12 -> 6963225.3
A13: =+A12+1 -> 6
A14: =+A13+1 -> 7 | B14: Winter Peak | C14: 0.093246476 | D14: 10587775 | E14: =+C14*D14 -> 987272.68 | G14: 0.13732371 | H14: 14795005 | I14: =+G14*H14 -> 2031705 | K14: 0.17308187 | L14: 15413271 | M14: =+K14*L14 -> 2667757.7
A15: =+A14+1 -> 8 | B15: Winter Off-Peak | C15: 0.074093676 | D15: 33921973 | E15: =+C15*D15 -> 2513403.7 | G15: 0.0019134675 | H15: 47401439 | I15: =+G15*H15 -> 90701.114 | K15: 0.03876 | L15: 49382290 | M15: =+K15*L15 -> 1914057.6
A16: =+A15+1 -> 9 | B16: Winter Mid-Peak | C16: 0.085590755 | D16: 13948679 | E16: =+C16*D16 -> 1193878 | G16: 0.012098805 | H16: 19491421 | I16: =+G16*H16 -> 235822.9 | K16: 0.099244506 | L16: 20305945 | M16: =+K16*L16 -> 2015253.4
A17: =+A16+1 -> 10 | C17: 0.080305861 | D17: =SUM(D14:D16) -> 58458427 | E17: =+C17*D17 -> 4694554.3 | G17: 0.02886878 | H17: =SUM(H14:H16) -> 81687865 | I17: =+G17*H17 -> 2358229 | K17: 0.07752 | L17: =SUM(L14:L16) -> 85101506 | M17: =+K17*L17 -> 6597068.7
A18: =+A17+1 -> 11
A19: =+A18+1 -> 12 | B19: Total | C19: =+E19/D19 -> 0.071841872 | D19: =+D12+D17 -> 1.1285934e+08 | E19: =+E12+E17 -> 8108026.1 | G19: =+I19/H19 -> 0.029272971 | H19: =+H12+H17 -> 167909646 | I19: =+I12+I17 -> 4915214.1 | K19: =+M19/L19 -> 0.07752 | L19: =+L12+L17 -> 1.7492639e+08 | M19: =+M12+M17 -> 13560294
B21: Option 2: Two Seasons (Jun-Nov Summer, Dec-May Winter); On-Peak (non-holiday weekdays, 3pm-8pm); Mid-Peak (non-holiday weekdays, 6am-3pm); Off-Peak (all other times)
B23: Proposed Change to Annual Rates:
B25: Basic Service | G25: Transmission | K25: Distribution
B26: Period | C26: Residential TOU Basic Service Rates (w/o REC & BSCA) (after losses) ($/kWh) | D26: Projected Residential Basic Service Purchases (kWh) | E26: Projected Basic Service Revenue ($) | G26: Residential TOU Transmission Rate ($/kWh) | H26: Est Residential Transmission Deliveries (kWh) | I26: Residential Transmission Cost ($) | K26: Residential TOU Base Distribution Rates ($/kWh) | L26: Total Residential Customers Energy (kWh) | M26: Residential TOU Base Distribution Revenues ($)
A27: =+A19+1 -> 13 | B27: Annual Peak | C27: =+E27/D27 -> 0.087063574 | D27: =+D9+D14 -> 20777354 | E27: =+E9+E14 -> 1808950.7 | G27: =+I27/H27 -> 0.12533337 | H27: =+H9+H14 -> 30944802 | I27: =+I9+I14 -> 3878416.5 | K27: =+M27/L27 -> 0.16381916 | L27: =+L9+L14 -> 32237949 | M27: =+M9+M14 -> 5281193.9
A28: =+A27+1 -> 14 | B28: Annul Off-Peak | C28: =+E28/D28 -> 0.065730004 | D28: =+D10+D15 -> 65331049 | E28: =+E10+E15 -> 4294210.1 | G28: =+I28/H28 -> 0.00093330505 | H28: =+H10+H15 -> 97182710 | I28: =+I10+I15 -> 90701.114 | K28: =+M28/L28 -> 0.03876 | L28: =+L10+L15 -> 1.0124386e+08 | M28: =+M10+M15 -> 3924212.1
A29: =+A28+1 -> 15 | B29: Annual Mid-Peak | C29: =+E29/D29 -> 0.074945617 | D29: =+D11+D16 -> 26750934 | E29: =+E11+E16 -> 2004865.3 | G29: =+I29/H29 -> 0.023781946 | H29: =+H11+H16 -> 39782134 | I29: =+I11+I16 -> 946096.55 | K29: =+M29/L29 -> 0.10507738 | L29: =+L11+L16 -> 41444582 | M29: =+M11+M16 -> 4354888
A30: =+A29+1 -> 16 | B30: Total | C30: =+E30/D30 -> 0.071841872 | D30: =+D27+D28+D29 -> 1.1285934e+08 | E30: =+E27+E28+E29 -> 8108026.1 | G30: =+I30/H30 -> 0.029272971 | H30: =+H27+H28+H29 -> 167909646 | I30: =+I27+I28+I29 -> 4915214.1 | K30: =+M30/L30 -> 0.07752 | L30: =+L27+L28+L29 -> 1.7492639e+08 | M30: =+M27+M28+M29 -> 13560294

Sheet Annual EV-RES
B1: Fitchburg Gas and Electric Light Company d/b/a Unitil
B2: Schedule EV-RES Rate Development
B3: Proposed Rates Effective September 1, 2023
C5: Annual | E5: Ratios Applied to
C6: Volumetric | D6: Ratios to | E6: Proposed 9/1/2023
C7: Rates (1) | D7: Current Rate | E7: Rates
A8: 1 | B8: Customer Charge: | E8: 6.39
A9: =+A8+1 -> 2
A10: =+A9+1 -> 3 | B10: 1/1/21 Dist. Rate | C10: =+C53 -> 0.07752 | D10: 9/1/23 Proposed Dist. Rate | E10: ='Rate Design'!G9 -> 0.10585
A11: =+A10+1 -> 4 | B11: Distribution Rate:
A12: =+A11+1 -> 5 | B12: Off Peak kWH (M-F 8 pm - 6 am, all day weekends and weekday holidays) | C12: =+C50 -> 0.03876 | D12: =+C12/C10 -> 0.5 | E12: =TRUNC(+E10*D12,5) -> 0.05292
A13: =+A12+1 -> 6 | B13: Mid Peak kWh (M-F 6 am -3 pm excluding weekday holidays) | C13: =+C51 -> 0.10507738 | D13: =+C13/C10 -> 1.3554873 | E13: =TRUNC(+E10*D13,5) -> 0.14347
A14: =+A13+1 -> 7 | B14: On Peak kWh (M-F 3 pm - 8 pm excluding weekday holidays) | C14: =+C52 -> 0.16381916 | D14: =+C14/C10 -> 2.1132503 | E14: =TRUNC(+E10*D14,5) -> 0.22368
A15: =+A14+1 -> 8
A16: =+A15+1 -> 9 | B16: 1/1/21 External Trans. Rate | C16: =+D53 -> 0.029272971 | D16: 1/1/23 External Trans. Rate | E16: 0.02805
A17: =+A16+1 -> 10 | B17: External Transmission Rate:
A18: =+A17+1 -> 11 | B18: Off Peak kWH (M-F 8 pm - 6 am, all day weekends and weekday holidays) | C18: =+D50 -> 0.00093330505 | D18: =+C18/C16 -> 0.031882827 | E18: =TRUNC(+E16*D18,5) -> 0.00089
A19: =+A18+1 -> 12 | B19: Mid Peak kWh (M-F 6 am -3 pm excluding weekday holidays) | C19: =+D51 -> 0.023781946 | D19: =+C19/C16 -> 0.81241997 | E19: =TRUNC(+E16*D19,5) -> 0.02278
A20: =+A19+1 -> 13 | B20: On Peak kWh (M-F 3 pm - 8 pm excluding weekday holidays) | C20: =+D52 -> 0.12533337 | D20: =+C20/C16 -> 4.2815393 | E20: =TRUNC(+E16*D20,5) -> 0.12009
A21: =+A20+1 -> 14
A22: =+A21+1 -> 15 | B22: 6/1/21 and 12/1/20 BS Rate without REC or Basic Service Cost Adder | C22: =+E53 -> 0.071841872 | D22: 8/1/23 BS Rate (2) | E22: 0.18326
A23: =+A22+1 -> 16 | B23: Basic Service Rate:
A24: =+A23+1 -> 17 | B24: Off Peak kWH (M-F 8 pm - 6 am, all day weekends and weekday holidays) | C24: =+E50 -> 0.065730004 | D24: =+C24/C22 -> 0.9149261 | E24: =TRUNC(+E22*D24,5) -> 0.16766
A25: =+A24+1 -> 18 | B25: Mid Peak kWh (M-F 6 am -3 pm excluding weekday holidays) | C25: =+E51 -> 0.074945617 | D25: =+C25/C22 -> 1.0432024 | E25: =TRUNC(+E22*D25,5) -> 0.19117
A26: =+A25+1 -> 19 | B26: On Peak kWh (M-F 3 pm - 8 pm excluding weekday holidays) | C26: =+E52 -> 0.087063574 | D26: =+C26/C22 -> 1.2118779 | E26: =TRUNC(+E22*D26,5) -> 0.22208
A27: =+A26+1 -> 20 | B27: All Hours REC Rate | E27: 0.02387
A28: =+A27+1 -> 21 | B28: All Hours Basic Service Cost Adder Rate | E28: 0.00493
A29: =+A28+1 -> 22
A30: =+A29+1 -> 23 | B30: Other Distribution | E30: 0.08375
A31: =+A30+1 -> 24 | B31: Internal Transmission + Internal Transmission Service Cost Adjustment ($/kWh) | E31: =0.00394+0.00158 -> 0.00552
A32: =+A31+1 -> 25 | B32: Renewable Resource ($/kWh) | E32: 0.0005
A33: =+A32+1 -> 26 | B33: Energy Efficiency ($/kWh) | E33: 0.0025
A34: =+A33+1 -> 27 | B34: Solar Massachusetts Renewable Target Factor ($/kWh) | E34: 0.00567
A35: =+A34+1 -> 28
A36: =+A35+1 -> 29 | B36: Total kWh Charges:
A37: =+A36+1 -> 30 | B37: Off Peak kWH (8 pm - 6 am, and weekends/holidays) | E37: =+E12+E18+E24+E27+E28 -> 0.25027
A38: =+A37+1 -> 31 | B38: Mid Peak kWh (6 am -3 pm, M-F) | E38: =+E13+E19+E25+E27+E28 -> 0.38622
A39: =+A38+1 -> 32 | B39: On Peak kWh (3 pm - 8 pm, M-F) | E39: =+E14+E20+E26+E27+E28 -> 0.59465
A40: =+A39+1 -> 33 | B40: All hours kWh | E40: =+E30+E31+E32+E33+E34 -> 0.09794
A41: =+A40+1 -> 34
...

Sheet Demand Charge Alternative
L1: D.P.U. 23-80
L2: Unitil - Electric Division
L3: Exhibit Unitil-JDT-8
L4: Page 1 of 1
A5: Fitchburg Gas and Electric Light Company
A6: Exhibit Unitil-JDT-8
A7: General Service EV Demand Charge Alternative Rates
E8: 100% reduction in demand charge | G8: 75% reduction in demand charge | I8: 50% reduction in demand charge | K8: Using Proposed Rates
D9: Load Factor | E9: 0%-5% | G9: 5%-10% | I9: 10%-15% | K9: > 15%
E10: Base | F10: Base | G10: Base | H10: Base | I10: Base | J10: Base | K10: Base | L10: Base
D11: Test Year | E11: Distribution | F11: Distribution | G11: Distribution | H11: Distribution | I11: Distribution | J11: Distribution | K11: Distribution | L11: Distribution
D12: Billing Units | E12: Rates | F12: Revenue | G12: Rates | H12: Revenue | I12: Rates | J12: Revenue | K12: Rates | L12: Revenue
D13: (a) | E13: (b) | F13: (c) | G13: (d) | H13: (e) | I13: (f) | J13: (g) | K13: (h) | L13: (i)
B14: GD-2: Regular General
A16: 1 | B16: Revenue Allocation Target | F16: =+L16 -> 6262145.3 | H16: =+F16 -> 6262145.3 | J16: =+H16 -> 6262145.3 | L16: =SUM(L18:L22) -> 6262145.3
A18: =A16+1 -> 2 | B18: Customer Charge | C18: No. of bills | D18: ='Rate Design'!C34 -> 18164.621 | E18: =+K18 -> 12 | F18: =$D18*E18 -> 217975.45 | G18: =+E18 -> 12 | H18: =$D18*G18 -> 217975.45 | I18: =+G18 -> 12 | J18: =$D18*I18 -> 217975.45 | K18: ='Rate Design'!G34 -> 12 | L18: =D18*K18 -> 217975.45
A20: =A18+1 -> 3 | B20: Energy-Based Rate | C20: All kWh | D20: ='Rate Design'!C36 -> 86826989 | E20: =+K20 -> 0.03234 | F20: =$D20*E20 -> 2807984.8 | G20: =+E20 -> 0.03234 | H20: =$D20*G20 -> 2807984.8 | I20: =+G20 -> 0.03234 | J20: =$D20*I20 -> 2807984.8 | K20: ='Rate Design'!G36 -> 0.03234 | L20: =K20*D20 -> 2807984.8
A22: =A20+1 -> 4 | B22: Demand-Based Rate | C22: kW | D22: ='Rate Design'!C35 -> 323618.5 | E22: 0 | F22: =($D22*E22) -> 0 | G22: =TRUNC($K22*0.25,2) -> 2.5 | H22: =($D22*G22) -> 809046.25 | I22: =TRUNC($K22*0.5,2) -> 5 | J22: =($D22*I22) -> 1618092.5 | K22: ='Rate Design'!G35 -> 10 | L22: =D22*K22 -> 3236185
A24: =A22+1 -> 5 | B24: Converted Demand-to-Energy Rate | C24: All kWh | D24: =+D20 -> 86826989 | E24: =TRUNC((L22)/D24,5) -> 0.03727 | F24: =($D24*E24) -> 3236041.9 | G24: =TRUNC((L22-H22)/$D24,5) -> 0.02795 | H24: =($D24*G24) -> 2426814.3 | I24: =TRUNC((L22-J22)/$D24,5) -> 0.01863 | J24: =($D24*I24) -> 1617586.8
A26: =A24+1 -> 6 | B26: Total Revenue | F26: =SUM(F18:F25) -> 6262002.2 | H26: =SUM(H18:H25) -> 6261820.9 | J26: =SUM(J18:J25) -> 6261639.6 | L26: =SUM(L18:L25) -> 6262145.3
A28: =A26+1 -> 7 | B28: Difference to Target (Due to Truncation of Energy Charge) | F28: =F26-F16 -> -143.11997 | H28: =H26-H16 -> -324.40745 | J28: =J26-J16 -> -505.69493 | L28: =L26-L16 -> 0
B30: GD-2: Regular General - Distribution Charges
A31: =A28+1 -> 8 | B31: Customer Charge | E31: =+E18 -> 12 | G31: =+G18 -> 12 | I31: =+I18 -> 12 | K31: =+K18 -> 12
A32: =A31+1 -> 9 | B32: Energy-Based Rate | C32: All kWh | E32: =+E20+E24 -> 0.06961 | G32: =+G20+G24 -> 0.06029 | I32: =+I20+I24 -> 0.05097 | K32: =+K20 -> 0.03234
A33: =A32+1 -> 10 | B33: Demand-Based Rate | C33: kW | E33: =+E22 -> 0 | G33: =+G22 -> 2.5 | I33: =+I22 -> 5 | K33: =+K22 -> 10
B35: GD-3: Large General
A37: =A33+1 -> 11 | B37: Revenue Allocation Target | F37: =L37 -> 4245756.2 | H37: =F37 -> 4245756.2 | J37: =H37 -> 4245756.2 | L37: =SUM(L39, L43:L45) -> 4245756.2
A39: =A37+1 -> 12 | B39: Customer Charge | C39: No. of bills | D39: ='Rate Design'!C44 -> 339 | E39: =K39 -> 338.75 | F39: =($D39*E39) -> 114836.25 | G39: =E39 -> 338.75 | H39: =($D39*G39) -> 114836.25 | I39: =G39 -> 338.75 | J39: =($D39*I39) -> 114836.25 | K39: ='Rate Design'!G44 -> 338.75 | L39: =(D39*K39) -> 114836.25
A41: =A39+1 -> 13 | B41: Peak Energy-Based Rate | C41: On Peak kWh | D41: ='Rate Design'!C50 -> 50297243 | E41: =K41 -> 0.01828 | F41: =$D41*E41 -> 919433.6 | G41: =E41 -> 0.01828 | H41: =($D41*G41) -> 919433.6 | I41: =G41 -> 0.01828 | J41: =$D41*I41 -> 919433.6 | K41: ='Rate Design'!G50 -> 0.01828 | L41: =(D41*K41) -> 919433.6
A42: =A41+1 -> 14 | B42: Off Peak Energy-Based Rate | C42: Off Peak kWh | D42: ='Rate Design'!C51 -> 77729812 | E42: =K42 -> 0.00407 | F42: =($D42*E42) -> 316360.33 | G42: =E42 -> 0.00407 | H42: =($D42*G42) -> 316360.33 | I42: =G42 -> 0.00407 | J42: =($D42*I42) -> 316360.33 | K42: ='Rate Design'!G51 -> 0.00407 | L42: =(D42*K42) -> 316360.33
A43: =A42+1 -> 15 | B43: Energy-Based Revenue | D43: =D41+D42 -> 128027055 | F43: =F41+F42 -> 1235793.9 | H43: =H41+H42 -> 1235793.9 | J43: =J41+J42 -> 1235793.9 | L43: =L41+L42 -> 1235793.9
A45: =A43+1 -> 16 | B45: Demand kW | C45: On Peak kW | D45: ='Rate Design'!C45 -> 296936 | E45: 0 | F45: =($D45*E45) -> 0 | G45: =TRUNC($K45*0.25,2) -> 2.43 | H45: =($D45*G45) -> 721554.48 | I45: =TRUNC($K45*0.5,2) -> 4.87 | J45: =($D45*I45) -> 1446078.3 | K45: ='Rate Design'!G45 -> 9.75 | L45: =(K45*D45) -> 2895126
A47: =A45+1 -> 17 | B47: Converted Demand-to-Energy Rate | C47: On Peak kWh | D47: =+D41 -> 50297243 | E47: =TRUNC((L45)/$D49,5) -> 0.02261 | F47: =($D47*E47) -> 1137220.7 | G47: =TRUNC((L45-H45)/$D49,5) -> 0.01697 | H47: =($D47*G47) -> 853544.21 | I47: =TRUNC((L45-J45)/$D49,5) -> 0.01131 | J47: =($D47*I47) -> 568861.82
A48: =A47+1 -> 18 | B48: Converted Demand-to-Energy Rate | C48: Off Peak kWh | D48: =+D42 -> 77729812 | E48: =E47 -> 0.02261 | F48: =($D48*E48) -> 1757471 | G48: =G47 -> 0.01697 | H48: =($D48*G48) -> 1319074.9 | I48: =I47 -> 0.01131 | J48: =($D48*I48) -> 879124.17
A49: =A48+1 -> 19 | B49: Energy-Based Revenue | C49: All kWh | D49: =D47+D48 -> 128027055
A51: =A49+1 -> 20 | B51: Total Revenue | F51: =SUM(F39:F40)+SUM(F43:F50) -> 4245321.9 | H51: =SUM(H39:H40)+SUM(H43:H50) -> 4244803.8 | J51: =SUM(J39:J40)+SUM(J43:J50) -> 4244694.5 | L51: =SUM(L43:L45, L39) -> 4245756.2
A53: =A51+1 -> 21 | B53: Difference to Target (Due to Truncation of Energy Charge) | F53: =F51-F37 -> -434.28645 | H53: =H51-H37 -> -952.39665 | J53: =J51-J37 -> -1061.6879 | L53: =L51-L37 -> 0
B55: GD-3: Large General - Distribution Charges
A56: =A53+1 -> 22 | B56: Customer Charge | E56: =+E39 -> 338.75 | G56: =+G39 -> 338.75 | I56: =+I39 -> 338.75 | K56: =+K39 -> 338.75
A57: =A56+1 -> 23 | B57: Energy-Based Rate | C57: On Peak kWh | E57: =+E41+E47 -> 0.04089 | G57: =+G41+G47 -> 0.03525 | I57: =+I41+I47 -> 0.02959 | K57: =+K41 -> 0.01828
...

Sheet Decoupling Target
G1: D.P.U. 23-80
G2: Unitil - Electric Division
G3: Exhibit Unitil-JDT-9
G4: Page 1 of 1
A6: D.P.U. 23-80
A7: Unitil - Electric Division
A8: Annual Target Revenue
A9: Revenue Decoupling Adjustment Clause
B11: Class | C11: Target Revenue | E11: Class Grouping | F11: Distribution Revenue | G11: Allocator
A13: 1 | B13: RD-1 & RD-2 | C13: ='Revenue Apportionment'!N10 -> 20932921 | J13: =C13/$C$27 -> 0.62280092
A14: =+A13+1 -> 2 | B14: Total Residential | C14: =SUM(C13:C13) -> 20932921 | E14: RD-1/RD-2 | F14: =C14 -> 20932921 | G14: =F14/$F$27 -> 0.62585559
A15: =+MAX(A$13:A14)+1 -> 3
A16: =+MAX(A$13:A15)+1 -> 4 | B16: GD-1 | C16: ='Revenue Apportionment'!N11 -> 991010.6 | J16: =C16/$C$27 -> 0.029484767
A17: =+MAX(A$13:A16)+1 -> 5
A18: =+MAX(A$13:A17)+1 -> 6 | B18: GD-2 | C18: ='Revenue Apportionment'!N12 -> 6258272.4 | J18: =C18/$C$27 -> 0.18619751
A19: =+MAX(A$13:A18)+1 -> 7 | B19: GD-4 | C19: ='Revenue Apportionment'!N14 -> 9037.3223 | J19: =C19/$C$27 -> 0.00026888042
A20: =+MAX(A$13:A19)+1 -> 8 | B20: GD-5 | C20: ='Revenue Apportionment'!N15 -> 24153.842 | J20: =C20/$C$27 -> 0.00071863048
A21: =+MAX(A$13:A20)+1 -> 9 | B21: Regular General Service | C21: =SUM(C18:C20) -> 6291463.6 | E21: GD-1/GD-2/GD-4/GD-5 | F21: =C21+C16 -> 7282474.2 | G21: =F21/$F$27 -> 0.2177325
A22: =+MAX(A$13:A21)+1 -> 10
A23: =+MAX(A$13:A22)+1 -> 11 | B23: GD-3/Special Contract | C23: 5020870.7 | E23: GD-3/Special Contract | F23: =C23 -> 5020870.7 | G23: =F23/$F$27 -> 0.15011474 | J23: =C23/$C$27 -> 0.14938206
A24: =+MAX(A$13:A23)+1 -> 12
A25: =+MAX(A$13:A24)+1 -> 13 | B25: Outdoor Lighting | C25: ='Revenue Apportionment'!N16+'Revenue Apportionment'!N17 -> 374669.02 | E25: Outdoor Lighting* | F25: =+F42 -> 210620.99 | G25: =F25/$F$27 -> 0.0062971775 | J25: =C25/$C$27 -> 0.011147236
A26: =+MAX(A$13:A25)+1 -> 14
A27: =+MAX(A$13:A26)+1 -> 15 | B27: TOTAL | C27: =SUM(C25,C23,C21,C14,C16) -> 33610935 | E27: TOTAL | F27: =F25+F23+F21+F14 -> 33446887 | G27: =G25+G23+G21+G14 -> 1 | J27: =SUM(J13:J25) -> 1
A28: =+MAX(A$13:A27)+1 -> 16
A29: =+MAX(A$13:A28)+1 -> 17 | B29: Note: Target Revenues are from Exhibit Unitil-JDT-3, Schedule 1. | E29: * Outdoor Lighting plant removed - see calculation below.
A30: =+MAX(A$13:A29)+1 -> 18
A31: =+MAX(A$13:A30)+1 -> 19 | B31: Calculation for Removal of Outdoor Lighting Plant:
A32: =+MAX(A$13:A31)+1 -> 20 | B32: SD Target Revenue | F32: ='Revenue Apportionment'!N16 -> 319067.58
A33: =+MAX(A$13:A32)+1 -> 21
A34: =+MAX(A$13:A33)+1 -> 22 | B34: SD Lighting Plant Rev Req | E34: 221382.85 | F34: =+E34/E36 -> 0.51414823 | G34: Exhibit Unitil-JDT-3, Schedule 2
A35: =+MAX(A$13:A34)+1 -> 23 | B35: SD Remaining Rev Req | E35: =+E36-E34 -> 209198.91 | F35: =+E35/E36 -> 0.48585177
A36: =+MAX(A$13:A35)+1 -> 24 | B36: SD Total Rev Req Req | E36: 430581.76 | G36: Exhibit Unitil-JDT-3, Schedule 2
A37: =+MAX(A$13:A36)+1 -> 25
A38: =+MAX(A$13:A37)+1 -> 26 | B38: SD Rev Req excl Outdoor Lighting Plant | E38: Line 20 * Line 23 | F38: =+F32*F35 -> 155019.55
A39: =+MAX(A$13:A38)+1 -> 27
A40: =+MAX(A$13:A39)+1 -> 28 | B40: SDC Target Revenue | F40: ='Revenue Apportionment'!N17 -> 55601.436
A41: =+MAX(A$13:A40)+1 -> 29
A42: =+MAX(A$13:A41)+1 -> 30 | B42: Outdoor Lighting Rev Req excluding Outdoor Lighting Plant | E42: Line 26 + Line 28 | F42: =+F38+F40 -> 210620.99

Sheet CONFIDENTIAL
A1: Intentionally blank. This sheet was redacted in its entirety.

Sheet Rates
A1: ='Rate Design Lighting'!A1 -> Fitchburg Gas and Electric Light Company
A2: Workpaper to Exhibit Unitil-JDT-4, Schedule 2
A3: WP - Current and Proposed Rates
A6: Line No. | B6: Description | C6: Current Rate | D6: Proposed Rate | H6: COSA Unit Cost | I6: Current Rate | J6: 20.34% Increase | K6: % of COSA Unit Cost | L6: If <25% then use 25% of Unit Cost | M6: Proposed Charge | N6: Resulting Change
A7: 1 | B7: ='Rate Design'!B7 -> RD-1: Residential | F7: Rate | G7: Component
A8: =A7+1 -> 2 | B8: Customer Charge | C8: =INDEX('Rates and Eff Dates'!$C$39:$C$47,MATCH(LEFT($B7,4),'Rates and Eff Dates'!$A$39:$A$47,0)) -> 7 | D8: ='Rate Design'!G8 -> 8.5 | F8: RD-1 / RD-2 Residential | G8: Customer | H8: 26.68041 | I8: =C8 -> 7 | J8: =I8*(1+('Revenue Apportionment'!$H$21)) -> 8.4239542 | K8: =J8/H8 -> 0.31573556 | L8: =ROUND(IF(K8>25%, J8, H8/4), 2) -> 8.42 | M8: 8.5 | N8: =(M8-I8)/I8 -> 0.21428571
A9: =A8+1 -> 3 | B9: Distribution Charge | C9: =INDEX('Rates and Eff Dates'!$D$39:$D$47,MATCH(LEFT($B7,4),'Rates and Eff Dates'!$A$39:$A$47,0)) -> 0.07903 | D9: ='Rate Design'!G9 -> 0.10585 | F9: =B15 -> GD-1: Small General | G9: Customer | H9: 23.263774 | I9: =C16 -> 10 | J9: =I9*(1+('Revenue Apportionment'!$H$21)) -> 12.03422 | K9: =J9/H9 -> 0.51729441 | L9: =ROUND(IF(K9>25%, J9, H9/4), 2) -> 12.03 | M9: 12 | N9: =(M9-I9)/I9 -> 0.2
A10: =A9+1 -> 4 | F10: =B19 -> GD-2: Regular General | G10: Customer | H10: 47.966259 | I10: =C20 -> 10 | J10: =I10*(1+('Revenue Apportionment'!$H$21)) -> 12.03422 | K10: =J10/H10 -> 0.25088928 | L10: =ROUND(IF(K10>25%, J10, H10/4), 2) -> 12.03 | M10: 12 | N10: =(M10-I10)/I10 -> 0.2
A11: =A10+1 -> 5 | B11: ='Rate Design'!B12 -> RD-2: Residential, Low Income | F11: =F10 -> GD-2: Regular General | G11: Demand | H11: 9.935266 | I11: =C21 -> 9.81 | J11: =I11*(1+('Revenue Apportionment'!$H$21)) -> 11.80557 | K11: =J11/H11 -> 1.188249 | L11: =ROUND(IF(K11>25%, J11, H11/4), 2) -> 11.81 | M11: 10 | N11: =(M11-I11)/I11 -> 0.019367992
A12: =A11+1 -> 6 | B12: Customer Charge | C12: =INDEX('Rates and Eff Dates'!$C$39:$C$47,MATCH(LEFT($B11,4),'Rates and Eff Dates'!$A$39:$A$47,0)) -> 7 | D12: ='Rate Design'!G13 -> 8.5 | F12: =B25 -> GD-3: Large General | G12: Customer | H12: 1548.482 | I12: =C26 -> 300 | J12: =I12*(1+('Revenue Apportionment'!$H$21)) -> 361.02661 | K12: =J12/H12 -> 0.23314873 | L12: =ROUND(IF(K12>25%, J12, H12/4), 2) -> 387.12 | M12: 338.75 | N12: =(M12-I12)/I12 -> 0.12916667
A13: =A12+1 -> 7 | B13: Distribution Charge | C13: =INDEX('Rates and Eff Dates'!$D$39:$D$47,MATCH(LEFT($B11,4),'Rates and Eff Dates'!$A$39:$A$47,0)) -> 0.07903 | D13: ='Rate Design'!G14 -> 0.10585 | F13: =F12 -> GD-3: Large General | G13: Demand | H13: 10.97226 | I13: =C27 -> 8.07 | J13: =I13*(1+('Revenue Apportionment'!$H$21)) -> 9.7116158 | K13: =J13/H13 -> 0.88510625 | L13: =ROUND(IF(K13>25%, J13, H13/4), 2) -> 9.71 | M13: 9.75 | N13: =(M13-I13)/I13 -> 0.20817844
A14: =A13+1 -> 8 | F14: =B33 -> GD-4: Regular General Optional TOU | G14: Customer | H14: =H10 -> 47.966259 | I14: =C34 -> 10 | J14: =I14*(1+('Revenue Apportionment'!$H$21)) -> 12.03422 | K14: =J14/H14 -> 0.25088928 | L14: =ROUND(IF(K14>25%, J14, H14/4), 2) -> 12.03 | M14: 12 | N14: =(M14-I14)/I14 -> 0.2
A15: =A14+1 -> 9 | B15: ='Rate Design'!B25 -> GD-1: Small General | F15: =F14 -> GD-4: Regular General Optional TOU | G15: Demand | H15: =H11 -> 9.935266 | I15: =C35 -> 3.92 | J15: =I15*(1+('Revenue Apportionment'!$H$21)) -> 4.7174144 | K15: =J15/H15 -> 0.4748151 | L15: =ROUND(IF(K15>25%, J15, H15/4), 2) -> 4.72 | M15: 4.75 | N15: =(M15-I15)/I15 -> 0.21173469
A16: =A15+1 -> 10 | B16: Customer Charge | C16: =INDEX('Rates and Eff Dates'!$C$39:$C$47,MATCH(LEFT($B15,4),'Rates and Eff Dates'!$A$39:$A$47,0)) -> 10 | D16: ='Rate Design'!G26 -> 12
A17: =A16+1 -> 11 | B17: Distribution Charge | C17: =INDEX('Rates and Eff Dates'!$D$39:$D$47,MATCH(LEFT($B15,4),'Rates and Eff Dates'!$A$39:$A$47,0)) -> 0.0785 | D17: ='Rate Design'!G27 -> 0.10572
A18: =A17+1 -> 12
A19: =A18+1 -> 13 | B19: ='Rate Design'!B33 -> GD-2: Regular General
A20: =A19+1 -> 14 | B20: Customer Charge | C20: =INDEX('Rates and Eff Dates'!$C$39:$C$47,MATCH(LEFT($B19,4),'Rates and Eff Dates'!$A$39:$A$47,0)) -> 10 | D20: ='Rate Design'!G34 -> 12
A21: =A20+1 -> 15 | B21: Demand Charge | C21: =INDEX('Rates and Eff Dates'!$F$39:$F$47,MATCH(LEFT($B19,4),'Rates and Eff Dates'!$A$39:$A$47,0)) -> 9.81 | D21: ='Rate Design'!G35 -> 10
A22: =A21+1 -> 16 | B22: Distribution Charge | C22: =INDEX('Rates and Eff Dates'!$D$39:$D$47,MATCH(LEFT($B19,4),'Rates and Eff Dates'!$A$39:$A$47,0)) -> 0.02377 | D22: ='Rate Design'!G36 -> 0.03234
A23: =A22+1 -> 17 | B23: Transformer Credit | C23: 0 | D23: ='Rate Design'!G37 -> -0.19
A24: =A23+1 -> 18
A25: =A24+1 -> 19 | B25: ='Rate Design'!B43 -> GD-3: Large General
A26: =A25+1 -> 20 | B26: Customer Charge | C26: =INDEX('Rates and Eff Dates'!$C$39:$C$47,MATCH(LEFT($B25,4),'Rates and Eff Dates'!$A$39:$A$47,0)) -> 300 | D26: ='Rate Design'!G44 -> 338.75
A27: =A26+1 -> 21 | B27: Demand Charge | C27: =INDEX('Rates and Eff Dates'!$F$39:$F$47,MATCH(LEFT($B25,4),'Rates and Eff Dates'!$A$39:$A$47,0)) -> 8.07 | D27: ='Rate Design'!G45 -> 9.75
A28: =A27+1 -> 22 | B28: Distribution Charge
A29: =A28+1 -> 23 | B29: On Peak Billed kWh | C29: =INDEX('Rates and Eff Dates'!$D$39:$D$47,MATCH(LEFT($B25,4),'Rates and Eff Dates'!$A$39:$A$47,0)) -> 0.01952 | D29: ='Rate Design'!G50 -> 0.01828
