Workbook
Name \A: #REF!
Name \B: '[1]My Worksheet'!#REF!
Name \C: #REF!
Name \D: #REF!
Name \E: #REF!
Name \F: [2]LIIncSt!#REF!
Name \G: [2]LIIncSt!#REF!
Name \H: [2]LIIncSt!#REF!
Name \I: #REF!
Name \K: '[3]PAGE 7'!#REF!
Name \L: [2]LIIncSt!#REF!
Name \M: #REF!
Name \N: #REF!
Name \O: #REF!
Name \P: #REF!
Name \Q: [2]LIIncSt!#REF!
Name \R: #REF!
Name \S: #REF!
Name \T: #REF!
Name \V: '[4]Var. Anal.'!#REF!
Name \W: #REF!
Name \Z: #REF!
Name ______BUV2: '[5]FYTD 12 Gas'!$E$346
Name ______SEG2: '[5]FYTD 12 Gas'!$B$347
Name _____BUV2: '[5]FYTD 12 Elec '!$E$386
Name _____FYR10: #REF!
Name _____FYR11: #REF!
Name _____FYR12: #REF!
Name _____FYR2: #REF!
Name _____FYR3: #REF!
Name _____FYR4: #REF!
Name _____FYR5: #REF!
Name _____FYR6: #REF!
Name _____FYR7: #REF!
Name _____FYR8: #REF!
Name _____FYR9: #REF!
Name _____PC1: #REF!
Name _____PC10: #REF!
Name _____PC11: #REF!
Name _____PC12: #REF!
Name _____PC2: #REF!
Name _____PC3: #REF!
Name _____PC4: #REF!
Name _____PC5: #REF!
Name _____PC6: #REF!
Name _____PC7: #REF!
Name _____PC8: #REF!
Name _____PC9: #REF!
Name _____PER1: #REF!
Name _____PER10: #REF!
Name _____PER11: #REF!
Name _____PER12: #REF!
Name _____PER2: #REF!
Name _____PER3: #REF!
Name _____PER4: #REF!
Name _____PER5: #REF!
Name _____PER6: #REF!
Name _____PER7: #REF!
Name _____PER8: #REF!
Name _____PER9: #REF!

Sheet R-1_R-2_Heat-Pump Rate
E1: Massachusetts Electric Company
E2: =rTitle2 -> Nantucket Electric Company
E3: =rTitle3 -> each d/b/a National Grid
E4: =rDocket -> D.P.U. 23-150
E5: Exhibit HP-3
E6: December 30, 2024
E7: Page 1 of 5
E8: H.O. Tassone
A9: =rMECO -> Massachusetts Electric Company
A10: =rNECO -> Nantucket Electric Company
A11: Rate Design for Proposed R-1/R-2 Optional HEAT PUMP Pricing-kWh Charge
C13: Billing Units | D13: Proposed Rates | E13: Proposed Revenue
C14: (a) | D14: (b) | E14: (c) = (a) x (b)
A16: -1 | B16: Revenue Allocation Target | E16: 6.7281812e+08
B18: Customer Charge:
A19: =A16-1 -> -2 | B19: All bills | C19: 14180780 | D19: 10 | E19: =C19*D19 -> 141807800
I21: R-1 kWh | J21: R-1 $
A22: =A19-1 -> -3 | B22: kWh Deliveries - Oct-Mar (R-1 & R-2 * 2.8) | C22: =I22*2.8 -> 1.0866947e+10 | D22: =TRUNC(J22/C22,5) -> 0.02337 | E22: =C22*D22 -> 2.5396054e+08 | I22: 3.8810524e+09 | J22: =I22*D23 -> 2.5405369e+08
A23: =A22-1 -> -4 | B23: kWh Deliveries - Summer- (R-1 & R-2) | C23: =I23 -> 4.2296978e+09 | D23: 0.06546 | E23: =C23*D23 -> 2.7687602e+08 | I23: 4.2296978e+09 | J23: =I23*D23 -> 2.7687602e+08
A24: =A23-1 -> -5 | B24: Total Revenue | E24: =SUM(E19:E23) -> 6.7264436e+08 | I24: =SUM(I22:I23) -> 8.1107502e+09 | J24: =SUM(J22:J23) -> 5.3092971e+08
A26: =A24-1 -> -6 | B26: Difference to Target | E26: =E24-E16 -> -173756.64
A29: =A16 -> -1 | B29: Exhibit NG-PP-6 (C) - Second Amended, Page 2, Line 1
A30: (2)(a) | B30: Exhibit NG-PP-6 (C) - Second Amended, Page 2, Line 2, Column (a)
A31: (2)(b) | B31: Exhibit NG-PP-6 (C) - Second Amended, Page 2, Line 2, Column (b)
A32: (3)(a) | B32: Workpaper NG-PP-2 (C), Page 9, Lines (87)-(92) for R-1 and R-2 * 2.8
A33: (3)(b) | B33: Workpaper NG-PP-2 (C), Page 9, Lines (87)-(92) for R-1 and R-2 * Summer kWh charge $0.06546 / Line (3), Column (a)
A34: (4)(a) | B34: Workpaper NG-PP-2 (C), Page 9, Line (81)-(86) for R-1 and R-2
A35: (4)(b) | B35: Exhibit NG-PP-6 (C) - Second Amended, Page 2, Line 3, Column (b)
A36: =A24 -> -5 | B36: Sum of Lines (2) through (4)
A37: =A26 -> -6 | B37: Line (5) - Line (1)

Sheet R-1 Factor & Bill Impacts
G1: ='R-1_R-2_Heat-Pump Rate'!E1 -> Massachusetts Electric Company
G2: ='R-1_R-2_Heat-Pump Rate'!E2 -> Nantucket Electric Company
G3: ='R-1_R-2_Heat-Pump Rate'!E3 -> each d/b/a National Grid
G4: ='R-1_R-2_Heat-Pump Rate'!E4 -> D.P.U. 23-150
G5: ='R-1_R-2_Heat-Pump Rate'!E5 -> Exhibit HP-3
G6: ='R-1_R-2_Heat-Pump Rate'!E6 -> December 30, 2024
G7: Page 2 of 5
G8: ='R-1_R-2_Heat-Pump Rate'!E8 -> H.O. Tassone
A11: Massachusetts Electric Company
A12: Nantucket Electric Company
A13: Calculation of Illustrative R-1 Heat-Pump Rate Customer Bill Impacts
C15: 3 Ton Heat-Pump | F15: 5 Ton Heat-Pump
C16: 841 kWh usage (October)* | D16: 2,269 kWh usage (January)** | F16: 1,127 kWh usage (October)*** | G16: 3,341 kWh usage (January)****
C17: (a) | D17: (b) | F17: (c) | G17: (d)
A19: -1 | B19: Illustrative R-1 Heat-Pump Customer Monthly Bill | C19: ='Resi Typical Bill (3 Ton HP)'!$H$53 -> 261.55 | D19: ='Resi Typical Bill (3 Ton HP)'!$I$53 -> 688.68 | F19: ='Resi Typical Bill (5 Ton HP)'!$H$53 -> 347.1 | G19: ='Resi Typical Bill (5 Ton HP)'!$I$53 -> 1009.34
A21: =A19-1 -> -2 | B21: Illustrative Typical Residential R-1 Monthly Bill | C21: ='Resi Typical Bill (3 Ton HP)'!$D$53 -> 296.94 | D21: ='Resi Typical Bill (3 Ton HP)'!$E$53 -> 784.18 | F21: ='Resi Typical Bill (5 Ton HP)'!$D$53 -> 394.54 | G21: ='Resi Typical Bill (5 Ton HP)'!$E$53 -> 1149.96
A23: =A21-1 -> -3 | B23: Illustrative R-1 Heat-Pump Customer Monthly Bill $ Increase/(Decrease) | C23: =C19-C21 -> -35.39 | D23: =D19-D21 -> -95.5 | F23: =F19-F21 -> -47.44 | G23: =G19-G21 -> -140.62
A25: =A23-1 -> -4 | B25: Illustrative R-1 Heat-Pump Customer Monthly Bill % Increase/(Decrease) | C25: =C23/C21 -> -0.11918233 | D25: =D23/D21 -> -0.12178326 | F25: =F23/F21 -> -0.12024129 | G25: =G23/G21 -> -0.12228251
A29: (1) (a) | B29: Page 4, Line 29, Column (e)
A30: (2) (a) | B30: Page 4, Line 29, Column (b)
A31: (1) (b) | B31: Page 4, Line 29, Column (f)
A32: (2) (b) | B32: Page 4, Line 29, Column (c)
A33: (1) (c) | B33: Page 5, Line 29, Column (e)
A34: (2) (c) | B34: Page 5, Line 29, Column (b)
A35: (1) (d) | B35: Page 5, Line 29, Column (f)
A36: (2) (d) | B36: Page 5, Line 29, Column (c)
A37: -3 | B37: Line (1) - Line (2)
A38: =A37-1 -> -4 | B38: Line (3) ÷ Line (2)
A39: * | B39: 841 kWh is equal to average residential customer usage in the month of October (600 kWh), plus 3-ton heat-pump usage in the same month
A40: ** | B40: 2,269 kWh is equal to average residential customer usage in the month of January (600 kWh), plus 3-ton heat-pump usage in the same month
A41: *** | B41: 1,127 kWh is equal to average residential customer usage in the month of October (600 kWh), plus 5-ton heat-pump usage in the same month
A42: **** | B42: 3,341 kWh is equal to average residential customer usage in the month of January (600 kWh), plus 5-ton heat-pump usage in the same month

Sheet R-2 Factor & Bill Impacts
G1: ='R-1_R-2_Heat-Pump Rate'!E1 -> Massachusetts Electric Company
G2: ='R-1_R-2_Heat-Pump Rate'!E2 -> Nantucket Electric Company
G3: ='R-1_R-2_Heat-Pump Rate'!E3 -> each d/b/a National Grid
G4: ='R-1_R-2_Heat-Pump Rate'!E4 -> D.P.U. 23-150
G5: ='R-1_R-2_Heat-Pump Rate'!E5 -> Exhibit HP-3
G6: ='R-1_R-2_Heat-Pump Rate'!E6 -> December 30, 2024
G7: Page 3 of 5
G8: ='R-1_R-2_Heat-Pump Rate'!E8 -> H.O. Tassone
A11: Massachusetts Electric Company
A12: Nantucket Electric Company
A13: Calculation of Illustrative R-2 Heat-Pump Rate Customer Bill Impacts
C15: 3 Ton Heat-Pump | F15: 5 Ton Heat-Pump
C16: 841 kWh usage (October)* | D16: 2269 kWh usage (January)** | F16: 1127 kWh usage (October)*** | G16: 3341 kWh usage (January)****
C17: (a) | D17: (b) | F17: (c) | G17: (d)
A20: -1 | B20: Illustrative R-2 Heat-Pump Customer Monthly Bill | C20: ='Resi Typical Bill (3 Ton HP)'!H57 -> 177.854 | D20: ='Resi Typical Bill (3 Ton HP)'!I57 -> 468.3024 | F20: ='Resi Typical Bill (5 Ton HP)'!H57 -> 236.028 | G20: ='Resi Typical Bill (5 Ton HP)'!I57 -> 686.3512
A22: =A20-1 -> -2 | B22: Illustrative R-2 Residential Monthly Bill | C22: ='Resi Typical Bill (3 Ton HP)'!D57 -> 201.9192 | D22: ='Resi Typical Bill (3 Ton HP)'!E57 -> 533.2424 | F22: ='Resi Typical Bill (5 Ton HP)'!D57 -> 268.2872 | G22: ='Resi Typical Bill (5 Ton HP)'!E57 -> 781.9728
A24: =A22-1 -> -3 | B24: Illustrative R-2 Heat-Pump Customer Monthly Bill $ Increase/(Decrease) | C24: =C20-C22 -> -24.0652 | D24: =D20-D22 -> -64.94 | F24: =F20-F22 -> -32.2592 | G24: =G20-G22 -> -95.6216
A26: =A24-1 -> -4 | B26: Illustrative R-2 Heat-Pump Customer Monthly Bill % Increase/(Decrease) | C26: =C24/C22 -> -0.11918233 | D26: =D24/D22 -> -0.12178326 | F26: =F24/F22 -> -0.12024129 | G26: =G24/G22 -> -0.12228251
A30: (1) (a) | B30: Page 4, Line 31, Column (e)
A31: (2) (a) | B31: Page 4, Line 31, Column (b)
A32: (1) (b) | B32: Page 4, Line 31, Column (f)
A33: (2) (b) | B33: Page 4, Line 31, Column (c)
A34: (1) (c) | B34: Page 5, Line 31, Column (e)
A35: (2) (c) | B35: Page 5, Line 31, Column (b)
A36: (1) (d) | B36: Page 5, Line 31, Column (f)
A37: (2) (d) | B37: Page 5, Line 31, Column (c)
A38: -3 | B38: Line (1) - Line (2)
A39: =A38-1 -> -4 | B39: Line (3) ÷ Line (2)
A40: * | B40: 841 kWh is equal to average residential customer usage in the month of October (600 kWh), plus 3-ton heat-pump usage in the same month
A41: ** | B41: 2269 kWh is equal to average residential customer usage in the month of January (600 kWh), plus 3-ton heat-pump usage in the same month
A42: *** | B42: 1127 kWh is equal to average residential customer usage in the month of October (600 kWh), plus 5-ton heat-pump usage in the same month
A43: **** | B43: 3341 kWh is equal to average residential customer usage in the month of January (600 kWh), plus 5-ton heat-pump usage in the same month

Sheet Resi Typical Bill (3 Ton HP)
I1: ='R-1_R-2_Heat-Pump Rate'!E1 -> Massachusetts Electric Company
I2: ='R-1_R-2_Heat-Pump Rate'!E2 -> Nantucket Electric Company
I3: ='R-1_R-2_Heat-Pump Rate'!E3 -> each d/b/a National Grid
I4: ='R-1_R-2_Heat-Pump Rate'!E4 -> D.P.U. 23-150
I5: ='R-1_R-2_Heat-Pump Rate'!E5 -> Exhibit HP-3
I6: ='R-1_R-2_Heat-Pump Rate'!E6 -> December 30, 2024
I7: Page 4 of 5
I8: ='R-1_R-2_Heat-Pump Rate'!E8 -> H.O. Tassone
A10: Massachusetts Electric Company
A11: Nantucket Electric Company
A12: Calculation of Monthly Residential Bills for Customers with 3 Ton Heat-Pump
C14: Residential (non-Heat-Pump) Customer Typical Bill | G14: Residential Heat-Pump Rate Customer Typical Bill
C15: Effective | G15: Effective
C16: Rate | D16: Amount (841 kWh October usage) | E16: Amount (2,269 kWh January usage) | G16: Rate | H16: Amount (841 kWh October usage) | I16: Amount (2,269 kWh January usage)
C17: (a) | D17: (b) | E17: (c) | G17: (d) | H17: (e) | I17: (f)
B19: Delivery Service
A20: -1 | B20: Customer Charge | D20: 10 | E20: =D20 -> 10 | H20: =D20 -> 10 | I20: =H20 -> 10
A21: =+A20-1 -> -2 | B21: Base Distribution Charge | C21: 0.06546 | G21: ='R-1_R-2_Heat-Pump Rate'!D22 -> 0.02337
A22: =+A21-1 -> -3 | B22: Basic Service Adjustment Factor | C22: -0.00057 | G22: =C22 -> -0.00057
A23: =+A22-1 -> -4 | B23: Residential Assistance Adjustment Factor | C23: 0.00976 | G23: =C23 -> 0.00976
A24: =+A23-1 -> -5 | B24: Storm Fund Replenishment Factor | C24: 0.00406 | G24: =C24 -> 0.00406
A25: =+A24-1 -> -6 | B25: Pension/PBOP Factor | C25: -0.00145 | G25: =C25 -> -0.00145
A26: =+A25-1 -> -7 | B26: Revenue Decoupling Mechanism Adjustment Factor | C26: 0.00226 | G26: =C26 -> 0.00226
A27: =+A26-1 -> -8 | B27: Attorney General Consulting Expense Factor | C27: 3e-05 | G27: =C27 -> 3e-05
A28: =+A27-1 -> -9 | B28: Solar Cost Adjustment Factor | C28: 0.00051 | G28: =C28 -> 0.00051
A29: =+A28-1 -> -10 | B29: Smart Grid Distribution Adjustment Factor | C29: 0 | G29: =C29 -> 0
A30: =A29-1 -> -11 | B30: Renewable Energy Recovery Factor | C30: 0.00013 | G30: =C30 -> 0.00013
A31: =+A30-1 -> -12 | B31: Tax Act Credit Factor | C31: 0 | G31: =C31 -> 0
A32: =+A31-1 -> -13 | B32: Vegetation Management Factor | C32: 0.00044 | G32: =C32 -> 0.00044
A33: =+A32-1 -> -14 | B33: Grid Modernization Factor | C33: 0.00144 | G33: =C33 -> 0.00144
A34: =+A33-1 -> -15 | B34: Exogenous Storm Fund Factor | C34: 0.00198 | G34: =C34 -> 0.00198
A35: =+A34-1 -> -16 | B35: Advanced Metering Infrastructure Factor | C35: 0.00027 | G35: =C35 -> 0.00027
A36: =+A35-1 -> -17 | B36: Total Distribution Energy Charge | C36: =SUM(C21:C35) -> 0.08432 | D36: =ROUND(C36*841,2) -> 70.91 | E36: =ROUND(C36*2269,2) -> 191.32 | G36: =SUM(G21:G35) -> 0.04223 | H36: =ROUND(G36*841,2) -> 35.52 | I36: =ROUND(G36*2269,2) -> 95.82
A38: =+A36-1 -> -18 | B38: SMART Factor | C38: 0.00729 | D38: =ROUND(C38*841,2) -> 6.13 | E38: =ROUND(C38*2269,2) -> 16.54 | G38: =C38 -> 0.00729 | H38: =ROUND(G38*841,2) -> 6.13 | I38: =ROUND(G38*2269,2) -> 16.54
A39: =+A38-1 -> -19 | B39: Electric Vehicle Program Factor | C39: 0.00038 | D39: =ROUND(C39*841,2) -> 0.32 | E39: =ROUND(C39*2269,2) -> 0.86 | G39: =C39 -> 0.00038 | H39: =ROUND(G39*841,2) -> 0.32 | I39: =ROUND(G39*2269,2) -> 0.86
A40: =+A39-1 -> -20 | B40: Transition Charge | C40: -0.0005 | D40: =ROUND(C40*841,2) -> -0.42 | E40: =ROUND(C40*2269,2) -> -1.13 | G40: =C40 -> -0.0005 | H40: =ROUND(G40*841,2) -> -0.42 | I40: =ROUND(G40*2269,2) -> -1.13
A41: =+A40-1 -> -21 | B41: Transmission Service Adjustment Factor | C41: 0.041 | D41: =ROUND(C41*841,2) -> 34.48 | E41: =ROUND(C41*2269,2) -> 93.03 | G41: =C41 -> 0.041 | H41: =ROUND(G41*841,2) -> 34.48 | I41: =ROUND(G41*2269,2) -> 93.03
A42: =+A41-1 -> -22 | B42: Energy Efficiency Charge | C42: 0.03025 | D42: =ROUND(C42*841,2) -> 25.44 | E42: =ROUND(C42*2269,2) -> 68.64 | G42: =C42 -> 0.03025 | H42: =ROUND(G42*841,2) -> 25.44 | I42: =ROUND(G42*2269,2) -> 68.64
A43: =+A42-1 -> -23 | B43: Net Metering Recovery Surcharge | C43: 0.01767 | D43: =ROUND(C43*841,2) -> 14.86 | E43: =ROUND(C43*2269,2) -> 40.09 | G43: =C43 -> 0.01767 | H43: =ROUND(G43*841,2) -> 14.86 | I43: =ROUND(G43*2269,2) -> 40.09
A44: =+A42-1 -> -23 | B44: Renewables Charge | C44: 0.0005 | D44: =ROUND(C44*841,2) -> 0.42 | E44: =ROUND(C44*2269,2) -> 1.13 | G44: =C44 -> 0.0005 | H44: =ROUND(G44*841,2) -> 0.42 | I44: =ROUND(G44*2269,2) -> 1.13
...

Sheet Resi Typical Bill (5 Ton HP)
I1: ='R-1_R-2_Heat-Pump Rate'!E1 -> Massachusetts Electric Company
I2: ='R-1_R-2_Heat-Pump Rate'!E2 -> Nantucket Electric Company
I3: ='R-1_R-2_Heat-Pump Rate'!E3 -> each d/b/a National Grid
I4: ='R-1_R-2_Heat-Pump Rate'!E4 -> D.P.U. 23-150
I5: ='R-1_R-2_Heat-Pump Rate'!E5 -> Exhibit HP-3
I6: ='R-1_R-2_Heat-Pump Rate'!E6 -> December 30, 2024
I7: Page 5 of 5
I8: ='R-1_R-2_Heat-Pump Rate'!E8 -> H.O. Tassone
A10: Massachusetts Electric Company
A11: Nantucket Electric Company
A12: Calculation of Monthly Residential Bills for Customers with 5 Ton Heat-Pump
C14: Residential (non-Heat-Pump) Customer Typical Bill | G14: Residential Heat-Pump Rate Customer Typical Bill
C15: Effective | G15: Effective
C16: Rate | D16: Amount (1,127 kWh October usage) | E16: Amount (3,341 kWh January usage) | G16: Rate | H16: Amount (1,127 kWh October usage) | I16: Amount (3,341 kWh January usage)
C17: (a) | D17: (b) | E17: (c) | G17: (d) | H17: (e) | I17: (f)
B19: Delivery Service
A20: -1 | B20: Customer Charge | D20: 10 | E20: =D20 -> 10 | H20: =D20 -> 10 | I20: =H20 -> 10
A21: =+A20-1 -> -2 | B21: Base Distribution Charge | C21: 0.06546 | G21: ='R-1_R-2_Heat-Pump Rate'!D22 -> 0.02337
A22: =+A21-1 -> -3 | B22: Basic Service Adjustment Factor | C22: -0.00057 | G22: =C22 -> -0.00057
A23: =+A22-1 -> -4 | B23: Residential Assistance Adjustment Factor | C23: 0.00976 | G23: =C23 -> 0.00976
A24: =+A23-1 -> -5 | B24: Storm Fund Replenishment Factor | C24: 0.00406 | G24: =C24 -> 0.00406
A25: =+A24-1 -> -6 | B25: Pension/PBOP Factor | C25: -0.00145 | G25: =C25 -> -0.00145
A26: =+A25-1 -> -7 | B26: Revenue Decoupling Mechanism Adjustment Factor | C26: 0.00226 | G26: =C26 -> 0.00226
A27: =+A26-1 -> -8 | B27: Attorney General Consulting Expense Factor | C27: 3e-05 | G27: =C27 -> 3e-05
A28: =+A27-1 -> -9 | B28: Solar Cost Adjustment Factor | C28: 0.00051 | G28: =C28 -> 0.00051
A29: =+A28-1 -> -10 | B29: Smart Grid Distribution Adjustment Factor | C29: 0 | G29: =C29 -> 0
A30: =A29-1 -> -11 | B30: Renewable Energy Recovery Factor | C30: 0.00013 | G30: =C30 -> 0.00013
A31: =+A30-1 -> -12 | B31: Tax Act Credit Factor | C31: 0 | G31: =C31 -> 0
A32: =+A31-1 -> -13 | B32: Vegetation Management Factor | C32: 0.00044 | G32: =C32 -> 0.00044
A33: =+A32-1 -> -14 | B33: Grid Modernization Factor | C33: 0.00144 | G33: =C33 -> 0.00144
A34: =+A33-1 -> -15 | B34: Exogenous Storm Fund Factor | C34: 0.00198 | G34: =C34 -> 0.00198
A35: =+A34-1 -> -16 | B35: Advanced Metering Infrastructure Factor | C35: 0.00027 | G35: =C35 -> 0.00027
A36: =+A35-1 -> -17 | B36: Total Distribution Energy Charge | C36: =SUM(C21:C35) -> 0.08432 | D36: =ROUND(C36*1127,2) -> 95.03 | E36: =ROUND(C36*3341,2) -> 281.71 | G36: =SUM(G21:G35) -> 0.04223 | H36: =ROUND(G36*1127,2) -> 47.59 | I36: =ROUND(G36*3341,2) -> 141.09
A38: =+A36-1 -> -18 | B38: SMART Factor | C38: 0.00729 | D38: =ROUND(C38*1127,2) -> 8.22 | E38: =ROUND(C38*3341,2) -> 24.36 | G38: =C38 -> 0.00729 | H38: =ROUND(G38*1127,2) -> 8.22 | I38: =ROUND(G38*3341,2) -> 24.36
A39: =+A38-1 -> -19 | B39: Electric Vehicle Program Factor | C39: 0.00038 | D39: =ROUND(C39*1127,2) -> 0.43 | E39: =ROUND(C39*3341,2) -> 1.27 | G39: =C39 -> 0.00038 | H39: =ROUND(G39*1127,2) -> 0.43 | I39: =ROUND(G39*3341,2) -> 1.27
A40: =+A39-1 -> -20 | B40: Transition Charge | C40: -0.0005 | D40: =ROUND(C40*1127,2) -> -0.56 | E40: =ROUND(C40*3341,2) -> -1.67 | G40: =C40 -> -0.0005 | H40: =ROUND(G40*1127,2) -> -0.56 | I40: =ROUND(G40*3341,2) -> -1.67
A41: =+A40-1 -> -21 | B41: Transmission Service Adjustment Factor | C41: 0.041 | D41: =ROUND(C41*1127,2) -> 46.21 | E41: =ROUND(C41*3341,2) -> 136.98 | G41: =C41 -> 0.041 | H41: =ROUND(G41*1127,2) -> 46.21 | I41: =ROUND(G41*3341,2) -> 136.98
A42: =+A41-1 -> -22 | B42: Energy Efficiency Charge | C42: 0.03025 | D42: =ROUND(C42*1127,2) -> 34.09 | E42: =ROUND(C42*3341,2) -> 101.07 | G42: =C42 -> 0.03025 | H42: =ROUND(G42*1127,2) -> 34.09 | I42: =ROUND(G42*3341,2) -> 101.07
A43: =+A42-1 -> -23 | B43: Net Metering Recovery Surcharge | C43: 0.01767 | D43: =ROUND(C43*1127,2) -> 19.91 | E43: =ROUND(C43*3341,2) -> 59.04 | G43: =C43 -> 0.01767 | H43: =ROUND(G43*1127,2) -> 19.91 | I43: =ROUND(G43*3341,2) -> 59.04
A44: =+A42-1 -> -23 | B44: Renewables Charge | C44: 0.0005 | D44: =ROUND(C44*1127,2) -> 0.56 | E44: =ROUND(C44*3341,2) -> 1.67 | G44: =C44 -> 0.0005 | H44: =ROUND(G44*1127,2) -> 0.56 | I44: =ROUND(G44*3341,2) -> 1.67
...
