Workbook
Name BeforeUseE: Electric!$M$2:$X$265

Sheet Summary Electric Increase
A1: DPU 23-80 | R1: Page 1 of 1
A2: DOER 2-02 Attachment 3
A4: Line | C4: % Number of Customers that Installed a Heat Pump | E4: Number of Customers that Installed a Heat Pump | G4: ID | H4: Installation Year | J4: Installation Month | L4: Average Monthly Electric Usage for Heating Season Prior to Installation of Heat Pump | N4: Average Monthly Electric Usage for Heating Season Following to Installation of Heat Pump | P4: Annualized Increase in Heating Season Monthly Average Electric Usage | R4: Weighted Annualized Increase in Heating Season Monthly Average Electric Usage
L5: (kwh) | N5: (kwh) | P5: (kwh) | R5: (kwh)
A7: 1 | C7: =E7/$E$41 -> 0.0037878788 | E7: =COUNTIFS('Electric Calendarize'!$K$11:$K$274,'Summary Electric Increase'!$G7) -> 1 | G7: 2021_3 | H7: =LEFT(G7,4) -> 2021 | J7: =IF(LEN(G7)=6,RIGHT(G7,1),RIGHT(G7,2)) -> 3 | L7: =AVERAGEIFS('Electric Calendarize'!$O$11:$BG$274,'Electric Calendarize'!$BK$11:$DC$274,1,'Electric Calendarize'!$DG$11:$EY$274,'Summary Electric Increase'!$G7,'Electric Calendarize'!$O$11:$BG$274,">0",'Electric Calendarize'!$FC$11:$GU$274,0) -> 685.2 | N7: =AVERAGEIFS('Electric Calendarize'!$O$11:$BG$274,'Electric Calendarize'!$BK$11:$DC$274,1,'Electric Calendarize'!$DG$11:$EY$274,'Summary Electric Increase'!$G7,'Electric Calendarize'!$O$11:$BG$274,">0",'Electric Calendarize'!$FC$11:$GU$274,1) -> 850 | P7: =+(N7-L7)*12 -> 1977.6 | R7: =+P7*C7 -> 7.4909091
A8: =+A7+1 -> 2 | C8: =E8/$E$41 -> 0.022727273 | E8: =COUNTIFS('Electric Calendarize'!$K$11:$K$274,'Summary Electric Increase'!$G8) -> 6 | G8: 2021_4 | H8: =LEFT(G8,4) -> 2021 | J8: =IF(LEN(G8)=6,RIGHT(G8,1),RIGHT(G8,2)) -> 4 | L8: =AVERAGEIFS('Electric Calendarize'!$O$11:$BG$274,'Electric Calendarize'!$BK$11:$DC$274,1,'Electric Calendarize'!$DG$11:$EY$274,'Summary Electric Increase'!$G8,'Electric Calendarize'!$O$11:$BG$274,">0",'Electric Calendarize'!$FC$11:$GU$274,0) -> 1194.3611 | N8: =AVERAGEIFS('Electric Calendarize'!$O$11:$BG$274,'Electric Calendarize'!$BK$11:$DC$274,1,'Electric Calendarize'!$DG$11:$EY$274,'Summary Electric Increase'!$G8,'Electric Calendarize'!$O$11:$BG$274,">0",'Electric Calendarize'!$FC$11:$GU$274,1) -> 1162.7222 | P8: =+(N8-L8)*12 -> -379.66667 | R8: =+P8*C8 -> -8.6287879
A9: =+A8+1 -> 3 | C9: =E9/$E$41 -> 0.0075757576 | E9: =COUNTIFS('Electric Calendarize'!$K$11:$K$274,'Summary Electric Increase'!$G9) -> 2 | G9: 2021_5 | H9: =LEFT(G9,4) -> 2021 | J9: =IF(LEN(G9)=6,RIGHT(G9,1),RIGHT(G9,2)) -> 5 | L9: =AVERAGEIFS('Electric Calendarize'!$O$11:$BG$274,'Electric Calendarize'!$BK$11:$DC$274,1,'Electric Calendarize'!$DG$11:$EY$274,'Summary Electric Increase'!$G9,'Electric Calendarize'!$O$11:$BG$274,">0",'Electric Calendarize'!$FC$11:$GU$274,0) -> 1205.1667 | N9: =AVERAGEIFS('Electric Calendarize'!$O$11:$BG$274,'Electric Calendarize'!$BK$11:$DC$274,1,'Electric Calendarize'!$DG$11:$EY$274,'Summary Electric Increase'!$G9,'Electric Calendarize'!$O$11:$BG$274,">0",'Electric Calendarize'!$FC$11:$GU$274,1) -> 881.91667 | P9: =+(N9-L9)*12 -> -3879 | R9: =+P9*C9 -> -29.386364
A10: =+A9+1 -> 4 | C10: =E10/$E$41 -> 0.011363636 | E10: =COUNTIFS('Electric Calendarize'!$K$11:$K$274,'Summary Electric Increase'!$G10) -> 3 | G10: 2021_6 | H10: =LEFT(G10,4) -> 2021 | J10: =IF(LEN(G10)=6,RIGHT(G10,1),RIGHT(G10,2)) -> 6 | L10: =AVERAGEIFS('Electric Calendarize'!$O$11:$BG$274,'Electric Calendarize'!$BK$11:$DC$274,1,'Electric Calendarize'!$DG$11:$EY$274,'Summary Electric Increase'!$G10,'Electric Calendarize'!$O$11:$BG$274,">0",'Electric Calendarize'!$FC$11:$GU$274,0) -> 627.22222 | N10: =AVERAGEIFS('Electric Calendarize'!$O$11:$BG$274,'Electric Calendarize'!$BK$11:$DC$274,1,'Electric Calendarize'!$DG$11:$EY$274,'Summary Electric Increase'!$G10,'Electric Calendarize'!$O$11:$BG$274,">0",'Electric Calendarize'!$FC$11:$GU$274,1) -> 1151.5 | P10: =+(N10-L10)*12 -> 6291.3333 | R10: =+P10*C10 -> 71.492424
A11: =+A10+1 -> 5 | C11: =E11/$E$41 -> 0.049242424 | E11: =COUNTIFS('Electric Calendarize'!$K$11:$K$274,'Summary Electric Increase'!$G11) -> 13 | G11: 2021_7 | H11: =LEFT(G11,4) -> 2021 | J11: =IF(LEN(G11)=6,RIGHT(G11,1),RIGHT(G11,2)) -> 7 | L11: =AVERAGEIFS('Electric Calendarize'!$O$11:$BG$274,'Electric Calendarize'!$BK$11:$DC$274,1,'Electric Calendarize'!$DG$11:$EY$274,'Summary Electric Increase'!$G11,'Electric Calendarize'!$O$11:$BG$274,">0",'Electric Calendarize'!$FC$11:$GU$274,0) -> 724.86885 | N11: =AVERAGEIFS('Electric Calendarize'!$O$11:$BG$274,'Electric Calendarize'!$BK$11:$DC$274,1,'Electric Calendarize'!$DG$11:$EY$274,'Summary Electric Increase'!$G11,'Electric Calendarize'!$O$11:$BG$274,">0",'Electric Calendarize'!$FC$11:$GU$274,1) -> 914.67949 | P11: =+(N11-L11)*12 -> 2277.7276 | R11: =+P11*C11 -> 112.16083
A12: =+A11+1 -> 6 | C12: =E12/$E$41 -> 0.03030303 | E12: =COUNTIFS('Electric Calendarize'!$K$11:$K$274,'Summary Electric Increase'!$G12) -> 8 | G12: 2021_8 | H12: =LEFT(G12,4) -> 2021 | J12: =IF(LEN(G12)=6,RIGHT(G12,1),RIGHT(G12,2)) -> 8 | L12: =AVERAGEIFS('Electric Calendarize'!$O$11:$BG$274,'Electric Calendarize'!$BK$11:$DC$274,1,'Electric Calendarize'!$DG$11:$EY$274,'Summary Electric Increase'!$G12,'Electric Calendarize'!$O$11:$BG$274,">0",'Electric Calendarize'!$FC$11:$GU$274,0) -> 1006.1944 | N12: =AVERAGEIFS('Electric Calendarize'!$O$11:$BG$274,'Electric Calendarize'!$BK$11:$DC$274,1,'Electric Calendarize'!$DG$11:$EY$274,'Summary Electric Increase'!$G12,'Electric Calendarize'!$O$11:$BG$274,">0",'Electric Calendarize'!$FC$11:$GU$274,1) -> 997.89583 | P12: =+(N12-L12)*12 -> -99.583333 | R12: =+P12*C12 -> -3.0176768
A13: =+A12+1 -> 7 | C13: =E13/$E$41 -> 0.045454545 | E13: =COUNTIFS('Electric Calendarize'!$K$11:$K$274,'Summary Electric Increase'!$G13) -> 12 | G13: 2021_9 | H13: =LEFT(G13,4) -> 2021 | J13: =IF(LEN(G13)=6,RIGHT(G13,1),RIGHT(G13,2)) -> 9 | L13: =AVERAGEIFS('Electric Calendarize'!$O$11:$BG$274,'Electric Calendarize'!$BK$11:$DC$274,1,'Electric Calendarize'!$DG$11:$EY$274,'Summary Electric Increase'!$G13,'Electric Calendarize'!$O$11:$BG$274,">0",'Electric Calendarize'!$FC$11:$GU$274,0) -> 757.53571 | N13: =AVERAGEIFS('Electric Calendarize'!$O$11:$BG$274,'Electric Calendarize'!$BK$11:$DC$274,1,'Electric Calendarize'!$DG$11:$EY$274,'Summary Electric Increase'!$G13,'Electric Calendarize'!$O$11:$BG$274,">0",'Electric Calendarize'!$FC$11:$GU$274,1) -> 937.41667 | P13: =+(N13-L13)*12 -> 2158.5714 | R13: =+P13*C13 -> 98.116883
A14: =+A13+1 -> 8 | C14: =E14/$E$41 -> 0.037878788 | E14: =COUNTIFS('Electric Calendarize'!$K$11:$K$274,'Summary Electric Increase'!$G14) -> 10 | G14: 2021_10 | H14: =LEFT(G14,4) -> 2021 | J14: =IF(LEN(G14)=6,RIGHT(G14,1),RIGHT(G14,2)) -> 10 | L14: =AVERAGEIFS('Electric Calendarize'!$O$11:$BG$274,'Electric Calendarize'!$BK$11:$DC$274,1,'Electric Calendarize'!$DG$11:$EY$274,'Summary Electric Increase'!$G14,'Electric Calendarize'!$O$11:$BG$274,">0",'Electric Calendarize'!$FC$11:$GU$274,0) -> 760.03704 | N14: =AVERAGEIFS('Electric Calendarize'!$O$11:$BG$274,'Electric Calendarize'!$BK$11:$DC$274,1,'Electric Calendarize'!$DG$11:$EY$274,'Summary Electric Increase'!$G14,'Electric Calendarize'!$O$11:$BG$274,">0",'Electric Calendarize'!$FC$11:$GU$274,1) -> 1132.15 | P14: =+(N14-L14)*12 -> 4465.3556 | R14: =+P14*C14 -> 169.14226
A15: =+A14+1 -> 9 | C15: =E15/$E$41 -> 0.026515152 | E15: =COUNTIFS('Electric Calendarize'!$K$11:$K$274,'Summary Electric Increase'!$G15) -> 7 | G15: 2021_11 | H15: =LEFT(G15,4) -> 2021 | J15: =IF(LEN(G15)=6,RIGHT(G15,1),RIGHT(G15,2)) -> 11 | L15: =AVERAGEIFS('Electric Calendarize'!$O$11:$BG$274,'Electric Calendarize'!$BK$11:$DC$274,1,'Electric Calendarize'!$DG$11:$EY$274,'Summary Electric Increase'!$G15,'Electric Calendarize'!$O$11:$BG$274,">0",'Electric Calendarize'!$FC$11:$GU$274,0) -> 815.35714 | N15: =AVERAGEIFS('Electric Calendarize'!$O$11:$BG$274,'Electric Calendarize'!$BK$11:$DC$274,1,'Electric Calendarize'!$DG$11:$EY$274,'Summary Electric Increase'!$G15,'Electric Calendarize'!$O$11:$BG$274,">0",'Electric Calendarize'!$FC$11:$GU$274,1) -> 1086.881 | P15: =+(N15-L15)*12 -> 3258.2857 | R15: =+P15*C15 -> 86.393939
A16: =+A15+1 -> 10 | C16: =E16/$E$41 -> 0.037878788 | E16: =COUNTIFS('Electric Calendarize'!$K$11:$K$274,'Summary Electric Increase'!$G16) -> 10 | G16: 2021_12 | H16: =LEFT(G16,4) -> 2021 | J16: =IF(LEN(G16)=6,RIGHT(G16,1),RIGHT(G16,2)) -> 12 | L16: =AVERAGEIFS('Electric Calendarize'!$O$11:$BG$274,'Electric Calendarize'!$BK$11:$DC$274,1,'Electric Calendarize'!$DG$11:$EY$274,'Summary Electric Increase'!$G16,'Electric Calendarize'!$O$11:$BG$274,">0",'Electric Calendarize'!$FC$11:$GU$274,0) -> 1000.9245 | N16: =AVERAGEIFS('Electric Calendarize'!$O$11:$BG$274,'Electric Calendarize'!$BK$11:$DC$274,1,'Electric Calendarize'!$DG$11:$EY$274,'Summary Electric Increase'!$G16,'Electric Calendarize'!$O$11:$BG$274,">0",'Electric Calendarize'!$FC$11:$GU$274,1) -> 1457.4 | P16: =+(N16-L16)*12 -> 5477.7057 | R16: =+P16*C16 -> 207.48885
A17: =+A16+1 -> 11 | C17: =E17/$E$41 -> 0.0075757576 | E17: =COUNTIFS('Electric Calendarize'!$K$11:$K$274,'Summary Electric Increase'!$G17) -> 2 | G17: 2022_1 | H17: =LEFT(G17,4) -> 2022 | J17: =IF(LEN(G17)=6,RIGHT(G17,1),RIGHT(G17,2)) -> 1 | L17: =AVERAGEIFS('Electric Calendarize'!$O$11:$BG$274,'Electric Calendarize'!$BK$11:$DC$274,1,'Electric Calendarize'!$DG$11:$EY$274,'Summary Electric Increase'!$G17,'Electric Calendarize'!$O$11:$BG$274,">0",'Electric Calendarize'!$FC$11:$GU$274,0) -> 1101.5 | N17: =AVERAGEIFS('Electric Calendarize'!$O$11:$BG$274,'Electric Calendarize'!$BK$11:$DC$274,1,'Electric Calendarize'!$DG$11:$EY$274,'Summary Electric Increase'!$G17,'Electric Calendarize'!$O$11:$BG$274,">0",'Electric Calendarize'!$FC$11:$GU$274,1) -> 1196.8333 | P17: =+(N17-L17)*12 -> 1144 | R17: =+P17*C17 -> 8.6666667
A18: =+A17+1 -> 12 | C18: =E18/$E$41 -> 0.0075757576 | E18: =COUNTIFS('Electric Calendarize'!$K$11:$K$274,'Summary Electric Increase'!$G18) -> 2 | G18: 2022_2 | H18: =LEFT(G18,4) -> 2022 | J18: =IF(LEN(G18)=6,RIGHT(G18,1),RIGHT(G18,2)) -> 2 | L18: =AVERAGEIFS('Electric Calendarize'!$O$11:$BG$274,'Electric Calendarize'!$BK$11:$DC$274,1,'Electric Calendarize'!$DG$11:$EY$274,'Summary Electric Increase'!$G18,'Electric Calendarize'!$O$11:$BG$274,">0",'Electric Calendarize'!$FC$11:$GU$274,0) -> 1162 | N18: =AVERAGEIFS('Electric Calendarize'!$O$11:$BG$274,'Electric Calendarize'!$BK$11:$DC$274,1,'Electric Calendarize'!$DG$11:$EY$274,'Summary Electric Increase'!$G18,'Electric Calendarize'!$O$11:$BG$274,">0",'Electric Calendarize'!$FC$11:$GU$274,1) -> 1310.4167 | P18: =+(N18-L18)*12 -> 1781 | R18: =+P18*C18 -> 13.492424
A19: =+A18+1 -> 13 | C19: =E19/$E$41 -> 0.022727273 | E19: =COUNTIFS('Electric Calendarize'!$K$11:$K$274,'Summary Electric Increase'!$G19) -> 6 | G19: 2022_3 | H19: =LEFT(G19,4) -> 2022 | J19: =IF(LEN(G19)=6,RIGHT(G19,1),RIGHT(G19,2)) -> 3 | L19: =AVERAGEIFS('Electric Calendarize'!$O$11:$BG$274,'Electric Calendarize'!$BK$11:$DC$274,1,'Electric Calendarize'!$DG$11:$EY$274,'Summary Electric Increase'!$G19,'Electric Calendarize'!$O$11:$BG$274,">0",'Electric Calendarize'!$FC$11:$GU$274,0) -> 509.36111 | N19: =AVERAGEIFS('Electric Calendarize'!$O$11:$BG$274,'Electric Calendarize'!$BK$11:$DC$274,1,'Electric Calendarize'!$DG$11:$EY$274,'Summary Electric Increase'!$G19,'Electric Calendarize'!$O$11:$BG$274,">0",'Electric Calendarize'!$FC$11:$GU$274,1) -> 767.72222 | P19: =+(N19-L19)*12 -> 3100.3333 | R19: =+P19*C19 -> 70.462121
... A39: =+A38+1 -> 33 | C39: =E39/$E$41 -> 0.0037878788 | E39: =COUNTIFS('Electric Calendarize'!$K$11:$K$274,'Summary Electric Increase'!$G39) -> 1 | G39: 2023_11 | H39: =LEFT(G39,4) -> 2023 | J39: =IF(LEN(G39)=6,RIGHT(G39,1),RIGHT(G39,2)) -> 11 | L39: =AVERAGEIFS('Electric Calendarize'!$O$11:$BG$274,'Electric Calendarize'!$BK$11:$DC$274,1,'Electric Calendarize'!$DG$11:$EY$274,'Summary Electric Increase'!$G39,'Electric Calendarize'!$O$11:$BG$274,">0",'Electric Calendarize'!$FC$11:$GU$274,0) -> 812 | N39: =AVERAGEIFS('Electric Calendarize'!$O$11:$BG$274,'Electric Calendarize'!$BK$11:$DC$274,1,'Electric Calendarize'!$DG$11:$EY$274,'Summary Electric Increase'!$G39,'Electric Calendarize'!$O$11:$BG$274,">0",'Electric Calendarize'!$FC$11:$GU$274,1) -> 606 | P39: =+(N39-L39)*12 -> -2472 | R39: =+P39*C39 -> -9.3636364
A41: =+A39+1 -> 34 | C41: =SUM(C7:C39) -> 1 | E41: =SUM(E7:E39) -> 264 | N41: Mean / Weighted | P41: =AVERAGE(P7:P39) -> 2904.7992 | R41: =SUM(R7:R39) -> 3387.0646
A42: =+A41+1 -> 35 | N42: Standard Deviation | P42: =_xlfn.STDEV.S(P7:P39) -> 3384.5152
N44: Remove 2023 Installs as not through a new heating heason post install.
N46: Mean / Weighted | P46: =AVERAGE(P7:P28) -> 3470.8197 | R46: {=SUMPRODUCT($P$7:$P$28,$E$7:$E$28/SUM($E$7:$E$29))} -> 3961.5975
N47: Standard Deviation | P47: =_xlfn.STDEV.S(P7:P28) -> 2931.8206
N49: Change Used in Heat Pump Rate Design | P49: 5927.3933 | R49: 5927.3933
N50: Standard Deviations from Mean | P50: =(P49-P46)/P47 -> 0.83790036 | R50: =(R49-R46)/P47 -> 0.67050343

Sheet Data==>

Sheet Electric
A1: Measure | B1: Customer Name | C1: Account Number | D1: Service Address | E1: Service City | F1: Service State | G1: Service Zip Code | H1: Intall Date | I1: Year | J1: Month | K1: ID | L1: Rate Class | M1: PreInstallDate(-12) | N1: PreInstallDate(-11) | O1: PreInstallDate(-10) | P1: PreInstallDate(-9) | Q1: PreInstallDate(-8) | R1: PreInstallDate(-7) | S1: PreInstallDate(-6) | T1: PreInstallDate(-5) | U1: PreInstallDate(-4) | V1: PreInstallDate(-3) | W1: PreInstallDate(-2) | X1: PreInstallDate(-1) | Y1: PostInstallDate(1) | Z1: PostInstallDate(2) | AA1: PostInstallDate(3) | AB1: PostInstallDate(4) | AC1: PostInstallDate(5) | AD1: PostInstallDate(6) | AE1: PostInstallDate(7) | AF1: PostInstallDate(8) | AG1: PostInstallDate(9) | AH1: PostInstallDate(10) | AI1: PostInstallDate(11) | AJ1: PostInstallDate(12)
A2: MSHP partially displacing Oil Heat (weatherization unverified) | C2: 3021214000 | D2: PRATT ST | E2: FITCHBURG | F2: MA | G2: 01420-4188 | H2: 44281 | I2: =YEAR(H2) -> 2021 | J2: =MONTH(H2) -> 3 | K2: =I2&"_"&J2 -> 2021_3 | L2: Residential | M2: 1790 | N2: 1461 | O2: 999 | P2: 458 | Q2: 284 | R2: 444 | S2: 623 | T2: 373 | U2: 374 | V2: 409 | W2: 480 | X2: 778 | Y2: 750 | Z2: 453 | AA2: 490 | AB2: 471 | AC2: 517 | AD2: 572 | AE2: 270 | AF2: 359 | AG2: 646 | AH2: 854 | AI2: 1398 | AJ2: 1165
A3: DMSHP, SEER 18.0 HSPF 10, Disp Electric Heat E19A2a278 | C3: 3120402002 | D3: HIGHLAND ST | E3: LUNENBURG | F3: MA | G3: 01462-1416 | H3: 44299 | I3: =YEAR(H3) -> 2021 | J3: =MONTH(H3) -> 4 | K3: =I3&"_"&J3 -> 2021_4 | L3: Residential | M3: 882 | N3: 767 | O3: 856 | P3: 879 | Q3: 785 | R3: 752 | S3: 1118 | T3: 1117 | U3: 1112 | V3: 1001 | W3: 739 | X3: 796 | Y3: 909 | Z3: 735 | AA3: 713 | AB3: 492 | AC3: 667 | AD3: 1125 | AE3: 888 | AF3: 1029 | AG3: 1071 | AH3: 952 | AI3: 1050 | AJ3: 876
A4: MSHP partially displacing Oil Heat | C4: 3150085004 | D4: ROLLING ACRES RD | E4: LUNENBURG | F4: MA | G4: 01462-1548 | H4: 44301 | I4: =YEAR(H4) -> 2021 | J4: =MONTH(H4) -> 4 | K4: =I4&"_"&J4 -> 2021_4 | L4: Residential | M4: 1832 | N4: 932 | O4: 1288 | P4: 1532 | Q4: 1880 | R4: 1416 | S4: 1556 | T4: 2006 | U4: 1774 | V4: 2078 | W4: 1408 | X4: 976 | Y4: 1146 | Z4: 850 | AA4: 1092 | AB4: 2216 | AC4: 2258 | AD4: 1504 | AE4: 1232 | AF4: 1292 | AG4: 1350 | AH4: 1844 | AI4: 1460 | AJ4: 1240
A5: MSHP partially displacing Oil Heat | C5: 3151746001 | D5: KRISTOPHER LN | E5: TOWNSEND | F5: MA | G5: 01474-1056 | H5: 44305 | I5: =YEAR(H5) -> 2021 | J5: =MONTH(H5) -> 4 | K5: =I5&"_"&J5 -> 2021_4 | L5: Residential | M5: 835 | N5: 831 | O5: 1084 | P5: 1364 | Q5: 1097 | R5: 876 | S5: 791 | T5: 714 | U5: 983 | V5: 685 | W5: 686 | X5: 618 | Y5: 644 | Z5: 612 | AA5: 1069 | AB5: 1419 | AC5: 1195 | AD5: 1110 | AE5: 654 | AF5: 914 | AG5: 1286 | AH5: 2024 | AI5: 1935 | AJ5: 1214
A6: MSHP partially displacing Oil Heat | C6: 3020110000 | D6: MADISON ST | E6: FITCHBURG | F6: MA | G6: 01420-5022 | H6: 44308 | I6: =YEAR(H6) -> 2021 | J6: =MONTH(H6) -> 4 | K6: =I6&"_"&J6 -> 2021_4 | L6: Residential | M6: 846 | N6: 786 | O6: 606 | P6: 832 | Q6: 108 | R6: 1626 | S6: 932 | T6: 998 | U6: 1398 | V6: 1856 | W6: 1582 | X6: 1802 | Y6: 832 | Z6: 606 | AA6: 516 | AB6: 924 | AC6: 1332 | AD6: 1442 | AE6: 1098 | AF6: 772 | AG6: 1556 | AH6: 1998 | AI6: 2730 | AJ6: 1884
A7: Central Heat Pump partially displacing Oil Heat | C7: 3132100001 | D7: LEOMINSTER RD | E7: LUNENBURG | F7: MA | G7: 01462-2009 | H7: 44313 | I7: =YEAR(H7) -> 2021 | J7: =MONTH(H7) -> 4 | K7: =I7&"_"&J7 -> 2021_4 | L7: Residential | M7: 973 | N7: 889 | O7: 1359 | P7: 1645 | Q7: 1741 | R7: 993 | S7: 661 | T7: 993 | U7: 1299 | V7: 1266 | W7: 1231 | X7: 769 | Y7: 568 | Z7: 522 | AA7: 897 | AB7: 1056 | AC7: 1080 | AD7: 794 | AE7: 555 | AF7: 702 | AG7: 1016 | AH7: 1102 | AI7: 621 | AJ7: 514
A8: MSHP partially displacing Oil Heat (weatherization unverified) | C8: 3120915001 | D8: MASSACHUSETTS AVE | E8: LUNENBURG | F8: MA | G8: 01462-1354 | H8: 44315 | I8: =YEAR(H8) -> 2021 | J8: =MONTH(H8) -> 4 | K8: =I8&"_"&J8 -> 2021_4 | L8: Residential | M8: 806 | N8: 707 | O8: 1222 | P8: 1359 | Q8: 2653 | R8: 1469 | S8: 954 | T8: 1127 | U8: 1518 | V8: 1412 | W8: 1440 | X8: 1439 | Y8: 975 | Z8: 924 | AA8: 1414 | AB8: 1334 | AC8: 1286 | AD8: 889 | AE8: 610 | AF8: 773 | AG8: 952 | AH8: 864 | AI8: 963 | AJ8: 800
A9: MSHP partially displacing Oil Heat (weatherization unverified) | C9: 3141643000 | D9: TYLER RD | E9: TOWNSEND | F9: MA | G9: 01469-1203 | H9: 44330 | I9: =YEAR(H9) -> 2021 | J9: =MONTH(H9) -> 5 | K9: =I9&"_"&J9 -> 2021_5 | L9: Residential | M9: 572 | N9: 937 | O9: 1132 | P9: 1077 | Q9: 751 | R9: 630 | S9: 526 | T9: 671 | U9: 687 | V9: 979 | W9: 573 | X9: 499 | Y9: 688 | Z9: 894 | AA9: 1097 | AB9: 1072 | AC9: 931 | AD9: 802 | AE9: 566 | AF9: 531 | AG9: 725 | AH9: 642 | AI9: 580 | AJ9: 501
A10: Central Heat Pump partially displacing Oil Heat | C10: 3121672000 | D10: NATICK ST | E10: LUNENBURG | F10: MA | G10: 01462-2405 | H10: 44342 | I10: =YEAR(H10) -> 2021 | J10: =MONTH(H10) -> 5 | K10: =I10&"_"&J10 -> 2021_5 | L10: Residential | M10: 950 | N10: 1124 | O10: 1224 | P10: 1390 | Q10: 1025 | R10: 920 | S10: 1416 | T10: 1852 | U10: 1779 | V10: 1907 | W10: 1903 | X10: 1670 | Y10: 1055 | Z10: 1209 | AA10: 1297 | AB10: 1483 | AC10: 1080 | AD10: 922 | AE10: 1116 | AF10: 1333 | AG10: 1220 | AH10: 1221 | AI10: 1188 | AJ10: 960
A11: MSHP partially displacing Oil Heat | C11: 3130420006 | D11: FLAT HILL RD | E11: LUNENBURG | F11: MA | G11: 01462-2118 | H11: 44356 | I11: =YEAR(H11) -> 2021 | J11: =MONTH(H11) -> 6 | K11: =I11&"_"&J11 -> 2021_6 | L11: Residential | M11: 0 | N11: 0 | O11: 0 | P11: 0 | Q11: 0 | R11: 104 | S11: 529 | T11: 617 | U11: 593 | V11: 564 | W11: 778 | X11: 741 | Y11: 654 | Z11: 704 | AA11: 808 | AB11: 872 | AC11: 719 | AD11: 1097 | AE11: 1682 | AF11: 2330 | AG11: 1868 | AH11: 1606 | AI11: 1842 | AJ11: 1162
A12: MSHP partially displacing Oil Heat | C12: 3012142001 | D12: SHELDON RD | E12: FITCHBURG | F12: MA | G12: 01420-1813 | H12: 44362 | I12: =YEAR(H12) -> 2021 | J12: =MONTH(H12) -> 6 | K12: =I12&"_"&J12 -> 2021_6 | L12: Residential | M12: 0 | N12: 0 | O12: 0 | P12: 0 | Q12: 126 | R12: 620 | S12: 672 | T12: 720 | U12: 714 | V12: 750 | W12: 611 | X12: 748 | Y12: 773 | Z12: 821 | AA12: 665 | AB12: 1297 | AC12: 982 | AD12: 863 | AE12: 1286 | AF12: 1221 | AG12: 1168 | AH12: 1301 | AI12: 911 | AJ12: 914
A13: MSHP partially displacing Oil Heat (weatherization unverified) | C13: 3072565000 | D13: APPLE TREE HL | E13: FITCHBURG | F13: MA | G13: 01420-2470 | H13: 44367 | I13: =YEAR(H13) -> 2021 | J13: =MONTH(H13) -> 6 | K13: =I13&"_"&J13 -> 2021_6 | L13: Residential | M13: 976 | N13: 1192 | O13: 1344 | P13: 1010 | Q13: 587 | R13: 610 | S13: 747 | T13: 811 | U13: 712 | V13: 627 | W13: 511 | X13: 616 | Y13: 898 | Z13: 878 | AA13: 1203 | AB13: 876 | AC13: 683 | AD13: 550 | AE13: 707 | AF13: 622 | AG13: 582 | AH13: 545 | AI13: 546 | AJ13: 606
... A20: MSHP partially displacing Oil Heat | C20: 3131911004 | D20: WHITING ST | E20: LUNENBURG | F20: MA | G20: 01462-1451 | H20: 44397 | I20: =YEAR(H20) -> 2021 | J20: =MONTH(H20) -> 7 | K20: =I20&"_"&J20 -> 2021_7 | L20: Residential | M20: 0 | N20: 0 | O20: 0 | P20: 326 | Q20: 540 | R20: 745 | S20: 733 | T20: 709 | U20: 768 | V20: 623 | W20: 645 | X20: 578 | Y20: 769 | Z20: 991 | AA20: 704 | AB20: 580 | AC20: 838 | AD20: 996 | AE20: 1165 | AF20: 1057 | AG20: 975 | AH20: 821 | AI20: 749 | AJ20: 615
A21: Central Heat Pump partially displacing Oil Heat | C21: 3010174002 | D21: SUNRISE AVE | E21: FITCHBURG | F21: MA | G21: 01420-3717 | H21: 44398 | I21: =YEAR(H21) -> 2021 | J21: =MONTH(H21) -> 7 | K21: =I21&"_"&J21 -> 2021_7 | L21: Residential | N21: 0 | O21: 0 | P21: 0 | Q21: 0 | R21: 0 | S21: 0 | T21: 0 | U21: 0 | V21: 415 | W21: 429 | X21: 443 | Y21: 682 | Z21: 641 | AA21: 658 | AB21: 441 | AC21: 556 | AD21: 1327 | AE21: 944 | AF21: 601 | AG21: 737 | AH21: 737 | AI21: 655 | AJ21: 685
A22: MSHP partially displacing Oil Heat | C22: 3130548000 | D22: GOODRICH ST | E22: LUNENBURG | F22: MA | G22: 01462-1620 | H22: 44398 | I22: =YEAR(H22) -> 2021 | J22: =MONTH(H22) -> 7 | K22: =I22&"_"&J22 -> 2021_7 | L22: Residential | M22: 2241 | N22: 2494 | O22: 1381 | P22: 1124 | Q22: 965 | R22: 1288 | S22: 1039 | T22: 1264 | U22: 1206 | V22: 1200 | W22: 1255 | X22: 1614 | Y22: 1717 | Z22: 1738 | AA22: 1347 | AB22: 888 | AC22: 1130 | AD22: 1273 | AE22: 1902 | AF22: 1753 | AG22: 1394 | AH22: 966 | AI22: 1697 | AJ22: 1326
A23: MSHP partially displacing Oil Heat (weatherized) | C23: 3012241001 | D23: ROOSEVELT ST | E23: FITCHBURG | F23: MA | G23: 01420-4755 | H23: 44399 | I23: =YEAR(H23) -> 2021 | J23: =MONTH(H23) -> 7 | K23: =I23&"_"&J23 -> 2021_7 | L23: Residential | M23: 1236 | N23: 1155 | O23: 1051 | P23: 629 | Q23: 650 | R23: 652 | S23: 859 | T23: 671 | U23: 615 | V23: 479 | W23: 474 | X23: 909 | Y23: 1232 | Z23: 1156 | AA23: 1015 | AB23: 839 | AC23: 1107 | AD23: 1749 | AE23: 1450 | AF23: 1241 | AG23: 1355 | AH23: 1004 | AI23: 715 | AJ23: 1026
A24: MSHP partially displacing Oil Heat (weatherization unverified) | C24: 3040859000 | D24: SAINT JOSEPH AVE | E24: FITCHBURG | F24: MA | G24: 01420-5158 | H24: 44403 | I24: =YEAR(H24) -> 2021 | J24: =MONTH(H24) -> 7 | K24: =I24&"_"&J24 -> 2021_7 | L24: Residential | M24: 540 | N24: 640 | O24: 474 | P24: 346 | Q24: 344 | R24: 386 | S24: 365 | T24: 322 | U24: 320 | V24: 322 | W24: 389 | X24: 424 | Y24: 485 | Z24: 393 | AA24: 540 | AB24: 341 | AC24: 317 | AD24: 456 | AE24: 518 | AF24: 361 | AG24: 355 | AH24: 354 | AI24: 322 | AJ24: 319
A25: MSHP partially displacing Oil Heat | C25: 3020142000 | D25: MADISON ST | E25: FITCHBURG | F25: MA | G25: 01420-5152 | H25: 44407 | I25: =YEAR(H25) -> 2021 | J25: =MONTH(H25) -> 7 | K25: =I25&"_"&J25 -> 2021_7 | L25: Residential | M25: 307 | N25: 477 | O25: 427 | P25: 325 | Q25: 475 | R25: 406 | S25: 403 | T25: 399 | U25: 386 | V25: 247 | W25: 353 | X25: 338 | Y25: 352 | Z25: 452 | AA25: 521 | AB25: 406 | AC25: 540 | AD25: 485 | AE25: 465 | AF25: 502 | AG25: 314 | AH25: 156 | AI25: 413 | AJ25: 345
A26: MSHP partially displacing Oil Heat | C26: 3131435001 | D26: PENINSULA DR | E26: LUNENBURG | F26: MA | G26: 01462-1110 | H26: 44407 | I26: =YEAR(H26) -> 2021 | J26: =MONTH(H26) -> 7 | K26: =I26&"_"&J26 -> 2021_7 | L26: Residential | M26: 390 | N26: 460 | O26: 378 | P26: 312 | Q26: 449 | R26: 620 | S26: 512 | T26: 423 | U26: 471 | V26: 405 | W26: 380 | X26: 392 | Y26: 398 | Z26: 488 | AA26: 281 | AB26: 367 | AC26: 476 | AD26: 548 | AE26: 566 | AF26: 461 | AG26: 444 | AH26: 431 | AI26: 419 | AJ26: 406
A27: MSHP partially displacing Oil Heat (weatherization unverified) | C27: 3050616002 | D27: HOLMAN ST | E27: FITCHBURG | F27: MA | G27: 01420-2645 | H27: 44418 | I27: =YEAR(H27) -> 2021 | J27: =MONTH(H27) -> 8 | K27: =I27&"_"&J27 -> 2021_8 | L27: Residential | M27: 1008 | N27: 866 | O27: 527 | P27: 482 | Q27: 470 | R27: 445 | S27: 404 | T27: 392 | U27: 456 | V27: 490 | W27: 609 | X27: 890 | Y27: 859 | Z27: 893 | AA27: 651 | AB27: 501 | AC27: 467 | AD27: 470 | AE27: 430 | AF27: 467 | AG27: 490 | AH27: 462 | AI27: 802 | AJ27: 745
A28: MSHP partially displacing Oil Heat (weatherized) | C28: 3062480000 | D28: MACINTOSH LN | E28: FITCHBURG | F28: MA | G28: 01420-1654 | H28: 44420 | I28: =YEAR(H28) -> 2021 | J28: =MONTH(H28) -> 8 | K28: =I28&"_"&J28 -> 2021_8 | L28: Residential | M28: 1880 | N28: 2009 | O28: 1005 | P28: 945 | Q28: 1209 | R28: 1421 | S28: 1334 | T28: 1421 | U28: 997 | V28: 836 | W28: 1551 | X28: 1629 | Y28: 1601 | Z28: 1804 | AA28: 1092 | AB28: 668 | AC28: 1079 | AD28: 1304 | AE28: 1111 | AF28: 1156 | AG28: 895 | AH28: 903 | AI28: 1495 | AJ28: 1636
A29: MSHP partially displacing Oil Heat | C29: 3040465001 | D29: PARKER ST | E29: FITCHBURG | F29: MA | G29: 01420-6143 | H29: 44427 | I29: =YEAR(H29) -> 2021 | J29: =MONTH(H29) -> 8 | K29: =I29&"_"&J29 -> 2021_8 | L29: Residential | M29: 422 | N29: 271 | O29: 205 | P29: 233 | Q29: 252 | R29: 267 | S29: 282 | T29: 293 | U29: 233 | V29: 209 | W29: 189 | X29: 247 | Y29: 304 | Z29: 394 | AA29: 283 | AB29: 277 | AC29: 631 | AD29: 605 | AE29: 365 | AF29: 326 | AG29: 310 | AH29: 297 | AI29: 289 | AJ29: 345
A30: MSHP partially displacing Oil Heat (weatherization unverified) | C30: 3121487003 | D30: PROSPECT ST | E30: LUNENBURG | F30: MA | G30: 01462-2238 | H30: 44431 | I30: =YEAR(H30) -> 2021 | J30: =MONTH(H30) -> 8 | K30: =I30&"_"&J30 -> 2021_8 | L30: Residential | M30: 0 | N30: 0 | O30: 0 | P30: 0 | Q30: 0 | R30: 0 | S30: 0 | T30: 0 | U30: 0 | V30: 0 | W30: 0 | X30: 15 | Y30: 297 | Z30: 230 | AA30: 443 | AB30: 756 | AC30: 1378 | AD30: 1832 | AE30: 1908 | AF30: 1386 | AG30: 985 | AH30: 799 | AI30: 645 | AJ30: 800
A31: MSHP partially displacing Oil Heat (weatherization unverified) | C31: 3150567002 | D31: HIGHLAND ST | E31: TOWNSEND | F31: MA | G31: 01469-1128 | H31: 44431 | I31: =YEAR(H31) -> 2021 | J31: =MONTH(H31) -> 8 | K31: =I31&"_"&J31 -> 2021_8 | L31: Residential | M31: 1136 | N31: 1168 | O31: 988 | P31: 643 | Q31: 823 | R31: 707 | S31: 712 | T31: 653 | U31: 621 | V31: 766 | W31: 1119 | X31: 1169 | Y31: 1042 | Z31: 992 | AA31: 545 | AB31: 634 | AC31: 764 | AD31: 729 | AE31: 756 | AF31: 666 | AG31: 580 | AH31: 1528 | AI31: 1951 | AJ31: 1768
A32: Central Heat Pump partially displacing Oil Heat | C32: 3080924002 | D32: FOREST PARK | E32: FITCHBURG | F32: MA | G32: 01420-5355 | H32: 44432 | I32: =YEAR(H32) -> 2021 | J32: =MONTH(H32) -> 8 | K32: =I32&"_"&J32 -> 2021_8 | L32: Residential | M32: 0 | N32: 0 | O32: 0 | P32: 0 | Q32: 0 | R32: 0 | S32: 0 | T32: 0 | U32: 0 | V32: 0 | W32: 367 | X32: 533 | Y32: 686 | Z32: 895 | AA32: 928 | AB32: 2198 | AC32: 2196 | AD32: 2126 | AE32: 1340 | AF32: 1384 | AG32: 1544 | AH32: 1290 | AI32: 656 | AJ32: 880
A33: MSHP partially displacing Oil Heat (weatherized) | C33: 3140412000 | D33: FORDWAY RD | E33: TOWNSEND | F33: MA | G33: 01469-1132 | H33: 44434 | I33: =YEAR(H33) -> 2021 | J33: =MONTH(H33) -> 8 | K33: =I33&"_"&J33 -> 2021_8 | L33: Residential | M33: 2980 | N33: 1967 | O33: 1988 | P33: 2315 | Q33: 3333 | R33: 3187 | S33: 3579 | T33: 2624 | U33: 1359 | V33: 1194 | W33: 2548 | X33: 2529 | Y33: 2233 | Z33: 1852 | AA33: 1181 | AB33: 1469 | AC33: 1663 | AD33: 2003 | AE33: 1769 | AF33: 1268 | AG33: 978 | AH33: 1383 | AI33: 1376 | AJ33: 1928
... A45: MSHP partially displacing Oil Heat | C45: 3131961001 | D45: LEOMINSTER RD | E45: LUNENBURG | F45: MA | G45: 01462-1340 | H45: 44463 | I45: =YEAR(H45) -> 2021 | J45: =MONTH(H45) -> 9 | K45: =I45&"_"&J45 -> 2021_9 | L45: Residential | M45: 494 | N45: 367 | O45: 410 | P45: 517 | Q45: 450 | R45: 424 | S45: 434 | T45: 483 | U45: 427 | V45: 554 | W45: 824 | X45: 774 | Y45: 717 | Z45: 633 | AA45: 775 | AB45: 1018 | AC45: 1217 | AD45: 1146 | AE45: 739 | AF45: 652 | AG45: 822 | AH45: 577 | AI45: 884 | AJ45: 860
A46: MSHP partially displacing Oil Heat | C46: 3052412005 | D46: VALLEY VIEW DR | E46: FITCHBURG | F46: MA | G46: 01420 | H46: 44469 | I46: =YEAR(H46) -> 2021 | J46: =MONTH(H46) -> 9 | K46: =I46&"_"&J46 -> 2021_9 | L46: Residential | M46: 0 | N46: 0 | O46: 0 | P46: 0 | R46: 0 | S46: 0 | T46: 0 | U46: 0 | V46: 0 | W46: 245 | X46: 1133 | Y46: 1114 | Z46: 975 | AA46: 780 | AB46: 874 | AC46: 1739 | AD46: 1556 | AE46: 1667 | AF46: 1533 | AG46: 939 | AH46: 1139 | AI46: 1058 | AJ46: 1180
A47: MSHP partially displacing Oil Heat | C47: 3021581000 | D47: HOWARD ST | E47: LUNENBURG | F47: MA | G47: 01462-1001 | H47: 44470 | I47: =YEAR(H47) -> 2021 | J47: =MONTH(H47) -> 10 | K47: =I47&"_"&J47 -> 2021_10 | L47: Residential | M47: 910 | N47: 1052 | O47: 1374 | P47: 2508 | Q47: 1294 | R47: 1138 | S47: 964 | T47: 912 | U47: 972 | V47: 1008 | W47: 976 | X47: 1024 | Y47: 904 | Z47: 1228 | AA47: 1434 | AB47: 1760 | AC47: 1320 | AD47: 1164 | AE47: 926 | AF47: 744 | AG47: 604 | AH47: 612 | AI47: 870 | AJ47: 744
A48: MSHP partially displacing Oil Heat (weatherization unverified) | C48: 3041644000 | D48: KLONDIKE AVE | E48: FITCHBURG | F48: MA | G48: 01420-6241 | H48: 44473 | I48: =YEAR(H48) -> 2021 | J48: =MONTH(H48) -> 10 | K48: =I48&"_"&J48 -> 2021_10 | L48: Residential | M48: 200 | N48: 186 | O48: 718 | P48: 1584 | Q48: 1632 | R48: 1606 | S48: 476 | T48: 164 | U48: 506 | V48: 704 | W48: 382 | X48: 920 | Y48: 728 | Z48: 1092 | AA48: 1644 | AB48: 2322 | AC48: 2578 | AD48: 1850 | AE48: 1218 | AF48: 688 | AG48: 514 | AH48: 360 | AI48: 352 | AJ48: 300
A49: MSHP partially displacing Oil Heat | C49: 3062459002 | D49: CORTLAND AVE | E49: FITCHBURG | F49: MA | G49: 01420-1653 | H49: 44473 | I49: =YEAR(H49) -> 2021 | J49: =MONTH(H49) -> 10 | K49: =I49&"_"&J49 -> 2021_10 | L49: Residential | M49: 456 | N49: 466 | O49: 622 | P49: 667 | Q49: 500 | R49: 502 | S49: 514 | T49: 553 | U49: 898 | V49: 1097 | W49: 1553 | X49: 1685 | Y49: 1040 | Z49: 1021 | AA49: 1048 | AB49: 674 | AC49: 535 | AD49: 746 | AE49: 561 | AF49: 461 | AG49: 624 | AH49: 1098 | AI49: 1834 | AJ49: 927
A50: MSHP partially displacing Oil Heat (weatherization unverified) | C50: 3021632001 | D50: BOYLSTON ST | E50: FITCHBURG | F50: MA | G50: 01420-5725 | H50: 44474 | I50: =YEAR(H50) -> 2021 | J50: =MONTH(H50) -> 10 | K50: =I50&"_"&J50 -> 2021_10 | L50: Residential | M50: 0 | N50: 0 | O50: 0 | P50: 0 | Q50: 0 | R50: 0 | S50: 0 | T50: 0 | U50: 278 | V50: 826 | W50: 966 | X50: 898 | Y50: 842 | Z50: 1216 | AA50: 2362 | AB50: 1824 | AC50: 328 | AD50: 420 | AE50: 378 | AF50: 454 | AG50: 652 | AH50: 776 | AI50: 984 | AJ50: 698
A51: MSHP partially displacing Oil Heat (weatherization unverified) | C51: 3121314001 | D51: THE CLEARING ST | E51: LUNENBURG | F51: MA | G51: 01462-2510 | H51: 44480 | I51: =YEAR(H51) -> 2021 | J51: =MONTH(H51) -> 10 | K51: =I51&"_"&J51 -> 2021_10 | L51: Residential | M51: 45 | N51: 81 | O51: 202 | P51: 480 | Q51: 604 | R51: 472 | S51: 95 | T51: 16 | U51: 41 | V51: 41 | W51: 37 | X51: 36 | Y51: 28 | Z51: 402 | AA51: 1549 | AB51: 2173 | AC51: 2101 | AD51: 1121 | AE51: 741 | AF51: 680 | AG51: 382 | AH51: 620 | AI51: 745 | AJ51: 563
A52: MSHP partially displacing Oil Heat | C52: 3132480000 | D52: LEOMINSTER SHIRLEY RD | E52: LUNENBURG | F52: MA | G52: 01462-1661 | H52: 44480 | I52: =YEAR(H52) -> 2021 | J52: =MONTH(H52) -> 10 | K52: =I52&"_"&J52 -> 2021_10 | L52: Residential | M52: 667 | N52: 716 | O52: 981 | P52: 868 | Q52: 836 | R52: 844 | S52: 705 | T52: 768 | U52: 1071 | V52: 1191 | W52: 1227 | X52: 960 | Y52: 690 | Z52: 755 | AA52: 769 | AB52: 1016 | AC52: 854 | AD52: 854 | AE52: 778 | AF52: 897 | AG52: 840 | AH52: 1310 | AI52: 1291 | AJ52: 880
A53: MSHP partially displacing Oil Heat | C53: 3131705000 | D53: SANDY COVE RD | E53: LUNENBURG | F53: MA | G53: 01462-1112 | H53: 44481 | I53: =YEAR(H53) -> 2021 | J53: =MONTH(H53) -> 10 | K53: =I53&"_"&J53 -> 2021_10 | L53: Residential | M53: 490 | N53: 491 | O53: 797 | P53: 890 | Q53: 534 | R53: 485 | S53: 400 | T53: 482 | U53: 828 | V53: 747 | W53: 910 | X53: 1047 | Y53: 758 | Z53: 1130 | AA53: 1224 | AB53: 793 | AC53: 1338 | AD53: 1524 | AE53: 967 | AF53: 847 | AG53: 737 | AH53: 794 | AI53: 829 | AJ53: 889
A54: MSHP partially displacing Oil Heat | C54: 3131913002 | D54: WHITING ST | E54: LUNENBURG | F54: MA | G54: 01462-1451 | H54: 44487 | I54: =YEAR(H54) -> 2021 | J54: =MONTH(H54) -> 10 | K54: =I54&"_"&J54 -> 2021_10 | L54: Residential | M54: 624 | N54: 783 | O54: 790 | P54: 754 | Q54: 608 | R54: 737 | S54: 609 | T54: 641 | U54: 673 | V54: 682 | W54: 717 | X54: 722 | Y54: 766 | Z54: 862 | AA54: 1195 | AB54: 2311 | AC54: 1930 | AD54: 1792 | AE54: 1319 | AF54: 1195 | AG54: 972 | AH54: 1228 | AI54: 1068 | AJ54: 998
A55: MSHP partially displacing Oil Heat (weatherization unverified) | C55: 3092548000 | D55: PEARL ST | E55: FITCHBURG | F55: MA | G55: 01420-2655 | H55: 44494 | I55: =YEAR(H55) -> 2021 | J55: =MONTH(H55) -> 10 | K55: =I55&"_"&J55 -> 2021_10 | L55: Residential | M55: 291 | N55: 392 | O55: 699 | P55: 716 | Q55: 827 | R55: 726 | S55: 383 | T55: 388 | U55: 367 | V55: 401 | W55: 359 | X55: 366 | Y55: 302 | Z55: 350 | AA55: 563 | AB55: 841 | AC55: 816 | AD55: 593 | AE55: 436 | AF55: 393 | AG55: 519 | AH55: 730 | AI55: 781 | AJ55: 575
A56: 2021 Carry Over | C56: 3140559001 | D56: WALLACE HILL RD | E56: TOWNSEND | F56: MA | G56: 01469-1158 | H56: 44495 | I56: =YEAR(H56) -> 2021 | J56: =MONTH(H56) -> 10 | K56: =I56&"_"&J56 -> 2021_10 | L56: Residential | M56: 636 | N56: 747 | O56: 868 | P56: 839 | Q56: 817 | R56: 796 | S56: 667 | T56: 753 | U56: 929 | V56: 1001 | W56: 1075 | X56: 788 | Y56: 719 | Z56: 689 | AA56: 889 | AB56: 1138 | AC56: 880 | AD56: 809 | AE56: 778 | AF56: 804 | AG56: 785 | AH56: 1134 | AI56: 1009 | AJ56: 827
A57: MSHP partially displacing Oil Heat (weatherized) | C57: 3011962000 | D57: WILLIAMS RD | E57: FITCHBURG | F57: MA | G57: 01420-1825 | H57: 44506 | I57: =YEAR(H57) -> 2021 | J57: =MONTH(H57) -> 11 | K57: =I57&"_"&J57 -> 2021_11 | L57: Residential | M57: 1178 | N57: 1502 | O57: 2563 | P57: 2135 | Q57: 2173 | R57: 1120 | S57: 948 | T57: 958 | U57: 880 | V57: 493 | W57: 943 | X57: 928 | Y57: 905 | Z57: 1567 | AA57: 2076 | AB57: 2480 | AC57: 1956 | AD57: 1112 | AE57: 898 | AF57: 733 | AG57: 768 | AH57: 1341 | AI57: 1100 | AJ57: 827
...

Sheet Data Org ==>

Sheet Electric Calendarize
N3: Date | O3: =DATE(O5,O6,1) -> 43922 | P3: =DATE(P5,P6,1) -> 43952 | Q3: =DATE(Q5,Q6,1) -> 43983 | R3: =DATE(R5,R6,1) -> 44013 | S3: =DATE(S5,S6,1) -> 44044 | T3: =DATE(T5,T6,1) -> 44075 | U3: =DATE(U5,U6,1) -> 44105 | V3: =DATE(V5,V6,1) -> 44136 | ... BG3: =DATE(BG5,BG6,1) -> 45261
N4: Count | O4: 0 | P4: =+O4+1 -> 1 | Q4: =+P4+1 -> 2 | R4: =+Q4+1 -> 3 | S4: =+R4+1 -> 4 | T4: =+S4+1 -> 5 | U4: =+T4+1 -> 6 | V4: =+U4+1 -> 7 | W4: =+V4+1 -> 8 | ... BG4: =+BF4+1 -> 44
N5: Year | O5: 2020 | P5: =+O5 -> 2020 | Q5: =+P5 -> 2020 | R5: =+Q5 -> 2020 | S5: =+R5 -> 2020 | T5: =+S5 -> 2020 | U5: =+T5 -> 2020 | V5: =+U5 -> 2020 | W5: =+V5 -> 2020 | X5: 2021 | Y5: =+X5 -> 2021 | Z5: =+Y5 -> 2021 | AA5: =+Z5 -> 2021 | AB5: =+AA5 -> 2021 | AC5: =+AB5 -> 2021 | AD5: =+AC5 -> 2021 | AE5: =+AD5 -> 2021 | AF5: =+AE5 -> 2021 | ... AI5: =+AH5 -> 2021 | AJ5: =+X5+1 -> 2022 | AK5: =+Y5+1 -> 2022 | AL5: =+Z5+1 -> 2022 | AM5: =+AA5+1 -> 2022 | AN5: =+AB5+1 -> 2022 | AO5: =+AC5+1 -> 2022 | AP5: =+AD5+1 -> 2022 | AQ5: =+AE5+1 -> 2022 | ... BG5: =+AU5+1 -> 2023
N6: Month | O6: 4 | P6: =+O6+1 -> 5 | Q6: =+P6+1 -> 6 | R6: =+Q6+1 -> 7 | S6: =+R6+1 -> 8 | T6: =+S6+1 -> 9 | U6: =+T6+1 -> 10 | V6: =+U6+1 -> 11 | W6: =+V6+1 -> 12 | X6: 1 | Y6: =+X6+1 -> 2 | Z6: =+Y6+1 -> 3 | AA6: =+O6 -> 4 | AB6: =+P6 -> 5 | AC6: =+Q6 -> 6 | AD6: =+R6 -> 7 | AE6: =+S6 -> 8 | AF6: =+T6 -> 9 | AG6: =+U6 -> 10 | AH6: =+V6 -> 11 | ... BG6: =+AU6 -> 12
N7: ID | O7: =+O5&"_"&O6 -> 2020_4 | P7: =+P5&"_"&P6 -> 2020_5 | Q7: =+Q5&"_"&Q6 -> 2020_6 | R7: =+R5&"_"&R6 -> 2020_7 | S7: =+S5&"_"&S6 -> 2020_8 | T7: =+T5&"_"&T6 -> 2020_9 | U7: =+U5&"_"&U6 -> 2020_10 | V7: =+V5&"_"&V6 -> 2020_11 | ... BG7: =+BG5&"_"&BG6 -> 2023_12
N8: Heating Month | O8: =IF(OR(O6<5,O6>10),1,0) -> 1 | P8: =IF(OR(P6<5,P6>10),1,0) -> 0 | Q8: =IF(OR(Q6<5,Q6>10),1,0) -> 0 | R8: =IF(OR(R6<5,R6>10),1,0) -> 0 | S8: =IF(OR(S6<5,S6>10),1,0) -> 0 | T8: =IF(OR(T6<5,T6>10),1,0) -> 0 | U8: =IF(OR(U6<5,U6>10),1,0) -> 0 | V8: =IF(OR(V6<5,V6>10),1,0) -> 1 | ... BG8: =IF(OR(BG6<5,BG6>10),1,0) -> 1
A10: Measure | B10: Customer Name | C10: Account Number | D10: Service Address | E10: Service City | F10: Service State | G10: Service Zip Code | H10: Intall Date | I10: Year | J10: Month | K10: ID | L10: Count | M10: IS Date | N10: Rate Class | O10: =O8&"_"&O5&"_"&O6 -> 1_2020_4 | P10: =P8&"_"&P5&"_"&P6 -> 0_2020_5 | Q10: =Q8&"_"&Q5&"_"&Q6 -> 0_2020_6 | R10: =R8&"_"&R5&"_"&R6 -> 0_2020_7 | S10: =S8&"_"&S5&"_"&S6 -> 0_2020_8 | T10: =T8&"_"&T5&"_"&T6 -> 0_2020_9 | U10: =U8&"_"&U5&"_"&U6 -> 0_2020_10 | V10: =V8&"_"&V5&"_"&V6 -> 1_2020_11 | ... BG10: =BG8&"_"&BG5&"_"&BG6 -> 1_2023_12 | BJ10: Rate Class | BK10: =+O10 -> 1_2020_4 | BL10: =+P10 -> 0_2020_5 | BM10: =+Q10 -> 0_2020_6 | BN10: =+R10 -> 0_2020_7 | BO10: =+S10 -> 0_2020_8 | BP10: =+T10 -> 0_2020_9 | BQ10: =+U10 -> 0_2020_10 | BR10: =+V10 -> 1_2020_11 | ... DC10: =+BG10 -> 1_2023_12 | DF10: Rate Class | DG10: =+BK10 -> 1_2020_4 | DH10: =+BL10 -> 0_2020_5 | DI10: =+BM10 -> 0_2020_6 | DJ10: =+BN10 -> 0_2020_7 | DK10: =+BO10 -> 0_2020_8 | DL10: =+BP10 -> 0_2020_9 | DM10: =+BQ10 -> 0_2020_10 | DN10: =+BR10 -> 1_2020_11 | ... EY10: =+DC10 -> 1_2023_12 | FB10: Rate Class | FC10: =+DG10 -> 1_2020_4 | FD10: =+DH10 -> 0_2020_5 | FE10: =+DI10 -> 0_2020_6 | FF10: =+DJ10 -> 0_2020_7 | FG10: =+DK10 -> 0_2020_8 | FH10: =+DL10 -> 0_2020_9 | FI10: =+DM10 -> 0_2020_10 | FJ10: =+DN10 -> 1_2020_11 | ... GU10: =+EY10 -> 1_2023_12
A11: MSHP partially displacing Oil Heat (weatherization unverified) | C11: 3021214000 | D11: PRATT ST | E11: FITCHBURG | F11: MA | G11: 01420-4188 | H11: 44281 | I11: =YEAR(H11) -> 2021 | J11: =MONTH(H11) -> 3 | K11: =I11&"_"&J11 -> 2021_3 | L11: =MAX(0,VLOOKUP($K11,lookups!$A$1:$B$45,2,0)-12) -> 0 | M11: =DATE(I11,J11,1) -> 44256 | N11: Residential | O11: =IF(OR($L11>O$4,O$4>$L11+23),"",OFFSET(Electric!$L2,0,-'Electric Calendarize'!$L11+'Electric Calendarize'!O$4+1)) -> 1790 | P11: =IF(OR($L11>P$4,P$4>$L11+23),"",OFFSET(Electric!$L2,0,-'Electric Calendarize'!$L11+'Electric Calendarize'!P$4+1)) -> 1461 | Q11: =IF(OR($L11>Q$4,Q$4>$L11+23),"",OFFSET(Electric!$L2,0,-'Electric Calendarize'!$L11+'Electric Calendarize'!Q$4+1)) -> 999 | R11: =IF(OR($L11>R$4,R$4>$L11+23),"",OFFSET(Electric!$L2,0,-'Electric Calendarize'!$L11+'Electric Calendarize'!R$4+1)) -> 458 | S11: =IF(OR($L11>S$4,S$4>$L11+23),"",OFFSET(Electric!$L2,0,-'Electric Calendarize'!$L11+'Electric Calendarize'!S$4+1)) -> 284 | T11: =IF(OR($L11>T$4,T$4>$L11+23),"",OFFSET(Electric!$L2,0,-'Electric Calendarize'!$L11+'Electric Calendarize'!T$4+1)) -> 444 | U11: =IF(OR($L11>U$4,U$4>$L11+23),"",OFFSET(Electric!$L2,0,-'Electric Calendarize'!$L11+'Electric Calendarize'!U$4+1)) -> 623 | V11: =IF(OR($L11>V$4,V$4>$L11+23),"",OFFSET(Electric!$L2,0,-'Electric Calendarize'!$L11+'Electric Calendarize'!V$4+1)) -> 373 | ... BG11: =IF(OR($L11>BG$4,BG$4>$L11+23),"",OFFSET(Electric!$L2,0,-'Electric Calendarize'!$L11+'Electric Calendarize'!BG$4+1)) | BJ11: Residential | BK11: =+O$8 -> 1 | BL11: =+P$8 -> 0 | BM11: =+Q$8 -> 0 | BN11: =+R$8 -> 0 | BO11: =+S$8 -> 0 | BP11: =+T$8 -> 0 | BQ11: =+U$8 -> 0 | BR11: =+V$8 -> 1 | ... DC11: =+BG$8 -> 1 | DF11: Residential | DG11: =$K11 -> 2021_3 | DH11: =$K11 -> 2021_3 | DI11: =$K11 -> 2021_3 | DJ11: =$K11 -> 2021_3 | DK11: =$K11 -> 2021_3 | DL11: =$K11 -> 2021_3 | DM11: =$K11 -> 2021_3 | DN11: =$K11 -> 2021_3 | ... EY11: =$K11 -> 2021_3 | FB11: Residential | FC11: =IF($M11<=O$3,1,0) -> 0 | FD11: =IF($M11<=P$3,1,0) -> 0 | FE11: =IF($M11<=Q$3,1,0) -> 0 | FF11: =IF($M11<=R$3,1,0) -> 0 | FG11: =IF($M11<=S$3,1,0) -> 0 | FH11: =IF($M11<=T$3,1,0) -> 0 | FI11: =IF($M11<=U$3,1,0) -> 0 | FJ11: =IF($M11<=V$3,1,0) -> 0 | ... GU11: =IF($M11<=BG$3,1,0) -> 1
A12: DMSHP, SEER 18.0 HSPF 10, Disp Electric Heat E19A2a278 | C12: 3120402002 | D12: HIGHLAND ST | E12: LUNENBURG | F12: MA | G12: 01462-1416 | H12: 44299 | I12: =YEAR(H12) -> 2021 | J12: =MONTH(H12) -> 4 | K12: =I12&"_"&J12 -> 2021_4 | L12: =MAX(0,VLOOKUP($K12,lookups!$A$1:$B$45,2,0)-12) -> 0 | M12: =DATE(I12,J12,1) -> 44287 | N12: Residential | O12: =IF(OR($L12>O$4,O$4>$L12+23),"",OFFSET(Electric!$L3,0,-'Electric Calendarize'!$L12+'Electric Calendarize'!O$4+1)) -> 882 | P12: =IF(OR($L12>P$4,P$4>$L12+23),"",OFFSET(Electric!$L3,0,-'Electric Calendarize'!$L12+'Electric Calendarize'!P$4+1)) -> 767 | Q12: =IF(OR($L12>Q$4,Q$4>$L12+23),"",OFFSET(Electric!$L3,0,-'Electric Calendarize'!$L12+'Electric Calendarize'!Q$4+1)) -> 856 | R12: =IF(OR($L12>R$4,R$4>$L12+23),"",OFFSET(Electric!$L3,0,-'Electric Calendarize'!$L12+'Electric Calendarize'!R$4+1)) -> 879 | S12: =IF(OR($L12>S$4,S$4>$L12+23),"",OFFSET(Electric!$L3,0,-'Electric Calendarize'!$L12+'Electric Calendarize'!S$4+1)) -> 785 | T12: =IF(OR($L12>T$4,T$4>$L12+23),"",OFFSET(Electric!$L3,0,-'Electric Calendarize'!$L12+'Electric Calendarize'!T$4+1)) -> 752 | U12: =IF(OR($L12>U$4,U$4>$L12+23),"",OFFSET(Electric!$L3,0,-'Electric Calendarize'!$L12+'Electric Calendarize'!U$4+1)) -> 1118 | V12: =IF(OR($L12>V$4,V$4>$L12+23),"",OFFSET(Electric!$L3,0,-'Electric Calendarize'!$L12+'Electric Calendarize'!V$4+1)) -> 1117 | ... BG12: =IF(OR($L12>BG$4,BG$4>$L12+23),"",OFFSET(Electric!$L3,0,-'Electric Calendarize'!$L12+'Electric Calendarize'!BG$4+1)) | BJ12: Residential | BK12: =+O$8 -> 1 | BL12: =+P$8 -> 0 | BM12: =+Q$8 -> 0 | BN12: =+R$8 -> 0 | BO12: =+S$8 -> 0 | BP12: =+T$8 -> 0 | BQ12: =+U$8 -> 0 | BR12: =+V$8 -> 1 | ... DC12: =+BG$8 -> 1 | DF12: Residential | DG12: =$K12 -> 2021_4 | DH12: =$K12 -> 2021_4 | DI12: =$K12 -> 2021_4 | DJ12: =$K12 -> 2021_4 | DK12: =$K12 -> 2021_4 | DL12: =$K12 -> 2021_4 | DM12: =$K12 -> 2021_4 | DN12: =$K12 -> 2021_4 | ... EY12: =$K12 -> 2021_4 | FB12: Residential | FC12: =IF($M12<=O$3,1,0) -> 0 | FD12: =IF($M12<=P$3,1,0) -> 0 | FE12: =IF($M12<=Q$3,1,0) -> 0 | FF12: =IF($M12<=R$3,1,0) -> 0 | FG12: =IF($M12<=S$3,1,0) -> 0 | FH12: =IF($M12<=T$3,1,0) -> 0 | FI12: =IF($M12<=U$3,1,0) -> 0 | FJ12: =IF($M12<=V$3,1,0) -> 0 | ... GU12: =IF($M12<=BG$3,1,0) -> 1
A13: MSHP partially displacing Oil Heat | C13: 3150085004 | D13: ROLLING ACRES RD | E13: LUNENBURG | F13: MA | G13: 01462-1548 | H13: 44301 | I13: =YEAR(H13) -> 2021 | J13: =MONTH(H13) -> 4 | K13: =I13&"_"&J13 -> 2021_4 | L13: =MAX(0,VLOOKUP($K13,lookups!$A$1:$B$45,2,0)-12) -> 0 | M13: =DATE(I13,J13,1) -> 44287 | N13: Residential | O13: =IF(OR($L13>O$4,O$4>$L13+23),"",OFFSET(Electric!$L4,0,-'Electric Calendarize'!$L13+'Electric Calendarize'!O$4+1)) -> 1832 | P13: =IF(OR($L13>P$4,P$4>$L13+23),"",OFFSET(Electric!$L4,0,-'Electric Calendarize'!$L13+'Electric Calendarize'!P$4+1)) -> 932 | Q13: =IF(OR($L13>Q$4,Q$4>$L13+23),"",OFFSET(Electric!$L4,0,-'Electric Calendarize'!$L13+'Electric Calendarize'!Q$4+1)) -> 1288 | R13: =IF(OR($L13>R$4,R$4>$L13+23),"",OFFSET(Electric!$L4,0,-'Electric Calendarize'!$L13+'Electric Calendarize'!R$4+1)) -> 1532 | S13: =IF(OR($L13>S$4,S$4>$L13+23),"",OFFSET(Electric!$L4,0,-'Electric Calendarize'!$L13+'Electric Calendarize'!S$4+1)) -> 1880 | T13: =IF(OR($L13>T$4,T$4>$L13+23),"",OFFSET(Electric!$L4,0,-'Electric Calendarize'!$L13+'Electric Calendarize'!T$4+1)) -> 1416 | U13: =IF(OR($L13>U$4,U$4>$L13+23),"",OFFSET(Electric!$L4,0,-'Electric Calendarize'!$L13+'Electric Calendarize'!U$4+1)) -> 1556 | V13: =IF(OR($L13>V$4,V$4>$L13+23),"",OFFSET(Electric!$L4,0,-'Electric Calendarize'!$L13+'Electric Calendarize'!V$4+1)) -> 2006 | ... BG13: =IF(OR($L13>BG$4,BG$4>$L13+23),"",OFFSET(Electric!$L4,0,-'Electric Calendarize'!$L13+'Electric Calendarize'!BG$4+1)) | BJ13: Residential | BK13: =+O$8 -> 1 | BL13: =+P$8 -> 0 | BM13: =+Q$8 -> 0 | BN13: =+R$8 -> 0 | BO13: =+S$8 -> 0 | BP13: =+T$8 -> 0 | BQ13: =+U$8 -> 0 | BR13: =+V$8 -> 1 | ... DC13: =+BG$8 -> 1 | DF13: Residential | DG13: =$K13 -> 2021_4 | DH13: =$K13 -> 2021_4 | DI13: =$K13 -> 2021_4 | DJ13: =$K13 -> 2021_4 | DK13: =$K13 -> 2021_4 | DL13: =$K13 -> 2021_4 | DM13: =$K13 -> 2021_4 | DN13: =$K13 -> 2021_4 | ... EY13: =$K13 -> 2021_4 | FB13: Residential | FC13: =IF($M13<=O$3,1,0) -> 0 | FD13: =IF($M13<=P$3,1,0) -> 0 | FE13: =IF($M13<=Q$3,1,0) -> 0 | FF13: =IF($M13<=R$3,1,0) -> 0 | FG13: =IF($M13<=S$3,1,0) -> 0 | FH13: =IF($M13<=T$3,1,0) -> 0 | FI13: =IF($M13<=U$3,1,0) -> 0 | FJ13: =IF($M13<=V$3,1,0) -> 0 | ... GU13: =IF($M13<=BG$3,1,0) -> 1
A14: MSHP partially displacing Oil Heat | C14: 3151746001 | D14: KRISTOPHER LN | E14: TOWNSEND | F14: MA | G14: 01474-1056 | H14: 44305 | I14: =YEAR(H14) -> 2021 | J14: =MONTH(H14) -> 4 | K14: =I14&"_"&J14 -> 2021_4 | L14: =MAX(0,VLOOKUP($K14,lookups!$A$1:$B$45,2,0)-12) -> 0 | M14: =DATE(I14,J14,1) -> 44287 | N14: Residential | O14: =IF(OR($L14>O$4,O$4>$L14+23),"",OFFSET(Electric!$L5,0,-'Electric Calendarize'!$L14+'Electric Calendarize'!O$4+1)) -> 835 | P14: =IF(OR($L14>P$4,P$4>$L14+23),"",OFFSET(Electric!$L5,0,-'Electric Calendarize'!$L14+'Electric Calendarize'!P$4+1)) -> 831 | Q14: =IF(OR($L14>Q$4,Q$4>$L14+23),"",OFFSET(Electric!$L5,0,-'Electric Calendarize'!$L14+'Electric Calendarize'!Q$4+1)) -> 1084 | R14: =IF(OR($L14>R$4,R$4>$L14+23),"",OFFSET(Electric!$L5,0,-'Electric Calendarize'!$L14+'Electric Calendarize'!R$4+1)) -> 1364 | S14: =IF(OR($L14>S$4,S$4>$L14+23),"",OFFSET(Electric!$L5,0,-'Electric Calendarize'!$L14+'Electric Calendarize'!S$4+1)) -> 1097 | T14: =IF(OR($L14>T$4,T$4>$L14+23),"",OFFSET(Electric!$L5,0,-'Electric Calendarize'!$L14+'Electric Calendarize'!T$4+1)) -> 876 | U14: =IF(OR($L14>U$4,U$4>$L14+23),"",OFFSET(Electric!$L5,0,-'Electric Calendarize'!$L14+'Electric Calendarize'!U$4+1)) -> 791 | V14: =IF(OR($L14>V$4,V$4>$L14+23),"",OFFSET(Electric!$L5,0,-'Electric Calendarize'!$L14+'Electric Calendarize'!V$4+1)) -> 714 | ... BG14: =IF(OR($L14>BG$4,BG$4>$L14+23),"",OFFSET(Electric!$L5,0,-'Electric Calendarize'!$L14+'Electric Calendarize'!BG$4+1)) | BJ14: Residential | BK14: =+O$8 -> 1 | BL14: =+P$8 -> 0 | BM14: =+Q$8 -> 0 | BN14: =+R$8 -> 0 | BO14: =+S$8 -> 0 | BP14: =+T$8 -> 0 | BQ14: =+U$8 -> 0 | BR14: =+V$8 -> 1 | ... DC14: =+BG$8 -> 1 | DF14: Residential | DG14: =$K14 -> 2021_4 | DH14: =$K14 -> 2021_4 | DI14: =$K14 -> 2021_4 | DJ14: =$K14 -> 2021_4 | DK14: =$K14 -> 2021_4 | DL14: =$K14 -> 2021_4 | DM14: =$K14 -> 2021_4 | DN14: =$K14 -> 2021_4 | ... EY14: =$K14 -> 2021_4 | FB14: Residential | FC14: =IF($M14<=O$3,1,0) -> 0 | FD14: =IF($M14<=P$3,1,0) -> 0 | FE14: =IF($M14<=Q$3,1,0) -> 0 | FF14: =IF($M14<=R$3,1,0) -> 0 | FG14: =IF($M14<=S$3,1,0) -> 0 | FH14: =IF($M14<=T$3,1,0) -> 0 | FI14: =IF($M14<=U$3,1,0) -> 0 | FJ14: =IF($M14<=V$3,1,0) -> 0 | ... GU14: =IF($M14<=BG$3,1,0) -> 1
A15: MSHP partially displacing Oil Heat | C15: 3020110000 | D15: MADISON ST | E15: FITCHBURG | F15: MA | G15: 01420-5022 | H15: 44308 | I15: =YEAR(H15) -> 2021 | J15: =MONTH(H15) -> 4 | K15: =I15&"_"&J15 -> 2021_4 | L15: =MAX(0,VLOOKUP($K15,lookups!$A$1:$B$45,2,0)-12) -> 0 | M15: =DATE(I15,J15,1) -> 44287 | N15: Residential | O15: =IF(OR($L15>O$4,O$4>$L15+23),"",OFFSET(Electric!$L6,0,-'Electric Calendarize'!$L15+'Electric Calendarize'!O$4+1)) -> 846 | P15: =IF(OR($L15>P$4,P$4>$L15+23),"",OFFSET(Electric!$L6,0,-'Electric Calendarize'!$L15+'Electric Calendarize'!P$4+1)) -> 786 | Q15: =IF(OR($L15>Q$4,Q$4>$L15+23),"",OFFSET(Electric!$L6,0,-'Electric Calendarize'!$L15+'Electric Calendarize'!Q$4+1)) -> 606 | R15: =IF(OR($L15>R$4,R$4>$L15+23),"",OFFSET(Electric!$L6,0,-'Electric Calendarize'!$L15+'Electric Calendarize'!R$4+1)) -> 832 | S15: =IF(OR($L15>S$4,S$4>$L15+23),"",OFFSET(Electric!$L6,0,-'Electric Calendarize'!$L15+'Electric Calendarize'!S$4+1)) -> 108 | T15: =IF(OR($L15>T$4,T$4>$L15+23),"",OFFSET(Electric!$L6,0,-'Electric Calendarize'!$L15+'Electric Calendarize'!T$4+1)) -> 1626 | U15: =IF(OR($L15>U$4,U$4>$L15+23),"",OFFSET(Electric!$L6,0,-'Electric Calendarize'!$L15+'Electric Calendarize'!U$4+1)) -> 932 | V15: =IF(OR($L15>V$4,V$4>$L15+23),"",OFFSET(Electric!$L6,0,-'Electric Calendarize'!$L15+'Electric Calendarize'!V$4+1)) -> 998 | ... BG15: =IF(OR($L15>BG$4,BG$4>$L15+23),"",OFFSET(Electric!$L6,0,-'Electric Calendarize'!$L15+'Electric Calendarize'!BG$4+1)) | BJ15: Residential | BK15: =+O$8 -> 1 | BL15: =+P$8 -> 0 | BM15: =+Q$8 -> 0 | BN15: =+R$8 -> 0 | BO15: =+S$8 -> 0 | BP15: =+T$8 -> 0 | BQ15: =+U$8 -> 0 | BR15: =+V$8 -> 1 | ... DC15: =+BG$8 -> 1 | DF15: Residential | DG15: =$K15 -> 2021_4 | DH15: =$K15 -> 2021_4 | DI15: =$K15 -> 2021_4 | DJ15: =$K15 -> 2021_4 | DK15: =$K15 -> 2021_4 | DL15: =$K15 -> 2021_4 | DM15: =$K15 -> 2021_4 | DN15: =$K15 -> 2021_4 | ... EY15: =$K15 -> 2021_4 | FB15: Residential | FC15: =IF($M15<=O$3,1,0) -> 0 | FD15: =IF($M15<=P$3,1,0) -> 0 | FE15: =IF($M15<=Q$3,1,0) -> 0 | FF15: =IF($M15<=R$3,1,0) -> 0 | FG15: =IF($M15<=S$3,1,0) -> 0 | FH15: =IF($M15<=T$3,1,0) -> 0 | FI15: =IF($M15<=U$3,1,0) -> 0 | FJ15: =IF($M15<=V$3,1,0) -> 0 | ... GU15: =IF($M15<=BG$3,1,0) -> 1
A16: Central Heat Pump partially displacing Oil Heat | C16: 3132100001 | D16: LEOMINSTER RD | E16: LUNENBURG | F16: MA | G16: 01462-2009 | H16: 44313 | I16: =YEAR(H16) -> 2021 | J16: =MONTH(H16) -> 4 | K16: =I16&"_"&J16 -> 2021_4 | L16: =MAX(0,VLOOKUP($K16,lookups!$A$1:$B$45,2,0)-12) -> 0 | M16: =DATE(I16,J16,1) -> 44287 | N16: Residential | O16: =IF(OR($L16>O$4,O$4>$L16+23),"",OFFSET(Electric!$L7,0,-'Electric Calendarize'!$L16+'Electric Calendarize'!O$4+1)) -> 973 | P16: =IF(OR($L16>P$4,P$4>$L16+23),"",OFFSET(Electric!$L7,0,-'Electric Calendarize'!$L16+'Electric Calendarize'!P$4+1)) -> 889 | Q16: =IF(OR($L16>Q$4,Q$4>$L16+23),"",OFFSET(Electric!$L7,0,-'Electric Calendarize'!$L16+'Electric Calendarize'!Q$4+1)) -> 1359 | R16: =IF(OR($L16>R$4,R$4>$L16+23),"",OFFSET(Electric!$L7,0,-'Electric Calendarize'!$L16+'Electric Calendarize'!R$4+1)) -> 1645 | S16: =IF(OR($L16>S$4,S$4>$L16+23),"",OFFSET(Electric!$L7,0,-'Electric Calendarize'!$L16+'Electric Calendarize'!S$4+1)) -> 1741 | T16: =IF(OR($L16>T$4,T$4>$L16+23),"",OFFSET(Electric!$L7,0,-'Electric Calendarize'!$L16+'Electric Calendarize'!T$4+1)) -> 993 | U16: =IF(OR($L16>U$4,U$4>$L16+23),"",OFFSET(Electric!$L7,0,-'Electric Calendarize'!$L16+'Electric Calendarize'!U$4+1)) -> 661 | V16: =IF(OR($L16>V$4,V$4>$L16+23),"",OFFSET(Electric!$L7,0,-'Electric Calendarize'!$L16+'Electric Calendarize'!V$4+1)) -> 993 | ... BG16: =IF(OR($L16>BG$4,BG$4>$L16+23),"",OFFSET(Electric!$L7,0,-'Electric Calendarize'!$L16+'Electric Calendarize'!BG$4+1)) | BJ16: Residential | BK16: =+O$8 -> 1 | BL16: =+P$8 -> 0 | BM16: =+Q$8 -> 0 | BN16: =+R$8 -> 0 | BO16: =+S$8 -> 0 | BP16: =+T$8 -> 0 | BQ16: =+U$8 -> 0 | BR16: =+V$8 -> 1 | ... DC16: =+BG$8 -> 1 | DF16: Residential | DG16: =$K16 -> 2021_4 | DH16: =$K16 -> 2021_4 | DI16: =$K16 -> 2021_4 | DJ16: =$K16 -> 2021_4 | DK16: =$K16 -> 2021_4 | DL16: =$K16 -> 2021_4 | DM16: =$K16 -> 2021_4 | DN16: =$K16 -> 2021_4 | ... EY16: =$K16 -> 2021_4 | FB16: Residential | FC16: =IF($M16<=O$3,1,0) -> 0 | FD16: =IF($M16<=P$3,1,0) -> 0 | FE16: =IF($M16<=Q$3,1,0) -> 0 | FF16: =IF($M16<=R$3,1,0) -> 0 | FG16: =IF($M16<=S$3,1,0) -> 0 | FH16: =IF($M16<=T$3,1,0) -> 0 | FI16: =IF($M16<=U$3,1,0) -> 0 | FJ16: =IF($M16<=V$3,1,0) -> 0 | ... GU16: =IF($M16<=BG$3,1,0) -> 1
A17: MSHP partially displacing Oil Heat (weatherization unverified) | C17: 3120915001 | D17: MASSACHUSETTS AVE | E17: LUNENBURG | F17: MA | G17: 01462-1354 | H17: 44315 | I17: =YEAR(H17) -> 2021 | J17: =MONTH(H17) -> 4 | K17: =I17&"_"&J17 -> 2021_4 | L17: =MAX(0,VLOOKUP($K17,lookups!$A$1:$B$45,2,0)-12) -> 0 | M17: =DATE(I17,J17,1) -> 44287 | N17: Residential | O17: =IF(OR($L17>O$4,O$4>$L17+23),"",OFFSET(Electric!$L8,0,-'Electric Calendarize'!$L17+'Electric Calendarize'!O$4+1)) -> 806 | P17: =IF(OR($L17>P$4,P$4>$L17+23),"",OFFSET(Electric!$L8,0,-'Electric Calendarize'!$L17+'Electric Calendarize'!P$4+1)) -> 707 | Q17: =IF(OR($L17>Q$4,Q$4>$L17+23),"",OFFSET(Electric!$L8,0,-'Electric Calendarize'!$L17+'Electric Calendarize'!Q$4+1)) -> 1222 | R17: =IF(OR($L17>R$4,R$4>$L17+23),"",OFFSET(Electric!$L8,0,-'Electric Calendarize'!$L17+'Electric Calendarize'!R$4+1)) -> 1359 | S17: =IF(OR($L17>S$4,S$4>$L17+23),"",OFFSET(Electric!$L8,0,-'Electric Calendarize'!$L17+'Electric Calendarize'!S$4+1)) -> 2653 | T17: =IF(OR($L17>T$4,T$4>$L17+23),"",OFFSET(Electric!$L8,0,-'Electric Calendarize'!$L17+'Electric Calendarize'!T$4+1)) -> 1469 | U17: =IF(OR($L17>U$4,U$4>$L17+23),"",OFFSET(Electric!$L8,0,-'Electric Calendarize'!$L17+'Electric Calendarize'!U$4+1)) -> 954 | V17: =IF(OR($L17>V$4,V$4>$L17+23),"",OFFSET(Electric!$L8,0,-'Electric Calendarize'!$L17+'Electric Calendarize'!V$4+1)) -> 1127 | ... BG17: =IF(OR($L17>BG$4,BG$4>$L17+23),"",OFFSET(Electric!$L8,0,-'Electric Calendarize'!$L17+'Electric Calendarize'!BG$4+1)) | BJ17: Residential | BK17: =+O$8 -> 1 | BL17: =+P$8 -> 0 | BM17: =+Q$8 -> 0 | BN17: =+R$8 -> 0 | BO17: =+S$8 -> 0 | BP17: =+T$8 -> 0 | BQ17: =+U$8 -> 0 | BR17: =+V$8 -> 1 | ... DC17: =+BG$8 -> 1 | DF17: Residential | DG17: =$K17 -> 2021_4 | DH17: =$K17 -> 2021_4 | DI17: =$K17 -> 2021_4 | DJ17: =$K17 -> 2021_4 | DK17: =$K17 -> 2021_4 | DL17: =$K17 -> 2021_4 | DM17: =$K17 -> 2021_4 | DN17: =$K17 -> 2021_4 | ... EY17: =$K17 -> 2021_4 | FB17: Residential | FC17: =IF($M17<=O$3,1,0) -> 0 | FD17: =IF($M17<=P$3,1,0) -> 0 | FE17: =IF($M17<=Q$3,1,0) -> 0 | FF17: =IF($M17<=R$3,1,0) -> 0 | FG17: =IF($M17<=S$3,1,0) -> 0 | FH17: =IF($M17<=T$3,1,0) -> 0 | FI17: =IF($M17<=U$3,1,0) -> 0 | FJ17: =IF($M17<=V$3,1,0) -> 0 | ... GU17: =IF($M17<=BG$3,1,0) -> 1
A18: MSHP partially displacing Oil Heat (weatherization unverified) | C18: 3141643000 | D18: TYLER RD | E18: TOWNSEND | F18: MA | G18: 01469-1203 | H18: 44330 | I18: =YEAR(H18) -> 2021 | J18: =MONTH(H18) -> 5 | K18: =I18&"_"&J18 -> 2021_5 | L18: =MAX(0,VLOOKUP($K18,lookups!$A$1:$B$45,2,0)-12) -> 1 | M18: =DATE(I18,J18,1) -> 44317 | N18: Residential | O18: =IF(OR($L18>O$4,O$4>$L18+23),"",OFFSET(Electric!$L9,0,-'Electric Calendarize'!$L18+'Electric Calendarize'!O$4+1)) | P18: =IF(OR($L18>P$4,P$4>$L18+23),"",OFFSET(Electric!$L9,0,-'Electric Calendarize'!$L18+'Electric Calendarize'!P$4+1)) -> 572 | Q18: =IF(OR($L18>Q$4,Q$4>$L18+23),"",OFFSET(Electric!$L9,0,-'Electric Calendarize'!$L18+'Electric Calendarize'!Q$4+1)) -> 937 | R18: =IF(OR($L18>R$4,R$4>$L18+23),"",OFFSET(Electric!$L9,0,-'Electric Calendarize'!$L18+'Electric Calendarize'!R$4+1)) -> 1132 | S18: =IF(OR($L18>S$4,S$4>$L18+23),"",OFFSET(Electric!$L9,0,-'Electric Calendarize'!$L18+'Electric Calendarize'!S$4+1)) -> 1077 | T18: =IF(OR($L18>T$4,T$4>$L18+23),"",OFFSET(Electric!$L9,0,-'Electric Calendarize'!$L18+'Electric Calendarize'!T$4+1)) -> 751 | U18: =IF(OR($L18>U$4,U$4>$L18+23),"",OFFSET(Electric!$L9,0,-'Electric Calendarize'!$L18+'Electric Calendarize'!U$4+1)) -> 630 | V18: =IF(OR($L18>V$4,V$4>$L18+23),"",OFFSET(Electric!$L9,0,-'Electric Calendarize'!$L18+'Electric Calendarize'!V$4+1)) -> 526 | ... BG18: =IF(OR($L18>BG$4,BG$4>$L18+23),"",OFFSET(Electric!$L9,0,-'Electric Calendarize'!$L18+'Electric Calendarize'!BG$4+1)) | BJ18: Residential | BK18: =+O$8 -> 1 | BL18: =+P$8 -> 0 | BM18: =+Q$8 -> 0 | BN18: =+R$8 -> 0 | BO18: =+S$8 -> 0 | BP18: =+T$8 -> 0 | BQ18: =+U$8 -> 0 | BR18: =+V$8 -> 1 | ... DC18: =+BG$8 -> 1 | DF18: Residential | DG18: =$K18 -> 2021_5 | DH18: =$K18 -> 2021_5 | DI18: =$K18 -> 2021_5 | DJ18: =$K18 -> 2021_5 | DK18: =$K18 -> 2021_5 | DL18: =$K18 -> 2021_5 | DM18: =$K18 -> 2021_5 | DN18: =$K18 -> 2021_5 | ... EY18: =$K18 -> 2021_5 | FB18: Residential | FC18: =IF($M18<=O$3,1,0) -> 0 | FD18: =IF($M18<=P$3,1,0) -> 0 | FE18: =IF($M18<=Q$3,1,0) -> 0 | FF18: =IF($M18<=R$3,1,0) -> 0 | FG18: =IF($M18<=S$3,1,0) -> 0 | FH18: =IF($M18<=T$3,1,0) -> 0 | FI18: =IF($M18<=U$3,1,0) -> 0 | FJ18: =IF($M18<=V$3,1,0) -> 0 | ... GU18: =IF($M18<=BG$3,1,0) -> 1
A19: Central Heat Pump partially displacing Oil Heat | C19: 3121672000 | D19: NATICK ST | E19: LUNENBURG | F19: MA | G19: 01462-2405 | H19: 44342 | I19: =YEAR(H19) -> 2021 | J19: =MONTH(H19) -> 5 | K19: =I19&"_"&J19 -> 2021_5 | L19: =MAX(0,VLOOKUP($K19,lookups!$A$1:$B$45,2,0)-12) -> 1 | M19: =DATE(I19,J19,1) -> 44317 | N19: Residential | O19: =IF(OR($L19>O$4,O$4>$L19+23),"",OFFSET(Electric!$L10,0,-'Electric Calendarize'!$L19+'Electric Calendarize'!O$4+1)) | P19: =IF(OR($L19>P$4,P$4>$L19+23),"",OFFSET(Electric!$L10,0,-'Electric Calendarize'!$L19+'Electric Calendarize'!P$4+1)) -> 950 | Q19: =IF(OR($L19>Q$4,Q$4>$L19+23),"",OFFSET(Electric!$L10,0,-'Electric Calendarize'!$L19+'Electric Calendarize'!Q$4+1)) -> 1124 | R19: =IF(OR($L19>R$4,R$4>$L19+23),"",OFFSET(Electric!$L10,0,-'Electric Calendarize'!$L19+'Electric Calendarize'!R$4+1)) -> 1224 | S19: =IF(OR($L19>S$4,S$4>$L19+23),"",OFFSET(Electric!$L10,0,-'Electric Calendarize'!$L19+'Electric Calendarize'!S$4+1)) -> 1390 | T19: =IF(OR($L19>T$4,T$4>$L19+23),"",OFFSET(Electric!$L10,0,-'Electric Calendarize'!$L19+'Electric Calendarize'!T$4+1)) -> 1025 | U19: =IF(OR($L19>U$4,U$4>$L19+23),"",OFFSET(Electric!$L10,0,-'Electric Calendarize'!$L19+'Electric Calendarize'!U$4+1)) -> 920 | V19: =IF(OR($L19>V$4,V$4>$L19+23),"",OFFSET(Electric!$L10,0,-'Electric Calendarize'!$L19+'Electric Calendarize'!V$4+1)) -> 1416 | ... BG19: =IF(OR($L19>BG$4,BG$4>$L19+23),"",OFFSET(Electric!$L10,0,-'Electric Calendarize'!$L19+'Electric Calendarize'!BG$4+1)) | BJ19: Residential | BK19: =+O$8 -> 1 | BL19: =+P$8 -> 0 | BM19: =+Q$8 -> 0 | BN19: =+R$8 -> 0 | BO19: =+S$8 -> 0 | BP19: =+T$8 -> 0 | BQ19: =+U$8 -> 0 | BR19: =+V$8 -> 1 | ... DC19: =+BG$8 -> 1 | DF19: Residential | DG19: =$K19 -> 2021_5 | DH19: =$K19 -> 2021_5 | DI19: =$K19 -> 2021_5 | DJ19: =$K19 -> 2021_5 | DK19: =$K19 -> 2021_5 | DL19: =$K19 -> 2021_5 | DM19: =$K19 -> 2021_5 | DN19: =$K19 -> 2021_5 | ... EY19: =$K19 -> 2021_5 | FB19: Residential | FC19: =IF($M19<=O$3,1,0) -> 0 | FD19: =IF($M19<=P$3,1,0) -> 0 | FE19: =IF($M19<=Q$3,1,0) -> 0 | FF19: =IF($M19<=R$3,1,0) -> 0 | FG19: =IF($M19<=S$3,1,0) -> 0 | FH19: =IF($M19<=T$3,1,0) -> 0 | FI19: =IF($M19<=U$3,1,0) -> 0 | FJ19: =IF($M19<=V$3,1,0) -> 0 | ... GU19: =IF($M19<=BG$3,1,0) -> 1
A20: MSHP partially displacing Oil Heat | C20: 3130420006 | D20: FLAT HILL RD | E20: LUNENBURG | F20: MA | G20: 01462-2118 | H20: 44356 | I20: =YEAR(H20) -> 2021 | J20: =MONTH(H20) -> 6 | K20: =I20&"_"&J20 -> 2021_6 | L20: =MAX(0,VLOOKUP($K20,lookups!$A$1:$B$45,2,0)-12) -> 2 | M20: =DATE(I20,J20,1) -> 44348 | N20: Residential | O20: =IF(OR($L20>O$4,O$4>$L20+23),"",OFFSET(Electric!$L11,0,-'Electric Calendarize'!$L20+'Electric Calendarize'!O$4+1)) | P20: =IF(OR($L20>P$4,P$4>$L20+23),"",OFFSET(Electric!$L11,0,-'Electric Calendarize'!$L20+'Electric Calendarize'!P$4+1)) | Q20: =IF(OR($L20>Q$4,Q$4>$L20+23),"",OFFSET(Electric!$L11,0,-'Electric Calendarize'!$L20+'Electric Calendarize'!Q$4+1)) -> 0 | R20: =IF(OR($L20>R$4,R$4>$L20+23),"",OFFSET(Electric!$L11,0,-'Electric Calendarize'!$L20+'Electric Calendarize'!R$4+1)) -> 0 | S20: =IF(OR($L20>S$4,S$4>$L20+23),"",OFFSET(Electric!$L11,0,-'Electric Calendarize'!$L20+'Electric Calendarize'!S$4+1)) -> 0 | T20: =IF(OR($L20>T$4,T$4>$L20+23),"",OFFSET(Electric!$L11,0,-'Electric Calendarize'!$L20+'Electric Calendarize'!T$4+1)) -> 0 | U20: =IF(OR($L20>U$4,U$4>$L20+23),"",OFFSET(Electric!$L11,0,-'Electric Calendarize'!$L20+'Electric Calendarize'!U$4+1)) -> 0 | V20: =IF(OR($L20>V$4,V$4>$L20+23),"",OFFSET(Electric!$L11,0,-'Electric Calendarize'!$L20+'Electric Calendarize'!V$4+1)) -> 104 | ... BG20: =IF(OR($L20>BG$4,BG$4>$L20+23),"",OFFSET(Electric!$L11,0,-'Electric Calendarize'!$L20+'Electric Calendarize'!BG$4+1)) | BJ20: Residential | BK20: =+O$8 -> 1 | BL20: =+P$8 -> 0 | BM20: =+Q$8 -> 0 | BN20: =+R$8 -> 0 | BO20: =+S$8 -> 0 | BP20: =+T$8 -> 0 | BQ20: =+U$8 -> 0 | BR20: =+V$8 -> 1 | ... DC20: =+BG$8 -> 1 | DF20: Residential | DG20: =$K20 -> 2021_6 | DH20: =$K20 -> 2021_6 | DI20: =$K20 -> 2021_6 | DJ20: =$K20 -> 2021_6 | DK20: =$K20 -> 2021_6 | DL20: =$K20 -> 2021_6 | DM20: =$K20 -> 2021_6 | DN20: =$K20 -> 2021_6 | ... EY20: =$K20 -> 2021_6 | FB20: Residential | FC20: =IF($M20<=O$3,1,0) -> 0 | FD20: =IF($M20<=P$3,1,0) -> 0 | FE20: =IF($M20<=Q$3,1,0) -> 0 | FF20: =IF($M20<=R$3,1,0) -> 0 | FG20: =IF($M20<=S$3,1,0) -> 0 | FH20: =IF($M20<=T$3,1,0) -> 0 | FI20: =IF($M20<=U$3,1,0) -> 0 | FJ20: =IF($M20<=V$3,1,0) -> 0 | ... GU20: =IF($M20<=BG$3,1,0) -> 1
