Workbook
Name A_Print_All: #REF!
Name IQ_CH: 110000
Name IQ_CQ: 5000
Name IQ_CY: 10000
Name IQ_DAILY: 500000
Name IQ_FH: 100000
Name IQ_FQ: 500
Name IQ_FY: 1000
Name IQ_LTM: 2000
Name IQ_MONTH: 15000
Name IQ_NTM: 6000
Name IQ_WEEK: 50000
Name IQ_YTD: 3000
Name shading: #REF!,#REF!,#REF!,#REF!,#REF!,#REF!,#REF!
Name shading2: #REF!,#REF!,#REF!,#REF!
Name tariff20: #REF!
Name tariff20a: #REF!

Sheet  Rate Change Summary
B1: Fitchburg Gas and Electric Light Company d/b/a Unitil
B2: Summary of Rate Changes Reflected in Bill Impacts
B5: Current rates:
B7: Current rates: February 1, 2026
B10: Proposed rates: July 1, 2026
B13: Rate Component Changes Reflected in Bill Impacts
C14: Proposed Rates
F15: GD-2,
B16: Rate Component | C16: RD-1 | D16: RD-2 | E16: GD-1 | F16: GD-4, GD-5, | G16: GD-3 | H16: SD | I16: SDC
A17: 1 | B17: Energy Efficiency Reconciliation Factor (Exhibits 2, 3, 4) | C17: 0 | D17: 0 | E17: 0 | F17: 0 | G17: 0 | H17: 0 | I17: 0
B31: Notes:

Sheet HP-RES
B3: Fitchburg Gas and Electric Light Company d/b/a Unitil
B4: Basic Service Customer Typical Bill Impacts
B5: Impact on HP-RES Rate Customers
H8: Current Rates | I8: Proposed Rates | M8: %
E9: Assumed | F9: Monthly | H9: Total | I9: Total | K9: Total | M9: Total
E10: Usage | F10: kWh | H10: Revenue | I10: Revenue | K10: Difference | M10: Difference
E12: January | F12: 2137.04 | H12: =$I$34+F12*$I$67 -> 801.0854 | I12: =$Q$34+F12*$Q$67 -> 743.34257 | K12: =I12-H12 -> -57.742821 | M12: =I12/H12-1 -> -0.072080731
E13: February | F13: 2019.85 | H13: =$I$34+F13*$I$67 -> 757.62197 | I13: =$Q$34+F13*$Q$67 -> 703.04562 | K13: =I13-H13 -> -54.576347 | M13: =I13/H13-1 -> -0.072036384
E14: March | F14: 1632.76 | H14: =$I$34+F14*$I$67 -> 614.05803 | I14: =$Q$34+F14*$Q$67 -> 569.94085 | K14: =I14-H14 -> -44.117175 | M14: =I14/H14-1 -> -0.071845287
E15: April | F15: 1130.16 | H15: =$I$34+F15*$I$67 -> 427.65374 | I15: =$Q$34+F15*$Q$67 -> 397.11682 | K15: =I15-H15 -> -30.536923 | M15: =I15/H15-1 -> -0.07140572
E16: May | F16: 434.82 | H16: =$H$34+F16*$H$67 -> 198.21631 | I16: =$P$34+F16*$P$67 -> 198.21631 | K16: =I16-H16 -> 0 | M16: =I16/H16-1 -> 0
E17: June | F17: 472.29 | H17: =$H$34+F17*$H$67 -> 214.56485 | I17: =$P$34+F17*$P$67 -> 214.56485 | K17: =I17-H17 -> 0 | M17: =I17/H17-1 -> 0
E18: July | F18: 596.23 | H18: =$H$34+F18*$H$67 -> 268.64111 | I18: =$P$34+F18*$P$67 -> 268.64111 | K18: =I18-H18 -> 0 | M18: =I18/H18-1 -> 0
E19: August | F19: 717.36 | H19: =$H$34+F19*$H$67 -> 321.49134 | I19: =$P$34+F19*$P$67 -> 321.49134 | K19: =I19-H19 -> 0 | M19: =I19/H19-1 -> 0
E20: September | F20: 537.72 | H20: =$H$34+F20*$H$67 -> 243.11261 | I20: =$P$34+F20*$P$67 -> 243.11261 | K20: =I20-H20 -> 0 | M20: =I20/H20-1 -> 0
E21: October | F21: 405.51 | H21: =$H$34+F21*$H$67 -> 185.42807 | I21: =$P$34+F21*$P$67 -> 185.42807 | K21: =I21-H21 -> 0 | M21: =I21/H21-1 -> 0
E22: November | F22: 864.76 | H22: =$I$34+F22*$I$67 -> 329.22219 | I22: =$Q$34+F22*$Q$67 -> 305.85637 | K22: =I22-H22 -> -23.365815 | M22: =I22/H22-1 -> -0.070972784
E23: December | F23: 1434.63 | H23: =$I$34+F23*$I$67 -> 540.57557 | I23: =$Q$34+F23*$Q$67 -> 501.81187 | K23: =I23-H23 -> -38.763703 | M23: =I23/H23-1 -> -0.071708202
E25: Summer | F25: =SUM(F16:F21) -> 3163.93 | H25: =SUM(H16:H21) -> 1431.4543 | I25: =SUM(I16:I21) -> 1431.4543 | K25: =I25-H25 -> 0 | M25: =I25/H25-1 -> 0
E26: Winter | F26: =SUM(F12:F15)+SUM(F22:F23) -> 9219.2 | H26: =SUM(H12:H15)+SUM(H22:H23) -> 3470.2169 | I26: =SUM(I12:I15)+SUM(I22:I23) -> 3221.1141 | K26: =I26-H26 -> -249.10278 | M26: =I26/H26-1 -> -0.071783059
E27: Annual | F27: =SUM(F12:F23) -> 12383.13 | H27: =$H$34*6+F25*$H$67+I34*6+F26*I67 -> 4901.6712 | I27: =$P$34*6+F25*$P$67+Q34*6+F26*Q67 -> 4652.5684 | K27: =I27-H27 -> -249.10278 | M27: =I27/H27-1 -> -0.05081997
B31: Current rates: June 1, 2026 | H31: Summer | I31: Winter | K31: Illustrative rates: November 1, 2026 | P31: Summer | Q31: Winter | S31: Summer | T31: Winter
H32: HP-Res | I32: HP-Res | P32: HP-Res | Q32: HP-Res | S32: Difference | T32: Difference
B33: Delivery Charges: | K33: Delivery Charges:
B34: Customer Charge | H34: 8.5 | I34: 8.5 | K34: Customer Charge | P34: =H34 -> 8.5 | Q34: =I34 -> 8.5 | S34: =+P34-H34 -> 0 | T34: =+Q34-I34 -> 0
H35: kWh | I35: kWh | P35: kWh | Q35: kWh | S35: kWh | T35: kWh
B36: Distribution | H36: 0.10176 | I36: 0.03633 | K36: Distribution | P36: =H36 -> 0.10176 | Q36: =I36 -> 0.03633 | S36: =+P36-H36 -> 0 | T36: =+Q36-I36 -> 0
B38: Pension/PBOP Adjustment Factor | H38: 0.00221 | I38: =H38 -> 0.00221 | K38: Pension/PBOP Adjustment Factor | P38: =H38 -> 0.00221 | Q38: =I38 -> 0.00221 | S38: =+P38-H38 -> 0 | T38: =+Q38-I38 -> 0
B39: Residential Assistance Adjustment Factor | H39: 0.03113 | I39: =H39 -> 0.03113 | K39: Residential Assistance Adjustment Factor | P39: =H39 -> 0.03113 | Q39: =I39 -> 0.03113 | S39: =+P39-H39 -> 0 | T39: =+Q39-I39 -> 0
B40: Attorney General Consultant Expense Factor | H40: 0.00032 | I40: =H40 -> 0.00032 | K40: Attorney General Consultant Expense Factor | P40: =H40 -> 0.00032 | Q40: =I40 -> 0.00032 | S40: =+P40-H40 -> 0 | T40: =+Q40-I40 -> 0
B41: L-T Renewable Contract Adjustment Factor | H41: 0.00127 | I41: =H41 -> 0.00127 | K41: L-T Renewable Contract Adjustment Factor | P41: =H41 -> 0.00127 | Q41: =I41 -> 0.00127 | S41: =+P41-H41 -> 0 | T41: =+Q41-I41 -> 0
B42: Basic Service Adjustment | H42: 0.00162 | I42: =H42 -> 0.00162 | K42: Basic Service Adjustment | P42: =H42 -> 0.00162 | Q42: =I42 -> 0.00162 | S42: =+P42-H42 -> 0 | T42: =+Q42-I42 -> 0
B43: Grid Modernization Factor | H43: 0.01411 | I43: =H43 -> 0.01411 | K43: Grid Modernization Factor | P43: =H43 -> 0.01411 | Q43: =I43 -> 0.01411 | S43: =+P43-H43 -> 0 | T43: =+Q43-I43 -> 0
B44: Capital Cost Adjustment Factor | H44: 0.00088 | I44: =H44 -> 0.00088 | K44: Capital Cost Adjustment Factor | P44: =H44 -> 0.00088 | Q44: =I44 -> 0.00088 | S44: =+P44-H44 -> 0 | T44: =+Q44-I44 -> 0
B45: Storm Reserve Adjustment Factor | H45: 0.00364 | I45: =H45 -> 0.00364 | K45: Storm Reserve Adjustment Factor | P45: =H45 -> 0.00364 | Q45: =I45 -> 0.00364 | S45: =+P45-H45 -> 0 | T45: =+Q45-I45 -> 0
G46: Total Reconciling Rate Adjustments | H46: =+SUM(H38:H45) -> 0.05518 | I46: =+SUM(I38:I45) -> 0.05518 | O46: Total Reconciling Rate Adjustments | P46: =+SUM(P38:P45) -> 0.05518 | Q46: =+SUM(Q38:Q45) -> 0.05518 | S46: =+P46-H46 -> 0 | T46: =+Q46-I46 -> 0
G47: Total Distribution | H47: =+H36+H46 -> 0.15694 | I47: =+I36+I46 -> 0.09151 | O47: Total Distribution | P47: =+P36+P46 -> 0.15694 | Q47: =+Q36+Q46 -> 0.09151 | S47: =+P47-H47 -> 0 | T47: =+Q47-I47 -> 0
B49: Revenue Decoupling Adjustment Factor | H49: 0.00663 | I49: =H49 -> 0.00663 | K49: Revenue Decoupling Adjustment Factor | P49: =H49 -> 0.00663 | Q49: =I49 -> 0.00663 | S49: =+P49-H49 -> 0 | T49: =+Q49-I49 -> 0
B50: Distributed Solar (SMART) | H50: 0.01437 | I50: =H50 -> 0.01437 | K50: Distributed Solar (SMART) | P50: =H50 -> 0.01437 | Q50: =I50 -> 0.01437 | S50: =+P50-H50 -> 0 | T50: =+Q50-I50 -> 0
B51: Net Metering Recovery Surcharge | H51: =+'Part A Delivery Rates '!L18 -> 0.02717 | I51: =H51 -> 0.02717 | K51: Net Metering Recovery Surcharge | P51: =H51 -> 0.02717 | Q51: =I51 -> 0.02717 | S51: =+P51-H51 -> 0 | T51: =+Q51-I51 -> 0
...

Sheet HP-RES LI
B3: Fitchburg Gas and Electric Light Company d/b/a Unitil
B4: Basic Service Customer Typical Bill Impacts
B5: Impact on HP-RES LI Rate Customers
H8: Current Rates | I8: Proposed Rates | M8: %
E9: Assumed | F9: Monthly | H9: Total | I9: Total | K9: Total | M9: Total
E10: Usage | F10: kWh | H10: Revenue | I10: Revenue | K10: Difference | M10: Difference
E12: January | F12: 2137.04 | H12: =$I$34+F12*$I$71 -> 484.05124 | I12: =$Q$34+F12*$Q$71 -> 449.40554 | K12: =I12-H12 -> -34.645692 | M12: =I12/H12-1 -> -0.071574432
E13: February | F13: 2019.85 | H13: =$I$34+F13*$I$71 -> 457.97318 | I13: =$Q$34+F13*$Q$71 -> 425.22737 | K13: =I13-H13 -> -32.745808 | M13: =I13/H13-1 -> -0.071501585
E14: March | F14: 1632.76 | H14: =$I$34+F14*$I$71 -> 371.83482 | I14: =$Q$34+F14*$Q$71 -> 345.36451 | K14: =I14-H14 -> -26.470305 | M14: =I14/H14-1 -> -0.071188345
E15: April | F15: 1130.16 | H15: =$I$34+F15*$I$71 -> 259.99224 | I15: =$Q$34+F15*$Q$71 -> 241.67009 | K15: =I15-H15 -> -18.322154 | M15: =I15/H15-1 -> -0.070471925
E16: May | F16: 434.82 | H16: =$H$34+F16*$H$71 -> 122.32979 | I16: =$P$34+F16*$P$71 -> 122.32979 | K16: =I16-H16 -> 0 | M16: =I16/H16-1 -> 0
E17: June | F17: 472.29 | H17: =$H$34+F17*$H$71 -> 132.13891 | I17: =$P$34+F17*$P$71 -> 132.13891 | K17: =I17-H17 -> 0 | M17: =I17/H17-1 -> 0
E18: July | F18: 596.23 | H18: =$H$34+F18*$H$71 -> 164.58467 | I18: =$P$34+F18*$P$71 -> 164.58467 | K18: =I18-H18 -> 0 | M18: =I18/H18-1 -> 0
E19: August | F19: 717.36 | H19: =$H$34+F19*$H$71 -> 196.2948 | I19: =$P$34+F19*$P$71 -> 196.2948 | K19: =I19-H19 -> 0 | M19: =I19/H19-1 -> 0
E20: September | F20: 537.72 | H20: =$H$34+F20*$H$71 -> 149.26757 | I20: =$P$34+F20*$P$71 -> 149.26757 | K20: =I20-H20 -> 0 | M20: =I20/H20-1 -> 0
E21: October | F21: 405.51 | H21: =$H$34+F21*$H$71 -> 114.65684 | I21: =$P$34+F21*$P$71 -> 114.65684 | K21: =I21-H21 -> 0 | M21: =I21/H21-1 -> 0
E22: November | F22: 864.76 | H22: =$I$34+F22*$I$71 -> 200.93331 | I22: =$Q$34+F22*$Q$71 -> 186.91382 | K22: =I22-H22 -> -14.019489 | M22: =I22/H22-1 -> -0.069771851
E23: December | F23: 1434.63 | H23: =$I$34+F23*$I$71 -> 327.74534 | I23: =$Q$34+F23*$Q$71 -> 304.48712 | K23: =I23-H23 -> -23.258222 | M23: =I23/H23-1 -> -0.070964308
E25: Summer | F25: =SUM(F16:F21) -> 3163.93 | H25: =SUM(H16:H21) -> 879.27258 | I25: =SUM(I16:I21) -> 879.27258 | K25: =I25-H25 -> 0 | M25: =I25/H25-1 -> 0
E26: Winter | F26: =SUM(F12:F15)+SUM(F22:F23) -> 9219.2 | H26: =SUM(H12:H15)+SUM(H22:H23) -> 2102.5301 | I26: =SUM(I12:I15)+SUM(I22:I23) -> 1953.0685 | K26: =I26-H26 -> -149.46167 | M26: =I26/H26-1 -> -0.071086577
E27: Annual | F27: =SUM(F12:F23) -> 12383.13 | H27: =$H$34*6+F25*$H$71+I34*6+F26*I71 -> 2981.8027 | I27: =$P$34*6+F25*$P$71+Q34*6+F26*Q71 -> 2832.341 | K27: =I27-H27 -> -149.46167 | M27: =I27/H27-1 -> -0.050124601 | X27: ='HP-RES'!K27*0.6-K27 -> -1.2789769e-12
B31: Current rates: June 1, 2026 | H31: Summer | I31: Winter | K31: Illustrative rates: November 1, 2026 | P31: Summer | Q31: Winter | S31: Summer | T31: Winter
H32: HP-Res LI | I32: HP-Res LI | P32: HP-Res LI | Q32: HP-Res LI | S32: Difference | T32: Difference
B33: Delivery Charges: | K33: Delivery Charges:
B34: Customer Charge | H34: 8.5 | I34: 8.5 | K34: Customer Charge | P34: =H34 -> 8.5 | Q34: =I34 -> 8.5 | S34: =+P34-H34 -> 0 | T34: =+Q34-I34 -> 0
H35: kWh | I35: kWh | P35: kWh | Q35: kWh | S35: kWh | T35: kWh
B36: Distribution | H36: 0.10176 | I36: 0.03633 | K36: Distribution | P36: =H36 -> 0.10176 | Q36: =I36 -> 0.03633 | S36: =+P36-H36 -> 0 | T36: =+Q36-I36 -> 0
B38: Pension/PBOP Adjustment Factor | H38: 0.00221 | I38: =H38 -> 0.00221 | K38: Pension/PBOP Adjustment Factor | P38: =H38 -> 0.00221 | Q38: =I38 -> 0.00221 | S38: =+P38-H38 -> 0 | T38: =+Q38-I38 -> 0
B39: Residential Assistance Adjustment Factor | H39: 0.03113 | I39: =H39 -> 0.03113 | K39: Residential Assistance Adjustment Factor | P39: =H39 -> 0.03113 | Q39: =I39 -> 0.03113 | S39: =+P39-H39 -> 0 | T39: =+Q39-I39 -> 0
B40: Attorney General Consultant Expense Factor | H40: 0.00032 | I40: =H40 -> 0.00032 | K40: Attorney General Consultant Expense Factor | P40: =H40 -> 0.00032 | Q40: =I40 -> 0.00032 | S40: =+P40-H40 -> 0 | T40: =+Q40-I40 -> 0
B41: L-T Renewable Contract Adjustment Factor | H41: 0.00127 | I41: =H41 -> 0.00127 | K41: L-T Renewable Contract Adjustment Factor | P41: =H41 -> 0.00127 | Q41: =I41 -> 0.00127 | S41: =+P41-H41 -> 0 | T41: =+Q41-I41 -> 0
B42: Basic Service Adjustment | H42: 0.00162 | I42: =H42 -> 0.00162 | K42: Basic Service Adjustment | P42: =H42 -> 0.00162 | Q42: =I42 -> 0.00162 | S42: =+P42-H42 -> 0 | T42: =+Q42-I42 -> 0
B43: Grid Modernization Factor | H43: 0.01411 | I43: =H43 -> 0.01411 | K43: Grid Modernization Factor | P43: =H43 -> 0.01411 | Q43: =I43 -> 0.01411 | S43: =+P43-H43 -> 0 | T43: =+Q43-I43 -> 0
B44: Capital Cost Adjustment Factor | H44: 0.00088 | I44: =H44 -> 0.00088 | K44: Capital Cost Adjustment Factor | P44: =H44 -> 0.00088 | Q44: =I44 -> 0.00088 | S44: =+P44-H44 -> 0 | T44: =+Q44-I44 -> 0
B45: Storm Reserve Adjustment Factor | H45: 0.00364 | I45: =H45 -> 0.00364 | K45: Storm Reserve Adjustment Factor | P45: =H45 -> 0.00364 | Q45: =I45 -> 0.00364 | S45: =+P45-H45 -> 0 | T45: =+Q45-I45 -> 0
G46: Total Reconciling Rate Adjustments | H46: =+SUM(H38:H45) -> 0.05518 | I46: =+SUM(I38:I45) -> 0.05518 | O46: Total Reconciling Rate Adjustments | P46: =+SUM(P38:P45) -> 0.05518 | Q46: =+SUM(Q38:Q45) -> 0.05518 | S46: =+P46-H46 -> 0 | T46: =+Q46-I46 -> 0
G47: Total Distribution | H47: =+H36+H46 -> 0.15694 | I47: =+I36+I46 -> 0.09151 | O47: Total Distribution | P47: =+P36+P46 -> 0.15694 | Q47: =+Q36+Q46 -> 0.09151 | S47: =+P47-H47 -> 0 | T47: =+Q47-I47 -> 0
B49: Revenue Decoupling Adjustment Factor | H49: 0.00663 | I49: =H49 -> 0.00663 | K49: Revenue Decoupling Adjustment Factor | P49: =H49 -> 0.00663 | Q49: =I49 -> 0.00663 | S49: =+P49-H49 -> 0 | T49: =+Q49-I49 -> 0
B50: Distributed Solar (SMART) | H50: 0.01437 | I50: =H50 -> 0.01437 | K50: Distributed Solar (SMART) | P50: =H50 -> 0.01437 | Q50: =I50 -> 0.01437 | S50: =+P50-H50 -> 0 | T50: =+Q50-I50 -> 0
B51: Net Metering Recovery Surcharge | H51: =+'Part A Delivery Rates '!L18 -> 0.02717 | I51: =H51 -> 0.02717 | K51: Net Metering Recovery Surcharge | P51: =H51 -> 0.02717 | Q51: =I51 -> 0.02717 | S51: =+P51-H51 -> 0 | T51: =+Q51-I51 -> 0
...

Sheet Part A Delivery Rates 
A1: Fitchburg Gas and Electric Light Company | U1: M.D.P.U. 312-26-B
A2: d/b/a Unitil | U2: Canceling M.D.P.U. 312-26-A
A3: Summary of Electric Service Rates | U3: Sheet 1
A6: PART A - TOTAL DELIVERY RATES
A7: (1) Reconciling Rates = Sum of Part B Rates
Y9: Informational Purposes Only
F10: Distribution Charges | K10: Distributed Solar (SMART) | L10: Net Metering | M10: Transmission Charges | Q10: Energy Efficiency Charge (EEC) | Y10: NBP SMART | Z10: NBP SMART
B11: MDPU | C11: Rate | D11: Service | E11: Rate | L11: Recovery | Q11: System Benefits | R11: Recon. Factor | Y11: Delivery less SMART | Z11: SMART Factor
A12: Schedule | B12: No. | C12: Code | D12: Area | E12: Component | F12: Base Distribution | G12: Exogenous Cost Adjust | H12: Reconciling Rate Adjust (1) | I12: Total Distribution | J12: Revenue Decoupling | L12: Surcharge (NMRS) | M12: Internal Transmission | N12: ITSCA | O12: External Transmission | P12: Total Transmission | S12: Total EEC | T12: Renewable Energy | U12: Total Delivery
G13: MDPU No. 461 | J13: MDPU No. 454 | K13: MDPU No. 465 | L13: MDPU No. 464 | N13: MDPU No. 304 | O13: MDPU No. 305 | R13: MDPU No. 436 | T13: MDTE No. 37
A15: Last change | F15: 45658 | G15: 45658 | H15: 45658 | I15: 45658 | J15: 45658 | K15: 45658 | L15: 45658 | M15: 41791 | N15: 45658 | O15: 45658 | P15: =MAX(M15:O15) -> 45658 | Q15: 37257 | R15: 45474 | S15: =R15 -> 45474 | T15: 37622 | U15: =+MAX(F15:T15) -> 45658
A17: RD-1 | B17: 455 | D17: ALL | E17: Customer Charge | F17: 6.38 | I17: 6.38 | U17: 6.38
A18: Residential | E18: Energy (kWh) | F18: 0.10176 | G18: 0 | H18: -0.06452 | I18: 0.03724 | J18: 0.00663 | K18: 0.01437 | L18: 0.02717 | M18: 0.00394 | N18: -0.00211 | O18: 0.04018 | P18: 0.04201 | Q18: 0.0025 | R18: 0.02424 | S18: 0.02674 | T18: 0.0005 | U18: 0.15466 | Y18: =U18-K18 -> 0.14029 | Z18: =K18 -> 0.01437
A20: Farm Credit | E20: Customer Charge | U20: -0.638
E21: Energy (kWh) | U21: -0.015466
A22: RD-2 | B22: 456 | D22: ALL | E22: Customer | F22: 6.38 | I22: 6.38 | U22: 6.38
A23: Residential Assistance | E23: Energy (kWh) | F23: 0.10176 | G23: 0 | H23: -0.06452 | I23: 0.03724 | J23: 0.00663 | K23: 0.01437 | L23: 0.02717 | M23: 0.00394 | N23: -0.00211 | O23: 0.04018 | P23: 0.04201 | Q23: 0.0025 | R23: 0.02424 | S23: 0.02674 | T23: 0.0005 | U23: 0.15466 | Y23: =U23-K23 -> 0.14029 | Z23: =K23 -> 0.01437
A25: 40.0% Low Income | E25: Customer | U25: -2.552
A26: Discount | E26: Energy (kWh) | U26: -0.06186 | Y26: =-ROUND(Y18*(0.4),5)+Y18-Y23 -> -0.05612 | Z26: =-ROUND(Z18*(0.4),5)+Z18-Z23 -> -0.00575
A28: Farm Credit | E28: Customer | U28: -0.3828
E29: Energy (kWh) | U29: -0.00928 | Y29: =-ROUND((Y26+Y23)/10,5) -> -0.00842 | Z29: =-ROUND((Z26+Z23)/10,5) -> -0.00086
A30: HP-RES | B30: 466 | D30: ALL | E30: Customer Charge | F30: 6.38 | I30: 6.38 | U30: 6.38
A31: Residential | E31: Energy - Nov - Apr (kWh) | F31: 0.03633 | G31: 0 | H31: -0.04849 | I31: -0.01216 | J31: 0.00663 | K31: 0.01437 | L31: 0.02717 | M31: 0.00394 | N31: -0.00211 | O31: 0.04018 | P31: 0.04201 | Q31: 0.0025 | R31: 0.02424 | S31: 0.02674 | T31: 0.0005 | U31: 0.10526
E32: Energy - May - Oct (kWh) | F32: 0.10176 | G32: 0 | H32: 0.04119 | I32: 0.14295 | J32: 0.00663 | K32: 0.01437 | L32: 0.02717 | M32: 0.00394 | N32: -0.00211 | O32: 0.04018 | P32: 0.04201 | Q32: 0.0025 | R32: 0.02424 | S32: 0.02674 | T32: 0.0005 | U32: 0.26037
A33: Farm Credit | E33: Customer Charge | U33: -0.638
E34: Energy - Nov - Apr (kWh) | U34: -0.010526
E35: Energy - May - Oct (kWh) | U35: -0.026037
A36: HP-RES LI | B36: 467 | D36: ALL | E36: Customer | F36: 6.38 | I36: 6.38 | U36: 6.38
A37: Residential Assistance | E37: Energy - Nov - Apr (kWh) | F37: 0.03633 | G37: 0 | H37: -0.04849 | I37: -0.01216 | J37: 0.00663 | K37: 0.01437 | L37: 0.02717 | M37: 0.00394 | N37: -0.00211 | O37: 0.04018 | P37: 0.04201 | Q37: 0.0025 | R37: 0.02424 | S37: 0.02674 | T37: 0.0005 | U37: 0.10526
E38: Energy - May - Oct (kWh) | F38: 0.10176 | G38: 0 | H38: 0.04119 | I38: 0.14295 | J38: 0.00663 | K38: 0.01437 | L38: 0.02717 | M38: 0.00394 | N38: -0.00211 | O38: 0.04018 | P38: 0.04201 | Q38: 0.0025 | R38: 0.02424 | S38: 0.02674 | T38: 0.0005 | U38: 0.26037
A40: 40.0% Low Income | E40: Customer | U40: -2.552
A41: Discount | E41: Energy - Nov - Apr (kWh) | U41: -0.0421
E42: Energy - May - Oct (kWh) | U42: -0.10415
A43: Farm Credit | E43: Customer | U43: -0.3828
E44: Energy - Nov - Apr (kWh) | U44: -0.006316
E45: Energy - May - Oct (kWh) | U45: -0.015622
A46: GD-1 | B46: 457 | D46: ALL | E46: Customer Charge | F46: 12 | I46: 12 | U46: 12
A47: Small General Service | E47: Energy (kWh) | F47: 0.07678 | G47: 0 | H47: 0.02344 | I47: 0.10022 | J47: 0.00359 | K47: 0.00779 | L47: 0.01473 | M47: 0.00323 | N47: -0.00175 | O47: 0.03337 | P47: 0.03485 | Q47: 0.0025 | R47: 0.0048 | S47: 0.0073 | T47: 0.0005 | U47: 0.16898
A49: Farm Credit | E49: Customer | U49: -1.2
E50: Energy (kWh) | U50: -0.016898
...

Sheet Part B Reconciling Rates 
A1: Fitchburg Gas and Electric Light Company | N1: M.D.P.U. No. 312-25-B
A2: d/b/a Unitil | N2: Canceling M.D.P.U. No. 312-25-A
A3: Summary of Electric Service Rates | N3: Sheet 2
A5: PART B - RECONCILING RATES
A6: All Rates are in $/kWh across all hours and usage levels; totals appear in Part A
A9: Sector | B9: Service Area | C9: Pension Adjustment Factor (PAF) | D9: Residential Assistance Adjustment Factor (RAAF) | E9: Attorney General Consulting Expense (AGCE) | F9: Long Term Renewable Contract Adjustment (LTRCA) | G9: Solar Cost Adjustment Factor (SCA) | H9: Basic Service Adjustment (BSA) | I9: Grid Modernization Factor (GMF) | J9: Capital Cost Adjustment Factor (CCA) | K9: Advanced Metering Infrastructure Factor (AMIF) | L9: Storm Resiliency Program Adjustment Factor (SRPAF) | M9: Storm Reserve Adjustment Factor (SRAF) | N9: Total
C11: MDPU No. 446 | D11: MDPU No. 463 | E11: MDPU No. 450 | F11: MDPU No. 444 | G11: MDPU No. 447 | H11: MDPU No. 449 | I11: MDPU No. 435 | J11: MDPU No. 438 | L11: MDPU No. 361 | M11: MDPU No. 462
A13: Last change | C13: 45658 | D13: =+$C13 -> 45658 | E13: =+$C13 -> 45658 | F13: =+$C13 -> 45658 | G13: 45474 | H13: =+$C13 -> 45658 | I13: 45444 | J13: 45658 | K13: 45474 | M13: =+$C13 -> 45658 | N13: =+MAX(C13:M13) -> 45658
A16: Residential RD-1, RD-2, RES-EV | B16: ALL | C16: 0.00221 | D16: -0.0854 | E16: 0.00032 | F16: 0.00127 | G16: 0 | H16: 0.00162 | I16: 0.01094 | J16: 0.00088 | M16: 0.00364 | N16: -0.06452
A18: Small General Service GD-1 | B18: ALL | C18: 0.00117 | D18: 0.01101 | E18: 0.00017 | F18: 0.00127 | G18: 0 | H18: 0.00087 | I18: 0.00618 | J18: 0.0008 | M18: 0.00197 | N18: 0.02344
A20: Regular General Service GD-2, GD-4, GD-5 | B20: ALL | C20: 0.00117 | D20: 0.01101 | E20: 0.00017 | F20: 0.00127 | G20: 0 | H20: 0.00087 | I20: 0.00618 | J20: 0.00056 | M20: 0.00197 | N20: 0.0232
A22: Large General Service GD-3 | B22: ALL | C22: 0.00078 | D22: 0.00902 | E22: 0.00014 | F22: 0.00127 | G22: 0 | H22: 0.00072 | I22: 0.00505 | J22: 0.00041 | M22: 0.00162 | N22: 0.01901
A24: Outdoor Lighting SD | B24: ALL | C24: 0.01316 | D24: 0.02865 | E24: 0.00045 | F24: 0.00127 | G24: 0 | H24: 0.00228 | I24: 0.01221 | J24: 0.00365 | M24: 0.00514 | N24: 0.06681
A26: Outdoor Lighting Customer Owned - SDC | B26: ALL | C26: 0.01316 | D26: 0.02865 | E26: 0.00045 | F26: 0.00127 | G26: 0 | H26: 0.00228 | I26: 0.01221 | J26: 0.00362 | M26: 0.00514 | N26: 0.06678
C32: .
A33: Issued by: Daniel Hurstak | N33: Issued: February 2, 2026
A34: Vice President and Treasurer | N34: Effective: February 1, 2026

Sheet Part B Outdoor Lighting 
A1: Fitchburg Gas and Electric Light Company | K1: M.D.P.U. 312-26-B
A2: d/b/a Unitil | K2: Canceling M.D.P.U. 312-26-A
A3: Summary of Electric Service Rates | K3: Sheet 3
A6: PART B - OUTDOOR LIGHTING DELIVERY RATES
A7: Company Owned Outdoor Lighting Delivery Service - Luminaire Charges
A8: M.D.P.U. No. 458
J10: Total
A11: Lamp Size | B11: Type of | J11: Farm Credit
A12: Lumens | B12: Luminaire | C12: Per Month | H12: Per Year | J12: Per Month
A13: Mercury Vapor*:
A16: 3500 | B16: Street and Highway Type | C16: 17.74 | H16: 212.88 | J16: -1.77
A17: 7000 | B17: Street and Highway Type | C17: 19.68 | H17: 236.16 | J17: -1.97
A18: 20000 | B18: Street and Highway Type | C18: 35.77 | H18: 429.24 | J18: -3.58
A19: 60000 | B19: Street and Highway Type | C19: 68.4 | H19: 820.8 | J19: -6.84
A20: 20000 | B20: Flood Light Type | C20: 39.56 | H20: 474.72 | J20: -3.96
A21: 3500 | B21: Power Bracket Included | C21: 18.58 | H21: 222.96 | J21: -1.86
A22: 7000 | B22: Power Bracket Included | C22: 20.92 | H22: 251.04 | J22: -2.09
A24: High Pressure Sodium**:
A27: 3300 | B27: Street and Highway Type | C27: 15.39 | H27: 184.68 | J27: -1.54
A28: 9500 | B28: Street and Highway Type | C28: 18.3 | H28: 219.6 | J28: -1.83
A29: 20000 | B29: Street and Highway Type | C29: 27.3 | H29: 327.6 | J29: -2.73
A30: 50000 | B30: Street and Highway Type | C30: 38.82 | H30: 465.84 | J30: -3.88
A31: 140000 | B31: Street and Highway Type | C31: 79.66 | H31: 955.92 | J31: -7.97
A32: 50000 | B32: Flood Light Type | C32: 45.07 | H32: 540.84 | J32: -4.51
A34: Light Emitting Diode (LED):
A35: Wattage Ranges
A36: 20-30 | B36: Cobra Head Type | C36: 9.97 | H36: 119.64 | J36: -1
A37: 31-40 | B37: Cobra Head Type | C37: 10.75 | H37: 129 | J37: -1.08
A38: 41-50 | B38: Cobra Head Type | C38: 11.54 | H38: 138.48 | J38: -1.15
A39: 51-60 | B39: Cobra Head Type | C39: 12.07 | H39: 144.84 | J39: -1.21
A40: 61-80 | B40: Cobra Head Type | C40: 17.31 | H40: 207.72 | J40: -1.73
A41: 81-110 | B41: Cobra Head Type | C41: 19.94 | H41: 239.28 | J41: -1.99
A42: 111-150 | B42: Cobra Head Type | C42: 22.04 | H42: 264.48 | J42: -2.2
A43: 40-60 | B43: Flood Light Type | C43: 17.31 | H43: 207.72 | J43: -1.73
A44: 61-80 | B44: Flood Light Type | C44: 18.89 | H44: 226.68 | J44: -1.89
A45: 81-110 | B45: Flood Light Type | C45: 19.94 | H45: 239.28 | J45: -1.99
A46: 110 | B46: Flood Light Type - CREE | C46: 27.07 | H46: 324.84 | J46: -2.71
A47: 111-150 | B47: Flood Light Type | C47: 25.19 | H47: 302.28 | J47: -2.52
A48: 350-390 | B48: Flood Light Type | C48: 31.48 | H48: 377.76 | J48: -3.15
A49: 20-30 | B49: Yard Light Type | C49: 11.02 | H49: 132.24 | J49: -1.1
...

Sheet Part C Basic Service 
A1: Fitchburg Gas and Electric Light Company | J1: M.D.P.U. 312-26-B
A2: d/b/a Unitil | J2: Canceling M.D.P.U. 312-26-A
A3: Summary of Electric Service Rates | J3: Sheet 4
A5: PART C - BASIC SERVICE RATES (1)
A6: All Rates are in $/kWh across all hours and usage levels
A9: Sector | B9: Service Area | C9: Type | D9: 46054 | E9: 46082 | F9: 46113 | G9: 46143 | H9: 46174 | I9: 46204 | J9: Last Change
A10: Residential - RD-1, RD-2, HP-RES, HP-RES LI | B10: ALL | C10: Fixed | D10: 0.16247 | E10: 0.16247 | F10: 0.16247 | G10: 0.16247 | H10: 0.16247 | I10: 0.16247 | J10: 46054
B11: ALL | C11: Variable | D11: 0.23367 | E11: 0.15115 | F11: 0.13454 | G11: 0.12967 | H11: 0.13627 | I11: 0.16304 | J11: 46054
A13: RD-1 Farm Credit | B13: ALL | C13: Fixed | D13: -0.01625 | E13: -0.01625 | F13: -0.01625 | G13: -0.01625 | H13: -0.01625 | I13: -0.01625 | J13: 46054
B14: =+B13 -> ALL | C14: Variable | D14: -0.02337 | E14: -0.01512 | F14: -0.01345 | G14: -0.01297 | H14: -0.01363 | I14: -0.0163 | J14: 46054
A16: Residential RD-2 | B16: =+B14 -> ALL | C16: Fixed | D16: -0.06499 | E16: -0.06499 | F16: -0.06499 | G16: -0.06499 | H16: -0.06499 | I16: -0.06499 | J16: 46054
A17: 40.0% Low Income Discount | B17: =+B16 -> ALL | C17: Variable | D17: -0.09347 | E17: -0.06046 | F17: -0.05382 | G17: -0.05187 | H17: -0.05451 | I17: -0.06522 | J17: 46054
A19: Residential RD-2 | B19: =+B17 -> ALL | C19: Fixed | D19: -0.00975 | E19: -0.00975 | F19: -0.00975 | G19: -0.00975 | H19: -0.00975 | I19: -0.00975 | J19: 46054
A20: Farm Credit | B20: =+B19 -> ALL | C20: Variable | D20: -0.01402 | E20: -0.00907 | F20: -0.00807 | G20: -0.00778 | H20: -0.00818 | I20: -0.00978 | J20: 46054
A23: Small General Service - GD-1 | B23: ALL | C23: Fixed | D23: 0.16247 | E23: 0.16247 | F23: 0.16247 | G23: 0.16247 | H23: 0.16247 | I23: 0.16247 | J23: 46054
B24: =+B23 -> ALL | C24: Variable | D24: 0.23367 | E24: 0.15115 | F24: 0.13454 | G24: 0.12967 | H24: 0.13627 | I24: 0.16304 | J24: 46054
A26: Small General Service - GD-1 | B26: =+B24 -> ALL | C26: Fixed | D26: -0.01625 | E26: -0.01625 | F26: -0.01625 | G26: -0.01625 | H26: -0.01625 | I26: -0.01625 | J26: 46054
A27: Farm Credit | B27: =+B26 -> ALL | C27: Variable | D27: -0.02337 | E27: -0.01512 | F27: -0.01345 | G27: -0.01297 | H27: -0.01363 | I27: -0.0163 | J27: 46054
A30: Medium General and Outdoor Lighting | B30: ALL | C30: Fixed | D30: 0.16066 | E30: 0.16066 | F30: 0.16066 | G30: 0.16066 | H30: 0.16066 | I30: 0.16066 | J30: 46054
A31: GD-2, GD-4, GD-5, SD | B31: ALL | C31: Variable | D31: 0.2382 | E31: 0.15336 | F31: 0.13309 | G31: 0.12937 | H31: 0.13515 | I31: 0.16748 | J31: 46054
A33: Medium General and Outdoor Lighting | B33: ALL | C33: Fixed | D33: -0.01607 | E33: -0.01607 | F33: -0.01607 | G33: -0.01607 | H33: -0.01607 | I33: -0.01607 | J33: 46054
A34: Farm Credit | B34: ALL | C34: Variable | D34: -0.02382 | E34: -0.01534 | F34: -0.01331 | G34: -0.01294 | H34: -0.01352 | I34: -0.01675 | J34: 46054
A37: Large General - GD-3 | B37: ALL | C37: Fixed | D37: N/A | E37: N/A | F37: N/A | G37: N/A | H37: N/A | I37: N/A | J37: 46054
B38: ALL | C38: Variable | D38: MARKET | E38: MARKET | F38: MARKET | G38: MARKET | H38: MARKET | I38: MARKET | J38: 46054
B40: ALL | C40: Fixed | D40: N/A | E40: N/A | F40: N/A | G40: N/A | H40: N/A | I40: N/A | J40: 46054
B41: ALL | C41: Variable | D41: MARKET | E41: MARKET | F41: MARKET | G41: MARKET | H41: MARKET | I41: MARKET | J41: 46054
A44: (1) Pursuant to Basic Service Schedule BS (M.D.P.U. 440), effective July 1, 2024.
A45: Rates include Basic Service Costs Adder of $0.00991/kWh effective February 1, 2026.
A47: Issued by: Daniel Hurstak | J47: Issued: February 2, 2026
A48: Vice President and Treasurer | J48: Effective: February 1, 2026

Sheet Part D EV-DCA
A1: Fitchburg Gas and Electric Light Company | Y1: M.D.P.U. 312-26-B
A2: d/b/a Unitil | Y2: Canceling M.D.P.U. 312-26-A
A3: Summary of Electric Service Rates | Y3: Sheet 5
A5: PART D - EV & DEMAND CHARGE ALTERNATIVE RATES
A6: Electric Vehicle Rates - Delivery and Supply | Y6: TOTAL
N7: Net
N8: Metering | P8: Internal | W8: Basic | X8: Total
F9: Exogenous | G9: Total | I9: Transition | K9: Revenue | L9: Total | M9: Distributed | N9: Recovery | P9: Transmission | V9: Basic | W9: Service | X9: Basic | Y9: Total
B10: M.D.P.U. | D10: Customer | E10: Base | F10: Cost | G10: Reconciling | H10: Transition | I10: Charge | K10: Decoupling | L10: Transition | M10: Solar | N10: Surcharge | O10: Internal | P10: Service Cost | Q10: External | R10: Total | S10: Renewable | T10: Energy | U10: Total | V10: Service | W10: Costs | X10: Service | Y10: Delivery and
A11: Class | B11: No. | C11: Blocks | D11: Charge | E11: Distribution | F11: Adjustment | G11: Adjustments | H11: Charge | I11: Surcharge | K11: Adjustment | L11: Charge | M11: (SMART) | N11: (NMRS) | O11: Transmission | P11: Adjustment | Q11: Transmission | R11: Transmission | S11: Resource | T11: Efficiency | U11: Delivery | V11: Charge | W11: Adder | X11: Charge | Y11: Supply
A12: EV-RES | C12: Customer Charge | D12: 4.79 | U12: 4.79 | Y12: 4.79
B13: 460 | C13: Off-Peak kWh | E13: 0.05088 | F13: 0 | G13: -0.06452 | H13: 0 | I13: 0 | K13: 0.00663 | L13: 0 | M13: 0.01437 | N13: 0.02717 | O13: 0.00394 | P13: -0.00211 | Q13: 0.00128 | R13: 0.00311 | S13: 0.0005 | T13: 0.02674 | U13: 0.06488 | V13: 0.14161 | W13: 0.00991 | X13: 0.15152 | Y13: 0.2164
C14: Mid-Peak kWh | E14: 0.13793 | F14: 0 | G14: -0.06452 | K14: 0.00663 | M14: 0.01437 | N14: 0.02717 | O14: 0.00394 | P14: -0.00211 | Q14: 0.03264 | R14: 0.03447 | S14: 0.0005 | T14: 0.02674 | U14: 0.18329 | V14: 0.15812 | W14: 0.00991 | X14: 0.16803 | Y14: 0.35132
C15: On-Peak kWh | E15: 0.21504 | F15: 0 | G15: -0.06452 | K15: 0.00663 | M15: 0.01437 | N15: 0.02717 | O15: 0.00394 | P15: -0.00211 | Q15: 0.17203 | R15: 0.17386 | S15: 0.0005 | T15: 0.02674 | U15: 0.39979 | V15: 0.17983 | W15: 0.00991 | X15: 0.18974 | Y15: 0.58953
A17: Farm Credit | C17: Customer Charge | U17: -0.48 | Y17: -0.48
C18: Off-Peak kWh | U18: -0.00649 | X18: -0.01515 | Y18: -0.02164
C19: Mid-Peak kWh | U19: -0.01833 | X19: -0.0168 | Y19: -0.03513
C20: On-Peak kWh | U20: -0.03998 | X20: -0.01897 | Y20: -0.05895
A22: Last Change | D22: 46054 | E22: 45839 | F22: 45658 | G22: 46054 | H22: 44197 | I22: 41518 | K22: 45658 | L22: 44197 | M22: 45658 | N22: 45658 | O22: 41791 | P22: 46023 | Q22: 46023 | R22: 46023 | S22: 37622 | T22: 45839 | U22: 46054 | V22: 46054 | W22: 46054 | X22: 46054 | Y22: 46054
A23: Regular General | C23: Customer Charge | D23: 12 | U23: 12
A24: GD-2 Electric Vehicle | B24: 457 | C24: All kW | E24: 0 | U24: 0
A25: Price Schedule A | C25: All kWh | E25: 0.06366 | F25: 0 | G25: 0.0232 | H25: 0 | I25: 0 | K25: 0.00359 | L25: 0 | M25: 0.00779 | N25: 0.01473 | O25: 0.00323 | P25: -0.00175 | Q25: 0.03337 | R25: 0.03485 | S25: 0.0005 | T25: 0.0073 | U25: 0.15562
A26: 0% <= Load Factor <=5%
A27: Farm Credit | C27: Customer Charge | U27: -1.2
C28: All kW | U28: 0
C29: All kWh | U29: -0.01556
A30: Regular General | C30: Customer Charge | D30: 12 | U30: 12
A31: GD-2 Electric Vehicle | B31: =+B24 -> 457 | C31: All kW | E31: 2.62 | U31: 2.62
A32: Price Schedule B | C32: All kWh | E32: 0.05389 | F32: 0 | G32: 0.0232 | H32: 0 | I32: 0 | K32: 0.00359 | L32: 0 | M32: 0.00779 | N32: 0.01473 | O32: 0.00323 | P32: -0.00175 | Q32: 0.03337 | R32: 0.03485 | S32: 0.0005 | T32: 0.0073 | U32: 0.14585
A33: 5% < Load Factor <=10%
A34: Farm Credit | C34: Customer Charge | U34: -1.2
C35: All kW | U35: -0.26
C36: All kWh | U36: -0.01459
A37: Regular General | C37: Customer Charge | D37: 12 | U37: 12
A38: GD-2 Electric Vehicle | B38: =+B31 -> 457 | C38: All kW | E38: 5.25 | U38: 5.25
A39: Price Schedule C | C39: All kWh | E39: 0.04409 | F39: 0 | G39: 0.0232 | H39: 0 | I39: 0 | K39: 0.00359 | L39: 0 | M39: 0.00779 | N39: 0.01473 | O39: 0.00323 | P39: -0.00175 | Q39: 0.03337 | R39: 0.03485 | S39: 0.0005 | T39: 0.0073 | U39: 0.13605
A40: 10% < Load Factor <=15%
A41: Farm Credit | C41: Customer Charge | U41: -1.2
C42: All kW | U42: -0.53
C43: All kWh | U43: -0.01361
...

Sheet Part E Appendix 
A1: Fitchburg Gas and Electric Light Company | E1: M.D.P.U. No. 312-25-C
A2: d/b/a Unitil | E2: Canceling M.D.P.U. No. 312-25-B
A3: Summary of Electric Service Rates | E3: Sheet 6
A5: PART E - APPENDIX
A9: Service Territories/Areas | B9: Description
A10: ALL | B10: Fitchburg, Ashby, Lunenburg, Townsend
A14: Sectors | B14: Rates | C14: MDPU No. | D14: Service Area
A15: Residential | B15: RD-1 Residential | C15: 455 | D15: ALL
B16: RD-2 Residential Assistance | C16: 456 | D16: ALL
B17: EV-RES Residential Electric Vehicle | C17: 460 | D17: ALL
B18: HP-RES Residential Heat Pump | C18: 466 | D18: ALL
B19: HP-RES LI Residential Assistance Heat Pump | C19: 467 | D19: ALL
A21: Small General Service | B21: GD-1 Small General Service | C21: 457 | D21: ALL
A23: Medium General Service | B23: GD-2 Medium General Service | C23: =+C21 -> 457 | D23: ALL
B24: GD-4 Optional Time of Use | C24: =+C23 -> 457 | D24: ALL
B25: GD-5 Water Heating and/or Space Heating | C25: =+C24 -> 457 | D25: ALL
B26: GD-2 Medium General Electric Vehicle Demand Charge Alternative | C26: =+C25 -> 457 | D26: ALL
A28: Large General Service | B28: GD-3 Large General Service | C28: =+C26 -> 457 | D28: ALL
B29: GD-3 Large General Electric Vehicle Demand Charge Alternative | C29: =+C28 -> 457 | D29: ALL
A31: Street Lighting | B31: SD Street and Security Lighting | C31: 458 | D31: ALL
B32: SDC Street and Security Lighting-Customer Owned | C32: 459 | D32: ALL
A35: Issued by: Daniel Hurstak | E35: Issued: January 30, 2025
A36: Vice President and Treasurer | E36: Effective: March 1, 2025
