Workbook
Name \A: #REF!
Name \A: #REF!
Name \A: #REF!
Name \A: #REF!
Name \B: #REF!
Name \B: #REF!
Name \B: #REF!
Name \C: #N/A
Name \D: #REF!
Name \D: #REF!
Name \D: #REF!
Name \E: #REF!
Name \E: #REF!
Name \E: #REF!
Name \F: #REF!
Name \F: #REF!
Name \F: #REF!
Name \H: #REF!
Name \I: #N/A
Name \K: #N/A
Name \L: #N/A
Name \M: #N/A
Name \N: #N/A
Name \P: #REF!
Name \R: #N/A
Name \S: #N/A
Name \W: #N/A
Name \X: #N/A
Name \Y: #N/A
Name \Z: #N/A
Name ______PG2: #REF!
Name ______PG3: #REF!
Name _____JAN1: #REF!
Name _____OM1: #REF!
Name _____om2: #REF!
Name _____om2: #REF!
Name _____PG1: #REF!
Name _____PG1: #REF!
Name _____PG2: #REF!
Name _____PG2: #REF!
Name _____PG3: #REF!
Name _____PG3: #REF!
Name _____RB1998: #REF!
Name _____RB1999: #REF!
Name _____REV2: #REF!
Name ____PG1: #REF!
Name ____PG2: #REF!
Name ____PG3: #REF!
Name ____RB1998: #REF!
Name ___CCR4: #REF!
Name ___CCR4: #REF!
Name ___CCR4: #REF!
Name ___CCR4: #REF!
Name ___CCR5: #REF!
Name ___CCR5: #REF!
Name ___CCR5: #REF!
Name ___CCR5: #REF!
Name ___CCT2: #REF!
Name ___CCT2: #REF!
Name ___CCT2: #REF!

Sheet Sch 1_Heat Pump Rate Design
A1: 1
A2: =A1+1 -> 2
A3: =A2+1 -> 3
A4: =A3+1 -> 4 | B4: Proposed Residential Heat Pump Rate Design (R-1HP/R-2HP)
A5: =A4+1 -> 5
A6: =A5+1 -> 6 | B6: Distribution Rate Design | C6: Proposed
A7: =A6+1 -> 7 | B7: Customer Charge | C7: 10
A8: =A7+1 -> 8 | B8: Energy Charge - Summer (June - Sept) | C8: =(0.06264*C15)/C12 -> 0.067395093
A9: =A8+1 -> 9 | B9: Energy Charge - Winter (Oct - May) | C9: =(C25-SUM(C21:C22))/C13 -> 0.021917056
A10: =A9+1 -> 10
A11: =A10+1 -> 11 | B11: Test Year Bills | C11: =SUM('WP_Electric Test Year BQs'!O42:O43) -> 13685092
A12: =A11+1 -> 12 | B12: Test Year Summer kWh - HP adjusted | C12: =SUM('WP_Electric Test Year BQs'!$H$9:$K$10)*C19 -> 2.6509934e+09
A13: =A12+1 -> 13 | B13: Test Year Winter kWh - HP adjusted | C13: =SUM('WP_Electric Test Year BQs'!$C$9:$G$10,'WP_Electric Test Year BQs'!$L$9:$N$10)*C18 -> 1.2465334e+10
A14: =A13+1 -> 14 | B14: Test Year kWh - HP Adjusted | C14: =C13+C12 -> 1.5116328e+10
A15: =A14+1 -> 15 | B15: Test Year Summer kWh | C15: =SUM('WP_Electric Test Year BQs'!$H$9:$K$10) -> 2.8522342e+09
A16: =A15+1 -> 16 | B16: Test Year Winter kWh | C16: =SUM('WP_Electric Test Year BQs'!$C$9:$G$10,'WP_Electric Test Year BQs'!$L$9:$N$10) -> 4.3612771e+09
A17: =A16+1 -> 17 | B17: Test Year Annual kWh | C17: =C16+C15 -> 7.2135113e+09
A18: =A17+1 -> 18 | B18: Winter Heat Pump Adj. Factor | C18: =SUM('Sch 2_HP Sales Conversion'!K11:K17,'Sch 2_HP Sales Conversion'!K22)/SUM('Sch 2_HP Sales Conversion'!E11:E17,'Sch 2_HP Sales Conversion'!E22) -> 2.8581845
A19: =A18+1 -> 19 | B19: Summer Heat Pump Adj. Factor | C19: =SUM('Sch 2_HP Sales Conversion'!K18:K21)/SUM('Sch 2_HP Sales Conversion'!E18:E21) -> 0.92944452
A20: =A19+1 -> 20
A21: =A20+1 -> 21 | B21: Customer Revenue | C21: =C7*C11 -> 1.3685092e+08
A22: =A21+1 -> 22 | B22: Energy Revenue - Summer | C22: =C8*C12 -> 1.7866395e+08
A23: =A22+1 -> 23 | B23: Energy Revenue - Winter | C23: =C9*C13 -> 2.7320343e+08
A24: =A23+1 -> 24 | B24: Total Base Rate Revenue | C24: =SUM(C21:C23) -> 5.887183e+08
A25: =A24+1 -> 25 | B25: 2025 Target Base Rate Revenue (DPU 24-137) | C25: 5.887183e+08
A26: =A25+1 -> 26 | B26: Difference from Target | C26: =C24/C25-1 -> 0
A27: =A26+1 -> 27
A28: =A27+1 -> 28 | B28: Transmission Rate Design | C28: Proposed
A29: =A28+1 -> 29 | B29: Energy Charge - Summer (June - Sept) | C29: =(0.04545*C35)/C32 -> 0.048900176
A30: =A29+1 -> 30 | B30: Energy Charge - Winter (Oct - May) | C30: =(C42-C39)/C33 -> 0.015906022
A31: =A30+1 -> 31
A32: =A31+1 -> 32 | B32: 2025 Forecast Sales - Summer - HP adjusted | C32: =C35*C19 -> 2.7475241e+09
A33: =A32+1 -> 33 | B33: 2025 Forecast Sales - Winter - HP adjusted | C33: =C36*C18 -> 1.4676172e+10
A34: =A33+1 -> 34 | B34: 2025 Forecast Sales (kWh) - HP Adjusted | C34: =C33+C32 -> 1.7423696e+10
A35: =A34+1 -> 35 | B35: 2025 Forecast Sales - Summer | C35: =SUM('WP_Sales Forecast'!H6:K6) -> 2.9560926e+09
A36: =A35+1 -> 36 | B36: 2025 Forecast Sales - Winter | C36: =C37-C35 -> 5.1347882e+09
A37: =A36+1 -> 37 | B37: 2025 Forecast Annual Sales (kWh) | C37: ='WP_Sales Forecast'!O6 -> 8.0908808e+09
A38: =A37+1 -> 38
A39: =A38+1 -> 39 | B39: Energy Revenue - Summer | C39: =C29*C32 -> 1.3435441e+08
A40: =A39+1 -> 40 | B40: Energy Revenue - Winter | C40: =C30*C33 -> 2.3343952e+08
...

Sheet Sch 2_HP Sales Conversion
A1: 1
A2: =A1+1 -> 2
A3: =A2+1 -> 3
A4: =A3+1 -> 4 | B4: Heat Pump Sales Adjustment
A5: =A4+1 -> 5
A6: =A5+1 -> 6
A7: =A6+1 -> 7
A8: =A7+1 -> 8 | C8: ELECTRIC | N8: THERMAL HEATING REQUIREMENTS
A9: =A8+1 -> 9 | C9: Rate R-1/R-2 | D9: Rate R-1/R-2 | E9: Rate R-1/R-2 | F9: Cooling | G9: Cooling | H9: ASHP | I9: Heating | J9: Cooling | K9: Post-ASHP | L9: Estimated Sales | N9: Rate R-3/R-4 | O9: Rate R-3/R-4 | P9: Rate R-3/R-4 | Q9: Heating | R9: Heating | S9: Non-Heat
A10: =A9+1 -> 10 | B10: Month | C10: TY Sales (kWh) | D10: TY Cust (Bills) | E10: TY Sales/Cust | F10: kWh | G10: kWh/Cust | H10: kWh/Cust | I10: COP (1) | J10: COP (1) | K10: kWh/Cust | L10: Adjustment (%) | N10: TY Sales (Therms) | O10: TY Cust (Bills) | P10: TY Sales/Cust | Q10: Therms | R10: Therms/Cust | S10: Therms
A11: =A10+1 -> 11 | B11: November | C11: =SUM('WP_Electric Test Year BQs'!M9:M10) -> 5.1302534e+08 | D11: =SUM('WP_Electric Test Year BQs'!M42:M43) -> 1164765.9 | E11: =C11/D11 -> 440.45361 | F11: 0 | G11: =F11/D11 -> 0 | H11: =R11*'WP_Efficiency Factors'!$B$6/(3412*I11) -> 697.54619 | I11: 2.71 | K11: =H11-G11+E11 -> 1137.9998 | L11: =K11/E11 -> 2.5836996 | N11: =SUM('WP_Gas Test Year BQs'!L14:L15) -> 22688057 | O11: =SUM('WP_Gas Test Year BQs'!L27:L28) -> 254228 | P11: =N11/O11 -> 89.242953 | Q11: =N11-S11 -> 18815132 | R11: =Q11/O11 -> 74.00889 | S11: =AVERAGE(N19:N20) -> 3872925.2
A12: =A11+1 -> 12 | B12: December | C12: =SUM('WP_Electric Test Year BQs'!N9:N10) -> 5.6834721e+08 | D12: =SUM('WP_Electric Test Year BQs'!N42:N43) -> 1142056.7 | E12: =C12/D12 -> 497.65237 | F12: 0 | G12: =F12/D12 -> 0 | H12: =R12*'WP_Efficiency Factors'!$B$6/(3412*I12) -> 1259.6151 | I12: 2.59 | K12: =H12-G12+E12 -> 1757.2675 | L12: =K12/E12 -> 3.5311144 | N12: =SUM('WP_Gas Test Year BQs'!M14:M15) -> 35933552 | O12: =SUM('WP_Gas Test Year BQs'!M27:M28) -> 251011 | P12: =N12/O12 -> 143.15529 | Q12: =N12-S12 -> 32060626 | R12: =Q12/O12 -> 127.72598 | S12: =S11 -> 3872925.2
A13: =A12+1 -> 13 | B13: January | C13: =SUM('WP_Electric Test Year BQs'!C9:C10) -> 6.4690523e+08 | D13: =SUM('WP_Electric Test Year BQs'!C$42:C$43) -> 1135602.1 | E13: =C13/D13 -> 569.65834 | F13: 0 | G13: =F13/D13 -> 0 | H13: =R13*'WP_Efficiency Factors'!$B$6/(3412*I13) -> 1671.7427 | I13: 2.42 | K13: =H13-G13+E13 -> 2241.401 | L13: =K13/E13 -> 3.934641 | N13: =SUM('WP_Gas Test Year BQs'!B$14:B$15) -> 43147823 | O13: =SUM('WP_Gas Test Year BQs'!B$27:B$28) -> 247964 | P13: =N13/O13 -> 174.00842 | Q13: =N13-S13 -> 39274898 | R13: =Q13/O13 -> 158.38952 | S13: =S12 -> 3872925.2
A14: =A13+1 -> 14 | B14: February | C14: =SUM('WP_Electric Test Year BQs'!D9:D10) -> 6.0805541e+08 | D14: =SUM('WP_Electric Test Year BQs'!D$42:D$43) -> 1136317.1 | E14: =C14/D14 -> 535.11066 | F14: 0 | G14: =F14/D14 -> 0 | H14: =R14*'WP_Efficiency Factors'!$B$6/(3412*I14) -> 1366.4551 | I14: 2.48 | K14: =H14-G14+E14 -> 1901.5658 | L14: =K14/E14 -> 3.5535936 | N14: =SUM('WP_Gas Test Year BQs'!C$14:C$15) -> 36776295 | O14: =SUM('WP_Gas Test Year BQs'!C$27:C$28) -> 248000 | P14: =N14/O14 -> 148.29151 | Q14: =N14-S14 -> 32903369 | R14: =Q14/O14 -> 132.67488 | S14: =S13 -> 3872925.2
A15: =A14+1 -> 15 | B15: March | C15: =SUM('WP_Electric Test Year BQs'!E9:E10) -> 5.5119418e+08 | D15: =SUM('WP_Electric Test Year BQs'!E$42:E$43) -> 1138190.9 | E15: =C15/D15 -> 484.27217 | F15: 0 | G15: =F15/D15 -> 0 | H15: =R15*'WP_Efficiency Factors'!$B$6/(3412*I15) -> 1049.6272 | I15: 2.67 | K15: =H15-G15+E15 -> 1533.8994 | L15: =K15/E15 -> 3.1674325 | N15: =SUM('WP_Gas Test Year BQs'!D$14:D$15) -> 31232622 | O15: =SUM('WP_Gas Test Year BQs'!D$27:D$28) -> 249358 | P15: =N15/O15 -> 125.25214 | Q15: =N15-S15 -> 27359697 | R15: =Q15/O15 -> 109.72055 | S15: =S14 -> 3872925.2
A16: =A15+1 -> 16 | B16: April | C16: =SUM('WP_Electric Test Year BQs'!F9:F10) -> 4.9712024e+08 | D16: =SUM('WP_Electric Test Year BQs'!F$42:F$43) -> 1140705.2 | E16: =C16/D16 -> 435.80078 | F16: 0 | G16: =F16/D16 -> 0 | H16: =R16*'WP_Efficiency Factors'!$B$6/(3412*I16) -> 526.65541 | I16: 2.78 | K16: =H16-G16+E16 -> 962.45619 | L16: =K16/E16 -> 2.2084774 | N16: =SUM('WP_Gas Test Year BQs'!E$14:E$15) -> 18148465 | O16: =SUM('WP_Gas Test Year BQs'!E$27:E$28) -> 249046 | P16: =N16/O16 -> 72.87194 | Q16: =N16-S16 -> 14275540 | R16: =Q16/O16 -> 57.320896 | S16: =S15 -> 3872925.2
A17: =A16+1 -> 17 | B17: May | C17: =SUM('WP_Electric Test Year BQs'!G9:G10) -> 4.5928212e+08 | D17: =SUM('WP_Electric Test Year BQs'!G$42:G$43) -> 1139718.5 | E17: =C17/D17 -> 402.97855 | F17: 0 | G17: =F17/D17 -> 0 | H17: =R17*'WP_Efficiency Factors'!$B$6/(3412*I17) -> 211.28365 | I17: 2.83 | J17: 4.28 | K17: =H17-G17+E17 -> 614.2622 | L17: =K17/E17 -> 1.524305 | N17: =SUM('WP_Gas Test Year BQs'!F$14:F$15) -> 9704419.9 | O17: =SUM('WP_Gas Test Year BQs'!F$27:F$28) -> 249107 | P17: =N17/O17 -> 38.956834 | Q17: =N17-S17 -> 5831494.7 | R17: =Q17/O17 -> 23.409598 | S17: =S16 -> 3872925.2
A18: =A17+1 -> 18 | B18: June | C18: =SUM('WP_Electric Test Year BQs'!H9:H10) -> 5.9137825e+08 | D18: =SUM('WP_Electric Test Year BQs'!H$42:H$43) -> 1142046.3 | E18: =C18/D18 -> 517.82334 | F18: =C18-AVERAGE($C$16:$C$17,$C$22) -> 1.0012836e+08 | G18: =F18/D18 -> 87.674512 | H18: =G18*('WP_Efficiency Factors'!$B$7/(3412*J18))+R18*('WP_Efficiency Factors'!$B$6/(3412*I17)) -> 114.04645 | J18: 4.54 | K18: =H18-G18+E18 -> 544.19528 | L18: =K18/E18 -> 1.0509284 | N18: =SUM('WP_Gas Test Year BQs'!G$14:G$15) -> 5301177.1 | O18: =SUM('WP_Gas Test Year BQs'!G$27:G$28) -> 248915 | P18: =N18/O18 -> 21.297138 | Q18: =N18-S18 -> 1428251.9 | R18: =Q18/O18 -> 5.7379102 | S18: =S17 -> 3872925.2
A19: =A18+1 -> 19 | B19: July | C19: =SUM('WP_Electric Test Year BQs'!I9:I10) -> 7.4550818e+08 | D19: =SUM('WP_Electric Test Year BQs'!I$42:I$43) -> 1141572.8 | E19: =C19/D19 -> 653.05354 | F19: =C19-AVERAGE($C$16:$C$17,$C$22) -> 2.5425829e+08 | G19: =F19/D19 -> 222.72629 | H19: =G19*('WP_Efficiency Factors'!$B$7/(3412*J19)) -> 157.12271 | J19: 4.57 | K19: =H19-G19+E19 -> 587.44995 | L19: =K19/E19 -> 0.89954333 | N19: =SUM('WP_Gas Test Year BQs'!H$14:H$15) -> 3872925.2 | O19: =SUM('WP_Gas Test Year BQs'!H$27:H$28) -> 248733 | P19: =N19/O19 -> 15.570613 | Q19: =N19-S19 -> 0 | R19: =Q19/O19 -> 0 | S19: =S18 -> 3872925.2
A20: =A19+1 -> 20 | B20: August | C20: =SUM('WP_Electric Test Year BQs'!J9:J10) -> 7.392397e+08 | D20: =SUM('WP_Electric Test Year BQs'!J$42:J$43) -> 1136129.1 | E20: =C20/D20 -> 650.66524 | F20: =C20-AVERAGE($C$16:$C$17,$C$22) -> 2.479898e+08 | G20: =F20/D20 -> 218.27608 | H20: =G20*('WP_Efficiency Factors'!$B$7/(3412*J20)) -> 149.72418 | J20: 4.7 | K20: =H20-G20+E20 -> 582.11335 | L20: =K20/E20 -> 0.89464337 | N20: =SUM('WP_Gas Test Year BQs'!I$14:I$15) -> 3872925.2 | O20: =SUM('WP_Gas Test Year BQs'!I$27:I$28) -> 248622 | P20: =N20/O20 -> 15.577564 | Q20: =N20-S20 -> 0 | R20: =Q20/O20 -> 0 | S20: =S19 -> 3872925.2
A21: =A20+1 -> 21 | B21: September | C21: =SUM('WP_Electric Test Year BQs'!K9:K10) -> 7.7610807e+08 | D21: =SUM('WP_Electric Test Year BQs'!K$42:K$43) -> 1145685.2 | E21: =C21/D21 -> 677.41823 | F21: =C21-AVERAGE($C$16:$C$17,$C$22) -> 2.8485818e+08 | G21: =F21/D21 -> 248.63563 | H21: =G21*('WP_Efficiency Factors'!$B$7/(3412*J21))+R21*('WP_Efficiency Factors'!$B$6/(3412*I22)) -> 180.10383 | J21: 4.64 | K21: =H21-G21+E21 -> 608.88642 | L21: =K21/E21 -> 0.89883383 | N21: =SUM('WP_Gas Test Year BQs'!J$14:J$15) -> 4072558.5 | O21: =SUM('WP_Gas Test Year BQs'!J$27:J$28) -> 248675 | P21: =N21/O21 -> 16.377032 | Q21: =N21-S21 -> 199633.23 | R21: =Q21/O21 -> 0.80278768 | S21: =S20 -> 3872925.2
A22: =A21+1 -> 22 | B22: October | C22: =SUM('WP_Electric Test Year BQs'!L9:L10) -> 5.1734733e+08 | D22: =SUM('WP_Electric Test Year BQs'!L$42:L$43) -> 1122302.2 | E22: =C22/D22 -> 460.96974 | F22: 0 | G22: =F22/D22 -> 0 | H22: =R22*'WP_Efficiency Factors'!$B$6/(3412*I22) -> 328.15382 | I22: 2.79 | J22: 4.56 | K22: =H22-G22+E22 -> 789.12356 | L22: =K22/E22 -> 1.7118771 | N22: =SUM('WP_Gas Test Year BQs'!K$14:K$15) -> 12679433 | O22: =SUM('WP_Gas Test Year BQs'!K$27:K$28) -> 245686 | P22: =N22/O22 -> 51.608283 | Q22: =N22-S22 -> 8806507.5 | R22: =Q22/O22 -> 35.844564 | S22: =S21 -> 3872925.2
A23: =A22+1 -> 23 | B23: Total | C23: =SUM(C11:C22) -> 7.2135113e+09 | D23: =SUM(D11:D22) -> 13685092 | E23: =SUM(E11:E22) -> 6325.8566 | F23: =SUM(F11:F22) -> 8.8723462e+08 | G23: =SUM(G11:G22) -> 777.31252 | H23: =SUM(H11:H22) -> 7712.0764 | K23: =SUM(K11:K22) -> 13260.62 | L23: =K23/E23 -> 2.0962569 | N23: =SUM(N11:N22) -> 2.2743025e+08 | O23: =SUM(O11:O22) -> 2989345 | P23: =SUM(P11:P22) -> 912.20971 | Q23: =SUM(Q11:Q22) -> 1.8095515e+08 | R23: =SUM(R11:R22) -> 725.63557 | S23: =SUM(S11:S22) -> 46475103
B25: Notes:
B26: (1) Monthly COP values were based on an analysis provided by Guidehouse Inc. Their results will be provided in an update to their Massachusetts and Connecticut Heat Pump Metering Study. The study is expected to be updated and published near the time of this filing.
B27: https://ma-eeac.org/wp-content/uploads/MA-HPMS-CT-R2246-Heat-Pump-Metering-Study-Final-Report_August_2024.pdf

Sheet Sch 3_Bill Impact_ASHP
A1: 1
A2: =A1+1 -> 2
A3: =A2+1 -> 3
A4: =A3+1 -> 4 | B4: AIR SOURCE HEAT PUMP AVERAGE ELECTRIC BILL IMPACTS
A5: =A4+1 -> 5
A6: =A5+1 -> 6 | C6: ELECTRIC | O6: HEATING REQUIREMENTS
A7: =A6+1 -> 7
A8: =A7+1 -> 8 | C8: Current | D8: Cooling | E8: Current R-1 | F8: Current R-3 Gas | G8: Total | H8: ASHP | I8: Post-ASHP | J8: Projected R-1 | K8: Projected R-1HP | L8: R-1 to R-1HP | M8: Total Electric/Gas | O8: R-3/R-4 | P8: R-3 Heating | Q8: R-3 Non-Heat
A9: =A8+1 -> 9 | B9: Bill Date | C9: kWh | D9: kWh | E9: Monthly Bill | F9: Monthly Bill (1) | G9: Electric/Gas | H9: kWh | I9: kWh | J9: Monthly Bill | K9: Monthly Bill | L9: Change (%) | M9: to R-1HP Change (%) | O9: Therms/Cust | P9: Therms/Cust | Q9: Therms/Cust
A10: =A9+1 -> 10 | B10: November | C10: ='Sch 2_HP Sales Conversion'!E11 -> 440.45361 | D10: 0 | E10: =(C10*'WP_Rate Inputs'!$B$11)+'WP_Rate Inputs'!$B$7 -> 152.544 | F10: ='WP_Rate Inputs'!$F$21*P10 -> 186.84779 | G10: =F10+E10 -> 339.39179 | H10: =P10*'WP_Efficiency Factors'!$B$6/'WP_Efficiency Factors'!$B$9 -> 792.6598 | I10: =H10-D10+C10 -> 1233.1134 | J10: =(I10*'WP_Rate Inputs'!$B$11)+'WP_Rate Inputs'!$B$10 -> 409.07249 | K10: =(I10*'WP_Rate Inputs'!$F$13)+'WP_Rate Inputs'!$F$12 -> 322.40928 | L10: =K10/J10-1 -> -0.21185294 | M10: =K10/G10-1 -> -0.050038059 | O10: ='Sch 2_HP Sales Conversion'!P11 -> 89.242953 | P10: =O10-Q10 -> 73.67234 | Q10: =Q18 -> 15.570613
A11: =A10+1 -> 11 | B11: December | C11: ='Sch 2_HP Sales Conversion'!E12 -> 497.65237 | D11: 0 | E11: =(C11*'WP_Rate Inputs'!$B$11)+'WP_Rate Inputs'!$B$7 -> 171.05524 | F11: ='WP_Rate Inputs'!$F$21*P11 -> 323.58025 | G11: =F11+E11 -> 494.63549 | H11: =P11*'WP_Efficiency Factors'!$B$6/'WP_Efficiency Factors'!$B$9 -> 1372.7166 | I11: =H11-D11+C11 -> 1870.369 | J11: =(I11*'WP_Rate Inputs'!$B$11)+'WP_Rate Inputs'!$B$10 -> 615.3075 | K11: =(I11*'WP_Rate Inputs'!$F$13)+'WP_Rate Inputs'!$F$12 -> 483.85797 | L11: =K11/J11-1 -> -0.21363226 | M11: =K11/G11-1 -> -0.021788796 | O11: ='Sch 2_HP Sales Conversion'!P12 -> 143.15529 | P11: =O11-Q11 -> 127.58467 | Q11: =Q10 -> 15.570613
A12: =A11+1 -> 12 | B12: January | C12: ='Sch 2_HP Sales Conversion'!E13 -> 569.65834 | D12: 0 | E12: =(C12*'WP_Rate Inputs'!$B$11)+'WP_Rate Inputs'!$B$7 -> 194.35853 | F12: ='WP_Rate Inputs'!$F$21*P12 -> 401.82996 | G12: =F12+E12 -> 596.18849 | H12: =P12*'WP_Efficiency Factors'!$B$6/'WP_Efficiency Factors'!$B$9 -> 1704.6734 | I12: =H12-D12+C12 -> 2274.3318 | J12: =(I12*'WP_Rate Inputs'!$B$11)+'WP_Rate Inputs'!$B$10 -> 746.04199 | K12: =(I12*'WP_Rate Inputs'!$F$13)+'WP_Rate Inputs'!$F$12 -> 586.20195 | L12: =K12/J12-1 -> -0.21425072 | M12: =K12/G12-1 -> -0.016750638 | O12: ='Sch 2_HP Sales Conversion'!P13 -> 174.00842 | P12: =O12-Q12 -> 158.43781 | Q12: =Q11 -> 15.570613
A13: =A12+1 -> 13 | B13: February | C13: ='Sch 2_HP Sales Conversion'!E14 -> 535.11066 | D13: 0 | E13: =(C13*'WP_Rate Inputs'!$B$11)+'WP_Rate Inputs'!$B$7 -> 183.17786 | F13: ='WP_Rate Inputs'!$F$21*P13 -> 336.60674 | G13: =F13+E13 -> 519.7846 | H13: =P13*'WP_Efficiency Factors'!$B$6/'WP_Efficiency Factors'!$B$9 -> 1427.9785 | I13: =H13-D13+C13 -> 1963.0892 | J13: =(I13*'WP_Rate Inputs'!$B$11)+'WP_Rate Inputs'!$B$10 -> 645.31456 | K13: =(I13*'WP_Rate Inputs'!$F$13)+'WP_Rate Inputs'!$F$12 -> 507.34865 | L13: =K13/J13-1 -> -0.21379637 | M13: =K13/G13-1 -> -0.023925205 | O13: ='Sch 2_HP Sales Conversion'!P14 -> 148.29151 | P13: =O13-Q13 -> 132.7209 | Q13: =Q12 -> 15.570613
A14: =A13+1 -> 14 | B14: March | C14: ='Sch 2_HP Sales Conversion'!E15 -> 484.27217 | D14: 0 | E14: =(C14*'WP_Rate Inputs'!$B$11)+'WP_Rate Inputs'!$B$7 -> 166.725 | F14: ='WP_Rate Inputs'!$F$21*P14 -> 278.17428 | G14: =F14+E14 -> 444.89928 | H14: =P14*'WP_Efficiency Factors'!$B$6/'WP_Efficiency Factors'!$B$9 -> 1180.0919 | I14: =H14-D14+C14 -> 1664.3641 | J14: =(I14*'WP_Rate Inputs'!$B$11)+'WP_Rate Inputs'!$B$10 -> 548.63816 | K14: =(I14*'WP_Rate Inputs'!$F$13)+'WP_Rate Inputs'!$F$12 -> 431.66665 | L14: =K14/J14-1 -> -0.21320338 | M14: =K14/G14-1 -> -0.029742986 | O14: ='Sch 2_HP Sales Conversion'!P15 -> 125.25214 | P14: =O14-Q14 -> 109.68152 | Q14: =Q13 -> 15.570613
A15: =A14+1 -> 15 | B15: April | C15: ='Sch 2_HP Sales Conversion'!E16 -> 435.80078 | D15: 0 | E15: =(C15*'WP_Rate Inputs'!$B$11)+'WP_Rate Inputs'!$B$7 -> 151.03821 | F15: ='WP_Rate Inputs'!$F$21*P15 -> 145.32763 | G15: =F15+E15 -> 296.36583 | H15: =P15*'WP_Efficiency Factors'!$B$6/'WP_Efficiency Factors'!$B$9 -> 616.51984 | I15: =H15-D15+C15 -> 1052.3206 | J15: =(I15*'WP_Rate Inputs'!$B$11)+'WP_Rate Inputs'!$B$10 -> 350.56252 | K15: =(I15*'WP_Rate Inputs'!$F$13)+'WP_Rate Inputs'!$F$12 -> 276.60543 | L15: =K15/J15-1 -> -0.21096691 | M15: =K15/G15-1 -> -0.066675717 | O15: ='Sch 2_HP Sales Conversion'!P16 -> 72.87194 | P15: =O15-Q15 -> 57.301327 | Q15: =Q14 -> 15.570613
A16: =A15+1 -> 16 | B16: May | C16: ='Sch 2_HP Sales Conversion'!E17 -> 402.97855 | D16: 0 | E16: =(C16*'WP_Rate Inputs'!$B$11)+'WP_Rate Inputs'!$B$7 -> 140.41595 | F16: ='WP_Rate Inputs'!$E$21*P16 -> 43.575545 | G16: =F16+E16 -> 183.99149 | H16: =P16*'WP_Efficiency Factors'!$B$6/'WP_Efficiency Factors'!$B$9 -> 251.61841 | I16: =H16-D16+C16 -> 654.59696 | J16: =(I16*'WP_Rate Inputs'!$B$11)+'WP_Rate Inputs'!$B$10 -> 221.84721 | K16: =(I16*'WP_Rate Inputs'!$F$13)+'WP_Rate Inputs'!$F$12 -> 175.84214 | L16: =K16/J16-1 -> -0.20737278 | M16: =K16/G16-1 -> -0.044292009 | O16: ='Sch 2_HP Sales Conversion'!P17 -> 38.956834 | P16: =O16-Q16 -> 23.386221 | Q16: =Q15 -> 15.570613
A17: =A16+1 -> 17 | B17: June | C17: ='Sch 2_HP Sales Conversion'!E18 -> 517.82334 | D17: =C17-AVERAGE($C$15:$C$16,$C$21) -> 84.573651 | E17: =(C17*'WP_Rate Inputs'!$B$11)+'WP_Rate Inputs'!$B$7 -> 177.58317 | F17: ='WP_Rate Inputs'!$E$21*P17 -> 10.670235 | G17: =F17+E17 -> 188.2534 | H17: =D17*'WP_Efficiency Factors'!$B$7/'WP_Efficiency Factors'!$B$10 -> 66.450726 | I17: =H17-D17+C17 -> 499.70041 | J17: =(I17*'WP_Rate Inputs'!$B$11)+'WP_Rate Inputs'!$B$10 -> 171.71805 | K17: =(I17*'WP_Rate Inputs'!$E$13)+'WP_Rate Inputs'!$E$12 -> 175.81559 | L17: =K17/J17-1 -> 0.023862043 | M17: =K17/G17-1 -> -0.066069529 | O17: ='Sch 2_HP Sales Conversion'!P18 -> 21.297138 | P17: =O17-Q17 -> 5.7265254 | Q17: =Q16 -> 15.570613
A18: =A17+1 -> 18 | B18: July | C18: ='Sch 2_HP Sales Conversion'!E19 -> 653.05354 | D18: =C18-AVERAGE($C$15:$C$16,$C$21) -> 219.80385 | E18: =(C18*'WP_Rate Inputs'!$B$11)+'WP_Rate Inputs'!$B$7 -> 221.34772 | F18: ='WP_Rate Inputs'!$E$21*P18 -> 0 | G18: =F18+E18 -> 221.34772 | H18: =D18*'WP_Efficiency Factors'!$B$7/'WP_Efficiency Factors'!$B$10 -> 172.70302 | I18: =H18-D18+C18 -> 605.95271 | J18: =(I18*'WP_Rate Inputs'!$B$11)+'WP_Rate Inputs'!$B$10 -> 206.10448 | K18: =(I18*'WP_Rate Inputs'!$E$13)+'WP_Rate Inputs'!$E$12 -> 211.07329 | L18: =K18/J18-1 -> 0.024108221 | M18: =K18/G18-1 -> -0.04641759 | O18: ='Sch 2_HP Sales Conversion'!P19 -> 15.570613 | P18: =O18-Q18 -> 0 | Q18: =O18 -> 15.570613
A19: =A18+1 -> 19 | B19: August | C19: ='Sch 2_HP Sales Conversion'!E20 -> 650.66524 | D19: =C19-AVERAGE($C$15:$C$16,$C$21) -> 217.41555 | E19: =(C19*'WP_Rate Inputs'!$B$11)+'WP_Rate Inputs'!$B$7 -> 220.57479 | F19: ='WP_Rate Inputs'!$E$21*P19 -> 0 | G19: =F19+E19 -> 220.57479 | H19: =D19*'WP_Efficiency Factors'!$B$7/'WP_Efficiency Factors'!$B$10 -> 170.82651 | I19: =H19-D19+C19 -> 604.0762 | J19: =(I19*'WP_Rate Inputs'!$B$11)+'WP_Rate Inputs'!$B$10 -> 205.49718 | K19: =(I19*'WP_Rate Inputs'!$E$13)+'WP_Rate Inputs'!$E$12 -> 210.4506 | L19: =K19/J19-1 -> 0.024104588 | M19: =K19/G19-1 -> -0.045899119 | O19: ='Sch 2_HP Sales Conversion'!P20 -> 15.577564 | P19: =O19-Q19 -> 0 | Q19: =O19 -> 15.577564
A20: =A19+1 -> 20 | B20: September | C20: ='Sch 2_HP Sales Conversion'!E21 -> 677.41823 | D20: =C20-AVERAGE($C$15:$C$16,$C$21) -> 244.16854 | E20: =(C20*'WP_Rate Inputs'!$B$11)+'WP_Rate Inputs'!$B$7 -> 229.23286 | F20: ='WP_Rate Inputs'!$E$21*P20 -> 1.489648 | G20: =F20+E20 -> 230.72251 | H20: =D20*'WP_Efficiency Factors'!$B$7/'WP_Efficiency Factors'!$B$10 -> 191.84671 | I20: =H20-D20+C20 -> 625.0964 | J20: =(I20*'WP_Rate Inputs'!$B$11)+'WP_Rate Inputs'!$B$10 -> 212.29995 | K20: =(I20*'WP_Rate Inputs'!$E$13)+'WP_Rate Inputs'!$E$12 -> 217.42574 | L20: =K20/J20-1 -> 0.024144097 | M20: =K20/G20-1 -> -0.057631011 | O20: ='Sch 2_HP Sales Conversion'!P21 -> 16.377032 | P20: =O20-Q20 -> 0.79946764 | Q20: =Q19 -> 15.577564
A21: =A20+1 -> 21 | B21: October | C21: ='Sch 2_HP Sales Conversion'!E22 -> 460.96974 | D21: 0 | E21: =(C21*'WP_Rate Inputs'!$B$11)+'WP_Rate Inputs'!$B$7 -> 159.18364 | F21: ='WP_Rate Inputs'!$E$21*P21 -> 67.136039 | G21: =F21+E21 -> 226.31968 | H21: =P21*'WP_Efficiency Factors'!$B$6/'WP_Efficiency Factors'!$B$9 -> 387.66385 | I21: =H21-D21+C21 -> 848.63359 | J21: =(I21*'WP_Rate Inputs'!$B$11)+'WP_Rate Inputs'!$B$10 -> 284.64329 | K21: =(I21*'WP_Rate Inputs'!$F$13)+'WP_Rate Inputs'!$F$12 -> 225.00132 | L21: =K21/J21-1 -> -0.20953232 | M21: =K21/G21-1 -> -0.0058251962 | O21: ='Sch 2_HP Sales Conversion'!P22 -> 51.608283 | P21: =O21-Q21 -> 36.030719 | Q21: =Q20 -> 15.577564
A22: =A21+1 -> 22 | B22: Total | C22: =SUM(C10:C21) -> 6325.8566 | D22: =SUM(D10:D21) -> 765.9616 | E22: =SUM(E10:E21) -> 2167.237 | F22: =SUM(F10:F21) -> 1795.2381 | G22: =SUM(G10:G21) -> 3962.4751 | H22: =SUM(H10:H21) -> 8335.7494 | I22: =SUM(I10:I21) -> 13895.644 | J22: =SUM(J10:J21) -> 4617.0474 | K22: =SUM(K10:K21) -> 3823.6986 | L22: =K22/J22-1 -> -0.17183033 | M22: =K22/G22-1 -> -0.03502267 | O22: =SUM(O10:O21) -> 912.20971 | P22: =SUM(P10:P21) -> 725.3415 | Q22: =SUM(Q10:Q21) -> 186.86821
A23: =A22+1 -> 23 | B23: Monthly Average | C23: =C22/12 -> 527.15471 | E23: =E22/12 -> 180.60308 | F23: =F22/12 -> 149.60318 | G23: =G22/12 -> 330.20626 | H23: =H22/12 -> 694.64578 | I23: =I22/12 -> 1157.9704 | J23: =J22/12 -> 384.75395 | K23: =K22/12 -> 318.64155 | L23: =K23/J23-1 -> -0.17183033 | M23: =K23/G23-1 -> -0.03502267 | O23: =O22/12 -> 76.017476 | P23: =P22/12 -> 60.445125 | Q23: =Q22/12 -> 15.572351
A24: =A23+1 -> 24
A25: =A24+1 -> 25 | B25: Notes
A26: =A25+1 -> 26 | B26: (1) Reflects heating portion of energy cost only; customer charge excluded under assumption that gas is still used for non-heating purposes

Sheet WP_Electric Test Year BQs
A1: NSTAR Electric Company
A2: d/b/a Eversource Energy
A7: Rate Class | B7: Service Area | C7: Jan | D7: Feb | E7: Mar | F7: Apr | G7: May | H7: Jun | I7: Jul | J7: Aug | K7: Sep | L7: Oct | M7: Nov | N7: Dec | O7: Total
A8: SALES
A9: R-1 | B9: All | C9: 5.7974582e+08 | D9: 5.4359087e+08 | E9: 4.9053307e+08 | F9: 4.4345001e+08 | G9: 4.1008498e+08 | H9: 5.2934876e+08 | I9: 6.7125715e+08 | J9: 6.6395282e+08 | K9: 6.9800001e+08 | L9: 4.6369975e+08 | M9: 4.583374e+08 | N9: 5.0545743e+08 | O9: =SUM(C9:N9) -> 6.4574581e+09
A10: R-2 | B10: All | C10: 67159413 | D10: 64464538 | E10: 60661112 | F10: 53670228 | G10: 49197137 | H10: 62029493 | I10: 74251035 | J10: 75286874 | K10: 78108062 | L10: 53647587 | M10: 54687948 | N10: 62889783 | O10: =SUM(C10:N10) -> 7.5605321e+08
A11: R-3 | B11: All | C11: 1.0326976e+08 | D11: 1.0944332e+08 | E11: 92545706 | F11: 65914590 | G11: 48298588 | H11: 48034673 | I11: 54488188 | J11: 54300578 | K11: 55684073 | L11: 40961747 | M11: 55322513 | N11: 80550461 | O11: =SUM(C11:N11) -> 8.088142e+08
A12: R-4 | B12: All | C12: 16393169 | D12: 17634579 | E12: 15604418 | F12: 10813764 | G12: 7982247.7 | H12: 7525123.7 | I12: 7919850.9 | J12: 7894910.2 | K12: 8067241.8 | L12: 6330519.2 | M12: 9249696.7 | N12: 14026581 | O12: =SUM(C12:N12) -> 1.294421e+08
A13: G-1 | B13: Boston | C13: 2.2869741e+08 | D13: 2.4024052e+08 | E13: 2.1565948e+08 | F13: 2.0719649e+08 | G13: 1.9241774e+08 | H13: 2.1918574e+08 | I13: 2.3557101e+08 | J13: 2.4363453e+08 | K13: 2.4882967e+08 | L13: 2.1217207e+08 | M13: 2.1013832e+08 | N13: 2.1711456e+08 | O13: =SUM(C13:N13) -> 2.6708575e+09
A14: T-1 | B14: Boston | C14: 1257422.3 | D14: 1175048.9 | E14: 1137746.2 | F14: 1324775.8 | G14: 1226771.2 | H14: 1224937.6 | I14: 1226774.2 | J14: 1195358 | K14: 1263518.7 | L14: 1210847 | M14: 1240440 | N14: 1204433 | O14: =SUM(C14:N14) -> 14688073
A15: G-2 | B15: Boston | C15: 3.1706193e+08 | D15: 3.1404181e+08 | E15: 2.957024e+08 | F15: 2.8073727e+08 | G15: 2.7016592e+08 | H15: 3.2631929e+08 | I15: 3.4121765e+08 | J15: 3.4833219e+08 | K15: 3.5232683e+08 | L15: 3.0291151e+08 | M15: 3.1484678e+08 | N15: 3.1019343e+08 | O15: =SUM(C15:N15) -> 3.773857e+09
A16: G-3 | B16: Boston | C16: 2.1272155e+08 | D16: 1.9651448e+08 | E16: 1.9978583e+08 | F16: 2.1155025e+08 | G16: 1.918495e+08 | H16: 2.4694111e+08 | I16: 2.3545266e+08 | J16: 2.4310035e+08 | K16: 2.6180672e+08 | L16: 2.2081035e+08 | M16: 2.114795e+08 | N16: 2.070297e+08 | O16: =SUM(C16:N16) -> 2.639042e+09
A17: WR | B17: Boston | C17: 9984033.1 | D17: 9153630.3 | E17: 8212827.2 | F17: 8673628.7 | G17: 8980829.8 | H17: 8827229.3 | I17: 7612825.2 | J17: 9384031.1 | K17: 8827229.3 | L17: 9729632.2 | M17: 9729632.2 | N17: 8505628.2 | O17: =SUM(C17:N17) -> 1.0762116e+08
A18: G-1 | B18: Cambridge | C18: 20085495 | D18: 21730808 | E18: 18468195 | F18: 17684157 | G18: 16642046 | H18: 18888368 | I18: 20050808 | J18: 21367520 | K18: 20439431 | L18: 18649890 | M18: 17986599 | N18: 20104738 | O18: =SUM(C18:N18) -> 2.3209805e+08
A19: G-6 | B19: Cambridge | C19: 133.39572 | D19: 100.81051 | E19: 74.335019 | F19: 0 | G19: 0 | H19: 0 | I19: 0 | J19: 0 | K19: 0 | L19: 0 | M19: 0 | N19: 0 | O19: =SUM(C19:N19) -> 308.54124
A20: G-2 | B20: Cambridge | C20: 44143087 | D20: 40886042 | E20: 41628851 | F20: 41768512 | G20: 39961481 | H20: 48116073 | I20: 57250206 | J20: 54366749 | K20: 51558336 | L20: 45380311 | M20: 40621290 | N20: 44014472 | O20: =SUM(C20:N20) -> 5.4969541e+08
... A28: G-6 | B28: South | C28: 434525.04 | D28: 491017.06 | E28: 456344.17 | F28: 406796.69 | G28: 336694.34 | H28: 388300.5 | I28: 384876.01 | J28: 392700.56 | K28: 485977.89 | L28: 353936.21 | M28: 434471.28 | N28: 388021.76 | O28: =SUM(C28:N28) -> 4953661.5
A29: 23 | B29: WMA | C29: 5802.8048 | D29: 4023.7794 | E29: 4432.6177 | F29: 3942.7831 | G29: 4151.0592 | H29: 4112.4896 | I29: 5764.2351 | J29: 5899.2289 | K29: 4209.878 | L29: 3215.7451 | M29: 3140.5342 | N29: 3809.7178 | O29: =SUM(C29:N29) -> 52504.873
A30: 24 | B30: WMA | C30: 430224.64 | D30: 450165.39 | E30: 442581.6 | F30: 355085.17 | G30: 287675.15 | H30: 349416.03 | I30: 422658.81 | J30: 433096.13 | K30: 471085.91 | L30: 318634.89 | M30: 334717.39 | N30: 427816.11 | O30: =SUM(C30:N30) -> 4723157.2
A31: G-1 | B31: WMA | C31: 50156801 | D31: 48811198 | E31: 50252619 | F31: 45371779 | G31: 40743347 | H31: 48286391 | I31: 52695884 | J31: 53027578 | K31: 55403701 | L31: 45678790 | M31: 42993751 | N31: 49798106 | O31: =SUM(C31:N31) -> 5.8321995e+08
A32: G-2 | B32: WMA | C32: 30164936 | D32: 29105671 | E32: 30432691 | F32: 27372911 | G32: 24304880 | H32: 28000200 | I32: 30535765 | J32: 30370011 | K32: 32253153 | L32: 26355973 | M32: 25296254 | N32: 29510786 | O32: =SUM(C32:N32) -> 3.4370323e+08
A33: T-4 | B33: WMA | C33: 791251.11 | D33: 727173.37 | E33: 843573.45 | F33: 940143.59 | G33: 897969.41 | H33: 988445.29 | I33: 1094209.3 | J33: 1068083.4 | K33: 1227726.2 | L33: 1017648 | M33: 1002851.9 | N33: 1061441.1 | O33: =SUM(C33:N33) -> 11660516
A34: G-3 | B34: WMA | C34: 49236543 | D34: 49683885 | E34: 53620977 | F34: 53222805 | G34: 49107026 | H34: 55338988 | I34: 56908034 | J34: 59367345 | K34: 61789353 | L34: 53504891 | M34: 50853728 | N34: 54172129 | O34: =SUM(C34:N34) -> 6.468057e+08
A35: T-5 | B35: WMA | C35: 22635488 | D35: 35925372 | E35: 35975102 | F35: 20538339 | G35: 35364083 | H35: 32212063 | I35: 35356662 | J35: 35557697 | K35: 43686217 | L35: 31523536 | M35: 38455908 | N35: 23011319 | O35: =SUM(C35:N35) -> 3.9024179e+08
A36: S-1 | B36: All | C36: 5308788.8 | D36: 4467152.8 | E36: 4431173.3 | F36: 3777790.5 | G36: 3432871.8 | H36: 3090197.8 | I36: 3332076 | J36: 3701939.9 | K36: 4087764.4 | L36: 4745852.8 | M36: 5047429.4 | N36: 5428388.1 | O36: =SUM(C36:N36) -> 50851426
A37: S-2 | B37: All | C37: 6269449.5 | D37: 5247220.1 | E37: 5207183.6 | F37: 4438671.9 | G37: 4059038.3 | H37: 3667879.5 | I37: 3936728.7 | J37: 4387840.4 | K37: 4825737.3 | L37: 5603021.4 | M37: 5952087.4 | N37: 6422348.9 | O37: =SUM(C37:N37) -> 60017207
C38: =SUM(C9:C37) -> 1.9614385e+09 | D38: =SUM(D9:D37) -> 1.9262967e+09 | E38: =SUM(E9:E37) -> 1.7979509e+09 | F38: =SUM(F9:F37) -> 1.6840497e+09 | G38: =SUM(G9:G37) -> 1.5779748e+09 | H38: =SUM(H9:H37) -> 1.9028271e+09 | I38: =SUM(I9:I37) -> 2.1203562e+09 | J38: =SUM(J9:J37) -> 2.1461129e+09 | ... O38: =SUM(O9:O37) -> 2.2651567e+10
A41: CUSTOMERS
A42: R-1 | B42: All | C42: 1013495.7 | D42: 1012735.3 | E42: 1013571.1 | F42: 1017962.3 | G42: 1015472 | H42: 1017370.1 | I42: 1016884.6 | J42: 1011234 | K42: 1020332.8 | L42: 998410.96 | M42: 1038357.9 | N42: 1017468 | O42: =SUM(C42:N42) -> 12193295
A43: R-2 | B43: All | C43: 122106.47 | D43: 123581.8 | E43: 124619.82 | F43: 122742.91 | G43: 124246.48 | H43: 124676.27 | I43: 124688.27 | J43: 124895.03 | K43: 125352.49 | L43: 123891.2 | M43: 126407.95 | N43: 124588.65 | O43: =SUM(C43:N43) -> 1491797.3
A44: R-3 | B44: All | C44: 89058.016 | D44: 88938.502 | E44: 88837.971 | F44: 89354.303 | G44: 89018.823 | H44: 88869.138 | I44: 88707.59 | J44: 88208.397 | K44: 88773.723 | L44: 86445.189 | M44: 90890.347 | N44: 88625.664 | O44: =SUM(C44:N44) -> 1065727.7
A45: R-4 | B45: All | C45: 11790.243 | D45: 12076.497 | E45: 12222.279 | F45: 11957.563 | G45: 12046.444 | H45: 12197.758 | I45: 12205.464 | J45: 12242.024 | K45: 12304.827 | L45: 12070.319 | M45: 12301.927 | N45: 12204.859 | O45: =SUM(C45:N45) -> 145620.2
A46: G-1 | B46: Boston | C46: 103989.93 | D46: 103669.61 | E46: 104558.44 | F46: 104475.64 | G46: 103746.54 | H46: 104456.29 | I46: 103625.3 | J46: 103509.98 | K46: 104013.29 | L46: 104031.79 | M46: 104329.69 | N46: 103550.87 | O46: =SUM(C46:N46) -> 1247957.4
A47: T-1 | B47: Boston | C47: 2671.69 | D47: 2632.768 | E47: 2673.0523 | F47: 2651.9525 | G47: 2640.9621 | H47: 2648.2344 | I47: 2642.5344 | J47: 2611.873 | K47: 2690.2292 | L47: 2649.2587 | M47: 2647.7223 | N47: 2601.9018 | O47: =SUM(C47:N47) -> 31762.179
A48: G-2 | B48: Boston | C48: 3049.5335 | D48: 3040.7447 | E48: 3061.7088 | F48: 2951.612 | G48: 3010.487 | H48: 3048.1496 | I48: 3115.9924 | J48: 3045.7123 | K48: 3085.0221 | L48: 3079.1153 | M48: 3098.1877 | N48: 3074.4781 | O48: =SUM(C48:N48) -> 36660.744
A49: G-3 | B49: Boston | C49: 473.25792 | D49: 470.16101 | E49: 469.50167 | F49: 457.0441 | G49: 440.83027 | H49: 480.12108 | I49: 461.73941 | J49: 455.81532 | K49: 473.09808 | L49: 466.10506 | M49: 463.53762 | N49: 458.47267 | O49: =SUM(C49:N49) -> 5569.6842
A50: WR | B50: Boston | C50: 1.0000033 | D50: 1.0000033 | E50: 1.0000033 | F50: 1.0000033 | G50: 1.0000033 | H50: 1.0000033 | I50: 1.0000033 | J50: 1.0000033 | K50: 1.0000033 | L50: 1.0000033 | M50: 1.0000033 | N50: 1.0000033 | O50: =SUM(C50:N50) -> 12.00004
A51: G-1 | B51: Cambridge | C51: 7618.9124 | D51: 7649.6131 | E51: 7688.8019 | F51: 7665.0198 | G51: 7655.1025 | H51: 7597.1541 | I51: 7642.3808 | J51: 7680.6037 | K51: 7617.469 | L51: 7607.961 | M51: 7652.5179 | N51: 7704.8737 | O51: =SUM(C51:N51) -> 91780.41
A52: G-6 | B52: Cambridge | C52: 11.201167 | D52: 11.201167 | E52: 12.219455 | F52: 12.219455 | G52: 11.201167 | H52: 13.237743 | I52: 11.201167 | J52: 12.219455 | K52: 12.219455 | L52: 13.237743 | M52: 5.0914397 | N52: 19.347471 | O52: =SUM(C52:N52) -> 144.59689
A53: G-2 | B53: Cambridge | C53: 497.74748 | D53: 473.98425 | E53: 498.82307 | F53: 478.32178 | G53: 487.64872 | H53: 488.83495 | I53: 496.89937 | J53: 486.50436 | K53: 485.61404 | L53: 489.89475 | M53: 480.61863 | N53: 509.67781 | O53: =SUM(C53:N53) -> 5874.5692
...

Sheet WP_Gas Test Year BQs
A1: NSTAR Gas Company
A2: d/b/a Eversource Energy
A6: SUMMARY OF WEATHER NORMALIZED TEST YEAR BILLING DETERMINANTS
A9: Rate | B9: January | C9: February | D9: March | E9: April | F9: May | G9: June | H9: July | I9: August | J9: September | K9: October | L9: November | M9: December | N9: Total
A11: Normalized Therms
A12: R-1 | B12: 253948.79 | C12: 223386.04 | D12: 214810.37 | E12: 161383.24 | F12: 125802.58 | G12: 96802.066 | H12: 91387.436 | I12: 90603.682 | J12: 90167.9 | K12: 143900.95 | L12: 179244.9 | M12: 227963.9 | N12: =SUM(B12:M12) -> 1899401.9
A13: R-2 | B13: 52152.819 | C13: 45786.7 | D13: 43389.699 | E13: 31674.295 | F13: 23596.523 | G13: 17322.083 | H13: 16133.598 | I13: 15948.089 | J13: 15433.634 | K13: 27785.876 | L13: 35751.748 | M13: 46392.128 | N13: =SUM(B13:M13) -> 371367.19
A14: R-3 | B14: 38458426 | C14: 32690357 | D14: 27736763 | E14: 16026499 | F14: 8496482.5 | G14: 4655244.6 | H14: 3408638.5 | I14: 3408638.5 | J14: 3612556.4 | K14: 11320803 | L14: 20260513 | M14: 32070719 | N14: =SUM(B14:M14) -> 2.0214564e+08
A15: R-4 | B15: 4689397.3 | C15: 4085937.5 | D15: 3495859.5 | E15: 2121966 | F15: 1207937.4 | G15: 645932.55 | H15: 464286.76 | I15: 464286.76 | J15: 460002.1 | K15: 1358629.3 | L15: 2427544.1 | M15: 3862832.3 | N15: =SUM(B15:M15) -> 25284612
A16: G-41 | B16: 9942815.8 | C16: 8373365 | D16: 6787552.2 | E16: 3647780.8 | F16: 1645559.7 | G16: 683775.71 | H16: 489970.41 | I16: 489970.41 | J16: 597446.28 | K16: 2334389.3 | L16: 4673102.2 | M16: 7969656.2 | N16: =SUM(B16:M16) -> 47635384
A17: G-42 | B17: 13897193 | C17: 12121747 | D17: 10340355 | E17: 5775332.9 | F17: 3305683.3 | G17: 1506720.1 | H17: 961036.57 | I17: 1312433.7 | J17: 1242315.5 | K17: 4581710 | L17: 7545290.5 | M17: 11378147 | N17: =SUM(B17:M17) -> 73967965
A18: G-43 | B18: 5834052 | C18: 5432999.4 | D18: 4683988.5 | E18: 3425153.9 | F18: 2112332.9 | G18: 1085158.5 | H18: 901915.23 | I18: 1098190.7 | J18: 1198896.2 | K18: 2202009 | L18: 3283582.4 | M18: 4495946.7 | N18: =SUM(B18:M18) -> 35754225
A19: G-51 | B19: 1491407.3 | C19: 1321371.6 | D19: 1307719.7 | E19: 1047352.3 | F19: 891303.95 | G19: 746953.09 | H19: 728696.63 | I19: 725673.98 | J19: 727403.84 | K19: 981865.16 | L19: 1135102 | M19: 1372015 | N19: =SUM(B19:M19) -> 12476865
A20: G-52 | B20: 4035891.1 | C20: 3573999.9 | D20: 3531318.7 | E20: 2818085.5 | F20: 2384540 | G20: 1986989.9 | H20: 1926840.5 | I20: 1929465.5 | J20: 2029249.5 | K20: 2627949.8 | L20: 3053635.9 | M20: 3704644.3 | N20: =SUM(B20:M20) -> 33602610
A21: G-53 | B21: 9015280.5 | C21: 7504433.4 | D21: 8150075 | E21: 7640152 | F21: 6746236 | G21: 5658370 | H21: 5250441 | I21: 5772606 | J21: 5742406 | K21: 6951750 | L21: 7686628 | M21: 8160212 | N21: =SUM(B21:M21) -> 84278590
A22: Total | B22: =SUM(B12:B21) -> 87670565 | C22: =SUM(C12:C21) -> 75373383 | D22: =SUM(D12:D21) -> 66291831 | E22: =SUM(E12:E21) -> 42695380 | F22: =SUM(F12:F21) -> 26939475 | G22: =SUM(G12:G21) -> 17083269 | H22: =SUM(H12:H21) -> 14239347 | I22: =SUM(I12:I21) -> 15307817 | ... N22: =SUM(N12:N21) -> 5.1741666e+08
A24: Number of Bills
A25: R-1 | B25: 15647 | C25: 15556 | D25: 15554 | E25: 15405 | F25: 15321 | G25: 15232 | H25: 15103 | I25: 15040 | J25: 15055 | K25: 14979 | L25: 15123 | M25: 15019 | N25: =SUM(B25:M25) -> 183034
A26: R-2 | B26: 1828 | C26: 1920 | D26: 1829 | E26: 1849 | F26: 1768 | G26: 1781 | H26: 1772 | I26: 1726 | J26: 1718 | K26: 1695 | L26: 1698 | M26: 1740 | N26: =SUM(B26:M26) -> 21324
A27: R-3 | B27: 220385 | C27: 219095 | D27: 221315 | E27: 220346 | F27: 219884 | G27: 219850 | H27: 219907 | I27: 219644 | J27: 220072 | K27: 217893 | L27: 225985 | M27: 223126 | N27: =SUM(B27:M27) -> 2647502
A28: R-4 | B28: 27579 | C28: 28905 | D28: 28043 | E28: 28700 | F28: 29223 | G28: 29065 | H28: 28826 | I28: 28978 | J28: 28603 | K28: 27793 | L28: 28243 | M28: 27885 | N28: =SUM(B28:M28) -> 341843
A29: G-41 | B29: 20974 | C29: 21171 | D29: 21269 | E29: 21050 | F29: 20961 | G29: 20812 | H29: 20777 | I29: 20625 | J29: 20596 | K29: 20546 | L29: 21080 | M29: 20893 | N29: =SUM(B29:M29) -> 250754
A30: G-42 | B30: 2727 | C30: 2711 | D30: 2734 | E30: 2740 | F30: 2715 | G30: 2724 | H30: 2710 | I30: 2694 | J30: 2730 | K30: 2706 | L30: 2751 | M30: 2711 | N30: =SUM(B30:M30) -> 32653
A31: G-43 | B31: 171 | C31: 165 | D31: 172 | E31: 173 | F31: 167 | G31: 176 | H31: 169 | I31: 159 | J31: 175 | K31: 175 | L31: 177 | M31: 165 | N31: =SUM(B31:M31) -> 2044
A32: G-51 | B32: 3661 | C32: 3653 | D32: 3685 | E32: 3664 | F32: 3649 | G32: 3648 | H32: 3639 | I32: 3628 | J32: 3612 | K32: 3629 | L32: 3658 | M32: 3638 | N32: =SUM(B32:M32) -> 43764
A33: G-52 | B33: 1134 | C33: 1118 | D33: 1121 | E33: 1139 | F33: 1123 | G33: 1127 | H33: 1137 | I33: 1117 | J33: 1127 | K33: 1132 | L33: 1124 | M33: 1133 | N33: =SUM(B33:M33) -> 13532
A34: G-53 | B34: 144 | C34: 145 | D34: 144 | E34: 145 | F34: 148 | G34: 148 | H34: 149 | I34: 149 | J34: 148 | K34: 148 | L34: 149 | M34: 151 | N34: =SUM(B34:M34) -> 1768
A35: Total | B35: =SUM(B25:B34) -> 294250 | C35: =SUM(C25:C34) -> 294439 | D35: =SUM(D25:D34) -> 295866 | E35: =SUM(E25:E34) -> 295211 | F35: =SUM(F25:F34) -> 294959 | G35: =SUM(G25:G34) -> 294563 | H35: =SUM(H25:H34) -> 294189 | I35: =SUM(I25:I34) -> 293760 | ... N35: =SUM(N25:N34) -> 3538218
A37: MDTQ
A38: R-1 | B38: 0 | C38: 0 | D38: 0 | E38: 0 | F38: 0 | G38: 0 | H38: 0 | I38: 0 | J38: 0 | K38: 0 | L38: 0 | M38: 0 | N38: =SUM(B38:M38) -> 0
A39: R-2 | B39: 0 | C39: 0 | D39: 0 | E39: 0 | F39: 0 | G39: 0 | H39: 0 | I39: 0 | J39: 0 | K39: 0 | L39: 0 | M39: 0 | N39: =SUM(B39:M39) -> 0
A40: R-3 | B40: 0 | C40: 0 | D40: 0 | E40: 0 | F40: 0 | G40: 0 | H40: 0 | I40: 0 | J40: 0 | K40: 0 | L40: 0 | M40: 0 | N40: =SUM(B40:M40) -> 0
A41: R-4 | B41: 0 | C41: 0 | D41: 0 | E41: 0 | F41: 0 | G41: 0 | H41: 0 | I41: 0 | J41: 0 | K41: 0 | L41: 0 | M41: 0 | N41: =SUM(B41:M41) -> 0
A42: G-41 | B42: 0 | C42: 0 | D42: 0 | E42: 0 | F42: 0 | G42: 0 | H42: 0 | I42: 0 | J42: 0 | K42: 0 | L42: 0 | M42: 0 | N42: =SUM(B42:M42) -> 0
A43: G-42 | B43: 0 | C43: 0 | D43: 0 | E43: 0 | F43: 0 | G43: 0 | H43: 0 | I43: 0 | J43: 0 | K43: 0 | L43: 0 | M43: 0 | N43: =SUM(B43:M43) -> 0
A44: G-43 | B44: 0 | C44: 0 | D44: 0 | E44: 0 | F44: 0 | G44: 0 | H44: 0 | I44: 0 | J44: 0 | K44: 0 | L44: 0 | M44: 0 | N44: =SUM(B44:M44) -> 0
A45: G-51 | B45: 0 | C45: 0 | D45: 0 | E45: 0 | F45: 0 | G45: 0 | H45: 0 | I45: 0 | J45: 0 | K45: 0 | L45: 0 | M45: 0 | N45: =SUM(B45:M45) -> 0
A46: G-52 | B46: 0 | C46: 0 | D46: 0 | E46: 0 | F46: 0 | G46: 0 | H46: 0 | I46: 0 | J46: 0 | K46: 0 | L46: 0 | M46: 0 | N46: =SUM(B46:M46) -> 0
A47: G-53 | B47: 457732 | C47: 457732 | D47: 457732 | E47: 458379 | F47: 360834 | G47: 360834 | H47: 362915 | I47: 361285 | J47: 360834 | K47: 360834 | L47: 466992 | M47: 467772 | N47: =SUM(B47:M47) -> 4933875
A48: Total | B48: =SUM(B38:B47) -> 457732 | C48: =SUM(C38:C47) -> 457732 | D48: =SUM(D38:D47) -> 457732 | E48: =SUM(E38:E47) -> 458379 | F48: =SUM(F38:F47) -> 360834 | G48: =SUM(G38:G47) -> 360834 | H48: =SUM(H38:H47) -> 362915 | I48: =SUM(I38:I47) -> 361285 | ... N48: =SUM(N38:N47) -> 4933875

Sheet WP_Sales Forecast
A1: 2025 Sales kWh Forecast
A2: By RATE GROUP
A4: CONSOLIDATED
A5: Service Area | B5: Rate Group | C5: Jan | D5: Feb | E5: Mar | F5: Apr | G5: May | H5: Jun | I5: Jul | J5: Aug | K5: Sep | L5: Oct | M5: Nov | N5: Dec | O5: Total
A6: All | B6: Residential | C6: =SUM(C15:C16) -> 7.8391214e+08 | D6: =SUM(D15:D16) -> 6.7184106e+08 | E6: =SUM(E15:E16) -> 6.516821e+08 | F6: =SUM(F15:F16) -> 5.6743489e+08 | G6: =SUM(G15:G16) -> 5.5185632e+08 | H6: =SUM(H15:H16) -> 6.472377e+08 | I6: =SUM(I15:I16) -> 8.3671675e+08 | J6: =SUM(J15:J16) -> 8.2472109e+08 | ... N6: =SUM(N15:N16) -> 7.3401992e+08 | O6: =SUM(C6:N6) -> 8.0908808e+09
A7: All | B7: Small General Service/Outdoor Lighting | C7: =SUM(C17,C20,C23:C24,C27:C31,C35:C36) -> 3.8962416e+08 | D7: =SUM(D17,D20,D23:D24,D27:D31,D35:D36) -> 3.6204994e+08 | E7: =SUM(E17,E20,E23:E24,E27:E31,E35:E36) -> 3.6286262e+08 | F7: =SUM(F17,F20,F23:F24,F27:F31,F35:F36) -> 3.2949775e+08 | G7: =SUM(G17,G20,G23:G24,G27:G31,G35:G36) -> 3.4744853e+08 | H7: =SUM(H17,H20,H23:H24,H27:H31,H35:H36) -> 3.8376605e+08 | I7: =SUM(I17,I20,I23:I24,I27:I31,I35:I36) -> 4.4874316e+08 | J7: =SUM(J17,J20,J23:J24,J27:J31,J35:J36) -> 4.3969939e+08 | ... N7: =SUM(N17,N20,N23:N24,N27:N31,N35:N36) -> 3.7476453e+08 | O7: =SUM(C7:N7) -> 4.503332e+09
A8: All | B8: Medium General Service | C8: =SUM(C18,C21,C25,C32,C37) -> 4.3745675e+08 | D8: =SUM(D18,D21,D25,D32,D37) -> 4.1107741e+08 | E8: =SUM(E18,E21,E25,E32,E37) -> 4.0692664e+08 | F8: =SUM(F18,F21,F25,F32,F37) -> 3.7342813e+08 | G8: =SUM(G18,G21,G25,G32,G37) -> 3.938457e+08 | H8: =SUM(H18,H21,H25,H32,H37) -> 4.3554404e+08 | I8: =SUM(I18,I21,I25,I32,I37) -> 5.0239782e+08 | J8: =SUM(J18,J21,J25,J32,J37) -> 4.875544e+08 | ... N8: =SUM(N18,N21,N25,N32,N37) -> 4.1987307e+08 | O8: =SUM(C8:N8) -> 5.0581633e+09
A9: All | B9: Large General Service | C9: =SUM(C19,C22,C26,C33:C34) -> 3.9799206e+08 | D9: =SUM(D19,D22,D26,D33:D34) -> 3.7393718e+08 | E9: =SUM(E19,E22,E26,E33:E34) -> 3.8348217e+08 | F9: =SUM(F19,F22,F26,F33:F34) -> 3.6171017e+08 | G9: =SUM(G19,G22,G26,G33:G34) -> 3.8488201e+08 | H9: =SUM(H19,H22,H26,H33:H34) -> 4.1896031e+08 | I9: =SUM(I19,I22,I26,I33:I34) -> 4.6684251e+08 | J9: =SUM(J19,J22,J26,J33:J34) -> 4.5012882e+08 | ... N9: =SUM(N19,N22,N26,N33:N34) -> 3.8928119e+08 | O9: =SUM(C9:N9) -> 4.7839134e+09
B10: Total | C10: =SUM(C6:C9) -> 2.0089851e+09 | D10: =SUM(D6:D9) -> 1.8189056e+09 | E10: =SUM(E6:E9) -> 1.8049535e+09 | F10: =SUM(F6:F9) -> 1.6320709e+09 | G10: =SUM(G6:G9) -> 1.6780326e+09 | H10: =SUM(H6:H9) -> 1.8855081e+09 | I10: =SUM(I6:I9) -> 2.2547002e+09 | J10: =SUM(J6:J9) -> 2.2021037e+09 | ... O10: =SUM(O6:O9) -> 2.243629e+10
C11: =+C10-C38 -> 0 | D11: =+D10-D38 -> 0 | E11: =+E10-E38 -> 0 | F11: =+F10-F38 -> 0 | G11: =+G10-G38 -> 0 | H11: =+H10-H38 -> 0 | I11: =+I10-I38 -> 0 | J11: =+J10-J38 -> 0 | ... O11: =+O10-O38 -> 0
A13: CONSOLIDATED
A14: Service Area | B14: Customer Class | C14: Jan | D14: Feb | E14: Mar | F14: Apr | G14: May | H14: Jun | I14: Jul | J14: Aug | K14: Sep | L14: Oct | M14: Nov | N14: Dec | O14: Total
A15: All | B15: Residential | C15: =+C79+C80+C104+C105 -> 6.9446311e+08 | D15: =+D79+D80+D104+D105 -> 5.9567928e+08 | E15: =+E79+E80+E104+E105 -> 5.7809221e+08 | F15: =+F79+F80+F104+F105 -> 5.03772e+08 | G15: =+G79+G80+G104+G105 -> 4.902777e+08 | H15: =+H79+H80+H104+H105 -> 5.7486464e+08 | I15: =+I79+I80+I104+I105 -> 7.4281762e+08 | J15: =+J79+J80+J104+J105 -> 7.3217175e+08 | ... N15: =+N79+N80+N104+N105 -> 6.5056171e+08 | O15: =SUM(C15:N15) -> 7.1801262e+09
A16: All | B16: Residential Heat | C16: =+C81+C82+C106+C107 -> 89449028 | D16: =+D81+D82+D106+D107 -> 76161785 | E16: =+E81+E82+E106+E107 -> 73589896 | F16: =+F81+F82+F106+F107 -> 63662898 | G16: =+G81+G82+G106+G107 -> 61578623 | H16: =+H81+H82+H106+H107 -> 72373063 | I16: =+I81+I82+I106+I107 -> 93899135 | J16: =+J81+J82+J106+J107 -> 92549333 | ... N16: =+N81+N82+N106+N107 -> 83458211 | O16: =SUM(C16:N16) -> 9.1075459e+08
A17: Greater Boston | B17: G-1/T-1 | C17: =+C83+C84+C87 -> 2.4068141e+08 | D17: =+D83+D84+D87 -> 2.2704751e+08 | E17: =+E83+E84+E87 -> 2.2020059e+08 | F17: =+F83+F84+F87 -> 2.0022353e+08 | G17: =+G83+G84+G87 -> 2.1141174e+08 | H17: =+H83+H84+H87 -> 2.3178822e+08 | I17: =+I83+I84+I87 -> 2.6733926e+08 | J17: =+J83+J84+J87 -> 2.6068261e+08 | ... N17: =+N83+N84+N87 -> 2.2874015e+08 | O17: =SUM(C17:N17) -> 2.7202548e+09
A18: Greater Boston | B18: G-2 | C18: =+C85 -> 3.3715846e+08 | D18: =+D85 -> 3.1781505e+08 | E18: =+E85 -> 3.0890982e+08 | F18: =+F85 -> 2.8130688e+08 | G18: =+G85 -> 2.9717603e+08 | H18: =+H85 -> 3.2539533e+08 | I18: =+I85 -> 3.743511e+08 | J18: =+J85 -> 3.650154e+08 | ... N18: =+N85 -> 3.2058902e+08 | O18: =SUM(C18:N18) -> 3.8162387e+09
A19: Greater Boston | B19: G3/WR | C19: =+C86+C88 -> 2.4202071e+08 | D19: =+D86+D88 -> 2.2482618e+08 | E19: =+E86+E88 -> 2.2625566e+08 | F19: =+F86+F88 -> 2.0948017e+08 | G19: =+G86+G88 -> 2.2385788e+08 | H19: =+H86+H88 -> 2.4117541e+08 | I19: =+I86+I88 -> 2.69578e+08 | J19: =+J86+J88 -> 2.6147451e+08 | ... N19: =+N86+N88 -> 2.317668e+08 | O19: =SUM(C19:N19) -> 2.7993642e+09
A20: Cambridge | B20: G-1/G-6 | C20: =C89+C93 -> 13236010 | D20: =D89+D93 -> 12495221 | E20: =E89+E93 -> 13042787 | F20: =F89+F93 -> 12749368 | G20: =G89+G93 -> 13101979 | H20: =H89+H93 -> 15449338 | I20: =I89+I93 -> 17624361 | J20: =J89+J93 -> 16259766 | ... N20: =N89+N93 -> 13144678 | O20: =SUM(C20:N20) -> 1.6862101e+08
A21: Cambridge | B21: G-2 | C21: =+C90 -> 40187268 | D21: =+D90 -> 37947312 | E21: =+E90 -> 39609338 | F21: =+F90 -> 38775765 | G21: =+G90 -> 39914875 | H21: =+H90 -> 47158703 | I21: =+I90 -> 53919708 | J21: =+J90 -> 49705995 | ... N21: =+N90 -> 39924261 | O21: =SUM(C21:N21) -> 5.1323806e+08
A22: Cambridge | B22: G3/SB1 | C22: =+C91+SUM(C103:C103) -> 51522601 | D22: =+D91+SUM(D103:D103) -> 48461467 | E22: =+E91+SUM(E103:E103) -> 50720426 | F22: =+F91+SUM(F103:F103) -> 49626624 | G22: =+G91+SUM(G103:G103) -> 51087342 | H22: =+H91+SUM(H103:H103) -> 60017213 | I22: =+I91+SUM(I103:I103) -> 68605577 | J22: =+J91+SUM(J103:J103) -> 63355616 | ... N22: =+N91+SUM(N103:N103) -> 51026418 | O22: =SUM(C22:N22) -> 6.5509647e+08
A23: Cambridge | B23: G-5 | C23: =+C92 -> 403689.47 | D23: =+D92 -> 381049.79 | E23: =+E92 -> 397712.04 | F23: =+F92 -> 389508.13 | G23: =+G92 -> 400822.9 | H23: =+H92 -> 473088.17 | I23: =+I92 -> 540554.09 | J23: =+J92 -> 498350.17 | ... N23: =+N92 -> 400978.71 | O23: =SUM(C23:N23) -> 5152137.5
A24: South | B24: G-1/G-7 | C24: =+C94+C99 -> 75872593 | D24: =+D94+D99 -> 68942814 | E24: =+E94+E99 -> 73182762 | F24: =+F94+F99 -> 66632464 | G24: =+G94+G99 -> 69742396 | H24: =+H94+H99 -> 77902348 | I24: =+I94+I99 -> 99509790 | J24: =+J94+J99 -> 99589543 | ... N24: =+N94+N99 -> 74061097 | O24: =SUM(C24:N24) -> 9.3002846e+08
A25: South | B25: G-2 | C25: =+C95 -> 30860676 | D25: =+D95 -> 28594121 | E25: =+E95 -> 30412139 | F25: =+F95 -> 28054962 | G25: =+G95 -> 29376084 | H25: =+H95 -> 32543877 | I25: =+I95 -> 40674118 | J25: =+J95 -> 40364991 | ... N25: =+N95 -> 30666000 | O25: =SUM(C25:N25) -> 3.8463403e+08
A26: South | B26: G-3 | C26: =+C96 -> 30239870 | D26: =+D96 -> 30035964 | E26: =+E96 -> 32196082 | F26: =+F96 -> 30980225 | G26: =+G96 -> 32495993 | H26: =+H96 -> 35058787 | I26: =+I96 -> 40663389 | J26: =+J96 -> 39142102 | ... N26: =+N96 -> 32051096 | O26: =SUM(C26:N26) -> 4.0045004e+08
A27: South | B27: G-4 | C27: =+C97 -> 169307.56 | D27: =+D97 -> 171428.1 | E27: =+E97 -> 183895.66 | F27: =+F97 -> 178301.11 | G27: =+G97 -> 186954.26 | H27: =+H97 -> 200667.03 | I27: =+I97 -> 228536.16 | J27: =+J97 -> 218422.26 | ... N27: =+N97 -> 182004.8 | O27: =SUM(C27:N27) -> 2274235.4
A28: South | B28: G-6 | C28: =+C98 -> 375434.83 | D28: =+D98 -> 340759.6 | E28: =+E98 -> 361509.27 | F28: =+F98 -> 328995.11 | G28: =+G98 -> 344244.95 | H28: =+H98 -> 384642.72 | I28: =+I98 -> 491796.43 | J28: =+J98 -> 492506.97 | ... N28: =+N98 -> 365810.08 | O28: =SUM(C28:N28) -> 4595203.5
A29: Western MA | B29: 23 | C29: =+C108 -> 5240.9057 | D29: =+D108 -> 4425.0996 | E29: =+E108 -> 4267.1531 | F29: =+F108 -> 3596.0887 | G29: =+G108 -> 3513.4038 | H29: =+H108 -> 4133.6052 | I29: =+I108 -> 5063.0532 | J29: =+J108 -> 4834.9828 | ... N29: =+N108 -> 4873.6634 | O29: =SUM(C29:N29) -> 51317.337
A30: Western MA | B30: 24 | C30: =+C109 -> 403630.04 | D30: =+D109 -> 368498.28 | E30: =+E109 -> 397502.86 | F30: =+F109 -> 351624.65 | G30: =+G109 -> 393434.78 | H30: =+H109 -> 443951.37 | I30: =+I109 -> 483936.4 | J30: =+J109 -> 468871.46 | ... N30: =+N109 -> 398455.78 | O30: =SUM(C30:N30) -> 4881198.1
A31: Western MA | B31: G-1 | C31: =SUM(C110:C112) -> 47400099 | D31: =SUM(D110:D112) -> 42969356 | E31: =SUM(E110:E112) -> 45738112 | F31: =SUM(F110:F112) -> 40718711 | G31: =SUM(G110:G112) -> 44617473 | H31: =SUM(H110:H112) -> 50364258 | I31: =SUM(I110:I112) -> 55283873 | J31: =SUM(J110:J112) -> 53603689 | ... N31: =SUM(N110:N112) -> 46526980 | O31: =SUM(C31:N31) -> 5.6171237e+08
A32: Western MA | B32: G-2/T-4 | C32: =+C113+C115 -> 28051717 | D32: =+D113+D115 -> 25520173 | E32: =+E113+E115 -> 26803184 | F32: =+F113+F115 -> 24104188 | G32: =+G113+G115 -> 26197966 | H32: =+H113+H115 -> 29260460 | I32: =+I113+I115 -> 32260505 | J32: =+J113+J115 -> 31282975 | ... N32: =+N113+N115 -> 27505315 | O32: =SUM(C32:N32) -> 3.2978809e+08
A33: Western MA | B33: G-3 | C33: =+C114 -> 47912587 | D33: =+D114 -> 45190184 | E33: =+E114 -> 47800056 | F33: =+F114 -> 45179561 | G33: =+G114 -> 49281063 | H33: =+H114 -> 53246688 | I33: =+I114 -> 56980254 | J33: =+J114 -> 55648958 | ... N33: =+N114 -> 47892161 | O33: =SUM(C33:N33) -> 5.9513389e+08
A34: Western MA | B34: T-5 | C34: =+C116 -> 26296292 | D34: =+D116 -> 25423385 | E34: =+E116 -> 26509948 | F34: =+F116 -> 26443598 | G34: =+G116 -> 28159731 | H34: =+H116 -> 29462216 | I34: =+I116 -> 31015286 | J34: =+J116 -> 30507635 | ... N34: =+N116 -> 26544716 | O34: =SUM(C34:N34) -> 3.3386882e+08
A35: All | B35: S-1 | C35: =+C100+C117 -> 5057972 | D35: =+D100+D117 -> 4280115.3 | E35: =+E100+E117 -> 4324434.4 | F35: =+F100+F117 -> 3687327.3 | G35: =+G100+G117 -> 3456801.9 | H35: =+H100+H117 -> 3330452.4 | I35: =+I100+I117 -> 3693090.9 | J35: =+J100+J117 -> 3955384 | ... N35: =+N100+N117 -> 5018151.7 | O35: =SUM(C35:N35) -> 49837545
A36: All | B36: S-2 | C36: =+C101+C118 -> 6018774.3 | D36: =+D101+D118 -> 5048761.7 | E36: =+E101+E118 -> 5029047.8 | F36: =+F101+F118 -> 4234316.1 | G36: =+G101+G118 -> 3789169.9 | H36: =+H101+H118 -> 3424951.2 | I36: =+I101+I118 -> 3542896.2 | J36: =+J101+J118 -> 3925419.1 | ... N36: =+N101+N118 -> 5921360.1 | O36: =SUM(C36:N36) -> 55923747
A37: All | B37: EV-2 | C37: =C57+C70 -> 1198632.5 | D37: =D57+D70 -> 1200749.1 | E37: =E57+E70 -> 1192161 | F37: =F57+F70 -> 1186335.3 | G37: =G57+G70 -> 1180741.4 | H37: =H57+H70 -> 1185674 | I37: =I57+I70 -> 1192395.2 | J37: =J57+J70 -> 1185038.1 | ... N37: =N57+N70 -> 1188469.5 | O37: =SUM(C37:N37) -> 14264429
C38: =SUM(C15:C37) -> 2.0089851e+09 | D38: =SUM(D15:D37) -> 1.8189056e+09 | E38: =SUM(E15:E37) -> 1.8049535e+09 | F38: =SUM(F15:F37) -> 1.6320709e+09 | G38: =SUM(G15:G37) -> 1.6780326e+09 | H38: =SUM(H15:H37) -> 1.8855081e+09 | I38: =SUM(I15:I37) -> 2.2547002e+09 | J38: =SUM(J15:J37) -> 2.2021037e+09 | ... N38: =SUM(N15:N37) -> 1.9179387e+09 | O38: =SUM(C38:N38) -> 2.243629e+10
C39: =+C38-C120 -> 0 | D39: =+D38-D120 -> 0 | E39: =+E38-E120 -> 0 | F39: =+F38-F120 -> 0 | G39: =+G38-G120 -> 0 | H39: =+H38-H120 -> 0 | I39: =+I38-I120 -> 0 | J39: =+J38-J120 -> 0 | ... O39: =+O38-O120 -> 0
A40: EMA ONLY
A41: Service Area | B41: Customer Class | C41: =+C14 -> Jan | D41: =+D14 -> Feb | E41: =+E14 -> Mar | F41: =+F14 -> Apr | G41: =+G14 -> May | H41: =+H14 -> Jun | I41: =+I14 -> Jul | J41: =+J14 -> Aug | ... O41: =+O14 -> Total
A42: Eastern MA | B42: Residential | C42: =+C79+C80 -> 5.7047484e+08 | D42: =+D79+D80 -> 4.93925e+08 | E42: =+E79+E80 -> 4.8486219e+08 | F42: =+F79+F80 -> 4.2702077e+08 | G42: =+G79+G80 -> 4.2104775e+08 | H42: =+H79+H80 -> 4.9120913e+08 | I42: =+I79+I80 -> 6.3367652e+08 | J42: =+J79+J80 -> 6.2876634e+08 | ... N42: =+N79+N80 -> 5.3791578e+08 | O42: =SUM(C42:N42) -> 6.0705781e+09
...

Sheet WP_Efficiency Factors
A4: Efficiency Factors
A6: Gas Heating Eff (2) | B6: =105000*0.83 -> 87150 | C6: BTU/CCF
A7: Central Air Cooling Eff (2) | B7: =3412*11/3.412 -> 11000 | C7: BTU/kWh
A8: Electric Res Eff | B8: 3412 | C8: BTU/kWh
A9: ASHP Heating Eff (1) | B9: =3412*(8.1/3.412) -> 8100 | C9: BTU/kWh
A10: ASHP Cooling Eff (1) | B10: =14/3.412*3412 -> 14000 | C10: BTU/kWh
A13: Notes:
A14: (1) Mass Save Qualified Product List standards
A15: (3) Based on 2025-27 Massachusetts Technical Reference Manual (TRM)

Sheet WP_Rate Inputs
A4: Rate Inputs
E5: 45689
A6: Rate R-1 | B6: 45689 | D6: Rate R-1HP | E6: Summer | F6: Winter
A7: Cust Chg | B7: 10 | D7: Cust Chg | E7: 10 | F7: 10
A8: Delivery | B8: 0.19122 | D8: Base Dist | E8: =TRUNC('Sch 1_Heat Pump Rate Design'!C8,5) -> 0.06739 | F8: =TRUNC('Sch 1_Heat Pump Rate Design'!C9,5) -> 0.02191
A9: Supply | B9: 0.13241 | D9: Transmission | E9: =TRUNC('Sch 1_Heat Pump Rate Design'!C29,5) -> 0.0489 | F9: =TRUNC('Sch 1_Heat Pump Rate Design'!C30,5) -> 0.0159
A10: Total Fixed | B10: =B7 -> 10 | D10: Other | E10: =B8-0.06264-0.04545 -> 0.08313 | F10: =E10 -> 0.08313
A11: Total Energy | B11: =B8+B9 -> 0.32363 | D11: Supply | E11: =B9 -> 0.13241 | F11: =E11 -> 0.13241
D12: Total Fixed | E12: =E7 -> 10 | F12: =F7 -> 10
D13: Total Energy | E13: =SUM(E8:E11) -> 0.33183 | F13: =SUM(F8:F11) -> 0.25335
E15: 45689
D16: Rate R-3 | E16: Summer | F16: Winter
D17: Cust Chg | E17: 10 | F17: 10
D18: Delivery | E18: 1.6109 | F18: 1.6102
D19: Supply | E19: 0.2524 | F19: 0.926
D20: Total Fixed | E20: =E17 -> 10 | F20: =F17 -> 10
D21: Total Energy | E21: =SUM(E18:E19) -> 1.8633 | F21: =SUM(F18:F19) -> 2.5362
