Workbook
Name _NH12: [1]Market!#REF!
Name _NH2: [1]Market!#REF!
Name _NH3: [1]Market!#REF!
Name _NH5: [1]Market!#REF!
Name _NH6: [1]Market!#REF!
Name _NH7: [1]Market!#REF!
Name _NH8: [1]Market!#REF!
Name _NH9: [1]Market!#REF!
Name _RI1: [1]Market!#REF!
Name _RI10: [1]Market!#REF!
Name _RI11: [1]Market!#REF!
Name _RI12: [1]Market!#REF!
Name _RI3: [1]Market!#REF!
Name _RI4: [1]Market!#REF!
Name _RI5: [1]Market!#REF!
Name _RI7: [1]Market!#REF!
Name _RI8: [1]Market!#REF!
Name _RI9: [1]Market!#REF!
Name Alloc0: [2]AllocFctr!$F$7
Name arClassOff: [2]Total!$7:$7
Name August_January_Basic_Service_Rate: '[3]Summary Bill Impacts'!$D$5
Name Delivery_Peak_Period_End: '[3]Summary Bill Impacts'!$D$7
Name Delivery_Peak_Period_Start: '[3]Summary Bill Impacts'!$D$6
Name February_July_Basic_Service_Rate: '[3]Summary Bill Impacts'!$D$4
Name ForecastError: '[4]NH Summary Ind'!#REF!
Name GranAvgLF: [4]NHLoads!$U$2
Name GranLrgLF: [4]NHLoads!$S$2
Name GranSmlLF: [4]NHLoads!$T$2
Name MassCLF: [4]MALoads!$AD$1
Name MidMonth2: [4]Data!$L$10
Name OnPeak: [5]Data!#REF!
Name Supply_Peak_Period_End: '[3]Summary Bill Impacts'!$D$9
Name Supply_Peak_Period_Start: '[3]Summary Bill Impacts'!$D$8
Name Title: [4]Data!$B$4

Sheet NG-4 Page 1
O1: Massachusetts Electric Company
O2: Nantucket Electric Company
O3: d/b/a National Grid
O4: D.P.U 23-150
O5: Exhibit NG-4
O6: Page 1 of 2
D7: Residential Heat Pump Rate Design (using Unitil's approach)
A9: Line
A10: 1 | B10: Assumptions:
A11: =IF(ISBLANK(B11),"",MAX($A$9:A10)+1)
A12: =IF(ISBLANK(B12),"",MAX($A$9:A11)+1) -> 2 | B12: R-1: Residential | C12: Proposed Rate
A13: =IF(ISBLANK(B13),"",MAX($A$9:A12)+1) -> 3 | B13: Customer Charge | C13: 10
A14: =IF(ISBLANK(B14),"",MAX($A$9:A13)+1) -> 4 | B14: Distribution Charge | C14: 0.06546
A15: =IF(ISBLANK(B15),"",MAX($A$9:A14)+1)
A16: =IF(ISBLANK(B16),"",MAX($A$9:A15)+1) -> 5 | B16: Average Monthly UPC | C16: R-1 Average Monthly Use (kWh) (a) | D16: Cost Recovery per Month (b) | E16: Fixed Cost Recovery in Volumetric Rate (c) | F16: Fixed Cost Recovery in Fixed Charge (d) | G16: Avg. Monthly Use with Heat Pump (kWh) (e) | J16: Normal Therm UPC (f) | K16: Therms (Heating Load) (g) | L16: Avg. Temp. (h) | M16: Avg. Temp COP (i) | N16: kWh Conversion (j) | O16: kWh Usage (k)
A17: =IF(ISBLANK(B17),"",MAX($A$9:A16)+1) -> 6 | B17: January | C17: 610.63541 | D17: =SUM(E17:F17) -> 49.972194 | E17: =($C$14-$C$46)*C17 -> 39.972194 | F17: =$C$13 -> 10 | G17: =C17+O17 -> 1891.8051 | J17: 132 | K17: =J17-$K$30 -> 114 | L17: 28.704892 | M17: 2.6071487 | N17: =K17*$K$31 -> 3340.2 | O17: =N17/M17 -> 1281.1697
A18: =IF(ISBLANK(B18),"",MAX($A$9:A17)+1) -> 7 | B18: February | C18: 530.69348 | D18: =SUM(E18:F18) -> 44.739195 | E18: =($C$14-$C$46)*C18 -> 34.739195 | F18: =$C$13 -> 10 | G18: =C18+O18 -> 1972.9964 | J18: 149 | K18: =J18-$K$30 -> 131 | L18: 30.572961 | M18: 2.6612302 | N18: =K18*$K$31 -> 3838.3 | O18: =N18/M18 -> 1442.3029
A19: =IF(ISBLANK(B19),"",MAX($A$9:A18)+1) -> 8 | B19: March | C19: 530.1181 | D19: =SUM(E19:F19) -> 44.701531 | E19: =($C$14-$C$46)*C19 -> 34.701531 | F19: =$C$13 -> 10 | G19: =C19+O19 -> 1712.1461 | J19: 133 | K19: =J19-$K$30 -> 115 | L19: 37.643763 | M19: 2.8506093 | N19: =K19*$K$31 -> 3369.5 | O19: =N19/M19 -> 1182.028
A20: =IF(ISBLANK(B20),"",MAX($A$9:A19)+1) -> 9 | B20: April | C20: 454.90082 | D20: =SUM(E20:F20) -> 39.777808 | E20: =($C$14-$C$46)*C20 -> 29.777808 | F20: =$C$13 -> 10 | G20: =C20+O20 -> 1131.2313 | J20: 90 | K20: =J20-$K$30 -> 72 | L20: 48.023181 | M20: 3.1191852 | N20: =K20*$K$31 -> 2109.6 | O20: =N20/M20 -> 676.33048
A21: =IF(ISBLANK(B21),"",MAX($A$9:A20)+1) -> 10 | B21: May | C21: 484.5277 | D21: =SUM(E21:F21) -> 41.717183 | E21: =($C$14-$C$46)*C21 -> 31.717183 | F21: =$C$13 -> 10 | G21: =C21+O21 -> 484.5277 | J21: 46
A22: =IF(ISBLANK(B22),"",MAX($A$9:A21)+1) -> 11 | B22: June | C22: 586.91619 | D22: =SUM(E22:F22) -> 48.419534 | E22: =($C$14-$C$46)*C22 -> 38.419534 | F22: =$C$13 -> 10 | G22: =C22+O22 -> 586.91619 | J22: 23
A23: =IF(ISBLANK(B23),"",MAX($A$9:A22)+1) -> 12 | B23: July | C23: 770.46363 | D23: =SUM(E23:F23) -> 60.434549 | E23: =($C$14-$C$46)*C23 -> 50.434549 | F23: =$C$13 -> 10 | G23: =C23+O23 -> 770.46363 | J23: 18
A24: =IF(ISBLANK(B24),"",MAX($A$9:A23)+1) -> 13 | B24: August | C24: 762.80177 | D24: =SUM(E24:F24) -> 59.933004 | E24: =($C$14-$C$46)*C24 -> 49.933004 | F24: =$C$13 -> 10 | G24: =C24+O24 -> 762.80177 | J24: 15
A25: =IF(ISBLANK(B25),"",MAX($A$9:A24)+1) -> 14 | B25: September | C25: 536.15882 | D25: =SUM(E25:F25) -> 45.096957 | E25: =($C$14-$C$46)*C25 -> 35.096957 | F25: =$C$13 -> 10 | G25: =C25+O25 -> 536.15882 | J25: 16
A26: =IF(ISBLANK(B26),"",MAX($A$9:A25)+1) -> 15 | B26: October | C26: 457.55933 | D26: =SUM(E26:F26) -> 39.951834 | E26: =($C$14-$C$46)*C26 -> 29.951834 | F26: =$C$13 -> 10 | G26: =C26+O26 -> 457.55933 | J26: 20
A27: =IF(ISBLANK(B27),"",MAX($A$9:A26)+1) -> 16 | B27: November | C27: 494.2623 | D27: =SUM(E27:F27) -> 42.35441 | E27: =($C$14-$C$46)*C27 -> 32.35441 | F27: =$C$13 -> 10 | G27: =C27+O27 -> 777.59007 | J27: 47 | K27: =J27-$K$30 -> 29 | L27: 43.20475 | M27: 2.999 | N27: =K27*$K$31 -> 849.7 | O27: =N27/M27 -> 283.32778
A28: =IF(ISBLANK(B28),"",MAX($A$9:A27)+1) -> 17 | B28: December | C28: 641.47874 | D28: =SUM(E28:F28) -> 51.991198 | E28: =($C$14-$C$46)*C28 -> 41.991198 | F28: =$C$13 -> 10 | G28: =C28+O28 -> 1436.4845 | J28: 93 | K28: =J28-$K$30 -> 75 | L28: 34.429086 | M28: 2.7641308 | N28: =K28*$K$31 -> 2197.5 | O28: =N28/M28 -> 795.00579
A29: =IF(ISBLANK(C29),"",MAX($A$9:A28)+1) -> 18 | C29: =SUM(C17:C28) -> 6860.5163 | D29: =SUM(D17:D28) -> 569.0894 | E29: =SUM(E17:E28) -> 449.0894 | F29: =SUM(F17:F28) -> 120 | G29: =SUM(G17:G28) -> 12520.681 | O29: =SUM(O17:O28) -> 5660.1646
A30: =IF(ISBLANK(K30),"",MAX($A$9:A29)+1) -> 19 | J30: Summer Base Load | K30: =AVERAGE(J22:J25) -> 18
A31: =IF(ISBLANK(B31),"",MAX($A$9:A30)+1) -> 20 | B31: Derrivation of Heat Pump Rate | J31: Therm to kWH Factor | K31: 29.3
A32: =IF(ISBLANK(B32),"",MAX($A$9:A31)+1) -> 21 | B32: Customer Charge | C32: =C13 -> 10
A33: =IF(ISBLANK(B33),"",MAX($A$9:A32)+1) -> 22 | B33: Customer Charge Revenue | C33: =C32*12 -> 120
A34: =IF(ISBLANK(B34),"",MAX($A$9:A33)+1)
A35: =IF(ISBLANK(B35),"",MAX($A$9:A34)+1) -> 23 | B35: Winter Volumetric Charge Revenue | C35: =SUM(E17:E20,E27:E28) -> 213.53634 | D35: per customer, November through April
A36: =IF(ISBLANK(B36),"",MAX($A$9:A35)+1) -> 24 | B36: Volumetric Fixed Cost Recovery Charge | C36: =TRUNC(C35/SUM(G17:G20,G27:G28),5) -> 0.02393 | D36: Line 21 divided by Heat Pump kWh for Nov. through Apr.
A37: =IF(ISBLANK(B37),"",MAX($A$9:A36)+1)
A38: =IF(ISBLANK(B38),"",MAX($A$9:A37)+1) -> 25 | B38: Results
A39: =IF(ISBLANK(B39),"",MAX($A$9:A38)+1) -> 26 | B39: R-1-HP: Residential Heat Pump Service | C39: Proposed Rate
A40: =IF(ISBLANK(B40),"",MAX($A$9:A39)+1) -> 27 | B40: Customer Charge | C40: =C32 -> 10
A41: =IF(ISBLANK(B41),"",MAX($A$9:A40)+1) -> 28 | B41: Distribution Charge - Winter | C41: =C36 -> 0.02393
...

Sheet NG-4 Page 2
J1: Massachusetts Electric Company
J2: Nantucket Electric Company
J3: d/b/a National Grid
J4: D.P.U 23-150
J5: Exhibit NG-4
J6: Page 2 of 2
D7: Residential Heat Pump Rate Design (alternative approach)
A9: Line
A10: 1 | B10: Assumptions:
A11: =IF(ISBLANK(B11),"",MAX($A$9:A10)+1)
A12: =IF(ISBLANK(B12),"",MAX($A$9:A11)+1) -> 2 | B12: R-1: Residential | C12: Proposed Rate
A13: =IF(ISBLANK(B13),"",MAX($A$9:A12)+1) -> 3 | B13: Customer Charge | C13: 10
A14: =IF(ISBLANK(B14),"",MAX($A$9:A13)+1) -> 4 | B14: Distribution Charge | C14: 0.06546
A15: =IF(ISBLANK(B15),"",MAX($A$9:A14)+1)
A16: =IF(ISBLANK(B16),"",MAX($A$9:A15)+1) -> 5 | B16: Average Monthly UPC | C16: R-1 Average Monthly Use (kWh) (a) | D16: Cost Recovery per Month (b) | E16: Fixed Cost Recovery in Volumetric Rate (c) | F16: Fixed Cost Recovery in Fixed Charge (d) | G16: Avg. Monthly Use with Heat Pump (kWh) (e) | J16: Average Forecasted kWh Usage (f)
A17: =IF(ISBLANK(B17),"",MAX($A$9:A16)+1) -> 6 | B17: January | C17: 610.63541 | D17: =SUM(E17:F17) -> 49.972194 | E17: =($C$14-$C$46)*C17 -> 39.972194 | F17: =$C$13 -> 10 | G17: =C17+J17 -> 2263.7189 | J17: 1653.0835
A18: =IF(ISBLANK(B18),"",MAX($A$9:A17)+1) -> 7 | B18: February | C18: 530.69348 | D18: =SUM(E18:F18) -> 44.739195 | E18: =($C$14-$C$46)*C18 -> 34.739195 | F18: =$C$13 -> 10 | G18: =C18+J18 -> 1759.9565 | J18: 1229.263
A19: =IF(ISBLANK(B19),"",MAX($A$9:A18)+1) -> 8 | B19: March | C19: 530.1181 | D19: =SUM(E19:F19) -> 44.701531 | E19: =($C$14-$C$46)*C19 -> 34.701531 | F19: =$C$13 -> 10 | G19: =C19+J19 -> 1439.8222 | J19: 909.70414
A20: =IF(ISBLANK(B20),"",MAX($A$9:A19)+1) -> 9 | B20: April | C20: 454.90082 | D20: =SUM(E20:F20) -> 39.777808 | E20: =($C$14-$C$46)*C20 -> 29.777808 | F20: =$C$13 -> 10 | G20: =C20+J20 -> 889.87223 | J20: 434.97141
A21: =IF(ISBLANK(B21),"",MAX($A$9:A20)+1) -> 10 | B21: May | C21: 484.5277 | D21: =SUM(E21:F21) -> 41.717183 | E21: =($C$14-$C$46)*C21 -> 31.717183 | F21: =$C$13 -> 10 | G21: =C21+J21 -> 484.5277
A22: =IF(ISBLANK(B22),"",MAX($A$9:A21)+1) -> 11 | B22: June | C22: 586.91619 | D22: =SUM(E22:F22) -> 48.419534 | E22: =($C$14-$C$46)*C22 -> 38.419534 | F22: =$C$13 -> 10 | G22: =C22+J22 -> 586.91619
A23: =IF(ISBLANK(B23),"",MAX($A$9:A22)+1) -> 12 | B23: July | C23: 770.46363 | D23: =SUM(E23:F23) -> 60.434549 | E23: =($C$14-$C$46)*C23 -> 50.434549 | F23: =$C$13 -> 10 | G23: =C23+J23 -> 770.46363
A24: =IF(ISBLANK(B24),"",MAX($A$9:A23)+1) -> 13 | B24: August | C24: 762.80177 | D24: =SUM(E24:F24) -> 59.933004 | E24: =($C$14-$C$46)*C24 -> 49.933004 | F24: =$C$13 -> 10 | G24: =C24+J24 -> 762.80177
A25: =IF(ISBLANK(B25),"",MAX($A$9:A24)+1) -> 14 | B25: September | C25: 536.15882 | D25: =SUM(E25:F25) -> 45.096957 | E25: =($C$14-$C$46)*C25 -> 35.096957 | F25: =$C$13 -> 10 | G25: =C25+J25 -> 536.15882
A26: =IF(ISBLANK(B26),"",MAX($A$9:A25)+1) -> 15 | B26: October | C26: 457.55933 | D26: =SUM(E26:F26) -> 39.951834 | E26: =($C$14-$C$46)*C26 -> 29.951834 | F26: =$C$13 -> 10 | G26: =C26+J26 -> 457.55933
A27: =IF(ISBLANK(B27),"",MAX($A$9:A26)+1) -> 16 | B27: November | C27: 494.2623 | D27: =SUM(E27:F27) -> 42.35441 | E27: =($C$14-$C$46)*C27 -> 32.35441 | F27: =$C$13 -> 10 | G27: =C27+J27 -> 1139.865 | J27: 645.60269
A28: =IF(ISBLANK(B28),"",MAX($A$9:A27)+1) -> 17 | B28: December | C28: 641.47874 | D28: =SUM(E28:F28) -> 51.991198 | E28: =($C$14-$C$46)*C28 -> 41.991198 | F28: =$C$13 -> 10 | G28: =C28+J28 -> 1749.7672 | J28: 1108.2885
A29: =IF(ISBLANK(C29),"",MAX($A$9:A28)+1) -> 18 | C29: =SUM(C17:C28) -> 6860.5163 | D29: =SUM(D17:D28) -> 569.0894 | E29: =SUM(E17:E28) -> 449.0894 | F29: =SUM(F17:F28) -> 120 | G29: =SUM(G17:G28) -> 12841.43 | J29: =SUM(J17:J28) -> 5980.9132
A30: =IF(ISBLANK(#REF!),"",MAX($A$9:A29)+1) -> 19
A31: =IF(ISBLANK(B31),"",MAX($A$9:A30)+1) -> 20 | B31: Derrivation of Heat Pump Rate
A32: =IF(ISBLANK(B32),"",MAX($A$9:A31)+1) -> 21 | B32: Customer Charge | C32: =C13 -> 10
A33: =IF(ISBLANK(B33),"",MAX($A$9:A32)+1) -> 22 | B33: Customer Charge Revenue | C33: =C32*12 -> 120
A34: =IF(ISBLANK(B34),"",MAX($A$9:A33)+1)
A35: =IF(ISBLANK(B35),"",MAX($A$9:A34)+1) -> 23 | B35: Winter Volumetric Charge Revenue | C35: =SUM(E17:E20,E27:E28) -> 213.53634 | D35: per customer, November through April
A36: =IF(ISBLANK(B36),"",MAX($A$9:A35)+1) -> 24 | B36: Volumetric Fixed Cost Recovery Charge | C36: =TRUNC(C35/SUM(G17:G20,G27:G28),5) -> 0.0231 | D36: Line 21 divided by Heat Pump kWh for Nov. through Apr.
A37: =IF(ISBLANK(B37),"",MAX($A$9:A36)+1)
A38: =IF(ISBLANK(B38),"",MAX($A$9:A37)+1) -> 25 | B38: Results
A39: =IF(ISBLANK(B39),"",MAX($A$9:A38)+1) -> 26 | B39: R-1-HP: Residential Heat Pump Service | C39: Proposed Rate
A40: =IF(ISBLANK(B40),"",MAX($A$9:A39)+1) -> 27 | B40: Customer Charge | C40: =C32 -> 10
A41: =IF(ISBLANK(B41),"",MAX($A$9:A40)+1) -> 28 | B41: Distribution Charge - Winter | C41: =C36 -> 0.0231
...

Sheet Heat Pump Rate Design R1
A1: Massachusetts Electric Company
A2: Nantucket Electric Company
A3: d/b/a National Grid
A4: D.P.U 23-150
A5: Exhibit NG-4
A6: Residential Heat Pump Rate Design
A9: Line
A10: 1 | B10: Assumptions:
A11: =IF(ISBLANK(B11),"",MAX($A$9:A10)+1)
A12: =IF(ISBLANK(B12),"",MAX($A$9:A11)+1) -> 2 | B12: R-1: Residential | C12: Proposed Rate
A13: =IF(ISBLANK(B13),"",MAX($A$9:A12)+1) -> 3 | B13: Customer Charge | C13: 10
A14: =IF(ISBLANK(B14),"",MAX($A$9:A13)+1) -> 4 | B14: Distribution Charge | C14: 0.06546
A15: =IF(ISBLANK(B15),"",MAX($A$9:A14)+1)
A16: =IF(ISBLANK(B16),"",MAX($A$9:A15)+1) -> 5 | B16: Average Monthly UPC | C16: R-1 Average Monthly Use (a) | D16: Cost Recovery per Month (b) | E16: Fixed Cost Recovery in Volumetric Rate (c) | F16: Fixed Cost Recovery in Fixed Charge (d) | G16: Avg. Monthly Use with Heat Pump (kWh) (e) | J16: Normal Therm UPC (f) | K16: Therms (Heating Load) (g) | L16: Avg. Temp. (h) | M16: Avg. Temp COP (i) | N16: kWh Conversion (j) | O16: kWh Usage (k) | R16: Temp | S16: COP
A17: =IF(ISBLANK(B17),"",MAX($A$9:A16)+1) -> 6 | B17: January | C17: 610.63541 | D17: =SUM(E17:F17) -> 49.972194 | E17: =($C$14-$C$46)*C17 -> 39.972194 | F17: =$C$13 -> 10 | G17: =C17+O17 -> 1896.6139 | J17: 132 | K17: =J17-$K$30 -> 114 | L17: 28.38707 | M17: 2.5973996 | N17: =K17*$K$31 -> 3340.2 | O17: =N17/M17 -> 1285.9785 | R17: =AVERAGE(#REF!) -> #REF! | S17: =AVERAGE(#REF!) -> #REF!
A18: =IF(ISBLANK(B18),"",MAX($A$9:A17)+1) -> 7 | B18: February | C18: 530.69348 | D18: =SUM(E18:F18) -> 44.739195 | E18: =($C$14-$C$46)*C18 -> 34.739195 | F18: =$C$13 -> 10 | G18: =C18+O18 -> 1975.0424 | J18: 149 | K18: =J18-$K$30 -> 131 | L18: 30.428333 | M18: 2.6574603 | N18: =K18*$K$31 -> 3838.3 | O18: =N18/M18 -> 1444.3489 | R18: =AVERAGE(#REF!) -> #REF! | S18: =AVERAGE(#REF!) -> #REF!
A19: =IF(ISBLANK(B19),"",MAX($A$9:A18)+1) -> 8 | B19: March | C19: 530.1181 | D19: =SUM(E19:F19) -> 44.701531 | E19: =($C$14-$C$46)*C19 -> 34.701531 | F19: =$C$13 -> 10 | G19: =C19+O19 -> 1718.5153 | J19: 133 | K19: =J19-$K$30 -> 115 | L19: 37.096062 | M19: 2.8353315 | N19: =K19*$K$31 -> 3369.5 | O19: =N19/M19 -> 1188.3972 | R19: =AVERAGE(#REF!) -> #REF! | S19: =AVERAGE(#REF!) -> #REF!
A20: =IF(ISBLANK(B20),"",MAX($A$9:A19)+1) -> 9 | B20: April | C20: 454.90082 | D20: =SUM(E20:F20) -> 39.777808 | E20: =($C$14-$C$46)*C20 -> 29.777808 | F20: =$C$13 -> 10 | G20: =C20+O20 -> 1133.447 | J20: 90 | K20: =J20-$K$30 -> 72 | L20: 47.340556 | M20: 3.109 | N20: =K20*$K$31 -> 2109.6 | O20: =N20/M20 -> 678.54616 | R20: =AVERAGE(#REF!) -> #REF! | S20: =AVERAGE(#REF!) -> #REF!
A21: =IF(ISBLANK(B21),"",MAX($A$9:A20)+1) -> 10 | B21: May | C21: 484.5277 | D21: =SUM(E21:F21) -> 41.717183 | E21: =($C$14-$C$46)*C21 -> 31.717183 | F21: =$C$13 -> 10 | G21: =C21+O21 -> 484.5277 | J21: 46
A22: =IF(ISBLANK(B22),"",MAX($A$9:A21)+1) -> 11 | B22: June | C22: 586.91619 | D22: =SUM(E22:F22) -> 48.419534 | E22: =($C$14-$C$46)*C22 -> 38.419534 | F22: =$C$13 -> 10 | G22: =C22+O22 -> 586.91619 | J22: 23
A23: =IF(ISBLANK(B23),"",MAX($A$9:A22)+1) -> 12 | B23: July | C23: 770.46363 | D23: =SUM(E23:F23) -> 60.434549 | E23: =($C$14-$C$46)*C23 -> 50.434549 | F23: =$C$13 -> 10 | G23: =C23+O23 -> 770.46363 | J23: 18
A24: =IF(ISBLANK(B24),"",MAX($A$9:A23)+1) -> 13 | B24: August | C24: 762.80177 | D24: =SUM(E24:F24) -> 59.933004 | E24: =($C$14-$C$46)*C24 -> 49.933004 | F24: =$C$13 -> 10 | G24: =C24+O24 -> 762.80177 | J24: 15
A25: =IF(ISBLANK(B25),"",MAX($A$9:A24)+1) -> 14 | B25: September | C25: 536.15882 | D25: =SUM(E25:F25) -> 45.096957 | E25: =($C$14-$C$46)*C25 -> 35.096957 | F25: =$C$13 -> 10 | G25: =C25+O25 -> 536.15882 | J25: 16
A26: =IF(ISBLANK(B26),"",MAX($A$9:A25)+1) -> 15 | B26: October | C26: 457.55933 | D26: =SUM(E26:F26) -> 39.951834 | E26: =($C$14-$C$46)*C26 -> 29.951834 | F26: =$C$13 -> 10 | G26: =C26+O26 -> 457.55933 | J26: 20
A27: =IF(ISBLANK(B27),"",MAX($A$9:A26)+1) -> 16 | B27: November | C27: 494.2623 | D27: =SUM(E27:F27) -> 42.35441 | E27: =($C$14-$C$46)*C27 -> 32.35441 | F27: =$C$13 -> 10 | G27: =C27+O27 -> 777.68108 | J27: 47 | K27: =J27-$K$30 -> 29 | L27: 43.187181 | M27: 2.998037 | N27: =K27*$K$31 -> 849.7 | O27: =N27/M27 -> 283.41878 | R27: =AVERAGE(#REF!) -> #REF! | S27: =AVERAGE(#REF!) -> #REF!
A28: =IF(ISBLANK(B28),"",MAX($A$9:A27)+1) -> 17 | B28: December | C28: 641.47874 | D28: =SUM(E28:F28) -> 51.991198 | E28: =($C$14-$C$46)*C28 -> 41.991198 | F28: =$C$13 -> 10 | G28: =C28+O28 -> 1437.5167 | J28: 93 | K28: =J28-$K$30 -> 75 | L28: 34.282298 | M28: 2.7605466 | N28: =K28*$K$31 -> 2197.5 | O28: =N28/M28 -> 796.038 | R28: =AVERAGE(#REF!) -> #REF! | S28: =AVERAGE(#REF!) -> #REF!
A29: =IF(ISBLANK(C29),"",MAX($A$9:A28)+1) -> 18 | C29: =SUM(C17:C28) -> 6860.5163 | D29: =SUM(D17:D28) -> 569.0894 | E29: =SUM(E17:E28) -> 449.0894 | F29: =SUM(F17:F28) -> 120 | G29: =SUM(G17:G28) -> 12537.244 | O29: =SUM(O17:O28) -> 5676.7275
A30: =IF(ISBLANK(K30),"",MAX($A$9:A29)+1) -> 19 | J30: Summer Base Load | K30: =AVERAGE(J22:J25) -> 18 | L30: =AVERAGE(L17:L28) -> 36.786917 | M30: =AVERAGE(M17:M28) -> 2.8262959 | R30: =AVERAGE(R17:R28) -> #REF! | S30: =AVERAGE(S17:S28) -> #REF!
A31: =IF(ISBLANK(B31),"",MAX($A$9:A30)+1) -> 20 | B31: Derrivation of Heat Pump Rate | J31: Therm to kWH Factor | K31: 29.3
A32: =IF(ISBLANK(B32),"",MAX($A$9:A31)+1) -> 21 | B32: Customer Charge | C32: =C13 -> 10
A33: =IF(ISBLANK(B33),"",MAX($A$9:A32)+1) -> 22 | B33: Customer Charge Revenue | C33: =C32*12 -> 120
A34: =IF(ISBLANK(B34),"",MAX($A$9:A33)+1)
A35: =IF(ISBLANK(B35),"",MAX($A$9:A34)+1) -> 23 | B35: Winter Volumetric Charge Revenue | C35: =SUM(E17:E20,E27:E28) -> 213.53634 | D35: per customer, November through April
A36: =IF(ISBLANK(B36),"",MAX($A$9:A35)+1) -> 24 | B36: Volumetric Fixed Cost Recovery Charge | C36: =TRUNC(C35/SUM(G17:G20,G27:G28),5) -> 0.02388 | D36: Line 21 divided by Heat Pump kWh for Nov. through Apr.
A37: =IF(ISBLANK(B37),"",MAX($A$9:A36)+1)
A38: =IF(ISBLANK(B38),"",MAX($A$9:A37)+1) -> 25 | B38: Results
A39: =IF(ISBLANK(B39),"",MAX($A$9:A38)+1) -> 26 | B39: R-1-HP: Residential Heat Pump Service | C39: Proposed Rate
A40: =IF(ISBLANK(B40),"",MAX($A$9:A39)+1) -> 27 | B40: Customer Charge | C40: =C32 -> 10
A41: =IF(ISBLANK(B41),"",MAX($A$9:A40)+1) -> 28 | B41: Distribution Charge - Winter | C41: =C36 -> 0.02388
A42: =IF(ISBLANK(B42),"",MAX($A$9:A41)+1) -> 29 | B42: Distribution Charge - Summer | C42: =C14 -> 0.06546
...

Sheet Heat Pump Rate Design R1 (2)
A8: Line
A9: 1 | B9: Assumptions:
A10: =IF(ISBLANK(B10),"",MAX($A$8:A9)+1)
A11: =IF(ISBLANK(B11),"",MAX($A$8:A10)+1) -> 2 | B11: RD-1: Residential | C11: Proposed Rate
A12: =IF(ISBLANK(B12),"",MAX($A$8:A11)+1) -> 3 | B12: Customer Charge | C12: 10
A13: =IF(ISBLANK(B13),"",MAX($A$8:A12)+1) -> 4 | B13: Distribution Charge | C13: 0.06546
A14: =IF(ISBLANK(B14),"",MAX($A$8:A13)+1)
A15: =IF(ISBLANK(B15),"",MAX($A$8:A14)+1) -> 5 | B15: Average Monthly UPC | C15: R-1 Average Monthly Use (1) | D15: Cost Recovery per Month | E15: Fixed Cost Recovery in Volumetric Rate | F15: Fixed Cost Recovery in Fixed Charge | G15: Avg. Monthly Use with Heat Pump (kWh) | H15: Winter Multiplier | J15: Normal Therm UPC (2) | K15: Therms (Heating Load) | L15: Avg. Temp. (3) | M15: Avg. Temp COP (4) | N15: kWh Conversion | O15: kWh Usage
A16: =IF(ISBLANK(B16),"",MAX($A$8:A15)+1) -> 6 | B16: January | C16: 610.63541 | D16: =$C$12+$C$13*C16 -> 49.972194 | E16: =($C$13-$C$45)*C16 -> 39.972194 | F16: =$C$12 -> 10 | G16: =C16+O16 -> 1891.8051 | H16: =G16/C16 -> 3.0980927 | I16: 1 | J16: 132 | K16: =J16-$K$29 -> 114 | N16: =K16*$K$30 -> 3340.2 | O16: =N16/'NG-4 Page 1'!M17 -> 1281.1697
A17: =IF(ISBLANK(B17),"",MAX($A$8:A16)+1) -> 7 | B17: February | C17: 530.69348 | D17: =$C$12+$C$13*C17 -> 44.739195 | E17: =($C$13-$C$45)*C17 -> 34.739195 | F17: =$C$12 -> 10 | G17: =C17+O17 -> 1972.9964 | H17: =G17/C17 -> 3.7177702 | I17: 2 | J17: 149 | K17: =J17-$K$29 -> 131 | N17: =K17*$K$30 -> 3838.3 | O17: =N17/'NG-4 Page 1'!M18 -> 1442.3029
A18: =IF(ISBLANK(B18),"",MAX($A$8:A17)+1) -> 8 | B18: March | C18: 530.1181 | D18: =$C$12+$C$13*C18 -> 44.701531 | E18: =($C$13-$C$45)*C18 -> 34.701531 | F18: =$C$12 -> 10 | G18: =C18+O18 -> 1712.1461 | H18: =G18/C18 -> 3.2297447 | I18: 3 | J18: 133 | K18: =J18-$K$29 -> 115 | N18: =K18*$K$30 -> 3369.5 | O18: =N18/'NG-4 Page 1'!M19 -> 1182.028
A19: =IF(ISBLANK(B19),"",MAX($A$8:A18)+1) -> 9 | B19: April | C19: 454.90082 | D19: =$C$12+$C$13*C19 -> 39.777808 | E19: =($C$13-$C$45)*C19 -> 29.777808 | F19: =$C$12 -> 10 | G19: =C19+O19 -> 1131.2313 | H19: =G19/C19 -> 2.4867647 | I19: 4 | J19: 90 | K19: =J19-$K$29 -> 72 | N19: =K19*$K$30 -> 2109.6 | O19: =N19/'NG-4 Page 1'!M20 -> 676.33048
A20: =IF(ISBLANK(B20),"",MAX($A$8:A19)+1) -> 10 | B20: May | C20: 484.5277 | D20: =$C$12+$C$13*C20 -> 41.717183 | E20: =($C$13-$C$45)*C20 -> 31.717183 | F20: =$C$12 -> 10 | G20: =C20+O20 -> 484.5277 | I20: 5 | J20: 46
A21: =IF(ISBLANK(B21),"",MAX($A$8:A20)+1) -> 11 | B21: June | C21: 586.91619 | D21: =$C$12+$C$13*C21 -> 48.419534 | E21: =($C$13-$C$45)*C21 -> 38.419534 | F21: =$C$12 -> 10 | G21: =C21+O21 -> 586.91619 | I21: 6 | J21: 23
A22: =IF(ISBLANK(B22),"",MAX($A$8:A21)+1) -> 12 | B22: July | C22: 770.46363 | D22: =$C$12+$C$13*C22 -> 60.434549 | E22: =($C$13-$C$45)*C22 -> 50.434549 | F22: =$C$12 -> 10 | G22: =C22+O22 -> 770.46363 | I22: 7 | J22: 18
A23: =IF(ISBLANK(B23),"",MAX($A$8:A22)+1) -> 13 | B23: August | C23: 762.80177 | D23: =$C$12+$C$13*C23 -> 59.933004 | E23: =($C$13-$C$45)*C23 -> 49.933004 | F23: =$C$12 -> 10 | G23: =C23+O23 -> 762.80177 | I23: 8 | J23: 15
A24: =IF(ISBLANK(B24),"",MAX($A$8:A23)+1) -> 14 | B24: September | C24: 536.15882 | D24: =$C$12+$C$13*C24 -> 45.096957 | E24: =($C$13-$C$45)*C24 -> 35.096957 | F24: =$C$12 -> 10 | G24: =C24+O24 -> 536.15882 | I24: 9 | J24: 16
A25: =IF(ISBLANK(B25),"",MAX($A$8:A24)+1) -> 15 | B25: October | C25: 457.55933 | D25: =$C$12+$C$13*C25 -> 39.951834 | E25: =($C$13-$C$45)*C25 -> 29.951834 | F25: =$C$12 -> 10 | G25: =C25+O25 -> 457.55933 | I25: 10 | J25: 20
A26: =IF(ISBLANK(B26),"",MAX($A$8:A25)+1) -> 16 | B26: November | C26: 494.2623 | D26: =$C$12+$C$13*C26 -> 42.35441 | E26: =($C$13-$C$45)*C26 -> 32.35441 | F26: =$C$12 -> 10 | G26: =C26+O26 -> 777.59007 | H26: =G26/C26 -> 1.5732336 | I26: 11 | J26: 47 | K26: =J26-$K$29 -> 29 | N26: =K26*$K$30 -> 849.7 | O26: =N26/'NG-4 Page 1'!M27 -> 283.32778
A27: =IF(ISBLANK(B27),"",MAX($A$8:A26)+1) -> 17 | B27: December | C27: 641.47874 | D27: =$C$12+$C$13*C27 -> 51.991198 | E27: =($C$13-$C$45)*C27 -> 41.991198 | F27: =$C$12 -> 10 | G27: =C27+O27 -> 1436.4845 | H27: =G27/C27 -> 2.239333 | I27: 12 | J27: 93 | K27: =J27-$K$29 -> 75 | N27: =K27*$K$30 -> 2197.5 | O27: =N27/'NG-4 Page 1'!M28 -> 795.00579
A28: =IF(ISBLANK(B28),"",MAX($A$8:A27)+1) | C28: =SUM(C16:C27) -> 6860.5163 | D28: =SUM(D16:D27) -> 569.0894 | E28: =SUM(E16:E27) -> 449.0894 | F28: =SUM(F16:F27) -> 120 | G28: =SUM(G16:G27) -> 12520.681 | H28: =AVERAGE(H16,H17,H18,H19,H26,H27) -> 2.7241565 | O28: =SUM(O16:O27) -> 5660.1646
A29: =IF(ISBLANK(B29),"",MAX($A$8:A28)+1) | J29: Summer Base Load | K29: =AVERAGE(J21:J24) -> 18 | L29: =AVERAGE('NG-4 Page 1'!L17:L20,'NG-4 Page 1'!L27:L28) -> 37.096439 | M29: =AVERAGE('NG-4 Page 1'!M17:M20,'NG-4 Page 1'!M27:M28) -> 2.8335507
A30: =IF(ISBLANK(B30),"",MAX($A$8:A29)+1) -> 18 | B30: Derrivation of Heat Pump Rate | J30: Therm to kWH Factor | K30: 29.3
A31: =IF(ISBLANK(B31),"",MAX($A$8:A30)+1) -> 19 | B31: Customer Charge | C31: =C12 -> 10
A32: =IF(ISBLANK(B32),"",MAX($A$8:A31)+1) -> 20 | B32: Customer Charge Revenue | C32: =C31*12 -> 120
A33: =IF(ISBLANK(B33),"",MAX($A$8:A32)+1)
A34: =IF(ISBLANK(B34),"",MAX($A$8:A33)+1) -> 21 | B34: Winter Volumetric Charge Revenue | C34: =SUM(E16:E19,E26:E27) -> 213.53634 | D34: per customer, November through April
A35: =IF(ISBLANK(B35),"",MAX($A$8:A34)+1) -> 22 | B35: Volumetric Fixed Cost Recovery Charge | C35: =TRUNC(C34/SUM(G16:G19,G26:G27),5) -> 0.02393 | D35: Line 21 divided by Heat Pump kWh for Nov. through Apr.
A36: =IF(ISBLANK(B36),"",MAX($A$8:A35)+1)
A37: =IF(ISBLANK(B37),"",MAX($A$8:A36)+1) -> 23 | B37: Results
A38: =IF(ISBLANK(B38),"",MAX($A$8:A37)+1) -> 24 | B38: HP-RES: Residential Heat Pump Service | C38: Proposed Rate
A39: =IF(ISBLANK(B39),"",MAX($A$8:A38)+1) -> 25 | B39: Customer Charge | C39: =C31 -> 10
A40: =IF(ISBLANK(B40),"",MAX($A$8:A39)+1) -> 26 | B40: Distribution Charge - Winter | C40: =C35 -> 0.02393
A41: =IF(ISBLANK(B41),"",MAX($A$8:A40)+1) -> 27 | B41: Distribution Charge - Summer | C41: =C13 -> 0.06546
A42: =IF(ISBLANK(B42),"",MAX($A$8:A41)+1) | C42: =C41/C40 -> 2.7354785
A43: =IF(ISBLANK(B43),"",MAX($A$8:A42)+1)
B44: (1) Workpaper NG-PP-3 (REV-2) page 2, line 2 (a)-(l) ÷ line 1 (a)-(l)
B45: (2) Internal Reports
B46: (3) Internal Reports
B47: (4) Internal Reports

Sheet Heat Pump Rate Design R1+R2
A8: Line
A9: 1 | B9: Assumptions:
A10: =IF(ISBLANK(B10),"",MAX($A$8:A9)+1)
A11: =IF(ISBLANK(B11),"",MAX($A$8:A10)+1) -> 2 | B11: RD-1: Residential | C11: Proposed Rate
A12: =IF(ISBLANK(B12),"",MAX($A$8:A11)+1) -> 3 | B12: Customer Charge | C12: 10
A13: =IF(ISBLANK(B13),"",MAX($A$8:A12)+1) -> 4 | B13: Distribution Charge | C13: 0.06546
A14: =IF(ISBLANK(B14),"",MAX($A$8:A13)+1)
A15: =IF(ISBLANK(B15),"",MAX($A$8:A14)+1) -> 5 | B15: Average Monthly UPC | C15: R-1/R-2 Average Monthly Use (1) | D15: Cost Recovery per Month | E15: Fixed Cost Recovery in Volumetric Rate | F15: Fixed Cost Recovery in Fixed Charge | G15: Avg. Monthly Use with Heat Pump (kWh) | H15: Winter Multiplier | J15: Normal Therm UPC (2) | K15: Therms (Heating Load) | L15: Avg. Temp. (3) | M15: Avg. Temp COP (4) | N15: kWh Conversion | O15: kWh Usage
A16: =IF(ISBLANK(B16),"",MAX($A$8:A15)+1) -> 6 | B16: January | C16: 459.79926 | D16: =$C$12+$C$13*C16 -> 40.09846 | E16: =($C$13-$C$45)*C16 -> 30.09846 | F16: =$C$12 -> 10 | G16: =C16+O16 -> 1745.7777 | H16: =G16/C16 -> 3.7968259 | J16: 132 | K16: =J16-$K$29 -> 114 | L16: 28.38707 | M16: 2.5973996 | N16: =K16*$K$30 -> 3340.2 | O16: =N16/M16 -> 1285.9785
A17: =IF(ISBLANK(B17),"",MAX($A$8:A16)+1) -> 7 | B17: February | C17: 485.03323 | D17: =$C$12+$C$13*C17 -> 41.750275 | E17: =($C$13-$C$45)*C17 -> 31.750275 | F17: =$C$12 -> 10 | G17: =C17+O17 -> 1929.3822 | H17: =G17/C17 -> 3.977835 | J17: 149 | K17: =J17-$K$29 -> 131 | L17: 30.428333 | M17: 2.6574603 | N17: =K17*$K$30 -> 3838.3 | O17: =N17/M17 -> 1444.3489
A18: =IF(ISBLANK(B18),"",MAX($A$8:A17)+1) -> 8 | B18: March | C18: 583.53512 | D18: =$C$12+$C$13*C18 -> 48.198209 | E18: =($C$13-$C$45)*C18 -> 38.198209 | F18: =$C$12 -> 10 | G18: =C18+O18 -> 1771.9323 | H18: =G18/C18 -> 3.0365478 | J18: 133 | K18: =J18-$K$29 -> 115 | L18: 37.096062 | M18: 2.8353315 | N18: =K18*$K$30 -> 3369.5 | O18: =N18/M18 -> 1188.3972
A19: =IF(ISBLANK(B19),"",MAX($A$8:A18)+1) -> 9 | B19: April | C19: 763.09179 | D19: =$C$12+$C$13*C19 -> 59.951989 | E19: =($C$13-$C$45)*C19 -> 49.951989 | F19: =$C$12 -> 10 | G19: =C19+O19 -> 1441.6379 | H19: =G19/C19 -> 1.8892065 | J19: 90 | K19: =J19-$K$29 -> 72 | L19: 47.340556 | M19: 3.109 | N19: =K19*$K$30 -> 2109.6 | O19: =N19/M19 -> 678.54616
A20: =IF(ISBLANK(B20),"",MAX($A$8:A19)+1) -> 10 | B20: May | C20: 754.92942 | D20: =$C$12+$C$13*C20 -> 59.41768 | E20: =($C$13-$C$45)*C20 -> 49.41768 | F20: =$C$12 -> 10 | G20: =C20+O20 -> 754.92942 | J20: 46
A21: =IF(ISBLANK(B21),"",MAX($A$8:A20)+1) -> 11 | B21: June | C21: 533.69263 | D21: =$C$12+$C$13*C21 -> 44.935519 | E21: =($C$13-$C$45)*C21 -> 34.935519 | F21: =$C$12 -> 10 | G21: =C21+O21 -> 533.69263 | J21: 23
A22: =IF(ISBLANK(B22),"",MAX($A$8:A21)+1) -> 12 | B22: July | C22: 459.49902 | D22: =$C$12+$C$13*C22 -> 40.078806 | E22: =($C$13-$C$45)*C22 -> 30.078806 | F22: =$C$12 -> 10 | G22: =C22+O22 -> 459.49902 | J22: 18
A23: =IF(ISBLANK(B23),"",MAX($A$8:A22)+1) -> 13 | B23: August | C23: 497.042 | D23: =$C$12+$C$13*C23 -> 42.536369 | E23: =($C$13-$C$45)*C23 -> 32.536369 | F23: =$C$12 -> 10 | G23: =C23+O23 -> 497.042 | J23: 15
A24: =IF(ISBLANK(B24),"",MAX($A$8:A23)+1) -> 14 | B24: September | C24: 642.65606 | D24: =$C$12+$C$13*C24 -> 52.068265 | E24: =($C$13-$C$45)*C24 -> 42.068265 | F24: =$C$12 -> 10 | G24: =C24+O24 -> 642.65606 | J24: 16
A25: =IF(ISBLANK(B25),"",MAX($A$8:A24)+1) -> 15 | B25: October | C25: 616.38163 | D25: =$C$12+$C$13*C25 -> 50.348341 | E25: =($C$13-$C$45)*C25 -> 40.348341 | F25: =$C$12 -> 10 | G25: =C25+O25 -> 616.38163 | J25: 20
A26: =IF(ISBLANK(B26),"",MAX($A$8:A25)+1) -> 16 | B26: November | C26: 535.15231 | D26: =$C$12+$C$13*C26 -> 45.03107 | E26: =($C$13-$C$45)*C26 -> 35.03107 | F26: =$C$12 -> 10 | G26: =C26+O26 -> 818.57109 | H26: =G26/C26 -> 1.529604 | J26: 47 | K26: =J26-$K$29 -> 29 | L26: 43.187181 | M26: 2.998037 | N26: =K26*$K$30 -> 849.7 | O26: =N26/M26 -> 283.41878
A27: =IF(ISBLANK(B27),"",MAX($A$8:A26)+1) -> 17 | B27: December | C27: 535.36689 | D27: =$C$12+$C$13*C27 -> 45.045116 | E27: =($C$13-$C$45)*C27 -> 35.045116 | F27: =$C$12 -> 10 | G27: =C27+O27 -> 1331.4049 | H27: =G27/C27 -> 2.4869018 | J27: 93 | K27: =J27-$K$29 -> 75 | L27: 34.282298 | M27: 2.7605466 | N27: =K27*$K$30 -> 2197.5 | O27: =N27/M27 -> 796.038
A28: =IF(ISBLANK(B28),"",MAX($A$8:A27)+1) | C28: =SUM(C16:C27) -> 6866.1793 | D28: =SUM(D16:D27) -> 569.4601 | E28: =SUM(E16:E27) -> 449.4601 | F28: =SUM(F16:F27) -> 120 | G28: =SUM(G16:G27) -> 12542.907 | H28: =AVERAGE(H16,H17,H18,H19,H26,H27) -> 2.7861535 | O28: =SUM(O16:O27) -> 5676.7275
A29: =IF(ISBLANK(B29),"",MAX($A$8:A28)+1) | J29: Summer Base Load | K29: =AVERAGE(J21:J24) -> 18
A30: =IF(ISBLANK(B30),"",MAX($A$8:A29)+1) -> 18 | B30: Derrivation of Heat Pump Rate | J30: Therm to kWH Factor | K30: 29.3
A31: =IF(ISBLANK(B31),"",MAX($A$8:A30)+1) -> 19 | B31: Customer Charge | C31: =C12 -> 10
A32: =IF(ISBLANK(B32),"",MAX($A$8:A31)+1) -> 20 | B32: Customer Charge Revenue | C32: =C31*12 -> 120
A33: =IF(ISBLANK(B33),"",MAX($A$8:A32)+1)
A34: =IF(ISBLANK(B34),"",MAX($A$8:A33)+1) -> 21 | B34: Winter Volumetric Charge Revenue | C34: =SUM(E16:E19,E26:E27) -> 220.07512 | D34: per customer, November through April
A35: =IF(ISBLANK(B35),"",MAX($A$8:A34)+1) -> 22 | B35: Volumetric Fixed Cost Recovery Charge | C35: =TRUNC(C34/SUM(G16:G19,G26:G27),5) -> 0.02434 | D35: Line 21 divided by Heat Pump kWh for Nov. through Apr.
A36: =IF(ISBLANK(B36),"",MAX($A$8:A35)+1)
A37: =IF(ISBLANK(B37),"",MAX($A$8:A36)+1) -> 23 | B37: Results
A38: =IF(ISBLANK(B38),"",MAX($A$8:A37)+1) -> 24 | B38: HP-RES: Residential Heat Pump Service | C38: Proposed Rate
A39: =IF(ISBLANK(B39),"",MAX($A$8:A38)+1) -> 25 | B39: Customer Charge | C39: =C31 -> 10
A40: =IF(ISBLANK(B40),"",MAX($A$8:A39)+1) -> 26 | B40: Distribution Charge - Winter | C40: =C35 -> 0.02434
A41: =IF(ISBLANK(B41),"",MAX($A$8:A40)+1) -> 27 | B41: Distribution Charge - Summer | C41: =C13 -> 0.06546
A42: =IF(ISBLANK(B42),"",MAX($A$8:A41)+1) | C42: =C41/C40 -> 2.6894002
A43: =IF(ISBLANK(B43),"",MAX($A$8:A42)+1)
B44: (1) Workpaper NG-PP-3 (REV-2) page 2, line 2 (a)-(l) ÷ line 1 (a)-(l)
B45: (2) Internal Reports
B46: (3) Internal Reports
B47: (4) Internal Reports

Sheet Heat Pump Rate Design R1+R2 (2)
A8: Line
A9: 1 | B9: Assumptions:
A10: =IF(ISBLANK(B10),"",MAX($A$8:A9)+1)
A11: =IF(ISBLANK(B11),"",MAX($A$8:A10)+1) -> 2 | B11: RD-1: Residential | C11: Proposed Rate
A12: =IF(ISBLANK(B12),"",MAX($A$8:A11)+1) -> 3 | B12: Customer Charge | C12: 10
A13: =IF(ISBLANK(B13),"",MAX($A$8:A12)+1) -> 4 | B13: Distribution Charge | C13: 0.06546
A14: =IF(ISBLANK(B14),"",MAX($A$8:A13)+1)
A15: =IF(ISBLANK(B15),"",MAX($A$8:A14)+1) -> 5 | B15: Average Monthly UPC | C15: R-1/R-2 Average Monthly Use (1) | D15: Cost Recovery per Month | E15: Fixed Cost Recovery in Volumetric Rate | F15: Fixed Cost Recovery in Fixed Charge | G15: Avg. Monthly Use with Heat Pump (kWh) | H15: Winter Multiplier | J15: Normal Therm UPC (2) | K15: Therms (Heating Load) | L15: Avg. Temp. (3) | M15: Avg. Temp COP (4) | N15: kWh Conversion | O15: kWh Usage
A16: =IF(ISBLANK(B16),"",MAX($A$8:A15)+1) -> 6 | B16: January | C16: 459.79926 | D16: =$C$12+$C$13*C16 -> 40.09846 | E16: =($C$13-$C$45)*C16 -> 30.09846 | F16: =$C$12 -> 10 | G16: =C16+O16 -> 1745.7777 | H16: =G16/C16 -> 3.7968259 | J16: 132 | K16: =J16-$K$29 -> 114 | L16: 28.38707 | M16: 2.5973996 | N16: =K16*$K$30 -> 3340.2 | O16: =N16/M16 -> 1285.9785
A17: =IF(ISBLANK(B17),"",MAX($A$8:A16)+1) -> 7 | B17: February | C17: 485.03323 | D17: =$C$12+$C$13*C17 -> 41.750275 | E17: =($C$13-$C$45)*C17 -> 31.750275 | F17: =$C$12 -> 10 | G17: =C17+O17 -> 1929.3822 | H17: =G17/C17 -> 3.977835 | J17: 149 | K17: =J17-$K$29 -> 131 | L17: 30.428333 | M17: 2.6574603 | N17: =K17*$K$30 -> 3838.3 | O17: =N17/M17 -> 1444.3489
A18: =IF(ISBLANK(B18),"",MAX($A$8:A17)+1) -> 8 | B18: March | C18: 583.53512 | D18: =$C$12+$C$13*C18 -> 48.198209 | E18: =($C$13-$C$45)*C18 -> 38.198209 | F18: =$C$12 -> 10 | G18: =C18+O18 -> 1771.9323 | H18: =G18/C18 -> 3.0365478 | J18: 133 | K18: =J18-$K$29 -> 115 | L18: 37.096062 | M18: 2.8353315 | N18: =K18*$K$30 -> 3369.5 | O18: =N18/M18 -> 1188.3972
A19: =IF(ISBLANK(B19),"",MAX($A$8:A18)+1) -> 9 | B19: April | C19: 763.09179 | D19: =$C$12+$C$13*C19 -> 59.951989 | E19: =($C$13-$C$45)*C19 -> 49.951989 | F19: =$C$12 -> 10 | G19: =C19+O19 -> 1441.6379 | H19: =G19/C19 -> 1.8892065 | J19: 90 | K19: =J19-$K$29 -> 72 | L19: 47.340556 | M19: 3.109 | N19: =K19*$K$30 -> 2109.6 | O19: =N19/M19 -> 678.54616
A20: =IF(ISBLANK(B20),"",MAX($A$8:A19)+1) -> 10 | B20: May | C20: 754.92942 | D20: =$C$12+$C$13*C20 -> 59.41768 | E20: =($C$13-$C$45)*C20 -> 49.41768 | F20: =$C$12 -> 10 | G20: =C20+O20 -> 754.92942 | J20: 46
A21: =IF(ISBLANK(B21),"",MAX($A$8:A20)+1) -> 11 | B21: June | C21: 533.69263 | D21: =$C$12+$C$13*C21 -> 44.935519 | E21: =($C$13-$C$45)*C21 -> 34.935519 | F21: =$C$12 -> 10 | G21: =C21+O21 -> 533.69263 | J21: 23
A22: =IF(ISBLANK(B22),"",MAX($A$8:A21)+1) -> 12 | B22: July | C22: 459.49902 | D22: =$C$12+$C$13*C22 -> 40.078806 | E22: =($C$13-$C$45)*C22 -> 30.078806 | F22: =$C$12 -> 10 | G22: =C22+O22 -> 459.49902 | J22: 18
A23: =IF(ISBLANK(B23),"",MAX($A$8:A22)+1) -> 13 | B23: August | C23: 497.042 | D23: =$C$12+$C$13*C23 -> 42.536369 | E23: =($C$13-$C$45)*C23 -> 32.536369 | F23: =$C$12 -> 10 | G23: =C23+O23 -> 497.042 | J23: 15
A24: =IF(ISBLANK(B24),"",MAX($A$8:A23)+1) -> 14 | B24: September | C24: 642.65606 | D24: =$C$12+$C$13*C24 -> 52.068265 | E24: =($C$13-$C$45)*C24 -> 42.068265 | F24: =$C$12 -> 10 | G24: =C24+O24 -> 642.65606 | J24: 16
A25: =IF(ISBLANK(B25),"",MAX($A$8:A24)+1) -> 15 | B25: October | C25: 616.38163 | D25: =$C$12+$C$13*C25 -> 50.348341 | E25: =($C$13-$C$45)*C25 -> 40.348341 | F25: =$C$12 -> 10 | G25: =C25+O25 -> 616.38163 | J25: 20
A26: =IF(ISBLANK(B26),"",MAX($A$8:A25)+1) -> 16 | B26: November | C26: 535.15231 | D26: =$C$12+$C$13*C26 -> 45.03107 | E26: =($C$13-$C$45)*C26 -> 35.03107 | F26: =$C$12 -> 10 | G26: =C26+O26 -> 818.57109 | H26: =G26/C26 -> 1.529604 | J26: 47 | K26: =J26-$K$29 -> 29 | L26: 43.187181 | M26: 2.998037 | N26: =K26*$K$30 -> 849.7 | O26: =N26/M26 -> 283.41878
A27: =IF(ISBLANK(B27),"",MAX($A$8:A26)+1) -> 17 | B27: December | C27: 535.36689 | D27: =$C$12+$C$13*C27 -> 45.045116 | E27: =($C$13-$C$45)*C27 -> 35.045116 | F27: =$C$12 -> 10 | G27: =C27+O27 -> 1331.4049 | H27: =G27/C27 -> 2.4869018 | J27: 93 | K27: =J27-$K$29 -> 75 | L27: 34.282298 | M27: 2.7605466 | N27: =K27*$K$30 -> 2197.5 | O27: =N27/M27 -> 796.038
A28: =IF(ISBLANK(B28),"",MAX($A$8:A27)+1) | C28: =SUM(C16:C27) -> 6866.1793 | D28: =SUM(D16:D27) -> 569.4601 | E28: =SUM(E16:E27) -> 449.4601 | F28: =SUM(F16:F27) -> 120 | G28: =SUM(G16:G27) -> 12542.907 | H28: =AVERAGE(H16,H17,H18,H19,H26,H27) -> 2.7861535 | O28: =SUM(O16:O27) -> 5676.7275
A29: =IF(ISBLANK(B29),"",MAX($A$8:A28)+1) | J29: Summer Base Load | K29: =AVERAGE(J21:J24) -> 18
A30: =IF(ISBLANK(B30),"",MAX($A$8:A29)+1) -> 18 | B30: Derrivation of Heat Pump Rate | J30: Therm to kWH Factor | K30: 29.3
A31: =IF(ISBLANK(B31),"",MAX($A$8:A30)+1) -> 19 | B31: Customer Charge | C31: =C12 -> 10
A32: =IF(ISBLANK(B32),"",MAX($A$8:A31)+1) -> 20 | B32: Customer Charge Revenue | C32: =C31*12 -> 120
A33: =IF(ISBLANK(B33),"",MAX($A$8:A32)+1)
A34: =IF(ISBLANK(B34),"",MAX($A$8:A33)+1) -> 21 | B34: Winter Volumetric Charge Revenue | C34: =SUM(E16:E19,E26:E27) -> 220.07512 | D34: per customer, November through April
A35: =IF(ISBLANK(B35),"",MAX($A$8:A34)+1) -> 22 | B35: Volumetric Fixed Cost Recovery Charge | C35: =TRUNC(C34/SUM(G16:G19,G26:G27),5) -> 0.02434 | D35: Line 21 divided by Heat Pump kWh for Nov. through Apr.
A36: =IF(ISBLANK(B36),"",MAX($A$8:A35)+1)
A37: =IF(ISBLANK(B37),"",MAX($A$8:A36)+1) -> 23 | B37: Results
A38: =IF(ISBLANK(B38),"",MAX($A$8:A37)+1) -> 24 | B38: HP-RES: Residential Heat Pump Service | C38: Proposed Rate
A39: =IF(ISBLANK(B39),"",MAX($A$8:A38)+1) -> 25 | B39: Customer Charge | C39: =C31 -> 10
A40: =IF(ISBLANK(B40),"",MAX($A$8:A39)+1) -> 26 | B40: Distribution Charge - Winter | C40: =C35 -> 0.02434
A41: =IF(ISBLANK(B41),"",MAX($A$8:A40)+1) -> 27 | B41: Distribution Charge - Summer | C41: =C13 -> 0.06546
B44: (1) Workpaper NG-PP-3 (REV-2) page 2, line 2 (a)-(l) ÷ line 1 (a)-(l)
B45: (2) Internal Reports
B46: (3) Internal Reports
B47: (4) Internal Reports
