Workbook

Sheet Model
A1: Heat Pump vs Gas/Propane Model | L1: Legend: model param, imported from sheet, calculated value
A2: Switchbox 2025 | E2: Natural gas furnace | H2: Propane furnace
D3: Units | E3: Zone 4 | F3: Zone 5 | G3: Zone 6 | H3: Zone 4 | I3: Zone 5 | J3: Zone 6 | L3: Source | M3: Notes
A4: Fuel prices
C5: Electricity price | D5: $ / kWh | E5: ='Fuel costs'!$B$10 * 0.01 -> 0.2165697 | F5: ='Fuel costs'!$B$10 * 0.01 -> 0.2165697 | G5: ='Fuel costs'!$B$10 * 0.01 -> 0.2165697 | H5: ='Fuel costs'!$B$10 * 0.01 -> 0.2165697 | I5: ='Fuel costs'!$B$10 * 0.01 -> 0.2165697 | J5: ='Fuel costs'!$B$10 * 0.01 -> 0.2165697 | L5: See Fuel costs tab | M5: Statewide average winter price, 2020-2025
C6: Natural gas or propane price | D6: $ / mcf or $ / gallon | E6: ='Fuel costs'!$B$22 -> 15.292188 | F6: ='Fuel costs'!$B$22 -> 15.292188 | G6: ='Fuel costs'!$B$22 -> 15.292188 | H6: ='Fuel costs'!$B$34 * 0.01 -> 3.2348788 | I6: ='Fuel costs'!$B$34 * 0.01 -> 3.2348788 | J6: ='Fuel costs'!$B$34 * 0.01 -> 3.2348788 | L6: See Fuel costs tab | M6: Statewide average winter price, 2020-2025
A8: Building
B9: Building design
C10: Avg sq. ft. (exlcuding basement) | D10: ft^2 | E10: 2363 | F10: 2363 | G10: 2363 | H10: 2363 | I10: 2363 | J10: 2363 | L10: https://www.census.gov/construction/nrc/pdf/quarterly_starts_completions.pdf | M10: 2024 median square feet of floor area for Single-family units, Northeast (Table Q2)
C11: Stories above ground | D11: stories | E11: 2 | F11: 2 | G11: 2 | H11: 2 | I11: 2 | J11: 2
C12: Avg wall length | D12: ft | E12: =SQRT(E10/E11) -> 34.372954 | F12: =SQRT(F10/F11) -> 34.372954 | G12: =SQRT(G10/G11) -> 34.372954 | H12: =SQRT(H10/H11) -> 34.372954 | I12: =SQRT(I10/I11) -> 34.372954 | J12: =SQRT(J10/J11) -> 34.372954 | M12: Assumes a square house
C13: Avg story height | D13: ft | E13: 10 | F13: 10 | G13: 10 | H13: 10 | I13: 10 | J13: 10 | L13: https://weekendbuilds.com/how-tall-is-a-house/
C14: Wall sufrace area | D14: ft^2 | E14: =(E12*4)*(E11*E13) -> 2749.8364 | F14: =(F12*4)*(F11*F13) -> 2749.8364 | G14: =(G12*4)*(G11*G13) -> 2749.8364 | H14: =(H12*4)*(H11*H13) -> 2749.8364 | I14: =(I12*4)*(I11*I13) -> 2749.8364 | J14: =(J12*4)*(J11*J13) -> 2749.8364
C15: Attic floor surface area | D15: ft^2 | E15: =E10/2 -> 1181.5 | F15: =F10/2 -> 1181.5 | G15: =G10/2 -> 1181.5 | H15: =H10/2 -> 1181.5 | I15: =I10/2 -> 1181.5 | J15: =J10/2 -> 1181.5 | M15: Treating attic floor as thermal boundary to simplify heat loss calculations vs steepled roof
C16: Percent of walls which are windows and doors | D16: percent | E16: 0.2 | F16: 0.2 | G16: 0.2 | H16: 0.2 | I16: 0.2 | J16: 0.2 | L16: https://www.resnet.us/wp-content/uploads/ANSIRESNETICC301-2022_resnetpblshd.pdf | M16: 17% windows, 3% doors
C17: Surface area of walls | D17: ft^2 | E17: =E14*(1-E16) -> 2199.8691 | F17: =F14*(1-F16) -> 2199.8691 | G17: =G14*(1-G16) -> 2199.8691 | H17: =H14*(1-H16) -> 2199.8691 | I17: =I14*(1-I16) -> 2199.8691 | J17: =J14*(1-J16) -> 2199.8691
C18: Surface area of windows and doors | D18: ft^2 | E18: =E14*E16 -> 549.96727 | F18: =F14*F16 -> 549.96727 | G18: =G14*G16 -> 549.96727 | H18: =H14*H16 -> 549.96727 | I18: =I14*I16 -> 549.96727 | J18: =J14*J16 -> 549.96727
C19: Above-grade basement wall height | D19: ft | E19: 2 | F19: 2 | G19: 2 | H19: 2 | I19: 2 | J19: 2
C20: Below-grade basement wall height | D20: ft | E20: 8 | F20: 8 | G20: 8 | H20: 8 | I20: 8 | J20: 8
C21: Above-grade basement walls surface area | D21: ft^3 | E21: =(4*E19*E12) -> 274.98364 | F21: =(4*F19*F12) -> 274.98364 | G21: =(4*G19*G12) -> 274.98364 | H21: =(4*H19*H12) -> 274.98364 | I21: =(4*I19*I12) -> 274.98364 | J21: =(4*J19*J12) -> 274.98364
C22: Below-grade basement walls surface area | D22: ft^2 | E22: =(4*E20*E12) -> 1099.9345 | F22: =(4*F20*F12) -> 1099.9345 | G22: =(4*G20*G12) -> 1099.9345 | H22: =(4*H20*H12) -> 1099.9345 | I22: =(4*I20*I12) -> 1099.9345 | J22: =(4*J20*J12) -> 1099.9345
C23: Below-grade basement floor | D23: ft | E23: =E12*4 -> 137.49182 | F23: =F12*4 -> 137.49182 | G23: =G12*4 -> 137.49182 | H23: =H12*4 -> 137.49182 | I23: =I12*4 -> 137.49182 | J23: =J12*4 -> 137.49182
C24: House cubic volume (including basement) | D24: ft^3 | E24: =E10*E13+(E19+E20)*E10/2 -> 35445 | F24: =F10*F13+(F19+F20)*F10/2 -> 35445 | G24: =G10*G13+(G19+G20)*G10/2 -> 35445 | H24: =H10*H13+(H19+H20)*H10/2 -> 35445 | I24: =I10*I13+(I19+I20)*I10/2 -> 35445 | J24: =J10*J13+(J19+J20)*J10/2 -> 35445
B26: BTU / degree calculations (air) | L26: https://neep.org/sites/default/files/Sizing%20%26%20Selecting%20ASHPs%20In%20Cold%20Climates.pdf | M26: Credit to (https://www.builditsolar.com/References/Calculators/HeatLoss/HeatLoss.htm)
C27: Minimum R value for attic | D27: (ft^2*F)/(BTU/hr) | E27: 49 | F27: 49 | G27: 49 | H27: 49 | I27: 49 | J27: 49 | L27: https://codes.iccsafe.org/content/NYSECC2025P1 | M27: R402.1.3
C28: Minimum R value for walls | D28: (ft^2*F)/(BTU/hr) | E28: 30 | F28: 30 | G28: 30 | H28: 30 | I28: 30 | J28: 30 | L28: https://codes.iccsafe.org/content/NYSECC2025P1 | M28: R402.1.3
C29: Minimum R value for windows and doors | D29: (ft^2*F)/(BTU/hr) | E29: =1/0.27 -> 3.7037037 | F29: =1/0.27 -> 3.7037037 | G29: =1/0.27 -> 3.7037037 | H29: =1/0.27 -> 3.7037037 | I29: =1/0.27 -> 3.7037037 | J29: =1/0.27 -> 3.7037037 | L29: https://codes.iccsafe.org/content/NYSECC2025P1 | M29: R402.1.3; R-value is 1/U-factor
C30: Minimum R value for basement wall | D30: (ft^2*F)/(BTU/hr) | E30: 15 | F30: 15 | G30: 15 | H30: 15 | I30: 15 | J30: 15 | L30: https://codes.iccsafe.org/content/NYSECC2025P1 | M30: R402.1.3
C31: Heated slab F-factor | D31: (BTU/hr)/(ft*F) | E31: 0.55 | F31: 0.55 | G31: 0.55 | H31: 0.55 | I31: 0.55 | J31: 0.55 | L31: https://codes.iccsafe.org/content/NYSECC2025P1 | M31: R402.1.2
C32: Air changes per hour (50 Pascals) | D32: ACH50 | E32: 3 | F32: 3 | G32: 2.5 | H32: 3 | I32: 3 | J32: 2.5 | L32: https://codes.iccsafe.org/content/NYSECC2025P1 | M32: R405.4
C33: Heat loss through attic per degree | D33: (BTU/hr)/F | E33: =E15/E27 -> 24.112245 | F33: =F15/F27 -> 24.112245 | G33: =G15/G27 -> 24.112245 | H33: =H15/H27 -> 24.112245 | I33: =I15/I27 -> 24.112245 | J33: =J15/J27 -> 24.112245 | L33: http://hyperphysics.phy-astr.gsu.edu/hbase/thermo/heatloss.html
C34: Heat loss in exterior walls per degree | D34: (BTU/hr)/F | E34: =E17/E28 -> 73.32897 | F34: =F17/F28 -> 73.32897 | G34: =G17/G28 -> 73.32897 | H34: =H17/H28 -> 73.32897 | I34: =I17/I28 -> 73.32897 | J34: =J17/J28 -> 73.32897 | L34: http://hyperphysics.phy-astr.gsu.edu/hbase/thermo/heatloss.html
C35: Heat loss through windows and doors per degree | D35: (BTU/hr)/F | E35: =E18/E29 -> 148.49116 | F35: =F18/F29 -> 148.49116 | G35: =G18/G29 -> 148.49116 | H35: =H18/H29 -> 148.49116 | I35: =I18/I29 -> 148.49116 | J35: =J18/J29 -> 148.49116 | L35: http://hyperphysics.phy-astr.gsu.edu/hbase/thermo/heatloss.html
C36: Heat loss through above-grade basement walls per degree | D36: (BTU/hr)/F | E36: =E21/E30 -> 18.332242 | F36: =F21/F30 -> 18.332242 | G36: =G21/G30 -> 18.332242 | H36: =H21/H30 -> 18.332242 | I36: =I21/I30 -> 18.332242 | J36: =J21/J30 -> 18.332242 | L36: http://hyperphysics.phy-astr.gsu.edu/hbase/thermo/heatloss.html
C37: Heat loss through air changes per degree | D37: (BTU/hr)/F | E37: =(0.018*(E32/20)*E24) -> 95.7015 | F37: =(0.018*(F32/20)*F24) -> 95.7015 | G37: =(0.018*(G32/20)*G24) -> 79.75125 | H37: =(0.018*(H32/20)*H24) -> 95.7015 | I37: =(0.018*(I32/20)*I24) -> 95.7015 | J37: =(0.018*(J32/20)*J24) -> 79.75125 | L37: https://eta-publications.lbl.gov/sites/default/files/the_use_of_blower-door_data_1995_sherman_lbl_35173_.pdf | M37: See note for derivation, but basically we convert ACH50 to ACHnat, and work out heat loss from there
C38: Heat loss through below-grade basement walls per degree to soil | D38: (BTU/hr)/F | E38: =E22/E30 -> 73.32897 | F38: =F22/F30 -> 73.32897 | G38: =G22/G30 -> 73.32897 | H38: =H22/H30 -> 73.32897 | I38: =I22/I30 -> 73.32897 | J38: =J22/J30 -> 73.32897 | L38: http://hyperphysics.phy-astr.gsu.edu/hbase/thermo/heatloss.html | M38: ASHRE designs the R-values and F-factors to allow us to use air temperature as an approximation
C39: Heat loss through slab per degree to soil | D39: (BTU/hr)/F | E39: =E23*E31 -> 75.6205 | F39: =F23*F31 -> 75.6205 | G39: =G23*G31 -> 75.6205 | H39: =H23*H31 -> 75.6205 | I39: =I23*I31 -> 75.6205 | J39: =J23*J31 -> 75.6205 | L39: https://bigladdersoftware.com/epx/docs/8-2/engineering-reference/ground-heat-transfer-calculations.html
C40: Total heat loss rate (air) | D40: (BTU/hr)/F | E40: =SUM(E33:E39) -> 508.91559 | F40: =SUM(F33:F39) -> 508.91559 | G40: =SUM(G33:G39) -> 492.96534 | H40: =SUM(H33:H39) -> 508.91559 | I40: =SUM(I33:I39) -> 508.91559 | J40: =SUM(J33:J39) -> 492.96534
B42: Yearly BTUs
C43: Heating degree days | D43: HDD | E43: 4500 | F43: 6300 | G43: 8100 | H43: 4500 | I43: 6300 | J43: 8100 | L43: https://codes.iccsafe.org/s/IRC2021P2/chapter-11-re-energy-efficiency/IRC2021P2-Pt04-Ch11-SecN1101.7.2 | M43: Heating degree days are part of the definition of being a climate zone in the 2024 IECC code.
...

Sheet Utility rebates
B1: ASHP / 10k BTU | C1: GSHP / 10k BTU | D1: HPHW | E1: Source | F1: Source notes
A2: Central Hudson | B2: 500 | C2: 2000 | D2: 1000 | E2: https://cleanheat.ny.gov/assets/pdf/Program%20Manual%20-%20CHG&E-%20NGrid-%20NYSEG-%20O&R-%20and%20RG&E%2004.01.25.pdf | F2: category 2 (p. 13), 3 (p.14), and 5 (p. 14)
A3: ConEd O&R | B3: 700 | C3: 2000 | D3: 1000 | E3: https://cleanheat.ny.gov/assets/pdf/Program%20Manual%20-%20CHG&E-%20NGrid-%20NYSEG-%20O&R-%20and%20RG&E%2004.01.25.pdf | F3: category 2 (p. 13), 3 (p.14), and 5 (p. 14)
A4: National Grid | B4: 1200 | C4: 2500 | D4: 1000 | E4: https://cleanheat.ny.gov/assets/pdf/Program%20Manual%20-%20CHG&E-%20NGrid-%20NYSEG-%20O&R-%20and%20RG&E%2004.01.25.pdf | F4: category 2 (p. 13), 3 (p.14), and 5 (p. 14)
A5: ConEd | B5: =2500*(1/(Model!$E$55/10000)) -> 756.31849 | C5: 5000 | D5: 1000 | E5: https://cleanheat.ny.gov/assets/pdf/CECONY%20Clean%20Heat%20Program%20Manual%20June%202%202025.pdf | F5: ConEd gives $2,500 for entire project, calculate per 10K BTU-equivalent incentive
A6: PSEG | B6: 833 | C6: 1250 | D6: 1200 | E6: https://www.psegliny.com/en/saveenergyandmoney/homeefficiency/HomeComfort/HeatPumps/Rebates, https://www.psegliny.com/saveenergyandmoney/energystarrebates | F6: ASHP $1000/12K BTU = $833/10K BTU; GSHP $1,500/12KBTU = $1,250
A7: NYSEG | B7: 1000 | C7: 2000 | D7: 900 | E7: https://cleanheat.ny.gov/assets/pdf/Program%20Manual%20-%20CHG&E-%20NGrid-%20NYSEG-%20O&R-%20and%20RG&E%2004.01.25.pdf | F7: category 2 (p. 13), 3 (p.14), and 5 (p. 14)
A8: RG&E | B8: 800 | C8: 1500 | D8: 900 | E8: https://cleanheat.ny.gov/assets/pdf/Program%20Manual%20-%20CHG&E-%20NGrid-%20NYSEG-%20O&R-%20and%20RG&E%2004.01.25.pdf | F8: category 2 (p. 13), 3 (p.14), and 5 (p. 14)

Sheet Service line costs
B1: Avg. length of new res. service lines (ft) | C1: Avg. per foot cost of installation - services ($) | D1: Avg. cost of new resi. service line (2021) | E1: Source
A2: NFG | B2: 84 | C2: 18 | D2: =B2*C2 -> 1512 | E2: https://www.documentcloud.org/documents/26185614-nys-utilities-costs-of-extending-service-to-new-customers/#document/p11/a2674171
A3: RG&E | B3: 67 | C3: 30 | D3: =B3*C3 -> 2010 | E3: https://www.documentcloud.org/documents/26185614-nys-utilities-costs-of-extending-service-to-new-customers/#document/p13/a2674173
A4: NiMo | B4: 74 | C4: 53 | D4: =B4*C4 -> 3922 | E4: https://www.documentcloud.org/documents/26185614-nys-utilities-costs-of-extending-service-to-new-customers/#document/p10/a2674170
A5: O&R | B5: 65 | C5: 59 | D5: =B5*C5 -> 3835 | E5: https://www.documentcloud.org/documents/26185614-nys-utilities-costs-of-extending-service-to-new-customers/#document/p14/a2674174
A6: KEDLI | B6: 81 | C6: 67 | D6: =B6*C6 -> 5427 | E6: https://www.documentcloud.org/documents/26185614-nys-utilities-costs-of-extending-service-to-new-customers/#document/p9/a2674169
A7: NYSEG | B7: 98 | C7: 89 | D7: =B7*C7 -> 8722 | E7: https://www.documentcloud.org/documents/26185614-nys-utilities-costs-of-extending-service-to-new-customers/#document/p12/a2674172
A8: CenHud | B8: 71 | C8: 133 | D8: =B8*C8 -> 9443 | E8: https://www.documentcloud.org/documents/26185614-nys-utilities-costs-of-extending-service-to-new-customers/#document/p4/a2674165
A9: KEDNY | B9: 46 | C9: 370 | D9: =B9*C9 -> 17020 | E9: https://www.documentcloud.org/documents/26185614-nys-utilities-costs-of-extending-service-to-new-customers/#document/p8/a2674168
A10: ConEd | B10: 43 | C10: 710 | D10: =B10*C10 -> 30530 | E10: https://www.documentcloud.org/documents/26185614-nys-utilities-costs-of-extending-service-to-new-customers/#document/p5/a2674166
A11: St. Lawrence | B11: 105 | C11: 89 | D11: =100*C11 -> 8900 | E11: https://www.documentcloud.org/documents/26185614-nys-utilities-costs-of-extending-service-to-new-customers/#document/p7/a2674177
A12: Corning | B12: 215 | C12: 49 | D12: =100*C12 -> 4900 | E12: https://www.documentcloud.org/documents/26185614-nys-utilities-costs-of-extending-service-to-new-customers/#document/p6/a2674176

Sheet Equipment costs
A1: Device | B1: Size | C1: Specs required | D1: Specs actual | E1: Link | F1: Last updated | G1: Prices | N1: Average
A2: ccASHP (Condenser), Zone 4 | B2: 36K BTU | C2: HSPF2 7.8 | D2: HSPF2 10 | E2: https://www.appliancesconnection.com/carrier-38mbrbq48aa3.html | F2: 2025 | G2: 2999 | H2: 2565 | I2: 2685 | N2: =AVERAGE(G2:M2) -> 2749.6667
A3: ccASHP (Condenser), Zones 5+6 | B3: 48K BTU | C3: HSPF2 8.1, capacity ≥ 70% at 5ºF | D3: HSPF2 10 | F3: 2025 | G3: 3790 | H3: 4648 | I3: 3575 | N3: =AVERAGE(G3:M3) -> 4004.3333
A4: Furnace | B4: 40K BTU | C4: AFUE 95% | E4: https://hvacdirect.com/furnaces/filter/40-000/92,96,97,98.html?product_list_limit=48 | F4: 2025 | G4: 1761 | H4: 1400 | I4: 1712 | J4: 1750 | K4: 2066 | L4: 1592 | M4: 1715 | N4: =AVERAGE(G4:M4) -> 1713.7143
A5: Heat Pump Water Heater | B5: 50 gallon | C5: UEF > 2.2 | E5: https://www.homedepot.com/p/Rheem-Performance-Platinum-40-Gal-10-Year-Hybrid-High-Efficiency-Smart-Tank-Electric-Water-Heater-XE40T10H45U0/312742067?irgwc=1&cm_mmc=afl-ir-3198627-456723-&clickid=Wpe1aqSQIxyLWRmUfcT1PR0YUkDVkyzBu01J280 | F5: 2025 | G5: 1799 | H5: 1699 | I5: 1550 | J5: 1819 | K5: 1799.99 | N5: =AVERAGE(G5:M5) -> 1733.398
A6: Gas Water Heater | B6: 50 gallon | C6: UEF > 0.81 | E6: https://www.homedepot.com/p/Rheem-Performance-50-Gal-Tall-6-Year-38-000-BTU-Natural-Gas-Tank-Water-Heater-XG50T06EC38U1/205811151?irgwc=1&cm_mmc=afl-ir-2084711-456723-&clickid=Wpe1aqSQIxyLWRmUfcT1PR0YUkDVky3pu01J280 | F6: 2025 | G6: 709 | H6: 679 | I6: 779 | J6: 1079.8 | K6: 889 | L6: 729.9 | M6: 889 | N6: =AVERAGE(G6:M6) -> 822.1
A7: AC (Condenser) | B7: 2.5 ton | C7: SEER2 15.2 | E7: https://hvacdirect.com/air-conditioning-systems/air-conditioner-split-systems.html?p=2 | F7: 2025 | G7: 2046.43 | H7: 2312.09 | I7: 2584 | J7: 2501.79 | K7: 2180 | L7: 2235 | N7: =AVERAGE(G7:M7) -> 2309.885

Sheet Fuel costs
A1: Monthly Average Retail Price of Electricity - Residential, New York - Statewide | E1: Source: EIA via NYSERDA | H1: Prices are cents per Kilowatt-hour (¢/kWh).
B2: 2025 | C2: 2024 | D2: 2023 | E2: 2022 | F2: 2021 | G2: 2020 | H2: 2019 | I2: 2018 | J2: 2017 | K2: 2016 | L2: 2015 | M2: 2014 | N2: 2013 | O2: 2012
A3: January | B3: 25.31 | C3: 23.44 | D3: 23.57 | E3: 21 | F3: 18.3 | G3: 17.6 | H3: 17.3 | I3: 17.8 | J3: 17.3 | K3: 16.5 | L3: 19.3 | M3: 19.5 | N3: 18 | O3: 16.8
A4: February | B4: 26.2 | C4: 24.23 | D4: 23.6 | E4: 21.6 | F4: 18.8 | G4: 17.4 | H4: 17.6 | I4: 18.2 | J4: 17.5 | K4: 16.8 | L4: 19.8 | M4: 21.7 | N4: 19 | O4: 16.6
A5: March | B5: 25.43 | C5: 23.64 | D5: 21.18 | E5: 19.7 | F5: 18 | G5: 17.2 | H5: 16.8 | I5: 17.5 | J5: 17 | K5: 16.9 | L5: 19 | M5: 20.9 | N5: 18.3 | O5: 16.7
A6: October | C6: 24.98 | D6: 22.7 | E6: 23.3 | F6: 20.6 | G6: 19.3 | H6: 18.6 | I6: 19.3 | J6: 18.7 | K6: 18.3 | L6: 18.3 | M6: 19.4 | N6: 18.9 | O6: 18.4
A7: November | C7: 24.69 | D7: 22.72 | E7: 23.7 | F7: 20 | G7: 19 | H7: 18 | I7: 18.2 | J7: 17.8 | K7: 17.7 | L7: 18.2 | M7: 19.5 | N7: 18.5 | O7: 17.4
A8: December | C8: 24.37 | D8: 22.52 | E8: 22.8 | F8: 19.5 | G8: 18.3 | H8: 17.3 | I8: 17.3 | J8: 17 | K8: 17.2 | L8: 17.5 | M8: 19.3 | N8: 18.2 | O8: 17.5
A10: Average 2020-2025 | B10: =AVERAGE(B3:G8) -> 21.65697 | D10: Average 2015-2025 | E10: =AVERAGE(B3:L8) -> 19.831429
A11: Average for 2025 | B11: =average(B3:B5) -> 25.646667 | D11: Average for 2022 | E11: =average(E3:E5) -> 20.766667
A13: Monthly Average Price of Natural Gas - Residential, New York - Statewide | E13: Source: EIA via NYSERDA | H13: Prices are dollars per thousand cubic feet ($/MCF).
B14: 2025 | C14: 2024 | D14: 2023 | E14: 2022 | F14: 2021 | G14: 2020 | H14: 2019 | I14: 2018 | J14: 2017 | K14: 2016 | L14: 2015 | M14: 2014 | N14: 2013 | O14: 2012
A15: January | B15: 14.48 | C15: 14.55 | D15: 17.2 | E15: 13.83 | F15: 11.21 | G15: 11.37 | H15: 12.28 | I15: 9.51 | J15: 9.86 | K15: 10.3 | L15: 10.51 | M15: 11.18 | N15: 11.27 | O15: 11.67
A16: February | B16: 14.54 | C16: 14.75 | D16: 16.57 | E16: 13.09 | F16: 10.87 | G16: 11.62 | H16: 11.44 | I16: 11.23 | J16: 11.04 | K16: 9.45 | L16: 9.79 | M16: 11.32 | N16: 10.8 | O16: 11.69
A17: March | B17: 16.12 | C17: 15.46 | D17: 16.08 | E17: 14.15 | F17: 11.53 | G17: 11.93 | H17: 10.86 | I17: 12.09 | J17: 10.81 | K17: 9.64 | L17: 9.34 | M17: 11.78 | N17: 11.41 | O17: 12.99
A18: October | C18: 22.31 | D18: 19.97 | E18: 21.93 | F18: N/A | G18: 16.08 | H18: 16.89 | I18: 17.15 | J18: 17.17 | K18: 14.87 | L18: 14.24 | M18: 15.99 | N18: 16.12 | O18: 15.26
A19: November | C19: 19.61 | D19: 16.28 | E19: 19.28 | F19: 17.29 | G19: 13.67 | H19: 12.45 | I19: 12.18 | J19: 13.07 | K19: 10.95 | L19: 12.26 | M19: 12.27 | N19: 12.27 | O19: 11.35
A20: December | C20: 15.34 | D20: 14.69 | E20: 16.75 | F20: 14.65 | G20: 12.15 | H20: 10.75 | I20: 11.64 | J20: 10.52 | K20: 9.6 | L20: 11.43 | M20: 10.66 | N20: 10.5 | O20: 11.97
A22: Average since 2020-2025 | B22: =AVERAGE(B15:G20) -> 15.292188 | D22: Average 2015-2025 | E22: =AVERAGE(B15:L20) -> 13.591452
A23: Average for 2025 | B23: =average(B15:B17) -> 15.046667 | D23: Average for 2022 | E23: =average(E15:E17) -> 13.69
A25: Monthly Average Price of Propane - Residential, New York - Statewide | E25: Source: EIA via NYSERDA | H25: Prices are in cents per gallon.
B26: 2025 | C26: 2024 | D26: 2023 | E26: 2022 | F26: 2021 | G26: 2020 | H26: 2019 | I26: 2018 | J26: 2017 | K26: 2016 | L26: 2015 | M26: 2014 | N26: 2013 | O26: 2012
A27: January | B27: 346.4 | C27: 342.6 | D27: 347.5 | E27: 334.4 | F27: 278.3 | G27: 287.8 | H27: 296.8 | I27: 310.6 | J27: 263.2 | K27: 231.5 | L27: 272.3 | M27: 335.4 | N27: 273.5 | O27: 309.3
A28: February | B28: 357.6 | C28: 351.3 | D28: 349.7 | E28: 348.7 | F28: 290.1 | G28: 285.7 | H28: 298.1 | I28: 313.6 | J28: 277 | K28: 233.5 | L28: 270.4 | M28: 377.5 | N28: 278.7 | O28: 311.9
A29: March | B29: 356.5 | C29: 348.6 | D29: 346.2 | E29: 372 | F29: 295.8 | G29: 284 | H29: 299.1 | I29: 310.2 | J29: 276.4 | K29: 235.7 | L29: 270.8 | M29: 366.3 | N29: 281.3 | O29: 311.6
A30: October | C30: 318.4 | D30: 327.3 | E30: 350.6 | F30: 322.4 | G30: 249 | H30: 273.1 | I30: 295.8 | J30: 265.5 | K30: 230.7 | L30: 220.9 | M30: 288.5 | N30: 273.2 | O30: 266
A31: November | C31: 326.3 | D31: 316.2 | E31: 351.8 | F31: 329.4 | G31: 255 | H31: 275 | I31: 296.1 | J31: 276.6 | K31: 237.5 | L31: 224.7 | M31: 281 | N31: 286.2 | O31: 268.2
A32: December | C32: 330.1 | D32: 329.3 | E32: 352.7 | F32: 329.3 | G32: 264.1 | H32: 284.8 | I32: 296.4 | J32: 291.6 | K32: 247.9 | L32: 228.9 | M32: 278 | N32: 309.4 | O32: 270.3
A34: Average since 2020-2025 | B34: =AVERAGE(B27:G32) -> 323.48788 | D34: Average 2015-2025 | E34: =AVERAGE(B27:L32) -> 298.09206
A35: Average for 2025 | B35: =average(B27:B29) -> 353.5 | D35: Average for 2022 | E35: =average(E27:E29) -> 351.7

Sheet County information
A1: County | B1: Population | C1: Primary Electrical Utility | D1: Primary Gas Utility | E1: Zone | F1: ccASHP Incentive | G1: GSHP Incentive | H1: HPHW Incentive | I1: Sevice line cost | J1: Design Temp (99% ºF) | K1: ccASHP net yearly savings for zone | L1: GSHP net yearly savings for zone | M1: # of new single family home construction in 2019
A2: Kings County | B2: 2641052 | C2: ConEd | D2: KEDNY | E2: {=INDEX('County zone mapping'!$E$2:$E$63,MATCH(A2,'County zone mapping'!$B$2:$B$63,0))} -> 4 | F2: {=XLOOKUP(C2, 'Utility rebates'!$A$2:$A$8, 'Utility rebates'!$B$2:$B$8)} -> 756.31849 | G2: {=XLOOKUP(C2, 'Utility rebates'!$A$2:$A$8, 'Utility rebates'!$C$2:$C$8)} -> 5000 | H2: {=XLOOKUP(C2, 'Utility rebates'!$A$2:$A$8, 'Utility rebates'!$D$2:$D$8)} -> 1000 | I2: {=XLOOKUP(D2, 'Service line costs'!$A$2:$A$12, 'Service line costs'!$D$2:$D$12)} -> 17020 | J2: {=XLOOKUP(A2,'Design temperatures'!A:A,'Design temperatures'!B:B)} -> 13 | K2: =IFS(EQ(E2,4),'Heat Pump vs Gas/Propane Model (OLD)'!$I$138,EQ(E2,5),'Heat Pump vs Gas/Propane Model (OLD)'!$J$138,EQ(E2,6),'Heat Pump vs Gas/Propane Model (OLD)'!$K$138) -> #REF! | L2: =IFS(EQ(E2,4),'Heat Pump vs Gas/Propane Model (OLD)'!$I$139,EQ(E2,5),'Heat Pump vs Gas/Propane Model (OLD)'!$J$139,EQ(E2,6),'Heat Pump vs Gas/Propane Model (OLD)'!$K$139) -> #REF! | M2: {=INDEX('2019 Building Permits Survey'!$C$2:$C$63,MATCH(A2,'2019 Building Permits Survey'!$A$2:$A$63,0))} -> 0.003718657
A3: Queens County | B3: 2331143 | C3: ConEd | D3: KEDNY | E3: {=INDEX('County zone mapping'!$E$2:$E$63,MATCH(A3,'County zone mapping'!$B$2:$B$63,0))} -> 4 | F3: {=XLOOKUP(C3, 'Utility rebates'!$A$2:$A$8, 'Utility rebates'!$B$2:$B$8)} -> 756.31849 | G3: {=XLOOKUP(C3, 'Utility rebates'!$A$2:$A$8, 'Utility rebates'!$C$2:$C$8)} -> 5000 | H3: {=XLOOKUP(C3, 'Utility rebates'!$A$2:$A$8, 'Utility rebates'!$D$2:$D$8)} -> 1000 | I3: {=XLOOKUP(D3, 'Service line costs'!$A$2:$A$12, 'Service line costs'!$D$2:$D$12)} -> 17020 | J3: {=XLOOKUP(A3,'Design temperatures'!A:A,'Design temperatures'!B:B)} -> 17 | K3: =IFS(EQ(E3,4),'Heat Pump vs Gas/Propane Model (OLD)'!$I$138,EQ(E3,5),'Heat Pump vs Gas/Propane Model (OLD)'!$J$138,EQ(E3,6),'Heat Pump vs Gas/Propane Model (OLD)'!$K$138) -> #REF! | L3: =IFS(EQ(E3,4),'Heat Pump vs Gas/Propane Model (OLD)'!$I$139,EQ(E3,5),'Heat Pump vs Gas/Propane Model (OLD)'!$J$139,EQ(E3,6),'Heat Pump vs Gas/Propane Model (OLD)'!$K$139) -> #REF! | M3: {=INDEX('2019 Building Permits Survey'!$C$2:$C$63,MATCH(A3,'2019 Building Permits Survey'!$A$2:$A$63,0))} -> 0.0099872503
A4: New York County | B4: 1576876 | C4: ConEd | D4: ConEd | E4: {=INDEX('County zone mapping'!$E$2:$E$63,MATCH(A4,'County zone mapping'!$B$2:$B$63,0))} -> 4 | F4: {=XLOOKUP(C4, 'Utility rebates'!$A$2:$A$8, 'Utility rebates'!$B$2:$B$8)} -> 756.31849 | G4: {=XLOOKUP(C4, 'Utility rebates'!$A$2:$A$8, 'Utility rebates'!$C$2:$C$8)} -> 5000 | H4: {=XLOOKUP(C4, 'Utility rebates'!$A$2:$A$8, 'Utility rebates'!$D$2:$D$8)} -> 1000 | I4: {=XLOOKUP(D4, 'Service line costs'!$A$2:$A$12, 'Service line costs'!$D$2:$D$12)} -> 30530 | J4: {=XLOOKUP(A4,'Design temperatures'!A:A,'Design temperatures'!B:B)} -> 13 | K4: =IFS(EQ(E4,4),'Heat Pump vs Gas/Propane Model (OLD)'!$I$138,EQ(E4,5),'Heat Pump vs Gas/Propane Model (OLD)'!$J$138,EQ(E4,6),'Heat Pump vs Gas/Propane Model (OLD)'!$K$138) -> #REF! | L4: =IFS(EQ(E4,4),'Heat Pump vs Gas/Propane Model (OLD)'!$I$139,EQ(E4,5),'Heat Pump vs Gas/Propane Model (OLD)'!$J$139,EQ(E4,6),'Heat Pump vs Gas/Propane Model (OLD)'!$K$139) -> #REF! | M4: {=INDEX('2019 Building Permits Survey'!$C$2:$C$63,MATCH(A4,'2019 Building Permits Survey'!$A$2:$A$63,0))} -> 0.00010624734
A5: Suffolk County | B5: 1526344 | C5: PSEG | D5: KEDLI | E5: {=INDEX('County zone mapping'!$E$2:$E$63,MATCH(A5,'County zone mapping'!$B$2:$B$63,0))} -> 4 | F5: {=XLOOKUP(C5, 'Utility rebates'!$A$2:$A$8, 'Utility rebates'!$B$2:$B$8)} -> 833 | G5: {=XLOOKUP(C5, 'Utility rebates'!$A$2:$A$8, 'Utility rebates'!$C$2:$C$8)} -> 1250 | H5: {=XLOOKUP(C5, 'Utility rebates'!$A$2:$A$8, 'Utility rebates'!$D$2:$D$8)} -> 1200 | I5: {=XLOOKUP(D5, 'Service line costs'!$A$2:$A$12, 'Service line costs'!$D$2:$D$12)} -> 5427 | J5: {=XLOOKUP(A5,'Design temperatures'!A:A,'Design temperatures'!B:B)} -> 10 | K5: =IFS(EQ(E5,4),'Heat Pump vs Gas/Propane Model (OLD)'!$I$138,EQ(E5,5),'Heat Pump vs Gas/Propane Model (OLD)'!$J$138,EQ(E5,6),'Heat Pump vs Gas/Propane Model (OLD)'!$K$138) -> #REF! | L5: =IFS(EQ(E5,4),'Heat Pump vs Gas/Propane Model (OLD)'!$I$139,EQ(E5,5),'Heat Pump vs Gas/Propane Model (OLD)'!$J$139,EQ(E5,6),'Heat Pump vs Gas/Propane Model (OLD)'!$K$139) -> #REF! | M5: {=INDEX('2019 Building Permits Survey'!$C$2:$C$63,MATCH(A5,'2019 Building Permits Survey'!$A$2:$A$63,0))} -> 0.072354441
A6: Bronx County | B6: 1424948 | C6: ConEd | D6: ConEd | E6: {=INDEX('County zone mapping'!$E$2:$E$63,MATCH(A6,'County zone mapping'!$B$2:$B$63,0))} -> 4 | F6: {=XLOOKUP(C6, 'Utility rebates'!$A$2:$A$8, 'Utility rebates'!$B$2:$B$8)} -> 756.31849 | G6: {=XLOOKUP(C6, 'Utility rebates'!$A$2:$A$8, 'Utility rebates'!$C$2:$C$8)} -> 5000 | H6: {=XLOOKUP(C6, 'Utility rebates'!$A$2:$A$8, 'Utility rebates'!$D$2:$D$8)} -> 1000 | I6: {=XLOOKUP(D6, 'Service line costs'!$A$2:$A$12, 'Service line costs'!$D$2:$D$12)} -> 30530 | J6: {=XLOOKUP(A6,'Design temperatures'!A:A,'Design temperatures'!B:B)} -> 17 | K6: =IFS(EQ(E6,4),'Heat Pump vs Gas/Propane Model (OLD)'!$I$138,EQ(E6,5),'Heat Pump vs Gas/Propane Model (OLD)'!$J$138,EQ(E6,6),'Heat Pump vs Gas/Propane Model (OLD)'!$K$138) -> #REF! | L6: =IFS(EQ(E6,4),'Heat Pump vs Gas/Propane Model (OLD)'!$I$139,EQ(E6,5),'Heat Pump vs Gas/Propane Model (OLD)'!$J$139,EQ(E6,6),'Heat Pump vs Gas/Propane Model (OLD)'!$K$139) -> #REF! | M6: {=INDEX('2019 Building Permits Survey'!$C$2:$C$63,MATCH(A6,'2019 Building Permits Survey'!$A$2:$A$63,0))} -> 0.00021249469
A7: Nassau County | B7: 1390907 | C7: PSEG | D7: KEDLI | E7: {=INDEX('County zone mapping'!$E$2:$E$63,MATCH(A7,'County zone mapping'!$B$2:$B$63,0))} -> 4 | F7: {=XLOOKUP(C7, 'Utility rebates'!$A$2:$A$8, 'Utility rebates'!$B$2:$B$8)} -> 833 | G7: {=XLOOKUP(C7, 'Utility rebates'!$A$2:$A$8, 'Utility rebates'!$C$2:$C$8)} -> 1250 | H7: {=XLOOKUP(C7, 'Utility rebates'!$A$2:$A$8, 'Utility rebates'!$D$2:$D$8)} -> 1200 | I7: {=XLOOKUP(D7, 'Service line costs'!$A$2:$A$12, 'Service line costs'!$D$2:$D$12)} -> 5427 | J7: {=XLOOKUP(A7,'Design temperatures'!A:A,'Design temperatures'!B:B)} -> 17 | K7: =IFS(EQ(E7,4),'Heat Pump vs Gas/Propane Model (OLD)'!$I$138,EQ(E7,5),'Heat Pump vs Gas/Propane Model (OLD)'!$J$138,EQ(E7,6),'Heat Pump vs Gas/Propane Model (OLD)'!$K$138) -> #REF! | L7: =IFS(EQ(E7,4),'Heat Pump vs Gas/Propane Model (OLD)'!$I$139,EQ(E7,5),'Heat Pump vs Gas/Propane Model (OLD)'!$J$139,EQ(E7,6),'Heat Pump vs Gas/Propane Model (OLD)'!$K$139) -> #REF! | M7: {=INDEX('2019 Building Permits Survey'!$C$2:$C$63,MATCH(A7,'2019 Building Permits Survey'!$A$2:$A$63,0))} -> 0.078198045
A8: Westchester County | B8: 997895 | C8: ConEd | D8: ConEd | E8: {=INDEX('County zone mapping'!$E$2:$E$63,MATCH(A8,'County zone mapping'!$B$2:$B$63,0))} -> 4 | F8: {=XLOOKUP(C8, 'Utility rebates'!$A$2:$A$8, 'Utility rebates'!$B$2:$B$8)} -> 756.31849 | G8: {=XLOOKUP(C8, 'Utility rebates'!$A$2:$A$8, 'Utility rebates'!$C$2:$C$8)} -> 5000 | H8: {=XLOOKUP(C8, 'Utility rebates'!$A$2:$A$8, 'Utility rebates'!$D$2:$D$8)} -> 1000 | I8: {=XLOOKUP(D8, 'Service line costs'!$A$2:$A$12, 'Service line costs'!$D$2:$D$12)} -> 30530 | J8: {=XLOOKUP(A8,'Design temperatures'!A:A,'Design temperatures'!B:B)} -> 12 | K8: =IFS(EQ(E8,4),'Heat Pump vs Gas/Propane Model (OLD)'!$I$138,EQ(E8,5),'Heat Pump vs Gas/Propane Model (OLD)'!$J$138,EQ(E8,6),'Heat Pump vs Gas/Propane Model (OLD)'!$K$138) -> #REF! | L8: =IFS(EQ(E8,4),'Heat Pump vs Gas/Propane Model (OLD)'!$I$139,EQ(E8,5),'Heat Pump vs Gas/Propane Model (OLD)'!$J$139,EQ(E8,6),'Heat Pump vs Gas/Propane Model (OLD)'!$K$139) -> #REF! | M8: {=INDEX('2019 Building Permits Survey'!$C$2:$C$63,MATCH(A8,'2019 Building Permits Survey'!$A$2:$A$63,0))} -> 0.042180196
A9: Erie County | B9: 950683 | C9: NYSEG | D9: NFG | E9: {=INDEX('County zone mapping'!$E$2:$E$63,MATCH(A9,'County zone mapping'!$B$2:$B$63,0))} -> 5 | F9: {=XLOOKUP(C9, 'Utility rebates'!$A$2:$A$8, 'Utility rebates'!$B$2:$B$8)} -> 1000 | G9: {=XLOOKUP(C9, 'Utility rebates'!$A$2:$A$8, 'Utility rebates'!$C$2:$C$8)} -> 2000 | H9: {=XLOOKUP(C9, 'Utility rebates'!$A$2:$A$8, 'Utility rebates'!$D$2:$D$8)} -> 900 | I9: {=XLOOKUP(D9, 'Service line costs'!$A$2:$A$12, 'Service line costs'!$D$2:$D$12)} -> 1512 | J9: {=XLOOKUP(A9,'Design temperatures'!A:A,'Design temperatures'!B:B)} -> 7 | K9: =IFS(EQ(E9,4),'Heat Pump vs Gas/Propane Model (OLD)'!$I$138,EQ(E9,5),'Heat Pump vs Gas/Propane Model (OLD)'!$J$138,EQ(E9,6),'Heat Pump vs Gas/Propane Model (OLD)'!$K$138) -> #REF! | L9: =IFS(EQ(E9,4),'Heat Pump vs Gas/Propane Model (OLD)'!$I$139,EQ(E9,5),'Heat Pump vs Gas/Propane Model (OLD)'!$J$139,EQ(E9,6),'Heat Pump vs Gas/Propane Model (OLD)'!$K$139) -> #REF! | M9: {=INDEX('2019 Building Permits Survey'!$C$2:$C$63,MATCH(A9,'2019 Building Permits Survey'!$A$2:$A$63,0))} -> 0.080322992
A10: Monroe County | B10: 755160 | C10: RG&E | D10: RG&E | E10: {=INDEX('County zone mapping'!$E$2:$E$63,MATCH(A10,'County zone mapping'!$B$2:$B$63,0))} -> 5 | F10: {=XLOOKUP(C10, 'Utility rebates'!$A$2:$A$8, 'Utility rebates'!$B$2:$B$8)} -> 800 | G10: {=XLOOKUP(C10, 'Utility rebates'!$A$2:$A$8, 'Utility rebates'!$C$2:$C$8)} -> 1500 | H10: {=XLOOKUP(C10, 'Utility rebates'!$A$2:$A$8, 'Utility rebates'!$D$2:$D$8)} -> 900 | I10: {=XLOOKUP(D10, 'Service line costs'!$A$2:$A$12, 'Service line costs'!$D$2:$D$12)} -> 2010 | J10: {=XLOOKUP(A10,'Design temperatures'!A:A,'Design temperatures'!B:B)} -> 6 | K10: =IFS(EQ(E10,4),'Heat Pump vs Gas/Propane Model (OLD)'!$I$138,EQ(E10,5),'Heat Pump vs Gas/Propane Model (OLD)'!$J$138,EQ(E10,6),'Heat Pump vs Gas/Propane Model (OLD)'!$K$138) -> #REF! | L10: =IFS(EQ(E10,4),'Heat Pump vs Gas/Propane Model (OLD)'!$I$139,EQ(E10,5),'Heat Pump vs Gas/Propane Model (OLD)'!$J$139,EQ(E10,6),'Heat Pump vs Gas/Propane Model (OLD)'!$K$139) -> #REF! | M10: {=INDEX('2019 Building Permits Survey'!$C$2:$C$63,MATCH(A10,'2019 Building Permits Survey'!$A$2:$A$63,0))} -> 0.066617085
A11: Richmond County | B11: 493494 | C11: ConEd | D11: KEDNY | E11: {=INDEX('County zone mapping'!$E$2:$E$63,MATCH(A11,'County zone mapping'!$B$2:$B$63,0))} -> 4 | F11: {=XLOOKUP(C11, 'Utility rebates'!$A$2:$A$8, 'Utility rebates'!$B$2:$B$8)} -> 756.31849 | G11: {=XLOOKUP(C11, 'Utility rebates'!$A$2:$A$8, 'Utility rebates'!$C$2:$C$8)} -> 5000 | H11: {=XLOOKUP(C11, 'Utility rebates'!$A$2:$A$8, 'Utility rebates'!$D$2:$D$8)} -> 1000 | I11: {=XLOOKUP(D11, 'Service line costs'!$A$2:$A$12, 'Service line costs'!$D$2:$D$12)} -> 17020 | J11: {=XLOOKUP(A11,'Design temperatures'!A:A,'Design temperatures'!B:B)} -> 17 | K11: =IFS(EQ(E11,4),'Heat Pump vs Gas/Propane Model (OLD)'!$I$138,EQ(E11,5),'Heat Pump vs Gas/Propane Model (OLD)'!$J$138,EQ(E11,6),'Heat Pump vs Gas/Propane Model (OLD)'!$K$138) -> #REF! | L11: =IFS(EQ(E11,4),'Heat Pump vs Gas/Propane Model (OLD)'!$I$139,EQ(E11,5),'Heat Pump vs Gas/Propane Model (OLD)'!$J$139,EQ(E11,6),'Heat Pump vs Gas/Propane Model (OLD)'!$K$139) -> #REF! | M11: {=INDEX('2019 Building Permits Survey'!$C$2:$C$63,MATCH(A11,'2019 Building Permits Survey'!$A$2:$A$63,0))} -> 0.021249469
A12: Onondaga County | B12: 473236 | C12: National Grid | D12: NiMo | E12: {=INDEX('County zone mapping'!$E$2:$E$63,MATCH(A12,'County zone mapping'!$B$2:$B$63,0))} -> 5 | F12: {=XLOOKUP(C12, 'Utility rebates'!$A$2:$A$8, 'Utility rebates'!$B$2:$B$8)} -> 1200 | G12: {=XLOOKUP(C12, 'Utility rebates'!$A$2:$A$8, 'Utility rebates'!$C$2:$C$8)} -> 2500 | H12: {=XLOOKUP(C12, 'Utility rebates'!$A$2:$A$8, 'Utility rebates'!$D$2:$D$8)} -> 1000 | I12: {=XLOOKUP(D12, 'Service line costs'!$A$2:$A$12, 'Service line costs'!$D$2:$D$12)} -> 3922 | J12: {=XLOOKUP(A12,'Design temperatures'!A:A,'Design temperatures'!B:B)} -> 3 | K12: =IFS(EQ(E12,4),'Heat Pump vs Gas/Propane Model (OLD)'!$I$138,EQ(E12,5),'Heat Pump vs Gas/Propane Model (OLD)'!$J$138,EQ(E12,6),'Heat Pump vs Gas/Propane Model (OLD)'!$K$138) -> #REF! | L12: =IFS(EQ(E12,4),'Heat Pump vs Gas/Propane Model (OLD)'!$I$139,EQ(E12,5),'Heat Pump vs Gas/Propane Model (OLD)'!$J$139,EQ(E12,6),'Heat Pump vs Gas/Propane Model (OLD)'!$K$139) -> #REF! | M12: {=INDEX('2019 Building Permits Survey'!$C$2:$C$63,MATCH(A12,'2019 Building Permits Survey'!$A$2:$A$63,0))} -> 0.034317892
A13: Orange County | B13: 404525 | C13: ConEd O&R | D13: O&R | E13: {=INDEX('County zone mapping'!$E$2:$E$63,MATCH(A13,'County zone mapping'!$B$2:$B$63,0))} -> 5 | F13: {=XLOOKUP(C13, 'Utility rebates'!$A$2:$A$8, 'Utility rebates'!$B$2:$B$8)} -> 700 | G13: {=XLOOKUP(C13, 'Utility rebates'!$A$2:$A$8, 'Utility rebates'!$C$2:$C$8)} -> 2000 | H13: {=XLOOKUP(C13, 'Utility rebates'!$A$2:$A$8, 'Utility rebates'!$D$2:$D$8)} -> 1000 | I13: {=XLOOKUP(D13, 'Service line costs'!$A$2:$A$12, 'Service line costs'!$D$2:$D$12)} -> 3835 | J13: {=XLOOKUP(A13,'Design temperatures'!A:A,'Design temperatures'!B:B)} -> 9 | K13: =IFS(EQ(E13,4),'Heat Pump vs Gas/Propane Model (OLD)'!$I$138,EQ(E13,5),'Heat Pump vs Gas/Propane Model (OLD)'!$J$138,EQ(E13,6),'Heat Pump vs Gas/Propane Model (OLD)'!$K$138) -> #REF! | L13: =IFS(EQ(E13,4),'Heat Pump vs Gas/Propane Model (OLD)'!$I$139,EQ(E13,5),'Heat Pump vs Gas/Propane Model (OLD)'!$J$139,EQ(E13,6),'Heat Pump vs Gas/Propane Model (OLD)'!$K$139) -> #REF! | M13: {=INDEX('2019 Building Permits Survey'!$C$2:$C$63,MATCH(A13,'2019 Building Permits Survey'!$A$2:$A$63,0))} -> 0.05439864
... A56: Orleans County | B56: 40191 | C56: National Grid | D56: NYSEG | E56: {=INDEX('County zone mapping'!$E$2:$E$63,MATCH(A56,'County zone mapping'!$B$2:$B$63,0))} -> 5 | F56: {=XLOOKUP(C56, 'Utility rebates'!$A$2:$A$8, 'Utility rebates'!$B$2:$B$8)} -> 1200 | G56: {=XLOOKUP(C56, 'Utility rebates'!$A$2:$A$8, 'Utility rebates'!$C$2:$C$8)} -> 2500 | H56: {=XLOOKUP(C56, 'Utility rebates'!$A$2:$A$8, 'Utility rebates'!$D$2:$D$8)} -> 1000 | I56: {=XLOOKUP(D56, 'Service line costs'!$A$2:$A$12, 'Service line costs'!$D$2:$D$12)} -> 8722 | J56: {=XLOOKUP(A56,'Design temperatures'!A:A,'Design temperatures'!B:B)} -> 5 | K56: =IFS(EQ(E56,4),'Heat Pump vs Gas/Propane Model (OLD)'!$I$138,EQ(E56,5),'Heat Pump vs Gas/Propane Model (OLD)'!$J$138,EQ(E56,6),'Heat Pump vs Gas/Propane Model (OLD)'!$K$138) -> #REF! | L56: =IFS(EQ(E56,4),'Heat Pump vs Gas/Propane Model (OLD)'!$I$139,EQ(E56,5),'Heat Pump vs Gas/Propane Model (OLD)'!$J$139,EQ(E56,6),'Heat Pump vs Gas/Propane Model (OLD)'!$K$139) -> #REF! | M56: {=INDEX('2019 Building Permits Survey'!$C$2:$C$63,MATCH(A56,'2019 Building Permits Survey'!$A$2:$A$63,0))} -> 0.0020186995
A57: Essex County | B57: 37268 | C57: National Grid | D57: - | E57: {=INDEX('County zone mapping'!$E$2:$E$63,MATCH(A57,'County zone mapping'!$B$2:$B$63,0))} -> 6 | F57: {=XLOOKUP(C57, 'Utility rebates'!$A$2:$A$8, 'Utility rebates'!$B$2:$B$8)} -> 1200 | G57: {=XLOOKUP(C57, 'Utility rebates'!$A$2:$A$8, 'Utility rebates'!$C$2:$C$8)} -> 2500 | H57: {=XLOOKUP(C57, 'Utility rebates'!$A$2:$A$8, 'Utility rebates'!$D$2:$D$8)} -> 1000 | J57: {=XLOOKUP(A57,'Design temperatures'!A:A,'Design temperatures'!B:B)} -> -11 | K57: =IFS(EQ(E57,4),'Heat Pump vs Gas/Propane Model (OLD)'!$I$138,EQ(E57,5),'Heat Pump vs Gas/Propane Model (OLD)'!$J$138,EQ(E57,6),'Heat Pump vs Gas/Propane Model (OLD)'!$K$138) -> #REF! | L57: =IFS(EQ(E57,4),'Heat Pump vs Gas/Propane Model (OLD)'!$I$139,EQ(E57,5),'Heat Pump vs Gas/Propane Model (OLD)'!$J$139,EQ(E57,6),'Heat Pump vs Gas/Propane Model (OLD)'!$K$139) -> #REF! | M57: {=INDEX('2019 Building Permits Survey'!$C$2:$C$63,MATCH(A57,'2019 Building Permits Survey'!$A$2:$A$63,0))} -> 0.011262218
A58: Seneca County | B58: 33688 | C58: NYSEG | D58: NYSEG | E58: {=INDEX('County zone mapping'!$E$2:$E$63,MATCH(A58,'County zone mapping'!$B$2:$B$63,0))} -> 5 | F58: {=XLOOKUP(C58, 'Utility rebates'!$A$2:$A$8, 'Utility rebates'!$B$2:$B$8)} -> 1000 | G58: {=XLOOKUP(C58, 'Utility rebates'!$A$2:$A$8, 'Utility rebates'!$C$2:$C$8)} -> 2000 | H58: {=XLOOKUP(C58, 'Utility rebates'!$A$2:$A$8, 'Utility rebates'!$D$2:$D$8)} -> 900 | I58: {=XLOOKUP(D58, 'Service line costs'!$A$2:$A$12, 'Service line costs'!$D$2:$D$12)} -> 8722 | J58: {=XLOOKUP(A58,'Design temperatures'!A:A,'Design temperatures'!B:B)} -> 2 | K58: =IFS(EQ(E58,4),'Heat Pump vs Gas/Propane Model (OLD)'!$I$138,EQ(E58,5),'Heat Pump vs Gas/Propane Model (OLD)'!$J$138,EQ(E58,6),'Heat Pump vs Gas/Propane Model (OLD)'!$K$138) -> #REF! | L58: =IFS(EQ(E58,4),'Heat Pump vs Gas/Propane Model (OLD)'!$I$139,EQ(E58,5),'Heat Pump vs Gas/Propane Model (OLD)'!$J$139,EQ(E58,6),'Heat Pump vs Gas/Propane Model (OLD)'!$K$139) -> #REF! | M58: {=INDEX('2019 Building Permits Survey'!$C$2:$C$63,MATCH(A58,'2019 Building Permits Survey'!$A$2:$A$63,0))} -> 0.0050998725
A59: Schoharie County | B59: 29863 | C59: National Grid | D59: NYSEG | E59: {=INDEX('County zone mapping'!$E$2:$E$63,MATCH(A59,'County zone mapping'!$B$2:$B$63,0))} -> 6 | F59: {=XLOOKUP(C59, 'Utility rebates'!$A$2:$A$8, 'Utility rebates'!$B$2:$B$8)} -> 1200 | G59: {=XLOOKUP(C59, 'Utility rebates'!$A$2:$A$8, 'Utility rebates'!$C$2:$C$8)} -> 2500 | H59: {=XLOOKUP(C59, 'Utility rebates'!$A$2:$A$8, 'Utility rebates'!$D$2:$D$8)} -> 1000 | I59: {=XLOOKUP(D59, 'Service line costs'!$A$2:$A$12, 'Service line costs'!$D$2:$D$12)} -> 8722 | J59: {=XLOOKUP(A59,'Design temperatures'!A:A,'Design temperatures'!B:B)} -> -2 | K59: =IFS(EQ(E59,4),'Heat Pump vs Gas/Propane Model (OLD)'!$I$138,EQ(E59,5),'Heat Pump vs Gas/Propane Model (OLD)'!$J$138,EQ(E59,6),'Heat Pump vs Gas/Propane Model (OLD)'!$K$138) -> #REF! | L59: =IFS(EQ(E59,4),'Heat Pump vs Gas/Propane Model (OLD)'!$I$139,EQ(E59,5),'Heat Pump vs Gas/Propane Model (OLD)'!$J$139,EQ(E59,6),'Heat Pump vs Gas/Propane Model (OLD)'!$K$139) -> #REF! | M59: {=INDEX('2019 Building Permits Survey'!$C$2:$C$63,MATCH(A59,'2019 Building Permits Survey'!$A$2:$A$63,0))} -> 0.0028686783
A60: Lewis County | B60: 26573 | C60: National Grid | D60: St. Lawrence | E60: {=INDEX('County zone mapping'!$E$2:$E$63,MATCH(A60,'County zone mapping'!$B$2:$B$63,0))} -> 6 | F60: {=XLOOKUP(C60, 'Utility rebates'!$A$2:$A$8, 'Utility rebates'!$B$2:$B$8)} -> 1200 | G60: {=XLOOKUP(C60, 'Utility rebates'!$A$2:$A$8, 'Utility rebates'!$C$2:$C$8)} -> 2500 | H60: {=XLOOKUP(C60, 'Utility rebates'!$A$2:$A$8, 'Utility rebates'!$D$2:$D$8)} -> 1000 | I60: {=XLOOKUP(D60, 'Service line costs'!$A$2:$A$12, 'Service line costs'!$D$2:$D$12)} -> 8900 | J60: {=XLOOKUP(A60,'Design temperatures'!A:A,'Design temperatures'!B:B)} -> 0 | K60: =IFS(EQ(E60,4),'Heat Pump vs Gas/Propane Model (OLD)'!$I$138,EQ(E60,5),'Heat Pump vs Gas/Propane Model (OLD)'!$J$138,EQ(E60,6),'Heat Pump vs Gas/Propane Model (OLD)'!$K$138) -> #REF! | L60: =IFS(EQ(E60,4),'Heat Pump vs Gas/Propane Model (OLD)'!$I$139,EQ(E60,5),'Heat Pump vs Gas/Propane Model (OLD)'!$J$139,EQ(E60,6),'Heat Pump vs Gas/Propane Model (OLD)'!$K$139) -> #REF! | M60: {=INDEX('2019 Building Permits Survey'!$C$2:$C$63,MATCH(A60,'2019 Building Permits Survey'!$A$2:$A$63,0))} -> 0.0053123672
A61: Yates County | B61: 24613 | C61: NYSEG | D61: NiMo | E61: {=INDEX('County zone mapping'!$E$2:$E$63,MATCH(A61,'County zone mapping'!$B$2:$B$63,0))} -> 5 | F61: {=XLOOKUP(C61, 'Utility rebates'!$A$2:$A$8, 'Utility rebates'!$B$2:$B$8)} -> 1000 | G61: {=XLOOKUP(C61, 'Utility rebates'!$A$2:$A$8, 'Utility rebates'!$C$2:$C$8)} -> 2000 | H61: {=XLOOKUP(C61, 'Utility rebates'!$A$2:$A$8, 'Utility rebates'!$D$2:$D$8)} -> 900 | I61: {=XLOOKUP(D61, 'Service line costs'!$A$2:$A$12, 'Service line costs'!$D$2:$D$12)} -> 3922 | J61: {=XLOOKUP(A61,'Design temperatures'!A:A,'Design temperatures'!B:B)} -> 7 | K61: =IFS(EQ(E61,4),'Heat Pump vs Gas/Propane Model (OLD)'!$I$138,EQ(E61,5),'Heat Pump vs Gas/Propane Model (OLD)'!$J$138,EQ(E61,6),'Heat Pump vs Gas/Propane Model (OLD)'!$K$138) -> #REF! | L61: =IFS(EQ(E61,4),'Heat Pump vs Gas/Propane Model (OLD)'!$I$139,EQ(E61,5),'Heat Pump vs Gas/Propane Model (OLD)'!$J$139,EQ(E61,6),'Heat Pump vs Gas/Propane Model (OLD)'!$K$139) -> #REF! | M61: {=INDEX('2019 Building Permits Survey'!$C$2:$C$63,MATCH(A61,'2019 Building Permits Survey'!$A$2:$A$63,0))} -> 0.0090310242
A62: Schuyler County | B62: 17752 | C62: NYSEG | D62: NYSEG | E62: {=INDEX('County zone mapping'!$E$2:$E$63,MATCH(A62,'County zone mapping'!$B$2:$B$63,0))} -> 6 | F62: {=XLOOKUP(C62, 'Utility rebates'!$A$2:$A$8, 'Utility rebates'!$B$2:$B$8)} -> 1000 | G62: {=XLOOKUP(C62, 'Utility rebates'!$A$2:$A$8, 'Utility rebates'!$C$2:$C$8)} -> 2000 | H62: {=XLOOKUP(C62, 'Utility rebates'!$A$2:$A$8, 'Utility rebates'!$D$2:$D$8)} -> 900 | I62: {=XLOOKUP(D62, 'Service line costs'!$A$2:$A$12, 'Service line costs'!$D$2:$D$12)} -> 8722 | J62: {=XLOOKUP(A62,'Design temperatures'!A:A,'Design temperatures'!B:B)} -> 7 | K62: =IFS(EQ(E62,4),'Heat Pump vs Gas/Propane Model (OLD)'!$I$138,EQ(E62,5),'Heat Pump vs Gas/Propane Model (OLD)'!$J$138,EQ(E62,6),'Heat Pump vs Gas/Propane Model (OLD)'!$K$138) -> #REF! | L62: =IFS(EQ(E62,4),'Heat Pump vs Gas/Propane Model (OLD)'!$I$139,EQ(E62,5),'Heat Pump vs Gas/Propane Model (OLD)'!$J$139,EQ(E62,6),'Heat Pump vs Gas/Propane Model (OLD)'!$K$139) -> #REF! | M62: {=INDEX('2019 Building Permits Survey'!$C$2:$C$63,MATCH(A62,'2019 Building Permits Survey'!$A$2:$A$63,0))} -> 0.0050998725
A63: Hamilton County | B63: 5119 | C63: National Grid | D63: - | E63: {=INDEX('County zone mapping'!$E$2:$E$63,MATCH(A63,'County zone mapping'!$B$2:$B$63,0))} -> 6 | F63: {=XLOOKUP(C63, 'Utility rebates'!$A$2:$A$8, 'Utility rebates'!$B$2:$B$8)} -> 1200 | G63: {=XLOOKUP(C63, 'Utility rebates'!$A$2:$A$8, 'Utility rebates'!$C$2:$C$8)} -> 2500 | H63: {=XLOOKUP(C63, 'Utility rebates'!$A$2:$A$8, 'Utility rebates'!$D$2:$D$8)} -> 1000 | J63: {=XLOOKUP(A63,'Design temperatures'!A:A,'Design temperatures'!B:B)} -> -2 | K63: =IFS(EQ(E63,4),'Heat Pump vs Gas/Propane Model (OLD)'!$I$138,EQ(E63,5),'Heat Pump vs Gas/Propane Model (OLD)'!$J$138,EQ(E63,6),'Heat Pump vs Gas/Propane Model (OLD)'!$K$138) -> #REF! | L63: =IFS(EQ(E63,4),'Heat Pump vs Gas/Propane Model (OLD)'!$I$139,EQ(E63,5),'Heat Pump vs Gas/Propane Model (OLD)'!$J$139,EQ(E63,6),'Heat Pump vs Gas/Propane Model (OLD)'!$K$139) -> #REF! | M63: {=INDEX('2019 Building Permits Survey'!$C$2:$C$63,MATCH(A63,'2019 Building Permits Survey'!$A$2:$A$63,0))} -> 0.0044623884
A66: Zone 4 | F66: {=SUM(IFS(EQ($E$2:$E$63,4),F$2:F$63,TRUE,0) * $M$2:$M$63)/SUM(IFS(EQ($E$2:$E$63,4),$M$2:$M$63,TRUE,0))} -> 806.95116 | G66: {=SUM(IFS(EQ($E$2:$E$63,4),G$2:G$63,TRUE,0) * $M$2:$M$63)/SUM(IFS(EQ($E$2:$E$63,4),$M$2:$M$63,TRUE,0))} -> 2523.8816 | H66: {=SUM(IFS(EQ($E$2:$E$63,4),H$2:H$63,TRUE,0) * $M$2:$M$63)/SUM(IFS(EQ($E$2:$E$63,4),$M$2:$M$63,TRUE,0))} -> 1132.0596 | I66: {=SUM(IFS(EQ($E$2:$E$63,4),I$2:I$63,TRUE,0) * $M$2:$M$63)/SUM(IFS(EQ($E$2:$E$63,4),$M$2:$M$63,TRUE,0))} -> 11883.336 | J66: {=SUM(IFS(EQ($E$2:$E$63,4),J$2:J$63,TRUE,0) * $M$2:$M$63)/SUM(IFS(EQ($E$2:$E$63,4),$M$2:$M$63,TRUE,0))} -> 13.78658 | M66: {=SUM(IFS(EQ($E$2:$E$63,4),M$2:M$63,TRUE,0))} -> 0.2280068
A67: Zone 5 | F67: {=SUM(IFS(EQ($E$2:$E$63,5),$F$2:$F$63,TRUE,0) * $M$2:$M$63)/SUM(IFS(EQ($E$2:$E$63,5),$M$2:$M$63,TRUE,0))} -> 964.34524 | G67: {=SUM(IFS(EQ($E$2:$E$63,5),$G$2:$G$63,TRUE,0) * $M$2:$M$63)/SUM(IFS(EQ($E$2:$E$63,5),$M$2:$M$63,TRUE,0))} -> 2094.7421 | H67: {=SUM(IFS(EQ($E$2:$E$63,5),$H$2:$H$63,TRUE,0) * $M$2:$M$63)/SUM(IFS(EQ($E$2:$E$63,5),$M$2:$M$63,TRUE,0))} -> 959.16667 | I67: {=SUM(IFS(EQ($E$2:$E$63,5),I$2:I$63,TRUE,0) * $M$2:$M$63)/SUM(IFS(EQ($E$2:$E$63,5),$M$2:$M$63,TRUE,0))} -> 4261.7796 | J67: {=SUM(IFS(EQ($E$2:$E$63,5),J$2:J$63,TRUE,0) * $M$2:$M$63)/SUM(IFS(EQ($E$2:$E$63,5),$M$2:$M$63,TRUE,0))} -> 4.4876984 | M67: {=SUM(IFS(EQ($E$2:$E$63,5),M$2:M$63,TRUE,0))} -> 0.53548661
A68: Zone 6 | F68: {=SUM(IFS(EQ($E$2:$E$63,6),$F$2:$F$63,TRUE,0) * $M$2:$M$63)/SUM(IFS(EQ($E$2:$E$63,6),$M$2:$M$63,TRUE,0))} -> 1045.9119 | G68: {=SUM(IFS(EQ($E$2:$E$63,6),$G$2:$G$63,TRUE,0) * $M$2:$M$63)/SUM(IFS(EQ($E$2:$E$63,6),$M$2:$M$63,TRUE,0))} -> 2220.3504 | H68: {=SUM(IFS(EQ($E$2:$E$63,6),$H$2:$H$63,TRUE,0) * $M$2:$M$63)/SUM(IFS(EQ($E$2:$E$63,6),$M$2:$M$63,TRUE,0))} -> 958.62534 | I68: {=SUM((($E$2:$E$63=6)*(I$2:I$63<>"")) * I$2:I$63 * $M$2:$M$63)/SUM((($E$2:$E$63=6)*(I$2:I$63<>"")) * $M$2:$M$63)} -> 6401.6641 | J68: {=SUM(IFS(EQ($E$2:$E$63,6),J$2:J$63,TRUE,0) * $M$2:$M$63)/SUM(IFS(EQ($E$2:$E$63,6),$M$2:$M$63,TRUE,0))} -> -1.6752022 | M68: {=SUM(IFS(EQ($E$2:$E$63,6),M$2:M$63,TRUE,0))} -> 0.23650659

Sheet Design temperatures
A1: County | B1: 99% Heating Temperature (ºF)
A2: Albany County | B2: 1
A3: Allegany County | B3: 3
A4: Bronx County | B4: 17
A5: Broome County | B5: 4
A6: Cattaraugus County | B6: 2
A7: Cayuga County | B7: 2
A8: Chautauqua County | B8: 3
A9: Chemung County | B9: 3
A10: Chenango County | B10: 4
A11: Clinton County | B11: -5
A12: Columbia County | B12: -3
A13: Cortland County | B13: 0
... A63: Yates County | B63: 7

Sheet 2019 Building Permits Survey
A1: County | B1: Imputed 1-unit new construction | C1: Percent of new construction
A2: Albany County | B2: 235 | C2: =B2/SUM($B$2:$B$63) -> 0.024968126
A3: Allegany County | B3: 50 | C3: =B3/SUM($B$2:$B$63) -> 0.0053123672
A4: Bronx County | B4: 2 | C4: =B4/SUM($B$2:$B$63) -> 0.00021249469
A5: Broome County | B5: 38 | C5: =B5/SUM($B$2:$B$63) -> 0.0040373991
A6: Cattaraugus County | B6: 79 | C6: =B6/SUM($B$2:$B$63) -> 0.0083935402
A7: Cayuga County | B7: 120 | C7: =B7/SUM($B$2:$B$63) -> 0.012749681
A8: Chautauqua County | B8: 105 | C8: =B8/SUM($B$2:$B$63) -> 0.011155971
A9: Chemung County | B9: 24 | C9: =B9/SUM($B$2:$B$63) -> 0.0025499363
A10: Chenango County | B10: 35 | C10: =B10/SUM($B$2:$B$63) -> 0.003718657
A11: Clinton County | B11: 80 | C11: =B11/SUM($B$2:$B$63) -> 0.0084997875
A12: Columbia County | B12: 73 | C12: =B12/SUM($B$2:$B$63) -> 0.0077560561
A13: Cortland County | B13: 24 | C13: =B13/SUM($B$2:$B$63) -> 0.0025499363
... A63: Yates County | B63: 85 | C63: =B63/SUM($B$2:$B$63) -> 0.0090310242

Sheet County zone mapping
A1: County Name | B1: Full County Name | C1: Main NYISO Zone | D1: CLCPA PATHWAYS Regions | E1: NYSERDA Climate Zones
A2: Albany | B2: =A2&" County" -> Albany County | C2: F | D2: Upstate NY F | E2: 5
A3: Allegany | B3: =A3&" County" -> Allegany County | C3: B | D3: Upstate NY A-E | E3: 6
A4: Bronx | B4: =A4&" County" -> Bronx County | C4: J | D4: Downstate NY - New York City | E4: 4
A5: Broome | B5: =A5&" County" -> Broome County | C5: C | D5: Upstate NY A-E | E5: 6
A6: Cattaraugus | B6: =A6&" County" -> Cattaraugus County | C6: A | D6: Upstate NY A-E | E6: 6
A7: Cayuga | B7: =A7&" County" -> Cayuga County | C7: C | D7: Upstate NY A-E | E7: 5
A8: Chautauqua | B8: =A8&" County" -> Chautauqua County | C8: A | D8: Upstate NY A-E | E8: 5
A9: Chemung | B9: =A9&" County" -> Chemung County | C9: C | D9: Upstate NY A-E | E9: 5
A10: Chenango | B10: =A10&" County" -> Chenango County | C10: E | D10: Upstate NY A-E | E10: 6
A11: Clinton | B11: =A11&" County" -> Clinton County | C11: D | D11: Upstate NY A-E | E11: 6
A12: Columbia | B12: =A12&" County" -> Columbia County | C12: F | D12: Upstate NY F | E12: 5
A13: Cortland | B13: =A13&" County" -> Cortland County | C13: C | D13: Upstate NY A-E | E13: 5
... A63: Yates | B63: =A63&" County" -> Yates County | C63: C | D63: Upstate NY A-E | E63: 5

Sheet Heating type by zone
C1: Primary Heating System Type
A2: Climate Zone | B2: Primary Fuel Type | C2: Furnace, ducts | D2: Boiler, radiator | E2: Air source heat pump | F2: Ground source heat pump | G2: Baseboard heat | H2: Fireplace + Stove | I2: Unknown | J2: Grand Total
A3: 4 | B3: Don’t know | C3: 1 | E3: 0 | H3: 0 | I3: 0 | J3: 1
B4: Electricity | C4: 1 | E4: 1 | H4: 0 | I4: 0 | J4: 2
B5: Fuel oil | C5: 1 | E5: 0 | H5: 0 | I5: 0 | J5: 1
B6: Natural gas from underground pipes | C6: 18 | D6: 7 | E6: 0 | H6: 0 | I6: 1 | J6: 26
B7: Propane (bottled gas) | C7: 1 | E7: 0 | H7: 0 | I7: 0 | J7: 1
B8: Total | C8: 22 | D8: 7 | E8: 1 | H8: 0 | I8: 1 | J8: 31
A11: 5 | B11: Don’t know | C11: 2 | D11: 0 | E11: 0 | H11: 0 | I11: 0 | J11: 2
B12: Electricity | C12: 24 | E12: 9 | F12: 15 | G12: 2 | H12: 0 | I12: 0 | J12: 50
B13: Fuel oil | C13: 1 | D13: 1 | E13: 0 | H13: 0 | I13: 0 | J13: 2
B14: Natural gas from underground pipes | C14: 252 | D14: 7 | E14: 0 | H14: 1 | I14: 1 | J14: 261
B15: Propane (bottled gas) | C15: 57 | D15: 13 | E15: 0 | H15: 0 | I15: 2 | J15: 72
B16: Solar | C16: 2 | D16: 1 | E16: 0 | H16: 0 | I16: 1 | J16: 4
B17: Wood | C17: 1 | E17: 0 | H17: 1 | I17: 0 | J17: 2
B18: Wood pellets | C18: 2 | E18: 0 | H18: 0 | I18: 0 | J18: 2
B19: Other (specify) | C19: 0 | E19: 0 | H19: 0 | I19: 0 | J19: 0
B20: Total | C20: 341 | D20: 22 | E20: 9 | F20: 15 | G20: 2 | H20: 2 | I20: 4 | J20: 395
A23: 6 | B23: Don’t know | D23: 0 | E23: 0 | H23: 0 | I23: 0 | J23: 0
B24: Electricity | C24: 2 | E24: 4 | F24: 8 | G24: 7 | H24: 0 | I24: 0 | J24: 21
B25: Fuel oil | C25: 2 | D25: 2 | E25: 0 | H25: 0 | I25: 1 | J25: 5
B26: Natural gas from underground pipes | C26: 23 | D26: 4 | E26: 0 | H26: 0 | I26: 1 | J26: 28
B27: Propane (bottled gas) | C27: 29 | D27: 22 | E27: 0 | H27: 0 | I27: 4 | J27: 55
B28: Wood | C28: 1 | D28: 1 | E28: 0 | H28: 1 | I28: 0 | J28: 3
B29: Wood pellets | E29: 0 | H29: 3 | I29: 0 | J29: 3
B30: Total | C30: 57 | D30: 29 | E30: 4 | F30: 8 | G30: 7 | H30: 4 | I30: 6 | J30: 115
B32: Grand Total | C32: 420 | D32: 58 | E32: 14 | F32: 23 | G32: 9 | H32: 6 | I32: 11 | J32: 541
B36: Zone 4 Counts | C36: Zone 4 Percent | D36: Zone 5 Counts | E36: Zone 5 Percent | F36: Zone 6 Counts | G36: Zone 6 Percent
A37: Furnace + Gas | B37: =C6 -> 18 | C37: =B37/$B$45 -> 0.58064516 | D37: =C14 -> 252 | E37: =D37/$D$45 -> 0.63797468 | F37: =C26 -> 23 | G37: =F37/$F$45 -> 0.2
A38: Furnace + Propane or Oil | B38: =C7+C5 -> 2 | C38: =B38/$B$45 -> 0.064516129 | D38: =C13+C15 -> 58 | E38: =D38/$D$45 -> 0.14683544 | F38: =C27+C25 -> 31 | G38: =F38/$F$45 -> 0.26956522 | H38: ='Heat Pump vs Gas/Propane Model (OLD)'!W203 -> #REF! | I38: ='GSHP vs Furnace'!R166 -> #REF!
A39: Boiler + Gas | B39: =D6 -> 7 | C39: =B39/$B$45 -> 0.22580645 | D39: =D14 -> 7 | E39: =D39/$D$45 -> 0.017721519 | F39: =D26 -> 4 | G39: =F39/$F$45 -> 0.034782609 | H39: ='ASHP vs Boiler'!R166 -> #REF! | I39: ='GSHP vs Boiler'!R166 -> #REF!
A40: Boiler + Propane or Oil | B40: =D5+D7 -> 0 | C40: =B40/$B$45 -> 0 | D40: =D15+D13 -> 14 | E40: =D40/$D$45 -> 0.035443038 | F40: =D27+D25 -> 24 | G40: =F40/$F$45 -> 0.20869565 | H40: ='ASHP vs Boiler'!M166 -> #REF! | I40: ='GSHP vs Boiler'!M166 -> #REF!
A41: Heat Pump | B41: =E8+F8 -> 1 | C41: =B41/$B$45 -> 0.032258065 | D41: =E20+F20 -> 24 | E41: =D41/$D$45 -> 0.060759494 | F41: =E30+F30 -> 12 | G41: =F41/$F$45 -> 0.10434783
A42: Electric resistance | B42: =G8+C4 -> 1 | C42: =B42/$B$45 -> 0.032258065 | D42: =C12+G12 -> 26 | E42: =D42/$D$45 -> 0.065822785 | F42: =C24+G24 -> 9 | G42: =F42/$F$45 -> 0.07826087
A43: Biomass | B43: =H8 -> 0 | C43: =B43/$B$45 -> 0 | D43: =H20+C17+C18 -> 5 | E43: =D43/$D$45 -> 0.012658228 | F43: =H30+C28+D28 -> 6 | G43: =F43/$F$45 -> 0.052173913
A44: Other | B44: =I8+C3 -> 2 | C44: =B44/$B$45 -> 0.064516129 | D44: =C11+C19+C16+D16+I20 -> 9 | E44: =D44/$D$45 -> 0.02278481 | F44: =I30 -> 6 | G44: =F44/$F$45 -> 0.052173913
A45: TOTAL | B45: =SUM(B37:B44) -> 31 | C45: =B45/$B$45 -> 1 | D45: =SUM(D37:D44) -> 395 | E45: =D45/$D$45 -> 1 | F45: =SUM(F37:F44) -> 115 | G45: =F45/$F$45 -> 1
A46: TOTAL: Fossil Fuel Furnace + Boilers | B46: =sum(B37:B40) -> 27 | C46: =B46/$B$45 -> 0.87096774 | D46: =sum(D37:D40) -> 331 | E46: =D46/$D$45 -> 0.83797468 | F46: =sum(F37:F40) -> 82 | G46: =F46/$F$45 -> 0.71304348

Sheet Propane - Zone 5
B2: Heat Pump vs Propane Model
B3: Win Climate 2022
E5: Citations | G5: Values | H5: Unit | J5: Notes
B6: Building
C7: Average sq. ft. | E7: https://www.census.gov/construction/nrc/pdf/quarterly_starts_completions.pdf | G7: 2534 | H7: ft^2 | J7: Northeast median size for 2021
C8: Heating BTU / sq ft @ zone 5 | E8: https://learnmetrics.com/heating-btu-calculator/ | G8: 50 | H8: btu/ft^2
C9: Total Heating BTU | G9: =G7*G8 -> 126700 | H9: btu
C10: Cooling BTU / sq ft @ zone 5 | E10: https://learnmetrics.com/how-many-btu-air-conditioner-do-i-need-air-conditioner/ | G10: 30 | H10: btu/ft^2
C11: Total cooling BTU | G11: =G10*G7 -> 76020 | H11: btu
B13: Central Air - Propane Furnace | E13: https://www.nahb.org/blog/2021/09/which-heating-and-cooling-systems-are-most-common-for-new-homes/#:~:text=Based%20on%20information%20from%20the,rise%20from%2085.5%25%20in%202000.
C14: New construction installation cost | E14: https://5estimates.com/central-ac-replacement-cost-in-new-york-ny/#:~:text=1%2C000%20square%20feet%20can%20range,averages%20between%20%246%2C000%20and%20%2410%2C000 | G14: 3085 | J14: If average new house in NYS is 1750 square feet, then this cost is much lower
C15: Installation cost | J15: Disregard because it's a marginal cost
C16: Yearly kWh needed | G16: 322 | J16: https://www.eia.gov/analysis/studies/buildings/equipcosts/pdf/full.pdf
C17: Gallons | G17: =G16/27 -> 11.925926
C18: $ / gallon | G18: 2.678 | J18: {Use highest price of 2022}
C19: Yearly maintenance cost
C20: Total yearly spend | G20: =G16*G18 -> 862.316
B22: AC Unit (assuming ducts)
C23: New construction installation cost | G23: 4726
C24: Yearly kWh needed
C25: $ / kWh
C26: Yearly maintenance cost
C27: Total yearly spend
B29: Water Heater - Propane | J29: jpvelez@gmail.com
C30: New construction unit cost (per Avg sq. ft. or Heating BTU) | G30: 3093 | J30: Should include water heater
C31: Water tank
C32: Installation cost | J32: Disregard because it's a marginal cost
C33: Yearly fuel gallons needed | E33: https://propanedeal.com/states/propane-new-york-ny | G33: 243 | J33: {Look at Census or HUD}
C34: $ / gallon | E34: https://www.nyserda.ny.gov/researchers-and-policymakers/energy-prices/propane/monthly-average-propane-prices | G34: 3.466 | J34: {Use highest price of 2022}
C35: Yearly maintenance cost
C36: Total yearly spend | G36: =G33*G34 -> 842.238
B38: Central Air - Heat pump
C39: New construction installation cost | E39: https://www.homeblue.com/heat-pump/new-york-ny-heat-pump-cost.htm | G39: 14678 | J39: I'm seeing costs way less...
C40: Installation cost | J40: Disregard because it's a marginal cost
C41: IRA tax credit
C42: State rebate
C43: Yearly kWh needed | G43: 1500
C44: $ / kWh | G44: 0.24
C45: Yearly maintenance cost
C46: Total yearly spend | G46: =G43*G44 -> 360
...

Sheet Sheet4
A1: Propane - boiler
A2: Natural gas - boiler

Sheet Natural Gas - Zone 5
B2: Heat Pump vs Propane Model
B3: Win Climate 2022
E5: Citations | G5: Values | H5: Unit | J5: Notes
B6: Building
C7: Average sq. ft. | E7: https://www.census.gov/construction/nrc/pdf/quarterly_starts_completions.pdf | G7: 2534 | H7: ft^2 | J7: Northeast median size for 2021
C8: Heating BTU / sq ft @ zone 5 | E8: https://learnmetrics.com/heating-btu-calculator/ | G8: 50 | H8: btu/ft^2
C9: Total Heating BTU | G9: =G7*G8 -> 126700 | H9: btu
C10: Cooling BTU / sq ft @ zone 5 | E10: https://learnmetrics.com/how-many-btu-air-conditioner-do-i-need-air-conditioner/ | G10: 30 | H10: btu/ft^2
C11: Total cooling BTU | G11: =G10*G7 -> 76020 | H11: btu
B13: Central air - Natural Gas Furnace | E13: https://www.nahb.org/blog/2021/09/which-heating-and-cooling-systems-are-most-common-for-new-homes/#:~:text=Based%20on%20information%20from%20the,rise%20from%2085.5%25%20in%202000.
C14: New construction installation cost | E14: https://5estimates.com/central-ac-replacement-cost-in-new-york-ny/#:~:text=1%2C000%20square%20feet%20can%20range,averages%20between%20%246%2C000%20and%20%2410%2C000 | G14: 3085 | J14: If average new house in NYS is 1750 square feet, then this cost is much lower
C15: Installation cost | J15: Disregard because it's a marginal cost
C16: Yearly kWh needed | E16: page 14 https://www.eia.gov/analysis/studies/buildings/equipcosts/pdf/full.pdf | G16: 322
C17: $ / kWh | E17: https://ycharts.com/indicators/us_residential_propane_price | G17: 3.019 | J17: {Use highest price of 2022}
C18: Yearly maintenance cost
C19: Total yearly spend | G19: =G16*G17 -> 972.118
B21: AC Unit (assuming ducts)
C22: New construction installation cost | G22: 4726
C23: Yearly kBTU needed | E23: page 30 https://www.eia.gov/analysis/studies/buildings/equipcosts/pdf/full.pdf
C24: $ / kWh
C25: Yearly maintenance cost
C26: Total yearly spend
B28: Water Heater - Natural Gas
C29: New construction unit cost (per Avg sq. ft. or Heating BTU) | G29: 3093 | J29: Should include water heater
C30: Water tank
C31: Installation cost | J31: Disregard because it's a marginal cost
C32: Yearly fuel gallons needed | E32: https://propanedeal.com/states/propane-new-york-ny | G32: 243 | J32: {Look at Census or HUD}
C33: $ / gallon | E33: https://www.nyserda.ny.gov/researchers-and-policymakers/energy-prices/propane/monthly-average-propane-prices | G33: 3.466 | J33: {Use highest price of 2022}
C34: Yearly maintenance cost
C35: Total yearly spend
B37: Central Air - Heat pump
C38: New construction installation cost | E38: https://www.homeblue.com/heat-pump/new-york-ny-heat-pump-cost.htm | G38: 14678 | J38: I'm seeing costs way less...
C39: Installation cost | J39: Disregard because it's a marginal cost
C40: IRA tax credit* | J40: See if this applies to new contruction
C41: State rebate
C42: Yearly kWh needed | G42: 10000
C43: $ / kWh | G43: 0.24
C44: Yearly maintenance cost
C45: Total yearly spend | G45: =G42*G43 -> 2400
B47: Water Heater - heat pump
...

Sheet Amit
